Workbook

Sheet Cover
E8: Test Report
C11: Project Name: | E11: DỰ ÁN TRIỂN KHAI BẢN QUYỀN PHẦN MỀM HỆ THỐNG AML MỚI | G11: Reviewer:
C12: Document Code: | E12: MSB_AML_Testcase_TM_Report | G12: Position:
C13: Originator: | G13: Reviewed Date:
C14: Position: | G14: Approver:
C15: Created Date: | E15: 46300 | G15: Position:
C16: Version: | E16: 1.0 | G16: Approved Date:

Sheet Records
A1: TABLE OF CONTENT
A3: No | B3: Items | C3: Content | H3: Note
A4: 1 | B4: Cover | C4: Cover
A5: 2 | B5: Records | C5: Record of changes
A6: 3 | B6: Test Report | C6: Tổng hợp kết quả thực thi test
A7: 4 | B7: Report | C7: Tổng hợp kết quả theo báo cáo
A8: 5 | B8: Report_TM_01 | C8: Test case Báo cáo thống kê số lượng báo cáo giao dịch đáng ngờ đã tạo
A9: 6 | B9: Report_TM_02 | C9: Test case Báo cáo đánh giá hiệu quả của kịch bản quét sàng lọc giao dịch của khách hàng
A10: 7 | B10: Report_TM_03 | C10: Test case Báo cáo các cảnh báo chưa được xử lý
A11: 8 | B11: Report_TM_04 | C11: Test case Báo cáo khách hàng phát sinh cảnh báo theo từng kịch bản
A15: Effective Date | B15: A, M, D | C15: Change Description | F15: New Version | G15: Author
A16: 46300 | B16: A | C16: Create new TC – 4 báo cáo TM theo Phụ lục 4 v1.4 | F16: 1

Sheet Test Report
B2: SYSTEM TEST REPORT
A5: Project | B5: DỰ ÁN TRIỂN KHAI BẢN QUYỀN PHẦN MỀM HỆ THỐNG AML MỚI | D5: Project manager
A6: Application | D6: Approved Date
A7: Consolidated By | D7: Reviewed By
A8: Build Versions | D8: Reviewed date
A9: Test Environment | B9: SIT
A10: Last Updated Date
A11: Test Execution Summary
A12: Reported by
A13: Date
A14: Test Results | B14: Passed | C14: Failed | D14: Accepted | E14: N/A | F14: Untested | G14: Total
A15: Tổng cộng | B15: =SUM(B16:B19) | C15: =SUM(C16:C19) | D15: =SUM(D16:D19) | E15: =SUM(E16:E19) | F15: =SUM(F16:F19) | G15: =SUM(B15:F15)
A16: Report_TM_01 | B16: =COUNTIF(Report_TM_01!J:J,"Passed") | C16: =COUNTIF(Report_TM_01!J:J,"Failed") | D16: =COUNTIF(Report_TM_01!J:J,"Accepted") | E16: =COUNTIF(Report_TM_01!J:J,"N/A") | F16: =COUNTIF(Report_TM_01!J:J,"Untested") | G16: =SUM(B16:F16)
A17: Report_TM_02 | B17: =COUNTIF(Report_TM_02!J:J,"Passed") | C17: =COUNTIF(Report_TM_02!J:J,"Failed") | D17: =COUNTIF(Report_TM_02!J:J,"Accepted") | E17: =COUNTIF(Report_TM_02!J:J,"N/A") | F17: =COUNTIF(Report_TM_02!J:J,"Untested") | G17: =SUM(B17:F17)
A18: Report_TM_03 | B18: =COUNTIF(Report_TM_03!J:J,"Passed") | C18: =COUNTIF(Report_TM_03!J:J,"Failed") | D18: =COUNTIF(Report_TM_03!J:J,"Accepted") | E18: =COUNTIF(Report_TM_03!J:J,"N/A") | F18: =COUNTIF(Report_TM_03!J:J,"Untested") | G18: =SUM(B18:F18)
A19: Report_TM_04 | B19: =COUNTIF(Report_TM_04!J:J,"Passed") | C19: =COUNTIF(Report_TM_04!J:J,"Failed") | D19: =COUNTIF(Report_TM_04!J:J,"Accepted") | E19: =COUNTIF(Report_TM_04!J:J,"N/A") | F19: =COUNTIF(Report_TM_04!J:J,"Untested") | G19: =SUM(B19:F19)
A25: Test coverage
A26: Test coverage | G26: =IFERROR(SUM(B15,C15,E15)/G15,0)
A27: Test successful coverage | G27: =IFERROR(SUM(B15,E15)/G15,0)
A28: Issues
A29: 1. Block testing issue
A30: 2. Critical defects
A35: BÁO CÁO | B35: Pass | C35: Fail | D35: Pending | E35: Cancel | F35: Untested | G35: Next | H35: TỔNG
A36: Report_TM_01 | B36: =COUNTIF(Report_TM_01!$K:$K,'Test Report'!B$35) | C36: =COUNTIF(Report_TM_01!$K:$K,'Test Report'!C$35) | D36: =COUNTIF(Report_TM_01!$K:$K,'Test Report'!D$35) | E36: =COUNTIF(Report_TM_01!$K:$K,'Test Report'!E$35) | F36: =COUNTIF(Report_TM_01!$K:$K,'Test Report'!F$35) | G36: =COUNTIF(Report_TM_01!$K:$K,'Test Report'!G$35) | H36: =SUM(B36:G36)
A37: Report_TM_02 | B37: =COUNTIF(Report_TM_02!$K:$K,'Test Report'!B$35) | C37: =COUNTIF(Report_TM_02!$K:$K,'Test Report'!C$35) | D37: =COUNTIF(Report_TM_02!$K:$K,'Test Report'!D$35) | E37: =COUNTIF(Report_TM_02!$K:$K,'Test Report'!E$35) | F37: =COUNTIF(Report_TM_02!$K:$K,'Test Report'!F$35) | G37: =COUNTIF(Report_TM_02!$K:$K,'Test Report'!G$35) | H37: =SUM(B37:G37)
A38: Report_TM_03 | B38: =COUNTIF(Report_TM_03!$K:$K,'Test Report'!B$35) | C38: =COUNTIF(Report_TM_03!$K:$K,'Test Report'!C$35) | D38: =COUNTIF(Report_TM_03!$K:$K,'Test Report'!D$35) | E38: =COUNTIF(Report_TM_03!$K:$K,'Test Report'!E$35) | F38: =COUNTIF(Report_TM_03!$K:$K,'Test Report'!F$35) | G38: =COUNTIF(Report_TM_03!$K:$K,'Test Report'!G$35) | H38: =SUM(B38:G38)
A39: Report_TM_04 | B39: =COUNTIF(Report_TM_04!$K:$K,'Test Report'!B$35) | C39: =COUNTIF(Report_TM_04!$K:$K,'Test Report'!C$35) | D39: =COUNTIF(Report_TM_04!$K:$K,'Test Report'!D$35) | E39: =COUNTIF(Report_TM_04!$K:$K,'Test Report'!E$35) | F39: =COUNTIF(Report_TM_04!$K:$K,'Test Report'!F$35) | G39: =COUNTIF(Report_TM_04!$K:$K,'Test Report'!G$35) | H39: =SUM(B39:G39)
A40: Tổng cộng | B40: =SUM(B36:B39) | C40: =SUM(C36:C39) | D40: =SUM(D36:D39) | E40: =SUM(E36:E39) | F40: =SUM(F36:F39) | G40: =SUM(G36:G39) | H40: =SUM(B40:G40)
B41: =IFERROR(B40/$H$40,0) | C41: =IFERROR(C40/$H$40,0) | D41: =IFERROR(D40/$H$40,0) | E41: =IFERROR(E40/$H$40,0) | F41: =IFERROR(F40/$H$40,0) | G41: =IFERROR(G40/$H$40,0)

Sheet Report
A1: BÁO CÁO | B1: Passed | C1: Failed | D1: Pending | E1: Cancel | F1: Untested | G1: Next | H1: TỔNG
A2: Report_TM_01 | B2: =Report_TM_01!E7 | C2: =Report_TM_01!E8 | D2: =Report_TM_01!E9 | E2: =Report_TM_01!E10 | F2: =Report_TM_01!E11 | G2: =Report_TM_01!E12 | H2: =SUM(B2:G2)
A3: Report_TM_02 | B3: =Report_TM_02!E7 | C3: =Report_TM_02!E8 | D3: =Report_TM_02!E9 | E3: =Report_TM_02!E10 | F3: =Report_TM_02!E11 | G3: =Report_TM_02!E12 | H3: =SUM(B3:G3)
A4: Report_TM_03 | B4: =Report_TM_03!E7 | C4: =Report_TM_03!E8 | D4: =Report_TM_03!E9 | E4: =Report_TM_03!E10 | F4: =Report_TM_03!E11 | G4: =Report_TM_03!E12 | H4: =SUM(B4:G4)
A5: Report_TM_04 | B5: =Report_TM_04!E7 | C5: =Report_TM_04!E8 | D5: =Report_TM_04!E9 | E5: =Report_TM_04!E10 | F5: =Report_TM_04!E11 | G5: =Report_TM_04!E12 | H5: =SUM(B5:G5)
A6: Tổng cộng | B6: =SUM(B2:B5) | C6: =SUM(C2:C5) | D6: =SUM(D2:D5) | E6: =SUM(E2:E5) | F6: =SUM(F2:F5) | G6: =SUM(G2:G5) | H6: =SUM(B6:G6)
B7: =IFERROR(B6/$H$6,0) | C7: =IFERROR(C6/$H$6,0) | D7: =IFERROR(D6/$H$6,0) | E7: =IFERROR(E6/$H$6,0) | F7: =IFERROR(F6/$H$6,0) | G7: =IFERROR(G6/$H$6,0)
A20: Passed
A21: Failed
A22: Pending
A23: Cancel
A24: Untested
A25: Next

Sheet Report_TM_01
A1: Functions | B1: =Cover!E11
A2: Build Version | B2: v1.0
A3: Report TM_01 – Báo cáo thống kê số lượng báo cáo giao dịch đáng ngờ đã tạo
A4: ROUND 2
B5: High | C5: Medium | D5: Low | E5: Total
B6: =SUM(B7:B11) | C6: =SUM(C7:C11) | D6: =SUM(D7:D11) | E6: =SUM(B6:D6)
A7: Passed | B7: =COUNTIFS($H:$H,B$5,$K:$K,$A7) | C7: =COUNTIFS($H:$H,C$5,$K:$K,$A7) | D7: =COUNTIFS($H:$H,D$5,$K:$K,$A7) | E7: =SUM(B7:D7)
A8: Failed | B8: =COUNTIFS($H:$H,B$5,$K:$K,$A8) | C8: =COUNTIFS($H:$H,C$5,$K:$K,$A8) | D8: =COUNTIFS($H:$H,D$5,$K:$K,$A8) | E8: =SUM(B8:D8)
A9: Pending | B9: =COUNTIFS($H:$H,B$5,$K:$K,$A9) | C9: =COUNTIFS($H:$H,C$5,$K:$K,$A9) | D9: =COUNTIFS($H:$H,D$5,$K:$K,$A9) | E9: =SUM(B9:D9)
A10: Cancel | B10: =COUNTIFS($H:$H,B$5,$K:$K,$A10) | C10: =COUNTIFS($H:$H,C$5,$K:$K,$A10) | D10: =COUNTIFS($H:$H,D$5,$K:$K,$A10) | E10: =SUM(B10:D10)
A11: Untested | B11: =COUNTIFS($H:$H,B$5,$K:$K,$A11) | C11: =COUNTIFS($H:$H,C$5,$K:$K,$A11) | D11: =COUNTIFS($H:$H,D$5,$K:$K,$A11) | E11: =SUM(B11:D11)
A12: Next | B12: =COUNTIFS($H:$H,B$5,$K:$K,$A12) | C12: =COUNTIFS($H:$H,C$5,$K:$K,$A12) | D12: =COUNTIFS($H:$H,D$5,$K:$K,$A12) | E12: =SUM(B12:D12)
A14: ROUND 3
B15: High | C15: Medium | D15: Low | E15: Total
B16: =SUM(B17:B21) | C16: =SUM(C17:C21) | D16: =SUM(D17:D21) | E16: =SUM(B16:D16)
A17: Passed | B17: =COUNTIFS($H:$H,B$15,$L:$L,$A17) | C17: =COUNTIFS($H:$H,C$15,$L:$L,$A17) | D17: =COUNTIFS($H:$H,D$15,$L:$L,$A17) | E17: =SUM(B17:D17)
A18: Failed | B18: =COUNTIFS($H:$H,B$15,$L:$L,$A18) | C18: =COUNTIFS($H:$H,C$15,$L:$L,$A18) | D18: =COUNTIFS($H:$H,D$15,$L:$L,$A18) | E18: =SUM(B18:D18)
A19: Pending | B19: =COUNTIFS($H:$H,B$15,$L:$L,$A19) | C19: =COUNTIFS($H:$H,C$15,$L:$L,$A19) | D19: =COUNTIFS($H:$H,D$15,$L:$L,$A19) | E19: =SUM(B19:D19)
A20: Cancel | B20: =COUNTIFS($H:$H,B$15,$L:$L,$A20) | C20: =COUNTIFS($H:$H,C$15,$L:$L,$A20) | D20: =COUNTIFS($H:$H,D$15,$L:$L,$A20) | E20: =SUM(B20:D20)
A21: Untested | B21: =COUNTIFS($H:$H,B$15,$L:$L,$A21) | C21: =COUNTIFS($H:$H,C$15,$L:$L,$A21) | D21: =COUNTIFS($H:$H,D$15,$L:$L,$A21) | E21: =SUM(B21:D21)
A22: Next | B22: =COUNTIFS($H:$H,B$15,$L:$L,$A22) | C22: =COUNTIFS($H:$H,C$15,$L:$L,$A22) | D22: =COUNTIFS($H:$H,D$15,$L:$L,$A22) | E22: =SUM(B22:D22)
A25: Test case Id | B25: Test case Title | C25: Pre-conditions | D25: Test Step | E25: Test Datas | F25: Expected result | G25: Test Environment | H25: Priority | I25: Automation Status | J25: 1st Test Results | K25: 2nd Test Results | L25: 3rd Test Results | M25: BugID | N25: Notes
A26: NHÓM FUNCTION (Risk High)
A27: — Hiển thị & nút chức năng
A28: MSB_TM-RP_TC_001 | B28: Kiểm tra hiển thị thành công kết quả báo cáo TM_01 đủ 5 cột khi nhập đủ tham số hợp lệ | C28: - User: Đăng nhập tm_aml_maker (AML Maker – HO, HO0000001) - Màn hình: trang chủ Oracle Analytics Server (OAS) môi trường SIT, chưa mở báo cáo - Dữ liệu: bộ dữ liệu D-TM01 (mục 3.2 file rollup) đã dựng và batch dữ liệu báo cáo đã chạy; kỳ 05/2026 có 13 case R1-HN-01 đến R1-HN-11, R1-HCM-01, R1-HCM-02 | D28: 1. Mở báo cáo "Báo cáo thống kê số lượng báo cáo giao dịch đáng ngờ đã tạo" (Report TM_01) trên OAS 2. Nhập tham số: Từ = 05/2026; Đến = 05/2026; Đơn vị = VN0010001 – CN Hà Nội, VN0010002 – CN Hồ Chí Minh 3. Nhấn nút Apply 4. Đối chiếu bảng kết quả với bảng kỳ vọng ở Test Data | E28: - Tham số: Từ = 05/2026; Đến = 05/2026; Đơn vị = VN0010001 – CN Hà Nội, VN0010002 – CN Hồ Chí Minh - Kỳ vọng: 4 dòng như Expected Result, lấy từ bộ D-TM01 | F28: 1. Báo cáo mở, hiển thị vùng tham số cùng nút Apply và Reset 2. Các tham số hiển thị đúng giá trị đã nhập 3. Báo cáo chạy xong, không hiển thị thông báo lỗi 4. Báo cáo có 5 cột Đơn vị, Thời gian, Nguồn tạo STR, Tổng số lượng báo cáo STR (chưa duyệt), Tổng số lượng báo cáo STR (đã duyệt) và đúng 4 dòng (Đơn vị | Thời gian | Nguồn | Chưa duyệt | Đã duyệt): + VN0010001 | 05/2026 | Tự động | 4 | 1 + VN0010001 | 05/2026 | Thủ công | 1 | 1 + VN0010002 | 05/2026 | Tự động | 0 | 1 + VN0010002 | 05/2026 | Thủ công | 1 | 0 | G28: SIT | H28: High | I28: Manual | J28: Untested | K28: Untested | L28: Untested
A29: MSB_TM-RP_TC_002 | B29: Kiểm tra chạy lại báo cáo thành công bằng nút Apply khi đổi tham số Đơn vị sau lần chạy đầu | C29: - User: Đăng nhập tm_aml_maker (AML Maker – HO, HO0000001) - Màn hình: trang chủ Oracle Analytics Server (OAS) môi trường SIT, chưa mở báo cáo - Dữ liệu: bộ dữ liệu D-TM01 (mục 3.2 file rollup) đã dựng và batch dữ liệu báo cáo đã chạy | D29: 1. Mở báo cáo "Báo cáo thống kê số lượng báo cáo giao dịch đáng ngờ đã tạo" (Report TM_01) trên OAS 2. Nhập tham số: Từ = 05/2026; Đến = 05/2026; Đơn vị = VN0010001 – CN Hà Nội, VN0010002 – CN Hồ Chí Minh 3. Nhấn nút Apply 4. Bỏ chọn VN0010002 trong tham số Đơn vị, giữ VN0010001 5. Nhấn nút Apply lần 2 | E29: - Tham số: Từ = 05/2026; Đến = 05/2026; Đơn vị = VN0010001 – CN Hà Nội, VN0010002 – CN Hồ Chí Minh - Lần 2: Đơn vị = VN0010001 – CN Hà Nội | F29: 1. Báo cáo mở, hiển thị vùng tham số cùng nút Apply và Reset 2. Các tham số hiển thị đúng giá trị đã nhập 3. Báo cáo chạy xong, không hiển thị thông báo lỗi 4. Tham số Đơn vị chỉ còn VN0010001 5. Báo cáo cập nhật, chỉ còn 2 dòng của VN0010001 (Tự động 4 | 1; Thủ công 1 | 1), không còn dòng VN0010002 | G29: SIT | H29: Medium | I29: Manual | J29: Untested | K29: Untested | L29: Untested
A30: — Logic số liệu
A31: MSB_TM-RP_TC_003 | B31: Kiểm tra đếm đúng cột STR (chưa duyệt) với case ở 4 trạng thái chờ duyệt STR | C31: - User: Đăng nhập tm_aml_maker (AML Maker – HO, HO0000001) - Màn hình: trang chủ Oracle Analytics Server (OAS) môi trường SIT, chưa mở báo cáo - Dữ liệu: bộ dữ liệu D-TM01 (mục 3.2 file rollup) đã dựng và batch dữ liệu báo cáo đã chạy; nguồn Tự động của VN0010001 kỳ 05/2026 có R1-HN-01 (Pending Checker Review STR), R1-HN-02 (Pending Supervisor Review), R1-HN-03 (Pending AML Maker), R1-HN-04 (Pending AML Checker review) | D31: 1. Mở báo cáo "Báo cáo thống kê số lượng báo cáo giao dịch đáng ngờ đã tạo" (Report TM_01) trên OAS 2. Nhập tham số: Từ = 05/2026; Đến = 05/2026; Đơn vị = VN0010001 – CN Hà Nội 3. Nhấn nút Apply 4. Xem giá trị cột Tổng số lượng báo cáo STR (chưa duyệt) tại dòng VN0010001 | 05/2026 | Tự động | E31: - Tham số: Từ = 05/2026; Đến = 05/2026; Đơn vị = VN0010001 – CN Hà Nội - Case: R1-HN-01, R1-HN-02, R1-HN-03, R1-HN-04 | F31: 1. Báo cáo mở, hiển thị vùng tham số cùng nút Apply và Reset 2. Các tham số hiển thị đúng giá trị đã nhập 3. Báo cáo chạy xong, không hiển thị thông báo lỗi 4. Giá trị = 4 (đủ 4 case R1-HN-01 đến R1-HN-04) | G31: SIT | H31: High | I31: Manual | J31: Untested | K31: Untested | L31: Untested | N31: Trạng thái 'Pending AML Maker review' trong Phụ lục 4 hiểu là 'Pending AML Maker' của BRD (Q4)
A32: MSB_TM-RP_TC_004 | B32: Kiểm tra đếm đúng cột STR (đã duyệt) chỉ với case ở trạng thái Approved STR | C32: - User: Đăng nhập tm_aml_maker (AML Maker – HO, HO0000001) - Màn hình: trang chủ Oracle Analytics Server (OAS) môi trường SIT, chưa mở báo cáo - Dữ liệu: bộ dữ liệu D-TM01 (mục 3.2 file rollup) đã dựng và batch dữ liệu báo cáo đã chạy; VN0010001 kỳ 05/2026 có R1-HN-05 (Tự động, Approved STR) và R1-HN-07 (Thủ công, Approved STR) | D32: 1. Mở báo cáo "Báo cáo thống kê số lượng báo cáo giao dịch đáng ngờ đã tạo" (Report TM_01) trên OAS 2. Nhập tham số: Từ = 05/2026; Đến = 05/2026; Đơn vị = VN0010001 – CN Hà Nội 3. Nhấn nút Apply 4. Xem cột Tổng số lượng báo cáo STR (đã duyệt) của 2 dòng VN0010001 | 05/2026 | E32: - Tham số: Từ = 05/2026; Đến = 05/2026; Đơn vị = VN0010001 – CN Hà Nội - Case: R1-HN-05, R1-HN-07 | F32: 1. Báo cáo mở, hiển thị vùng tham số cùng nút Apply và Reset 2. Các tham số hiển thị đúng giá trị đã nhập 3. Báo cáo chạy xong, không hiển thị thông báo lỗi 4. Dòng Tự động = 1 (R1-HN-05); dòng Thủ công = 1 (R1-HN-07) | G32: SIT | H32: High | I32: Manual | J32: Untested | K32: Untested | L32: Untested
A33: MSB_TM-RP_TC_005 | B33: Kiểm tra loại trừ thành công case Rejected sending STR và Closed - Not Send STR khỏi cả 2 cột số lượng STR | C33: - User: Đăng nhập tm_aml_maker (AML Maker – HO, HO0000001) - Màn hình: trang chủ Oracle Analytics Server (OAS) môi trường SIT, chưa mở báo cáo - Dữ liệu: bộ dữ liệu D-TM01 (mục 3.2 file rollup) đã dựng và batch dữ liệu báo cáo đã chạy; VN0010001 kỳ 05/2026 có thêm R1-HN-08 (STR tạo 18/05/2026, Rejected sending STR) và R1-HN-09 (STR tạo 19/05/2026, Closed - Not Send STR) | D33: 1. Mở báo cáo "Báo cáo thống kê số lượng báo cáo giao dịch đáng ngờ đã tạo" (Report TM_01) trên OAS 2. Nhập tham số: Từ = 05/2026; Đến = 05/2026; Đơn vị = VN0010001 – CN Hà Nội 3. Nhấn nút Apply 4. Xem 2 cột số lượng STR của dòng VN0010001 | 05/2026 | Tự động | E33: - Tham số: Từ = 05/2026; Đến = 05/2026; Đơn vị = VN0010001 – CN Hà Nội - Case: R1-HN-08, R1-HN-09 | F33: 1. Báo cáo mở, hiển thị vùng tham số cùng nút Apply và Reset 2. Các tham số hiển thị đúng giá trị đã nhập 3. Báo cáo chạy xong, không hiển thị thông báo lỗi 4. Chưa duyệt = 4 và Đã duyệt = 1; R1-HN-08, R1-HN-09 không được đếm vào cột nào | G33: SIT | H33: High | I33: Manual | J33: Untested | K33: Untested | L33: Untested | N33: Q4
A34: MSB_TM-RP_TC_006 | B34: Kiểm tra loại trừ thành công case Pending Generate STR chưa tạo STR khỏi báo cáo | C34: - User: Đăng nhập tm_aml_maker (AML Maker – HO, HO0000001) - Màn hình: trang chủ Oracle Analytics Server (OAS) môi trường SIT, chưa mở báo cáo - Dữ liệu: bộ dữ liệu D-TM01 (mục 3.2 file rollup) đã dựng và batch dữ liệu báo cáo đã chạy; R1-HN-10 (case tự động tạo 21/05/2026, VN0010001) đang Pending Generate STR, chưa Save STR | D34: 1. Mở báo cáo "Báo cáo thống kê số lượng báo cáo giao dịch đáng ngờ đã tạo" (Report TM_01) trên OAS 2. Nhập tham số: Từ = 05/2026; Đến = 05/2026; Đơn vị = VN0010001 – CN Hà Nội 3. Nhấn nút Apply 4. Xem cột Tổng số lượng báo cáo STR (chưa duyệt) của dòng VN0010001 | 05/2026 | Tự động | E34: - Tham số: Từ = 05/2026; Đến = 05/2026; Đơn vị = VN0010001 – CN Hà Nội - Case: R1-HN-10 | F34: 1. Báo cáo mở, hiển thị vùng tham số cùng nút Apply và Reset 2. Các tham số hiển thị đúng giá trị đã nhập 3. Báo cáo chạy xong, không hiển thị thông báo lỗi 4. Giá trị = 4, không tính R1-HN-10 | G34: SIT | H34: High | I34: Manual | J34: Untested | K34: Untested | L34: Untested
A35: MSB_TM-RP_TC_007 | B35: Kiểm tra loại trừ case Pending Maker bị trả về sau khi đã tạo STR khỏi cột STR (chưa duyệt) | C35: - User: Đăng nhập tm_aml_maker (AML Maker – HO, HO0000001) - Màn hình: trang chủ Oracle Analytics Server (OAS) môi trường SIT, chưa mở báo cáo - Dữ liệu: bộ dữ liệu D-TM01 (mục 3.2 file rollup) đã dựng và batch dữ liệu báo cáo đã chạy; R1-HN-11 (VN0010001, STR tạo 16/05/2026) bị DVKH Checker yêu cầu bổ sung tại bước Pending Checker Review STR, hiện ở trạng thái Pending Maker | D35: 1. Mở báo cáo "Báo cáo thống kê số lượng báo cáo giao dịch đáng ngờ đã tạo" (Report TM_01) trên OAS 2. Nhập tham số: Từ = 05/2026; Đến = 05/2026; Đơn vị = VN0010001 – CN Hà Nội 3. Nhấn nút Apply 4. Xem cột Tổng số lượng báo cáo STR (chưa duyệt) của dòng VN0010001 | 05/2026 | Tự động | E35: - Tham số: Từ = 05/2026; Đến = 05/2026; Đơn vị = VN0010001 – CN Hà Nội - Case: R1-HN-11 | F35: 1. Báo cáo mở, hiển thị vùng tham số cùng nút Apply và Reset 2. Các tham số hiển thị đúng giá trị đã nhập 3. Báo cáo chạy xong, không hiển thị thông báo lỗi 4. Giá trị = 4, không tính R1-HN-11 | G35: SIT | H35: Medium | I35: Manual | J35: Untested | K35: Untested | L35: Untested | N35: Q4
A36: MSB_TM-RP_TC_008 | B36: Kiểm tra xác định đúng Nguồn tạo STR = Tự động với case sinh từ kịch bản | C36: - User: Đăng nhập tm_aml_maker (AML Maker – HO, HO0000001) - Màn hình: trang chủ Oracle Analytics Server (OAS) môi trường SIT, chưa mở báo cáo - Dữ liệu: bộ dữ liệu D-TM01 (mục 3.2 file rollup) đã dựng và batch dữ liệu báo cáo đã chạy; R1-HN-01 đến R1-HN-05 là case hệ thống sinh từ kịch bản AML-01 | D36: 1. Mở báo cáo "Báo cáo thống kê số lượng báo cáo giao dịch đáng ngờ đã tạo" (Report TM_01) trên OAS 2. Nhập tham số: Từ = 05/2026; Đến = 05/2026; Đơn vị = VN0010001 – CN Hà Nội 3. Nhấn nút Apply 4. Xem cột Nguồn tạo STR của dòng có Chưa duyệt = 4 | E36: - Tham số: Từ = 05/2026; Đến = 05/2026; Đơn vị = VN0010001 – CN Hà Nội - Case: R1-HN-01 đến R1-HN-05 (case type của case tự động) | F36: 1. Báo cáo mở, hiển thị vùng tham số cùng nút Apply và Reset 2. Các tham số hiển thị đúng giá trị đã nhập 3. Báo cáo chạy xong, không hiển thị thông báo lỗi 4. Nguồn tạo STR = Tự động | G36: SIT | H36: High | I36: Manual | J36: Untested | K36: Untested | L36: Untested | N36: Q3
A37: MSB_TM-RP_TC_009 | B37: Kiểm tra xác định đúng Nguồn tạo STR = Thủ công với case Type AML_MN do DVKH Maker tạo | C37: - User: Đăng nhập tm_aml_maker (AML Maker – HO, HO0000001) - Màn hình: trang chủ Oracle Analytics Server (OAS) môi trường SIT, chưa mở báo cáo - Dữ liệu: bộ dữ liệu D-TM01 (mục 3.2 file rollup) đã dựng và batch dữ liệu báo cáo đã chạy; R1-HN-06 (Pending Checker Review STR) và R1-HN-07 (Approved STR) là case thủ công Type = AML_MN do tm_dvkh_maker_hn tạo | D37: 1. Mở báo cáo "Báo cáo thống kê số lượng báo cáo giao dịch đáng ngờ đã tạo" (Report TM_01) trên OAS 2. Nhập tham số: Từ = 05/2026; Đến = 05/2026; Đơn vị = VN0010001 – CN Hà Nội 3. Nhấn nút Apply 4. Xem dòng VN0010001 | 05/2026 có Nguồn tạo STR = Thủ công | E37: - Tham số: Từ = 05/2026; Đến = 05/2026; Đơn vị = VN0010001 – CN Hà Nội - Case: R1-HN-06, R1-HN-07 (Type = AML_MN) | F37: 1. Báo cáo mở, hiển thị vùng tham số cùng nút Apply và Reset 2. Các tham số hiển thị đúng giá trị đã nhập 3. Báo cáo chạy xong, không hiển thị thông báo lỗi 4. Có đúng 1 dòng Thủ công với Chưa duyệt = 1, Đã duyệt = 1 | G37: SIT | H37: High | I37: Manual | J37: Untested | K37: Untested | L37: Untested | N37: Q3
A38: MSB_TM-RP_TC_010 | B38: Kiểm tra xác định đúng Nguồn tạo STR = Thủ công với case Type AML_MN do AML Maker tạo | C38: - User: Đăng nhập tm_aml_maker (AML Maker – HO, HO0000001) - Màn hình: trang chủ Oracle Analytics Server (OAS) môi trường SIT, chưa mở báo cáo - Dữ liệu: bộ dữ liệu D-TM01 (mục 3.2 file rollup) đã dựng và batch dữ liệu báo cáo đã chạy; R1-HCM-02 là case thủ công Type = AML_MN do tm_aml_maker tạo cho khách hàng CIF 10020002 (đơn vị quản lý CIF VN0010002), trạng thái Pending AML Checker review | D38: 1. Mở báo cáo "Báo cáo thống kê số lượng báo cáo giao dịch đáng ngờ đã tạo" (Report TM_01) trên OAS 2. Nhập tham số: Từ = 05/2026; Đến = 05/2026; Đơn vị = VN0010002 – CN Hồ Chí Minh 3. Nhấn nút Apply 4. Xem dòng VN0010002 | 05/2026 | Thủ công | E38: - Tham số: Từ = 05/2026; Đến = 05/2026; Đơn vị = VN0010002 – CN Hồ Chí Minh - Case: R1-HCM-02 | F38: 1. Báo cáo mở, hiển thị vùng tham số cùng nút Apply và Reset 2. Các tham số hiển thị đúng giá trị đã nhập 3. Báo cáo chạy xong, không hiển thị thông báo lỗi 4. Dòng hiển thị Chưa duyệt = 1, Đã duyệt = 0 | G38: SIT | H38: High | I38: Manual | J38: Untested | K38: Untested | L38: Untested | N38: Q3
A39: MSB_TM-RP_TC_011 | B39: Kiểm tra lấy đúng Đơn vị theo đơn vị quản lý CIF với case do user HO lập STR | C39: - User: Đăng nhập tm_aml_maker (AML Maker – HO, HO0000001) - Màn hình: trang chủ Oracle Analytics Server (OAS) môi trường SIT, chưa mở báo cáo - Dữ liệu: bộ dữ liệu D-TM01 (mục 3.2 file rollup) đã dựng và batch dữ liệu báo cáo đã chạy; R1-HCM-02 do tm_aml_maker (đơn vị HO0000001) tạo và lập STR, CIF 10020002 do VN0010002 quản lý | D39: 1. Mở báo cáo "Báo cáo thống kê số lượng báo cáo giao dịch đáng ngờ đã tạo" (Report TM_01) trên OAS 2. Nhập tham số: Từ = 05/2026; Đến = 05/2026; Đơn vị = VN0010001 – CN Hà Nội, VN0010002 – CN Hồ Chí Minh 3. Nhấn nút Apply 4. Tìm dòng chứa số liệu của R1-HCM-02 | E39: - Tham số: Từ = 05/2026; Đến = 05/2026; Đơn vị = VN0010001 – CN Hà Nội, VN0010002 – CN Hồ Chí Minh - Case: R1-HCM-02 | F39: 1. Báo cáo mở, hiển thị vùng tham số cùng nút Apply và Reset 2. Các tham số hiển thị đúng giá trị đã nhập 3. Báo cáo chạy xong, không hiển thị thông báo lỗi 4. Số liệu R1-HCM-02 nằm ở dòng Đơn vị = VN0010002, không có dòng nào Đơn vị = HO0000001 | G39: SIT | H39: High | I39: Manual | J39: Untested | K39: Untested | L39: Untested
A40: MSB_TM-RP_TC_012 | B40: Kiểm tra không hiển thị dòng Đơn vị – Tháng – Nguồn khi cả 2 cột số lượng STR bằng 0 | C40: - User: Đăng nhập tm_aml_maker (AML Maker – HO, HO0000001) - Màn hình: trang chủ Oracle Analytics Server (OAS) môi trường SIT, chưa mở báo cáo - Dữ liệu: bộ dữ liệu D-TM01 (mục 3.2 file rollup) đã dựng và batch dữ liệu báo cáo đã chạy; VN0010001 tháng 04/2026 và 06/2026 chỉ có STR nguồn Tự động (R1-HN-12, R1-HN-13), không có STR thủ công | D40: 1. Mở báo cáo "Báo cáo thống kê số lượng báo cáo giao dịch đáng ngờ đã tạo" (Report TM_01) trên OAS 2. Nhập tham số: Từ = 04/2026; Đến = 06/2026; Đơn vị = VN0010001 – CN Hà Nội 3. Nhấn nút Apply 4. Tìm dòng VN0010001 | 04/2026 | Thủ công và VN0010001 | 06/2026 | Thủ công | E40: - Tham số: Từ = 04/2026; Đến = 06/2026; Đơn vị = VN0010001 – CN Hà Nội | F40: 1. Báo cáo mở, hiển thị vùng tham số cùng nút Apply và Reset 2. Các tham số hiển thị đúng giá trị đã nhập 3. Báo cáo chạy xong, không hiển thị thông báo lỗi 4. Không có 2 dòng này trên báo cáo | G40: SIT | H40: Medium | I40: Manual | J40: Untested | K40: Untested | L40: Untested | N40: Q5
A41: — Tham số lọc & biên kỳ
A42: MSB_TM-RP_TC_013 | B42: Kiểm tra tách đúng từng dòng theo tháng với kỳ báo cáo nhiều tháng 04/2026 – 06/2026 | C42: - User: Đăng nhập tm_aml_maker (AML Maker – HO, HO0000001) - Màn hình: trang chủ Oracle Analytics Server (OAS) môi trường SIT, chưa mở báo cáo - Dữ liệu: bộ dữ liệu D-TM01 (mục 3.2 file rollup) đã dựng và batch dữ liệu báo cáo đã chạy; R1-HN-12 (STR tạo 30/04/2026, Approved STR), STR tháng 05/2026 của VN0010001, R1-HN-13 (STR tạo 01/06/2026, Pending Checker Review STR) | D42: 1. Mở báo cáo "Báo cáo thống kê số lượng báo cáo giao dịch đáng ngờ đã tạo" (Report TM_01) trên OAS 2. Nhập tham số: Từ = 04/2026; Đến = 06/2026; Đơn vị = VN0010001 – CN Hà Nội 3. Nhấn nút Apply 4. Đối chiếu bảng kết quả | E42: - Tham số: Từ = 04/2026; Đến = 06/2026; Đơn vị = VN0010001 – CN Hà Nội - Case: R1-HN-12, R1-HN-13 | F42: 1. Báo cáo mở, hiển thị vùng tham số cùng nút Apply và Reset 2. Các tham số hiển thị đúng giá trị đã nhập 3. Báo cáo chạy xong, không hiển thị thông báo lỗi 4. Báo cáo có 4 dòng, cột Thời gian dạng MM/YYYY: + VN0010001 | 04/2026 | Tự động | 0 | 1 + VN0010001 | 05/2026 | Tự động | 4 | 1 + VN0010001 | 05/2026 | Thủ công | 1 | 1 + VN0010001 | 06/2026 | Tự động | 1 | 0 | G42: SIT | H42: High | I42: Manual | J42: Untested | K42: Untested | L42: Untested | N42: Q2
A43: MSB_TM-RP_TC_014 | B43: Kiểm tra loại trừ đúng STR tạo ngày 30/04/2026 khỏi kỳ báo cáo 05/2026 | C43: - User: Đăng nhập tm_aml_maker (AML Maker – HO, HO0000001) - Màn hình: trang chủ Oracle Analytics Server (OAS) môi trường SIT, chưa mở báo cáo - Dữ liệu: bộ dữ liệu D-TM01 (mục 3.2 file rollup) đã dựng và batch dữ liệu báo cáo đã chạy; R1-HN-12 (VN0010001, Tự động) tạo STR ngày 30/04/2026, trạng thái Approved STR | D43: 1. Mở báo cáo "Báo cáo thống kê số lượng báo cáo giao dịch đáng ngờ đã tạo" (Report TM_01) trên OAS 2. Nhập tham số: Từ = 05/2026; Đến = 05/2026; Đơn vị = VN0010001 – CN Hà Nội 3. Nhấn nút Apply 4. Xem cột Tổng số lượng báo cáo STR (đã duyệt) dòng VN0010001 | 05/2026 | Tự động | E43: - Tham số: Từ = 05/2026; Đến = 05/2026; Đơn vị = VN0010001 – CN Hà Nội - Case: R1-HN-12 | F43: 1. Báo cáo mở, hiển thị vùng tham số cùng nút Apply và Reset 2. Các tham số hiển thị đúng giá trị đã nhập 3. Báo cáo chạy xong, không hiển thị thông báo lỗi 4. Giá trị = 1 (chỉ R1-HN-05), không tính R1-HN-12 | G43: SIT | H43: Medium | I43: Manual | J43: Untested | K43: Untested | L43: Untested | N43: Q2
...

Sheet Report_TM_02
A1: Functions | B1: =Cover!E11
A2: Build Version | B2: v1.0
A3: Report TM_02 – Báo cáo đánh giá hiệu quả của kịch bản quét sàng lọc giao dịch của khách hàng
A4: ROUND 2
B5: High | C5: Medium | D5: Low | E5: Total
B6: =SUM(B7:B11) | C6: =SUM(C7:C11) | D6: =SUM(D7:D11) | E6: =SUM(B6:D6)
A7: Passed | B7: =COUNTIFS($H:$H,B$5,$K:$K,$A7) | C7: =COUNTIFS($H:$H,C$5,$K:$K,$A7) | D7: =COUNTIFS($H:$H,D$5,$K:$K,$A7) | E7: =SUM(B7:D7)
A8: Failed | B8: =COUNTIFS($H:$H,B$5,$K:$K,$A8) | C8: =COUNTIFS($H:$H,C$5,$K:$K,$A8) | D8: =COUNTIFS($H:$H,D$5,$K:$K,$A8) | E8: =SUM(B8:D8)
A9: Pending | B9: =COUNTIFS($H:$H,B$5,$K:$K,$A9) | C9: =COUNTIFS($H:$H,C$5,$K:$K,$A9) | D9: =COUNTIFS($H:$H,D$5,$K:$K,$A9) | E9: =SUM(B9:D9)
A10: Cancel | B10: =COUNTIFS($H:$H,B$5,$K:$K,$A10) | C10: =COUNTIFS($H:$H,C$5,$K:$K,$A10) | D10: =COUNTIFS($H:$H,D$5,$K:$K,$A10) | E10: =SUM(B10:D10)
A11: Untested | B11: =COUNTIFS($H:$H,B$5,$K:$K,$A11) | C11: =COUNTIFS($H:$H,C$5,$K:$K,$A11) | D11: =COUNTIFS($H:$H,D$5,$K:$K,$A11) | E11: =SUM(B11:D11)
A12: Next | B12: =COUNTIFS($H:$H,B$5,$K:$K,$A12) | C12: =COUNTIFS($H:$H,C$5,$K:$K,$A12) | D12: =COUNTIFS($H:$H,D$5,$K:$K,$A12) | E12: =SUM(B12:D12)
A14: ROUND 3
B15: High | C15: Medium | D15: Low | E15: Total
B16: =SUM(B17:B21) | C16: =SUM(C17:C21) | D16: =SUM(D17:D21) | E16: =SUM(B16:D16)
A17: Passed | B17: =COUNTIFS($H:$H,B$15,$L:$L,$A17) | C17: =COUNTIFS($H:$H,C$15,$L:$L,$A17) | D17: =COUNTIFS($H:$H,D$15,$L:$L,$A17) | E17: =SUM(B17:D17)
A18: Failed | B18: =COUNTIFS($H:$H,B$15,$L:$L,$A18) | C18: =COUNTIFS($H:$H,C$15,$L:$L,$A18) | D18: =COUNTIFS($H:$H,D$15,$L:$L,$A18) | E18: =SUM(B18:D18)
A19: Pending | B19: =COUNTIFS($H:$H,B$15,$L:$L,$A19) | C19: =COUNTIFS($H:$H,C$15,$L:$L,$A19) | D19: =COUNTIFS($H:$H,D$15,$L:$L,$A19) | E19: =SUM(B19:D19)
A20: Cancel | B20: =COUNTIFS($H:$H,B$15,$L:$L,$A20) | C20: =COUNTIFS($H:$H,C$15,$L:$L,$A20) | D20: =COUNTIFS($H:$H,D$15,$L:$L,$A20) | E20: =SUM(B20:D20)
A21: Untested | B21: =COUNTIFS($H:$H,B$15,$L:$L,$A21) | C21: =COUNTIFS($H:$H,C$15,$L:$L,$A21) | D21: =COUNTIFS($H:$H,D$15,$L:$L,$A21) | E21: =SUM(B21:D21)
A22: Next | B22: =COUNTIFS($H:$H,B$15,$L:$L,$A22) | C22: =COUNTIFS($H:$H,C$15,$L:$L,$A22) | D22: =COUNTIFS($H:$H,D$15,$L:$L,$A22) | E22: =SUM(B22:D22)
A25: Test case Id | B25: Test case Title | C25: Pre-conditions | D25: Test Step | E25: Test Datas | F25: Expected result | G25: Test Environment | H25: Priority | I25: Automation Status | J25: 1st Test Results | K25: 2nd Test Results | L25: 3rd Test Results | M25: BugID | N25: Notes
A26: NHÓM FUNCTION (Risk High)
A27: — Hiển thị & nút chức năng
A28: MSB_TM-RP_TC_042 | B28: Kiểm tra hiển thị thành công kết quả báo cáo TM_02 đủ 7 cột khi chỉ nhập tham số bắt buộc | C28: - User: Đăng nhập tm_aml_maker (AML Maker – HO, HO0000001) - Màn hình: trang chủ Oracle Analytics Server (OAS) môi trường SIT, chưa mở báo cáo - Dữ liệu: bộ dữ liệu D-EVT (mục 3.3 file rollup) đã dựng và batch dữ liệu báo cáo đã chạy; kỳ 09/2026 có event của kịch bản AML-01, AML-02, AML-05, AML-07, AML-08 | D28: 1. Mở báo cáo "Báo cáo đánh giá hiệu quả của kịch bản quét sàng lọc giao dịch của khách hàng" (Report TM_02) trên OAS 2. Nhập tham số: Từ ngày = 01/09/2026; Đến ngày = 30/09/2026 3. Nhấn nút Apply 4. Đối chiếu bảng kết quả với Test Data | E28: - Tham số: Từ ngày = 01/09/2026; Đến ngày = 30/09/2026 - Mã kịch bản, Tên kịch bản: không chọn | F28: 1. Báo cáo mở, hiển thị vùng tham số cùng nút Apply và Reset 2. Các tham số hiển thị đúng giá trị đã nhập 3. Báo cáo chạy xong, không hiển thị thông báo lỗi 4. Báo cáo có 7 cột và đúng 5 dòng (Mã KB | Số lượng cảnh báo xử lý | False Positive | True Positive | Tỷ lệ FP | Tỷ lệ TP), Tên kịch bản hiển thị theo mã: + AML-01 | 4 | 1 | 3 | 25,00% | 75,00% + AML-02 | 4 | 4 | 0 | 100,00% | 0,00% + AML-05 | 0 | 0 | 0 | 0,00% | 0,00% + AML-07 | 2 | 1 | 1 | 50,00% | 50,00% + AML-08 | 3 | 2 | 1 | 66,67% | 33,33% | G28: SIT | H28: High | I28: Manual | J28: Untested | K28: Untested | L28: Untested | N28: Q6, Q8
A29: — Logic số liệu
A30: MSB_TM-RP_TC_043 | B30: Kiểm tra cột Số lượng cảnh báo xử lý loại trừ đúng event chưa đánh giá (P) | C30: - User: Đăng nhập tm_aml_maker (AML Maker – HO, HO0000001) - Màn hình: trang chủ Oracle Analytics Server (OAS) môi trường SIT, chưa mở báo cáo - Dữ liệu: bộ dữ liệu D-EVT (mục 3.3 file rollup) đã dựng và batch dữ liệu báo cáo đã chạy; AML-01 có 5 event trong kỳ: E01, E04, E06 (Y), E09 (N), E18 (P) | D30: 1. Mở báo cáo "Báo cáo đánh giá hiệu quả của kịch bản quét sàng lọc giao dịch của khách hàng" (Report TM_02) trên OAS 2. Nhập tham số: Từ ngày = 01/09/2026; Đến ngày = 30/09/2026 3. Nhấn nút Apply 4. Xem cột Số lượng cảnh báo xử lý của dòng AML-01 | E30: - Tham số: Từ ngày = 01/09/2026; Đến ngày = 30/09/2026 - Event: E01, E04, E06, E09, E18 | F30: 1. Báo cáo mở, hiển thị vùng tham số cùng nút Apply và Reset 2. Các tham số hiển thị đúng giá trị đã nhập 3. Báo cáo chạy xong, không hiển thị thông báo lỗi 4. Giá trị = 4 (không tính E18 đang P) | G30: SIT | H30: High | I30: Manual | J30: Untested | K30: Untested | L30: Untested | N30: Q7
A31: MSB_TM-RP_TC_044 | B31: Kiểm tra cột Số lượng False Positive đếm đúng event được đánh giá không đáng ngờ (N) | C31: - User: Đăng nhập tm_aml_maker (AML Maker – HO, HO0000001) - Màn hình: trang chủ Oracle Analytics Server (OAS) môi trường SIT, chưa mở báo cáo - Dữ liệu: bộ dữ liệu D-EVT (mục 3.3 file rollup) đã dựng và batch dữ liệu báo cáo đã chạy; AML-01 có 1 event N (E09); AML-02 có 4 event N (E03, E05, E10, E12) | D31: 1. Mở báo cáo "Báo cáo đánh giá hiệu quả của kịch bản quét sàng lọc giao dịch của khách hàng" (Report TM_02) trên OAS 2. Nhập tham số: Từ ngày = 01/09/2026; Đến ngày = 30/09/2026 3. Nhấn nút Apply 4. Xem cột Số lượng False Positive của dòng AML-01 và AML-02 | E31: - Tham số: Từ ngày = 01/09/2026; Đến ngày = 30/09/2026 - Event: E09, E03, E05, E10, E12 | F31: 1. Báo cáo mở, hiển thị vùng tham số cùng nút Apply và Reset 2. Các tham số hiển thị đúng giá trị đã nhập 3. Báo cáo chạy xong, không hiển thị thông báo lỗi 4. AML-01 = 1; AML-02 = 4 | G31: SIT | H31: High | I31: Manual | J31: Untested | K31: Untested | L31: Untested | N31: Q7
A32: MSB_TM-RP_TC_045 | B32: Kiểm tra cột Số lượng True Positive đếm đúng event được đánh giá đáng ngờ (Y) | C32: - User: Đăng nhập tm_aml_maker (AML Maker – HO, HO0000001) - Màn hình: trang chủ Oracle Analytics Server (OAS) môi trường SIT, chưa mở báo cáo - Dữ liệu: bộ dữ liệu D-EVT (mục 3.3 file rollup) đã dựng và batch dữ liệu báo cáo đã chạy; AML-01 có 3 event Y (E01, E04, E06); AML-02 không có event Y | D32: 1. Mở báo cáo "Báo cáo đánh giá hiệu quả của kịch bản quét sàng lọc giao dịch của khách hàng" (Report TM_02) trên OAS 2. Nhập tham số: Từ ngày = 01/09/2026; Đến ngày = 30/09/2026 3. Nhấn nút Apply 4. Xem cột Số lượng True Positive của dòng AML-01 và AML-02 | E32: - Tham số: Từ ngày = 01/09/2026; Đến ngày = 30/09/2026 - Event: E01, E04, E06 | F32: 1. Báo cáo mở, hiển thị vùng tham số cùng nút Apply và Reset 2. Các tham số hiển thị đúng giá trị đã nhập 3. Báo cáo chạy xong, không hiển thị thông báo lỗi 4. AML-01 = 3; AML-02 = 0 | G32: SIT | H32: High | I32: Manual | J32: Untested | K32: Untested | L32: Untested | N32: Q7
A33: MSB_TM-RP_TC_046 | B33: Kiểm tra tính đúng Tỷ lệ False Positive bằng False Positive chia Số lượng cảnh báo xử lý | C33: - User: Đăng nhập tm_aml_maker (AML Maker – HO, HO0000001) - Màn hình: trang chủ Oracle Analytics Server (OAS) môi trường SIT, chưa mở báo cáo - Dữ liệu: bộ dữ liệu D-EVT (mục 3.3 file rollup) đã dựng và batch dữ liệu báo cáo đã chạy | D33: 1. Mở báo cáo "Báo cáo đánh giá hiệu quả của kịch bản quét sàng lọc giao dịch của khách hàng" (Report TM_02) trên OAS 2. Nhập tham số: Từ ngày = 01/09/2026; Đến ngày = 30/09/2026 3. Nhấn nút Apply 4. Xem cột Tỷ lệ False Positive của dòng AML-01 và AML-02 | E33: - Tham số: Từ ngày = 01/09/2026; Đến ngày = 30/09/2026 | F33: 1. Báo cáo mở, hiển thị vùng tham số cùng nút Apply và Reset 2. Các tham số hiển thị đúng giá trị đã nhập 3. Báo cáo chạy xong, không hiển thị thông báo lỗi 4. AML-01 = 1/4 = 25,00%; AML-02 = 4/4 = 100,00% | G33: SIT | H33: High | I33: Manual | J33: Untested | K33: Untested | L33: Untested | N33: Q8
A34: MSB_TM-RP_TC_047 | B34: Kiểm tra tính đúng Tỷ lệ True Positive bằng True Positive chia Số lượng cảnh báo xử lý | C34: - User: Đăng nhập tm_aml_maker (AML Maker – HO, HO0000001) - Màn hình: trang chủ Oracle Analytics Server (OAS) môi trường SIT, chưa mở báo cáo - Dữ liệu: bộ dữ liệu D-EVT (mục 3.3 file rollup) đã dựng và batch dữ liệu báo cáo đã chạy | D34: 1. Mở báo cáo "Báo cáo đánh giá hiệu quả của kịch bản quét sàng lọc giao dịch của khách hàng" (Report TM_02) trên OAS 2. Nhập tham số: Từ ngày = 01/09/2026; Đến ngày = 30/09/2026 3. Nhấn nút Apply 4. Xem cột Tỷ lệ True Positive của dòng AML-01 và AML-02 | E34: - Tham số: Từ ngày = 01/09/2026; Đến ngày = 30/09/2026 | F34: 1. Báo cáo mở, hiển thị vùng tham số cùng nút Apply và Reset 2. Các tham số hiển thị đúng giá trị đã nhập 3. Báo cáo chạy xong, không hiển thị thông báo lỗi 4. AML-01 = 3/4 = 75,00%; AML-02 = 0/4 = 0,00% | G34: SIT | H34: High | I34: Manual | J34: Untested | K34: Untested | L34: Untested | N34: Q8
A35: MSB_TM-RP_TC_048 | B35: Kiểm tra làm tròn đúng 2 chữ số thập phân với tỷ lệ chia không hết của kịch bản AML-08 | C35: - User: Đăng nhập tm_aml_maker (AML Maker – HO, HO0000001) - Màn hình: trang chủ Oracle Analytics Server (OAS) môi trường SIT, chưa mở báo cáo - Dữ liệu: bộ dữ liệu D-EVT (mục 3.3 file rollup) đã dựng và batch dữ liệu báo cáo đã chạy; AML-08 có 3 event: E11 (N), E13 (Y), E16 (N) | D35: 1. Mở báo cáo "Báo cáo đánh giá hiệu quả của kịch bản quét sàng lọc giao dịch của khách hàng" (Report TM_02) trên OAS 2. Nhập tham số: Từ ngày = 01/09/2026; Đến ngày = 30/09/2026 3. Nhấn nút Apply 4. Xem 2 cột tỷ lệ của dòng AML-08 | E35: - Tham số: Từ ngày = 01/09/2026; Đến ngày = 30/09/2026 - Event: E11, E13, E16 | F35: 1. Báo cáo mở, hiển thị vùng tham số cùng nút Apply và Reset 2. Các tham số hiển thị đúng giá trị đã nhập 3. Báo cáo chạy xong, không hiển thị thông báo lỗi 4. Tỷ lệ False Positive = 66,67%; Tỷ lệ True Positive = 33,33% | G35: SIT | H35: Medium | I35: Manual | J35: Untested | K35: Untested | L35: Untested | N35: Q8
A36: MSB_TM-RP_TC_049 | B36: Kiểm tra tổng False Positive và True Positive bằng Số lượng cảnh báo xử lý trên mọi dòng | C36: - User: Đăng nhập tm_aml_maker (AML Maker – HO, HO0000001) - Màn hình: trang chủ Oracle Analytics Server (OAS) môi trường SIT, chưa mở báo cáo - Dữ liệu: bộ dữ liệu D-EVT (mục 3.3 file rollup) đã dựng và batch dữ liệu báo cáo đã chạy | D36: 1. Mở báo cáo "Báo cáo đánh giá hiệu quả của kịch bản quét sàng lọc giao dịch của khách hàng" (Report TM_02) trên OAS 2. Nhập tham số: Từ ngày = 01/09/2026; Đến ngày = 30/09/2026 3. Nhấn nút Apply 4. Với từng dòng, cộng cột False Positive và True Positive rồi so với cột Số lượng cảnh báo xử lý | E36: - Tham số: Từ ngày = 01/09/2026; Đến ngày = 30/09/2026 | F36: 1. Báo cáo mở, hiển thị vùng tham số cùng nút Apply và Reset 2. Các tham số hiển thị đúng giá trị đã nhập 3. Báo cáo chạy xong, không hiển thị thông báo lỗi 4. Cả 5 dòng: False Positive + True Positive = Số lượng cảnh báo xử lý | G36: SIT | H36: Medium | I36: Manual | J36: Untested | K36: Untested | L36: Untested
A37: MSB_TM-RP_TC_050 | B37: Kiểm tra không lỗi chia cho 0 với kịch bản chỉ có event chưa đánh giá AML-05 | C37: - User: Đăng nhập tm_aml_maker (AML Maker – HO, HO0000001) - Màn hình: trang chủ Oracle Analytics Server (OAS) môi trường SIT, chưa mở báo cáo - Dữ liệu: bộ dữ liệu D-EVT (mục 3.3 file rollup) đã dựng và batch dữ liệu báo cáo đã chạy; AML-05 có 2 event đều P (E14, E15) | D37: 1. Mở báo cáo "Báo cáo đánh giá hiệu quả của kịch bản quét sàng lọc giao dịch của khách hàng" (Report TM_02) trên OAS 2. Nhập tham số: Từ ngày = 01/09/2026; Đến ngày = 30/09/2026 3. Nhấn nút Apply 4. Xem dòng AML-05 | E37: - Tham số: Từ ngày = 01/09/2026; Đến ngày = 30/09/2026 - Event: E14, E15 | F37: 1. Báo cáo mở, hiển thị vùng tham số cùng nút Apply và Reset 2. Các tham số hiển thị đúng giá trị đã nhập 3. Báo cáo chạy xong, không hiển thị thông báo lỗi 4. Dòng AML-05 hiển thị 0 | 0 | 0 | 0,00% | 0,00%, không hiện #DIV/0 hay lỗi | G37: SIT | H37: Medium | I37: Manual | J37: Untested | K37: Untested | L37: Untested | N37: Q8
A38: MSB_TM-RP_TC_051 | B38: Kiểm tra không hiển thị dòng kịch bản không phát sinh event trong kỳ báo cáo | C38: - User: Đăng nhập tm_aml_maker (AML Maker – HO, HO0000001) - Màn hình: trang chủ Oracle Analytics Server (OAS) môi trường SIT, chưa mở báo cáo - Dữ liệu: bộ dữ liệu D-EVT (mục 3.3 file rollup) đã dựng và batch dữ liệu báo cáo đã chạy; kịch bản AML-03 đang hiệu lực nhưng không có event nào trong kỳ 09/2026 | D38: 1. Mở báo cáo "Báo cáo đánh giá hiệu quả của kịch bản quét sàng lọc giao dịch của khách hàng" (Report TM_02) trên OAS 2. Nhập tham số: Từ ngày = 01/09/2026; Đến ngày = 30/09/2026 3. Nhấn nút Apply 4. Tìm dòng AML-03 | E38: - Tham số: Từ ngày = 01/09/2026; Đến ngày = 30/09/2026 | F38: 1. Báo cáo mở, hiển thị vùng tham số cùng nút Apply và Reset 2. Các tham số hiển thị đúng giá trị đã nhập 3. Báo cáo chạy xong, không hiển thị thông báo lỗi 4. Không có dòng AML-03 trên báo cáo | G38: SIT | H38: Medium | I38: Manual | J38: Untested | K38: Untested | L38: Untested | N38: Q8
A39: — Tham số lọc & biên kỳ
A40: MSB_TM-RP_TC_052 | B40: Kiểm tra lấy đúng event ngày 01/09/2026 và loại trừ event ngày 31/08/2026 ở biên đầu kỳ | C40: - User: Đăng nhập tm_aml_maker (AML Maker – HO, HO0000001) - Màn hình: trang chủ Oracle Analytics Server (OAS) môi trường SIT, chưa mở báo cáo - Dữ liệu: bộ dữ liệu D-EVT (mục 3.3 file rollup) đã dựng và batch dữ liệu báo cáo đã chạy; E05 (AML-02, N) thuộc case ngày 01/09/2026; E07 (AML-01, Y) thuộc case ngày 31/08/2026 | D40: 1. Mở báo cáo "Báo cáo đánh giá hiệu quả của kịch bản quét sàng lọc giao dịch của khách hàng" (Report TM_02) trên OAS 2. Nhập tham số: Từ ngày = 01/09/2026; Đến ngày = 30/09/2026 3. Nhấn nút Apply 4. Xem dòng AML-02 và AML-01 | E40: - Tham số: Từ ngày = 01/09/2026; Đến ngày = 30/09/2026 - Event: E05, E07 | F40: 1. Báo cáo mở, hiển thị vùng tham số cùng nút Apply và Reset 2. Các tham số hiển thị đúng giá trị đã nhập 3. Báo cáo chạy xong, không hiển thị thông báo lỗi 4. AML-02 có Số lượng cảnh báo xử lý = 4 (gồm E05); AML-01 có True Positive = 3 (không gồm E07) | G40: SIT | H40: Medium | I40: Manual | J40: Untested | K40: Untested | L40: Untested | N40: Q9
A41: MSB_TM-RP_TC_053 | B41: Kiểm tra lấy đúng event ngày 30/09/2026 và loại trừ event ngày 01/10/2026 ở biên cuối kỳ | C41: - User: Đăng nhập tm_aml_maker (AML Maker – HO, HO0000001) - Màn hình: trang chủ Oracle Analytics Server (OAS) môi trường SIT, chưa mở báo cáo - Dữ liệu: bộ dữ liệu D-EVT (mục 3.3 file rollup) đã dựng và batch dữ liệu báo cáo đã chạy; E06 (AML-01, Y) thuộc case ngày 30/09/2026; E08 (AML-01, Y) thuộc case ngày 01/10/2026 | D41: 1. Mở báo cáo "Báo cáo đánh giá hiệu quả của kịch bản quét sàng lọc giao dịch của khách hàng" (Report TM_02) trên OAS 2. Nhập tham số: Từ ngày = 01/09/2026; Đến ngày = 30/09/2026 3. Nhấn nút Apply 4. Xem dòng AML-01 | E41: - Tham số: Từ ngày = 01/09/2026; Đến ngày = 30/09/2026 - Event: E06, E08 | F41: 1. Báo cáo mở, hiển thị vùng tham số cùng nút Apply và Reset 2. Các tham số hiển thị đúng giá trị đã nhập 3. Báo cáo chạy xong, không hiển thị thông báo lỗi 4. True Positive = 3 (gồm E06, không gồm E08) | G41: SIT | H41: Medium | I41: Manual | J41: Untested | K41: Untested | L41: Untested | N41: Q9
A42: MSB_TM-RP_TC_054 | B42: Kiểm tra lọc thành công báo cáo TM_02 với Mã kịch bản chọn 1 giá trị | C42: - User: Đăng nhập tm_aml_maker (AML Maker – HO, HO0000001) - Màn hình: trang chủ Oracle Analytics Server (OAS) môi trường SIT, chưa mở báo cáo - Dữ liệu: bộ dữ liệu D-EVT (mục 3.3 file rollup) đã dựng và batch dữ liệu báo cáo đã chạy | D42: 1. Mở báo cáo "Báo cáo đánh giá hiệu quả của kịch bản quét sàng lọc giao dịch của khách hàng" (Report TM_02) trên OAS 2. Nhập tham số: Từ ngày = 01/09/2026; Đến ngày = 30/09/2026; Mã kịch bản = AML-01 3. Nhấn nút Apply 4. Xem bảng kết quả | E42: - Tham số: Từ ngày = 01/09/2026; Đến ngày = 30/09/2026; Mã kịch bản = AML-01 | F42: 1. Báo cáo mở, hiển thị vùng tham số cùng nút Apply và Reset 2. Các tham số hiển thị đúng giá trị đã nhập 3. Báo cáo chạy xong, không hiển thị thông báo lỗi 4. Chỉ có 1 dòng AML-01 | 4 | 1 | 3 | 25,00% | 75,00% | G42: SIT | H42: High | I42: Manual | J42: Untested | K42: Untested | L42: Untested
A43: MSB_TM-RP_TC_055 | B43: Kiểm tra lọc thành công báo cáo TM_02 với Mã kịch bản chọn nhiều giá trị | C43: - User: Đăng nhập tm_aml_maker (AML Maker – HO, HO0000001) - Màn hình: trang chủ Oracle Analytics Server (OAS) môi trường SIT, chưa mở báo cáo - Dữ liệu: bộ dữ liệu D-EVT (mục 3.3 file rollup) đã dựng và batch dữ liệu báo cáo đã chạy | D43: 1. Mở báo cáo "Báo cáo đánh giá hiệu quả của kịch bản quét sàng lọc giao dịch của khách hàng" (Report TM_02) trên OAS 2. Nhập tham số: Từ ngày = 01/09/2026; Đến ngày = 30/09/2026; Mã kịch bản = AML-01, AML-02 3. Nhấn nút Apply 4. Xem bảng kết quả | E43: - Tham số: Từ ngày = 01/09/2026; Đến ngày = 30/09/2026; Mã kịch bản = AML-01, AML-02 | F43: 1. Báo cáo mở, hiển thị vùng tham số cùng nút Apply và Reset 2. Các tham số hiển thị đúng giá trị đã nhập 3. Báo cáo chạy xong, không hiển thị thông báo lỗi 4. Có đúng 2 dòng AML-01 và AML-02 với số liệu như TC hiển thị kết quả | G43: SIT | H43: High | I43: Manual | J43: Untested | K43: Untested | L43: Untested
...

Sheet Report_TM_03
A1: Functions | B1: =Cover!E11
A2: Build Version | B2: v1.0
A3: Report TM_03 – Báo cáo các cảnh báo chưa được xử lý
A4: ROUND 2
B5: High | C5: Medium | D5: Low | E5: Total
B6: =SUM(B7:B11) | C6: =SUM(C7:C11) | D6: =SUM(D7:D11) | E6: =SUM(B6:D6)
A7: Passed | B7: =COUNTIFS($H:$H,B$5,$K:$K,$A7) | C7: =COUNTIFS($H:$H,C$5,$K:$K,$A7) | D7: =COUNTIFS($H:$H,D$5,$K:$K,$A7) | E7: =SUM(B7:D7)
A8: Failed | B8: =COUNTIFS($H:$H,B$5,$K:$K,$A8) | C8: =COUNTIFS($H:$H,C$5,$K:$K,$A8) | D8: =COUNTIFS($H:$H,D$5,$K:$K,$A8) | E8: =SUM(B8:D8)
A9: Pending | B9: =COUNTIFS($H:$H,B$5,$K:$K,$A9) | C9: =COUNTIFS($H:$H,C$5,$K:$K,$A9) | D9: =COUNTIFS($H:$H,D$5,$K:$K,$A9) | E9: =SUM(B9:D9)
A10: Cancel | B10: =COUNTIFS($H:$H,B$5,$K:$K,$A10) | C10: =COUNTIFS($H:$H,C$5,$K:$K,$A10) | D10: =COUNTIFS($H:$H,D$5,$K:$K,$A10) | E10: =SUM(B10:D10)
A11: Untested | B11: =COUNTIFS($H:$H,B$5,$K:$K,$A11) | C11: =COUNTIFS($H:$H,C$5,$K:$K,$A11) | D11: =COUNTIFS($H:$H,D$5,$K:$K,$A11) | E11: =SUM(B11:D11)
A12: Next | B12: =COUNTIFS($H:$H,B$5,$K:$K,$A12) | C12: =COUNTIFS($H:$H,C$5,$K:$K,$A12) | D12: =COUNTIFS($H:$H,D$5,$K:$K,$A12) | E12: =SUM(B12:D12)
A14: ROUND 3
B15: High | C15: Medium | D15: Low | E15: Total
B16: =SUM(B17:B21) | C16: =SUM(C17:C21) | D16: =SUM(D17:D21) | E16: =SUM(B16:D16)
A17: Passed | B17: =COUNTIFS($H:$H,B$15,$L:$L,$A17) | C17: =COUNTIFS($H:$H,C$15,$L:$L,$A17) | D17: =COUNTIFS($H:$H,D$15,$L:$L,$A17) | E17: =SUM(B17:D17)
A18: Failed | B18: =COUNTIFS($H:$H,B$15,$L:$L,$A18) | C18: =COUNTIFS($H:$H,C$15,$L:$L,$A18) | D18: =COUNTIFS($H:$H,D$15,$L:$L,$A18) | E18: =SUM(B18:D18)
A19: Pending | B19: =COUNTIFS($H:$H,B$15,$L:$L,$A19) | C19: =COUNTIFS($H:$H,C$15,$L:$L,$A19) | D19: =COUNTIFS($H:$H,D$15,$L:$L,$A19) | E19: =SUM(B19:D19)
A20: Cancel | B20: =COUNTIFS($H:$H,B$15,$L:$L,$A20) | C20: =COUNTIFS($H:$H,C$15,$L:$L,$A20) | D20: =COUNTIFS($H:$H,D$15,$L:$L,$A20) | E20: =SUM(B20:D20)
A21: Untested | B21: =COUNTIFS($H:$H,B$15,$L:$L,$A21) | C21: =COUNTIFS($H:$H,C$15,$L:$L,$A21) | D21: =COUNTIFS($H:$H,D$15,$L:$L,$A21) | E21: =SUM(B21:D21)
A22: Next | B22: =COUNTIFS($H:$H,B$15,$L:$L,$A22) | C22: =COUNTIFS($H:$H,C$15,$L:$L,$A22) | D22: =COUNTIFS($H:$H,D$15,$L:$L,$A22) | E22: =SUM(B22:D22)
A25: Test case Id | B25: Test case Title | C25: Pre-conditions | D25: Test Step | E25: Test Datas | F25: Expected result | G25: Test Environment | H25: Priority | I25: Automation Status | J25: 1st Test Results | K25: 2nd Test Results | L25: 3rd Test Results | M25: BugID | N25: Notes
A26: NHÓM FUNCTION (Risk High)
A27: — Hiển thị & nút chức năng
A28: MSB_TM-RP_TC_076 | B28: Kiểm tra hiển thị thành công kết quả báo cáo TM_03 đủ 9 cột khi chỉ nhập tham số bắt buộc | C28: - User: Đăng nhập tm_aml_maker (AML Maker – HO, HO0000001) - Màn hình: trang chủ Oracle Analytics Server (OAS) môi trường SIT, chưa mở báo cáo - Dữ liệu: bộ dữ liệu D-TM03 (mục 3.4 file rollup) đã dựng và batch dữ liệu báo cáo đã chạy; kỳ 07/2026 có 13 case chưa đóng và 5 case đã đóng | D28: 1. Mở báo cáo "Báo cáo các cảnh báo chưa được xử lý" (Report TM_03) trên OAS 2. Nhập tham số: Từ ngày = 01/07/2026; Đến ngày = 31/07/2026 3. Nhấn nút Apply 4. Đối chiếu bảng kết quả với Test Data | E28: - Tham số: Từ ngày = 01/07/2026; Đến ngày = 31/07/2026 - Loại khách hàng, Trạng thái sự vụ: không chọn | F28: 1. Báo cáo mở, hiển thị vùng tham số cùng nút Apply và Reset 2. Các tham số hiển thị đúng giá trị đã nhập 3. Báo cáo chạy xong, không hiển thị thông báo lỗi 4. Báo cáo có 9 cột (STT, CIF, Tên KH, Loại KH, Mã sự vụ, Ngày phát sinh sự vụ, Trạng thái sự vụ, Cấp Đơn vị đang xử lý sự vụ, Mã Đơn vị) và đúng 13 dòng: C301–C309, C315, C316, C318, C319 | G28: SIT | H28: High | I28: Manual | J28: Untested | K28: Untested | L28: Untested | N28: Q11
A29: — Logic số liệu
A30: MSB_TM-RP_TC_077 | B30: Kiểm tra không hiển thị case ở 5 trạng thái đã đóng trên báo cáo TM_03 | C30: - User: Đăng nhập tm_aml_maker (AML Maker – HO, HO0000001) - Màn hình: trang chủ Oracle Analytics Server (OAS) môi trường SIT, chưa mở báo cáo - Dữ liệu: bộ dữ liệu D-TM03 (mục 3.4 file rollup) đã dựng và batch dữ liệu báo cáo đã chạy; C310 (Closed - No Further Action), C311 (Closed - Under Monitoring), C312 (Approved STR), C313 (Rejected sending STR), C314 (Closed - Not Send STR) | D30: 1. Mở báo cáo "Báo cáo các cảnh báo chưa được xử lý" (Report TM_03) trên OAS 2. Nhập tham số: Từ ngày = 01/07/2026; Đến ngày = 31/07/2026 3. Nhấn nút Apply 4. Tìm Mã sự vụ C310 đến C314 | E30: - Tham số: Từ ngày = 01/07/2026; Đến ngày = 31/07/2026 - Case: C310–C314 | F30: 1. Báo cáo mở, hiển thị vùng tham số cùng nút Apply và Reset 2. Các tham số hiển thị đúng giá trị đã nhập 3. Báo cáo chạy xong, không hiển thị thông báo lỗi 4. Không có dòng nào của C310, C311, C312, C313, C314 | G30: SIT | H30: High | I30: Manual | J30: Untested | K30: Untested | L30: Untested | N30: Q11
A31: MSB_TM-RP_TC_078 | B31: Kiểm tra hiển thị đủ case ở 8 trạng thái chưa đóng trên báo cáo TM_03 | C31: - User: Đăng nhập tm_aml_maker (AML Maker – HO, HO0000001) - Màn hình: trang chủ Oracle Analytics Server (OAS) môi trường SIT, chưa mở báo cáo - Dữ liệu: bộ dữ liệu D-TM03 (mục 3.4 file rollup) đã dựng và batch dữ liệu báo cáo đã chạy; C301 (New), C302 (Pending Checker Review), C303 (Pending Maker), C304 (Pending Generate STR), C305 (Pending Checker Review STR), C306 (Pending Supervisor Review), C307 (Pending AML Maker), C308 (Pending AML Checker review) | D31: 1. Mở báo cáo "Báo cáo các cảnh báo chưa được xử lý" (Report TM_03) trên OAS 2. Nhập tham số: Từ ngày = 01/07/2026; Đến ngày = 31/07/2026 3. Nhấn nút Apply 4. Xem cột Trạng thái sự vụ của C301 đến C308 | E31: - Tham số: Từ ngày = 01/07/2026; Đến ngày = 31/07/2026 - Case: C301–C308 | F31: 1. Báo cáo mở, hiển thị vùng tham số cùng nút Apply và Reset 2. Các tham số hiển thị đúng giá trị đã nhập 3. Báo cáo chạy xong, không hiển thị thông báo lỗi 4. Có đủ 8 dòng, Trạng thái sự vụ đúng trạng thái hiện tại của từng case | G31: SIT | H31: High | I31: Manual | J31: Untested | K31: Untested | L31: Untested | N31: Q11
A32: MSB_TM-RP_TC_079 | B32: Kiểm tra gộp thành 1 dòng với CIF có 1 case phát sinh nhiều kịch bản | C32: - User: Đăng nhập tm_aml_maker (AML Maker – HO, HO0000001) - Màn hình: trang chủ Oracle Analytics Server (OAS) môi trường SIT, chưa mở báo cáo - Dữ liệu: bộ dữ liệu D-TM03 (mục 3.4 file rollup) đã dựng và batch dữ liệu báo cáo đã chạy; case C301 của CIF 10070001 có 3 event thuộc AML-01, AML-02, AML-07 | D32: 1. Mở báo cáo "Báo cáo các cảnh báo chưa được xử lý" (Report TM_03) trên OAS 2. Nhập tham số: Từ ngày = 01/07/2026; Đến ngày = 31/07/2026 3. Nhấn nút Apply 4. Đếm số dòng có Mã sự vụ = C301 | E32: - Tham số: Từ ngày = 01/07/2026; Đến ngày = 31/07/2026 - Case: C301 | F32: 1. Báo cáo mở, hiển thị vùng tham số cùng nút Apply và Reset 2. Các tham số hiển thị đúng giá trị đã nhập 3. Báo cáo chạy xong, không hiển thị thông báo lỗi 4. Chỉ có 1 dòng C301 | G32: SIT | H32: High | I32: Manual | J32: Untested | K32: Untested | L32: Untested
A33: MSB_TM-RP_TC_080 | B33: Kiểm tra tách mỗi case 1 dòng với CIF có nhiều case trong kỳ | C33: - User: Đăng nhập tm_aml_maker (AML Maker – HO, HO0000001) - Màn hình: trang chủ Oracle Analytics Server (OAS) môi trường SIT, chưa mở báo cáo - Dữ liệu: bộ dữ liệu D-TM03 (mục 3.4 file rollup) đã dựng và batch dữ liệu báo cáo đã chạy; CIF 10070001 có 2 case chưa đóng: C301 (03/07/2026, New) và C319 (20/07/2026, Pending Checker Review) | D33: 1. Mở báo cáo "Báo cáo các cảnh báo chưa được xử lý" (Report TM_03) trên OAS 2. Nhập tham số: Từ ngày = 01/07/2026; Đến ngày = 31/07/2026 3. Nhấn nút Apply 4. Lọc các dòng có CIF = 10070001 | E33: - Tham số: Từ ngày = 01/07/2026; Đến ngày = 31/07/2026 - Case: C301, C319 | F33: 1. Báo cáo mở, hiển thị vùng tham số cùng nút Apply và Reset 2. Các tham số hiển thị đúng giá trị đã nhập 3. Báo cáo chạy xong, không hiển thị thông báo lỗi 4. Có 2 dòng: C301 và C319, mỗi dòng đúng Ngày phát sinh và Trạng thái của case đó | G33: SIT | H33: High | I33: Manual | J33: Untested | K33: Untested | L33: Untested
A34: MSB_TM-RP_TC_081 | B34: Kiểm tra xác định đúng Cấp Đơn vị đang xử lý = ĐVKD với case đang chờ DVKH xử lý | C34: - User: Đăng nhập tm_aml_maker (AML Maker – HO, HO0000001) - Màn hình: trang chủ Oracle Analytics Server (OAS) môi trường SIT, chưa mở báo cáo - Dữ liệu: bộ dữ liệu D-TM03 (mục 3.4 file rollup) đã dựng và batch dữ liệu báo cáo đã chạy; C301, C302, C303, C304, C305, C306 là case tự động đang ở bước DVKH Maker, DVKH Checker hoặc Checker N+1 | D34: 1. Mở báo cáo "Báo cáo các cảnh báo chưa được xử lý" (Report TM_03) trên OAS 2. Nhập tham số: Từ ngày = 01/07/2026; Đến ngày = 31/07/2026 3. Nhấn nút Apply 4. Xem cột Cấp Đơn vị đang xử lý sự vụ của C301 đến C306 | E34: - Tham số: Từ ngày = 01/07/2026; Đến ngày = 31/07/2026 - Case: C301–C306 | F34: 1. Báo cáo mở, hiển thị vùng tham số cùng nút Apply và Reset 2. Các tham số hiển thị đúng giá trị đã nhập 3. Báo cáo chạy xong, không hiển thị thông báo lỗi 4. Cả 6 dòng = ĐVKD | G34: SIT | H34: High | I34: Manual | J34: Untested | K34: Untested | L34: Untested | N34: Q12
A35: MSB_TM-RP_TC_082 | B35: Kiểm tra xác định đúng Cấp Đơn vị đang xử lý = AML với case đang chờ bộ phận AML xử lý | C35: - User: Đăng nhập tm_aml_maker (AML Maker – HO, HO0000001) - Màn hình: trang chủ Oracle Analytics Server (OAS) môi trường SIT, chưa mở báo cáo - Dữ liệu: bộ dữ liệu D-TM03 (mục 3.4 file rollup) đã dựng và batch dữ liệu báo cáo đã chạy; C307 (Pending AML Maker), C308 (Pending AML Checker review) | D35: 1. Mở báo cáo "Báo cáo các cảnh báo chưa được xử lý" (Report TM_03) trên OAS 2. Nhập tham số: Từ ngày = 01/07/2026; Đến ngày = 31/07/2026 3. Nhấn nút Apply 4. Xem cột Cấp Đơn vị đang xử lý sự vụ của C307, C308 | E35: - Tham số: Từ ngày = 01/07/2026; Đến ngày = 31/07/2026 - Case: C307, C308 | F35: 1. Báo cáo mở, hiển thị vùng tham số cùng nút Apply và Reset 2. Các tham số hiển thị đúng giá trị đã nhập 3. Báo cáo chạy xong, không hiển thị thông báo lỗi 4. Cả 2 dòng = AML | G35: SIT | H35: High | I35: Manual | J35: Untested | K35: Untested | L35: Untested
A36: MSB_TM-RP_TC_083 | B36: Kiểm tra xác định Cấp Đơn vị = AML với case thủ công AML Maker tạo đang Pending Generate STR | C36: - User: Đăng nhập tm_aml_maker (AML Maker – HO, HO0000001) - Màn hình: trang chủ Oracle Analytics Server (OAS) môi trường SIT, chưa mở báo cáo - Dữ liệu: bộ dữ liệu D-TM03 (mục 3.4 file rollup) đã dựng và batch dữ liệu báo cáo đã chạy; C309 là case thủ công Type AML_MN do tm_aml_maker tạo, đang Pending Generate STR | D36: 1. Mở báo cáo "Báo cáo các cảnh báo chưa được xử lý" (Report TM_03) trên OAS 2. Nhập tham số: Từ ngày = 01/07/2026; Đến ngày = 31/07/2026 3. Nhấn nút Apply 4. Xem cột Cấp Đơn vị đang xử lý sự vụ của C309 | E36: - Tham số: Từ ngày = 01/07/2026; Đến ngày = 31/07/2026 - Case: C309 | F36: 1. Báo cáo mở, hiển thị vùng tham số cùng nút Apply và Reset 2. Các tham số hiển thị đúng giá trị đã nhập 3. Báo cáo chạy xong, không hiển thị thông báo lỗi 4. Giá trị = AML | G36: SIT | H36: Medium | I36: Manual | J36: Untested | K36: Untested | L36: Untested | N36: Q12
A37: MSB_TM-RP_TC_084 | B37: Kiểm tra lấy đúng Tên KH theo loại khách hàng KHCN và KHTC | C37: - User: Đăng nhập tm_aml_maker (AML Maker – HO, HO0000001) - Màn hình: trang chủ Oracle Analytics Server (OAS) môi trường SIT, chưa mở báo cáo - Dữ liệu: bộ dữ liệu D-TM03 (mục 3.4 file rollup) đã dựng và batch dữ liệu báo cáo đã chạy; C301 của KHCN CIF 10070001 (họ tên Nguyễn Văn An); C302 của KHTC CIF 20070002 (tên giao dịch đầy đủ Công ty TNHH Thương mại Minh Phát) | D37: 1. Mở báo cáo "Báo cáo các cảnh báo chưa được xử lý" (Report TM_03) trên OAS 2. Nhập tham số: Từ ngày = 01/07/2026; Đến ngày = 31/07/2026 3. Nhấn nút Apply 4. Xem cột Tên KH của C301 và C302 | E37: - Tham số: Từ ngày = 01/07/2026; Đến ngày = 31/07/2026 - Case: C301, C302 | F37: 1. Báo cáo mở, hiển thị vùng tham số cùng nút Apply và Reset 2. Các tham số hiển thị đúng giá trị đã nhập 3. Báo cáo chạy xong, không hiển thị thông báo lỗi 4. C301 = Nguyễn Văn An; C302 = Công ty TNHH Thương mại Minh Phát | G37: SIT | H37: High | I37: Manual | J37: Untested | K37: Untested | L37: Untested
A38: MSB_TM-RP_TC_085 | B38: Kiểm tra hiển thị đúng Loại KH theo CIF của case | C38: - User: Đăng nhập tm_aml_maker (AML Maker – HO, HO0000001) - Màn hình: trang chủ Oracle Analytics Server (OAS) môi trường SIT, chưa mở báo cáo - Dữ liệu: bộ dữ liệu D-TM03 (mục 3.4 file rollup) đã dựng và batch dữ liệu báo cáo đã chạy; C302, C305, C307 là KHTC; các case còn lại là KHCN | D38: 1. Mở báo cáo "Báo cáo các cảnh báo chưa được xử lý" (Report TM_03) trên OAS 2. Nhập tham số: Từ ngày = 01/07/2026; Đến ngày = 31/07/2026 3. Nhấn nút Apply 4. Xem cột Loại KH của 13 dòng | E38: - Tham số: Từ ngày = 01/07/2026; Đến ngày = 31/07/2026 | F38: 1. Báo cáo mở, hiển thị vùng tham số cùng nút Apply và Reset 2. Các tham số hiển thị đúng giá trị đã nhập 3. Báo cáo chạy xong, không hiển thị thông báo lỗi 4. C302, C305, C307 = KHTC; 10 dòng còn lại = KHCN | G38: SIT | H38: High | I38: Manual | J38: Untested | K38: Untested | L38: Untested | N38: Q13
A39: MSB_TM-RP_TC_086 | B39: Kiểm tra lấy đúng Mã Đơn vị theo đơn vị quản lý CIF của case | C39: - User: Đăng nhập tm_aml_maker (AML Maker – HO, HO0000001) - Màn hình: trang chủ Oracle Analytics Server (OAS) môi trường SIT, chưa mở báo cáo - Dữ liệu: bộ dữ liệu D-TM03 (mục 3.4 file rollup) đã dựng và batch dữ liệu báo cáo đã chạy; C318 của CIF 10070018 do VN0010002 quản lý; các case khác do VN0010001 quản lý | D39: 1. Mở báo cáo "Báo cáo các cảnh báo chưa được xử lý" (Report TM_03) trên OAS 2. Nhập tham số: Từ ngày = 01/07/2026; Đến ngày = 31/07/2026 3. Nhấn nút Apply 4. Xem cột Mã Đơn vị của C318 và C301 | E39: - Tham số: Từ ngày = 01/07/2026; Đến ngày = 31/07/2026 - Case: C318, C301 | F39: 1. Báo cáo mở, hiển thị vùng tham số cùng nút Apply và Reset 2. Các tham số hiển thị đúng giá trị đã nhập 3. Báo cáo chạy xong, không hiển thị thông báo lỗi 4. C318 = VN0010002; C301 = VN0010001 | G39: SIT | H39: High | I39: Manual | J39: Untested | K39: Untested | L39: Untested
A40: MSB_TM-RP_TC_087 | B40: Kiểm tra hiển thị đúng Mã sự vụ và Ngày phát sinh sự vụ định dạng dd/mm/yyyy | C40: - User: Đăng nhập tm_aml_maker (AML Maker – HO, HO0000001) - Màn hình: trang chủ Oracle Analytics Server (OAS) môi trường SIT, chưa mở báo cáo - Dữ liệu: bộ dữ liệu D-TM03 (mục 3.4 file rollup) đã dựng và batch dữ liệu báo cáo đã chạy; C302 phát sinh ngày 05/07/2026 | D40: 1. Mở báo cáo "Báo cáo các cảnh báo chưa được xử lý" (Report TM_03) trên OAS 2. Nhập tham số: Từ ngày = 01/07/2026; Đến ngày = 31/07/2026 3. Nhấn nút Apply 4. Xem cột Mã sự vụ và Ngày phát sinh sự vụ của C302 | E40: - Tham số: Từ ngày = 01/07/2026; Đến ngày = 31/07/2026 - Case: C302 | F40: 1. Báo cáo mở, hiển thị vùng tham số cùng nút Apply và Reset 2. Các tham số hiển thị đúng giá trị đã nhập 3. Báo cáo chạy xong, không hiển thị thông báo lỗi 4. Mã sự vụ = Case ID thật của C302; Ngày phát sinh sự vụ = 05/07/2026 | G40: SIT | H40: Medium | I40: Manual | J40: Untested | K40: Untested | L40: Untested
A41: MSB_TM-RP_TC_088 | B41: Kiểm tra cột STT tự sinh tăng dần liên tục từ 1 | C41: - User: Đăng nhập tm_aml_maker (AML Maker – HO, HO0000001) - Màn hình: trang chủ Oracle Analytics Server (OAS) môi trường SIT, chưa mở báo cáo - Dữ liệu: bộ dữ liệu D-TM03 (mục 3.4 file rollup) đã dựng và batch dữ liệu báo cáo đã chạy | D41: 1. Mở báo cáo "Báo cáo các cảnh báo chưa được xử lý" (Report TM_03) trên OAS 2. Nhập tham số: Từ ngày = 01/07/2026; Đến ngày = 31/07/2026 3. Nhấn nút Apply 4. Xem cột STT từ dòng đầu đến dòng cuối | E41: - Tham số: Từ ngày = 01/07/2026; Đến ngày = 31/07/2026 | F41: 1. Báo cáo mở, hiển thị vùng tham số cùng nút Apply và Reset 2. Các tham số hiển thị đúng giá trị đã nhập 3. Báo cáo chạy xong, không hiển thị thông báo lỗi 4. STT chạy 1, 2, …, 13, không trùng, không ngắt quãng | G41: SIT | H41: Low | I41: Manual | J41: Untested | K41: Untested | L41: Untested
A42: — Tham số lọc & biên kỳ
A43: MSB_TM-RP_TC_089 | B43: Kiểm tra lấy đúng case ngày 01/07/2026 và loại trừ case ngày 30/06/2026 ở biên đầu kỳ | C43: - User: Đăng nhập tm_aml_maker (AML Maker – HO, HO0000001) - Màn hình: trang chủ Oracle Analytics Server (OAS) môi trường SIT, chưa mở báo cáo - Dữ liệu: bộ dữ liệu D-TM03 (mục 3.4 file rollup) đã dựng và batch dữ liệu báo cáo đã chạy; C315 (New) phát sinh 01/07/2026; C317 (New) phát sinh 30/06/2026 | D43: 1. Mở báo cáo "Báo cáo các cảnh báo chưa được xử lý" (Report TM_03) trên OAS 2. Nhập tham số: Từ ngày = 01/07/2026; Đến ngày = 31/07/2026 3. Nhấn nút Apply 4. Tìm C315 và C317 | E43: - Tham số: Từ ngày = 01/07/2026; Đến ngày = 31/07/2026 - Case: C315, C317 | F43: 1. Báo cáo mở, hiển thị vùng tham số cùng nút Apply và Reset 2. Các tham số hiển thị đúng giá trị đã nhập 3. Báo cáo chạy xong, không hiển thị thông báo lỗi 4. Có dòng C315; không có dòng C317 | G43: SIT | H43: Medium | I43: Manual | J43: Untested | K43: Untested | L43: Untested
