Workbook

Sheet Cover
E8: Test Report
C11: Project Name: | E11: DỰ ÁN TRIỂN KHAI BẢN QUYỀN PHẦN MỀM HỆ THỐNG AML MỚI | G11: Reviewer:
C12: Document Code: | E12: MSB_AML_Testcase_TF_Report | G12: Position:
C13: Originator: | G13: Reviewed Date:
C14: Position: | G14: Approver:
C15: Created Date: | E15: 46255 | G15: Position:
C16: Version: | E16: 1.1 | G16: Approved Date:

Sheet Records
A1: TABLE OF CONTENT
A3: No | B3: Items | C3: Content | H3: Note
A4: 1 | B4: Cover | C4: Cover
A5: 2 | B5: Records | C5: Record of changes
A6: 3 | B6: Changelog | C6: Bảng ghi nhận thay đổi so với phiên bản trước
A7: 4 | B7: Test Report | C7: Tổng hợp kết quả thực thi test
A8: 5 | B8: Report_01 | C8: Test case Báo cáo thống kê HIT theo từng giao dịch
A9: 6 | B9: Report_02 | C9: Test case Báo cáo tỷ lệ cảnh báo HIT theo nghiệp vụ
A10: 7 | B10: Report_03 | C10: Test case Báo cáo tỷ lệ cảnh báo theo rule quét sàng lọc
A11: 8 | B11: Report_04 | C11: Test case Báo cáo theo dõi Good Guy sắp đến hạn
A12: 9 | B12: Report_05 | C12: Test case Báo cáo các giao dịch đã bị từ chối
A13: 10 | B13: Report_Permission | C13: Test case phân quyền báo cáo (xem/xuất, phạm vi dữ liệu)
A15: Effective Date | B15: A, M, D | C15: Change Description | F15: New Version | G15: Author
A16: 46153 | B16: A | C16: Create new TC | F16: 1
A17: 46255 | B17: M | C17: Chi tiết tại sheet Changelog. | F17: 1.1

Sheet Test Report
B2: SYSTEM TEST REPORT
A5: Project | B5: DỰ ÁN TRIỂN KHAI BẢN QUYỀN PHẦN MỀM HỆ THỐNG AML MỚI | D5: Project manager
A6: Application | D6: Approved Date
A7: Consolidated By | D7: Reviewed By
A8: Build Versions | D8: Reviewed date
A9: Test Environment | B9: SIT
A10: Last Updated Date
A11: Test Execution Summary
A12: Reported by
A13: Date
A14: Test Results | B14: Passed | C14: Failed | D14: Accepted | E14: N/A | F14: Untested | G14: Total
A15: Tổng cộng | B15: =SUM(B16:B21) -> 105 | C15: =SUM(C16:C21) -> 0 | D15: =SUM(D16:D21) -> 0 | E15: =SUM(E16:E21) -> 0 | F15: =SUM(F16:F21) -> 34 | G15: =SUM(B15:F15) -> 139
A16: Report_01 | B16: =COUNTIF(Report_01!J:J,"Passed") -> 0 | C16: =COUNTIF(Report_01!J:J,"Failed") -> 0 | D16: =COUNTIF(Report_01!J:J,"Accepted") -> 0 | E16: =COUNTIF(Report_01!J:J,"N/A") -> 0 | F16: =COUNTIF(Report_01!J:J,"Untested") -> 34 | G16: =SUM(B16:F16) -> 34
A17: Report_02 | B17: =COUNTIF(Report_02!K:K,"Passed") -> 30 | C17: =COUNTIF(Report_02!K:K,"Failed") -> 0 | D17: =COUNTIF(Report_02!K:K,"Accepted") -> 0 | E17: =COUNTIF(Report_02!K:K,"N/A") -> 0 | F17: =COUNTIF(Report_02!K:K,"Untested") -> 0 | G17: =SUM(B17:F17) -> 30
A18: Report_03 | B18: =COUNTIF(Report_03!J:J,"Passed") -> 28 | C18: =COUNTIF(Report_03!J:J,"Failed") -> 0 | D18: =COUNTIF(Report_03!J:J,"Accepted") -> 0 | E18: =COUNTIF(Report_03!J:J,"N/A") -> 0 | F18: =COUNTIF(Report_03!J:J,"Untested") -> 0 | G18: =SUM(B18:F18) -> 28
A19: Report_04 | B19: =COUNTIF(Report_04!J:J,"Passed") -> 18 | C19: =COUNTIF(Report_04!J:J,"Failed") -> 0 | D19: =COUNTIF(Report_04!J:J,"Accepted") -> 0 | E19: =COUNTIF(Report_04!J:J,"N/A") -> 0 | F19: =COUNTIF(Report_04!J:J,"Untested") -> 0 | G19: =SUM(B19:F19) -> 18
A20: Report_05 | B20: =COUNTIF(Report_05!J:J,"Passed") -> 29 | C20: =COUNTIF(Report_05!J:J,"Failed") -> 0 | D20: =COUNTIF(Report_05!J:J,"Accepted") -> 0 | E20: =COUNTIF(Report_05!J:J,"N/A") -> 0 | F20: =COUNTIF(Report_05!J:J,"Untested") -> 0 | G20: =SUM(B20:F20) -> 29
A21: Report_Permission | B21: =COUNTIF(Report_Permission!J:J,"Passed") -> 0 | C21: =COUNTIF(Report_Permission!J:J,"Failed") -> 0 | D21: =COUNTIF(Report_Permission!J:J,"Accepted") -> 0 | E21: =COUNTIF(Report_Permission!J:J,"N/A") -> 0 | F21: =COUNTIF(Report_Permission!J:J,"Untested") -> 0 | G21: =SUM(B21:F21) -> 0
A25: Test coverage
A26: Test coverage | G26: =IFERROR(SUM(B15,C15,E15)/G15,0) -> 0.75539568
A27: Test successful coverage | G27: =IFERROR(SUM(B15,E15)/G15,0) -> 0.75539568
A28: Issues
A29: 1. Block testing issue
A30: 2. Critical defects
A35: BÁO CÁO | B35: Pass | C35: Fail | D35: Pending | E35: Cancel | F35: Untested | G35: Next | H35: TỔNG
A36: Report_01 | B36: =COUNTIF(Report_01!$K:$K,'Test Report'!B35) -> 0 | C36: =COUNTIF(Report_01!$K:$K,'Test Report'!C35) -> 0 | D36: =COUNTIF(Report_01!$K:$K,'Test Report'!D35) -> 0 | E36: =COUNTIF(Report_01!$K:$K,'Test Report'!E35) -> 0 | F36: =COUNTIF(Report_01!$K:$K,'Test Report'!F35) -> 0 | G36: =COUNTIF(Report_01!$K:$K,'Test Report'!G35) -> 0 | H36: =SUM(B36:G36) -> 0
A37: Report_02 | B37: =COUNTIF(Report_02!$K:$K,'Test Report'!B35) -> 0 | C37: =COUNTIF(Report_02!$K:$K,'Test Report'!C35) -> 0 | D37: =COUNTIF(Report_02!$K:$K,'Test Report'!D35) -> 0 | E37: =COUNTIF(Report_02!$K:$K,'Test Report'!E35) -> 0 | F37: =COUNTIF(Report_02!$K:$K,'Test Report'!F35) -> 0 | G37: =COUNTIF(Report_02!$K:$K,'Test Report'!G35) -> 0 | H37: =SUM(B37:G37) -> 0
A38: Report_03 | B38: =COUNTIF(Report_03!$J:$J,'Test Report'!B35) -> 0 | C38: =COUNTIF(Report_03!$J:$J,'Test Report'!C35) -> 0 | D38: =COUNTIF(Report_03!$J:$J,'Test Report'!D35) -> 0 | E38: =COUNTIF(Report_03!$J:$J,'Test Report'!E35) -> 0 | F38: =COUNTIF(Report_03!$J:$J,'Test Report'!F35) -> 0 | G38: =COUNTIF(Report_03!$J:$J,'Test Report'!G35) -> 0 | H38: =SUM(B38:G38) -> 0
A39: Report_04 | B39: =COUNTIF(Report_04!$J:$J,B35) -> 0 | C39: =COUNTIF(Report_04!$J:$J,C35) -> 0 | D39: =COUNTIF(Report_04!$J:$J,D35) -> 0 | E39: =COUNTIF(Report_04!$J:$J,E35) -> 0 | F39: =COUNTIF(Report_04!$J:$J,F35) -> 0 | G39: =COUNTIF(Report_04!$J:$J,G35) -> 0 | H39: =SUM(B39:G39) -> 0
A40: Report_05 | B40: =COUNTIF(Report_05!$J:$J,B35) -> 0 | C40: =COUNTIF(Report_05!$J:$J,C35) -> 0 | D40: =COUNTIF(Report_05!$J:$J,D35) -> 2 | E40: =COUNTIF(Report_05!$J:$J,E35) -> 0 | F40: =COUNTIF(Report_05!$J:$J,F35) -> 0 | G40: =COUNTIF(Report_05!$J:$J,G35) -> 0 | H40: =SUM(B40:G40) -> 2
A41: Tổng cộng | B41: =SUM(B36:B40) -> 0 | C41: =SUM(C36:C40) -> 0 | D41: =SUM(D36:D40) -> 2 | E41: =SUM(E36:E40) -> 0 | F41: =SUM(F36:F40) -> 0 | G41: =SUM(G36:G40) -> 0 | H41: =SUM(B41:G41) -> 2
B42: =B41/$H$41 -> 0 | C42: =C41/$H$41 -> 0 | D42: =D41/$H$41 -> 1 | E42: =E41/$H$41 -> 0 | F42: =F41/$H$41 -> 0 | G42: =G41/$H$41 -> 0

Sheet Report
A1: BÁO CÁO | B1: Passed | C1: Failed | D1: Pending | E1: Cancel | F1: Untested | G1: Next | H1: TỔNG
A2: Report_01 | B2: =Report_01!E7 -> 34 | C2: =Report_01!E8 -> 0 | D2: =Report_01!E9 -> 0 | E2: =Report_01!E10 -> 0 | F2: =Report_01!E11 -> 0 | G2: =Report_01!E12 -> 0 | H2: =SUM(B2:G2) -> 34
A3: Report_02 | B3: =Report_02!E7 -> 30 | C3: =Report_02!E8 -> 0 | D3: =Report_02!E9 -> 0 | E3: =Report_02!E10 -> 0 | F3: =Report_02!E11 -> 0 | G3: =Report_02!E12 -> 0 | H3: =SUM(B3:G3) -> 30
A4: Report_03 | B4: =Report_03!E7 -> 28 | C4: =Report_03!E8 -> 0 | D4: =Report_03!E9 -> 0 | E4: =Report_03!E10 -> 0 | F4: =Report_03!E11 -> 0 | G4: =Report_03!E12 -> 0 | H4: =SUM(B4:G4) -> 28
A5: Report_04 | B5: =Report_04!E7 -> 18 | C5: =Report_04!E8 -> 0 | D5: =Report_04!E9 -> 0 | E5: =Report_04!E10 -> 0 | F5: =Report_04!E11 -> 0 | G5: =Report_04!E12 -> 0 | H5: =SUM(B5:G5) -> 18
A6: Report_05 | B6: =Report_05!E7 -> 29 | C6: =Report_05!E8 -> 0 | D6: =Report_05!E9 -> 2 | E6: =Report_05!E10 -> 0 | F6: =Report_05!E11 -> 0 | G6: =Report_05!E12 -> 0 | H6: =SUM(B6:G6) -> 31
A7: Tổng cộng | B7: =SUM(B2:B6) -> 139 | C7: =SUM(C2:C6) -> 0 | D7: =SUM(D2:D6) -> 2 | E7: =SUM(E2:E6) -> 0 | F7: =SUM(F2:F6) -> 0 | G7: =SUM(G2:G6) -> 0 | H7: =SUM(B7:G7) -> 141
B8: =B7/$H$7 -> 0.9858156 | C8: =C7/$H$7 -> 0 | D8: =D7/$H$7 -> 0.014184397 | E8: =E7/$H$7 -> 0 | F8: =F7/$H$7 -> 0 | G8: =G7/$H$7 -> 0
A20: Passed
A21: Failed
A22: Pending
A23: Cancel
A24: Untested
A25: Next

Sheet Report_01
A1: Functions | B1: =Cover!E11 -> DỰ ÁN TRIỂN KHAI BẢN QUYỀN PHẦN MỀM HỆ THỐNG AML MỚI
A2: Build Version | B2: v1.0
A4: ROUND 2
B5: High | C5: Medium | D5: Low | E5: Total
B6: =SUM(B7:B11) -> 14 | C6: =SUM(C7:C11) -> 20 | D6: =SUM(D7:D11) -> 0 | E6: =SUM(B6:D6) -> 34
A7: Passed | B7: =COUNTIFS($H:$H,B$5,$K:$K,$A7) -> 14 | C7: =COUNTIFS($H:$H,C$5,$K:$K,$A7) -> 20 | D7: =COUNTIFS($H:$H,D$5,$K:$K,$A7) -> 0 | E7: =SUM(B7:D7) -> 34
A8: Failed | B8: =COUNTIFS($H:$H,B$5,$K:$K,$A8) -> 0 | C8: =COUNTIFS($H:$H,C$5,$K:$K,$A8) -> 0 | D8: =COUNTIFS($H:$H,D$5,$K:$K,$A8) -> 0 | E8: =SUM(B8:D8) -> 0
A9: Pending | B9: =COUNTIFS($H:$H,B$5,$K:$K,$A9) -> 0 | C9: =COUNTIFS($H:$H,C$5,$K:$K,$A9) -> 0 | D9: =COUNTIFS($H:$H,D$5,$K:$K,$A9) -> 0 | E9: =SUM(B9:D9) -> 0
A10: Cancel | B10: =COUNTIFS($H:$H,B$5,$K:$K,$A10) -> 0 | C10: =COUNTIFS($H:$H,C$5,$K:$K,$A10) -> 0 | D10: =COUNTIFS($H:$H,D$5,$K:$K,$A10) -> 0 | E10: =SUM(B10:D10) -> 0
A11: Untested | B11: =COUNTIFS($H:$H,B$5,$K:$K,$A11) -> 0 | C11: =COUNTIFS($H:$H,C$5,$K:$K,$A11) -> 0 | D11: =COUNTIFS($H:$H,D$5,$K:$K,$A11) -> 0 | E11: =SUM(B11:D11) -> 0
A12: Next | B12: =COUNTIFS($H:$H,B$5,$K:$K,$A12) -> 0 | C12: =COUNTIFS($H:$H,C$5,$K:$K,$A12) -> 0 | D12: =COUNTIFS($H:$H,D$5,$K:$K,$A12) -> 0 | E12: =SUM(B12:D12) -> 0
A14: ROUND 3
B15: High | C15: Medium | D15: Low | E15: Total
B16: =SUM(B17:B21) -> 14 | C16: =SUM(C17:C21) -> 20 | D16: =SUM(D17:D21) -> 0 | E16: =SUM(B16:D16) -> 34
A17: Passed | B17: =COUNTIFS($H:$H,B$15,$L:$L,$A17) -> 0 | C17: =COUNTIFS($H:$H,C$15,$L:$L,$A17) -> 0 | D17: =COUNTIFS($H:$H,D$15,$L:$L,$A17) -> 0 | E17: =SUM(B17:D17) -> 0
A18: Failed | B18: =COUNTIFS($H:$H,B$15,$L:$L,$A18) -> 0 | C18: =COUNTIFS($H:$H,C$15,$L:$L,$A18) -> 0 | D18: =COUNTIFS($H:$H,D$15,$L:$L,$A18) -> 0 | E18: =SUM(B18:D18) -> 0
A19: Pending | B19: =COUNTIFS($H:$H,B$15,$L:$L,$A19) -> 0 | C19: =COUNTIFS($H:$H,C$15,$L:$L,$A19) -> 0 | D19: =COUNTIFS($H:$H,D$15,$L:$L,$A19) -> 0 | E19: =SUM(B19:D19) -> 0
A20: Cancel | B20: =COUNTIFS($H:$H,B$15,$L:$L,$A20) -> 0 | C20: =COUNTIFS($H:$H,C$15,$L:$L,$A20) -> 0 | D20: =COUNTIFS($H:$H,D$15,$L:$L,$A20) -> 0 | E20: =SUM(B20:D20) -> 0
A21: Untested | B21: =COUNTIFS($H:$H,B$15,$L:$L,$A21) -> 14 | C21: =COUNTIFS($H:$H,C$15,$L:$L,$A21) -> 20 | D21: =COUNTIFS($H:$H,D$15,$L:$L,$A21) -> 0 | E21: =SUM(B21:D21) -> 34
A22: Next | B22: =COUNTIFS($H:$H,B$15,$L:$L,$A22) -> 0 | C22: =COUNTIFS($H:$H,C$15,$L:$L,$A22) -> 0 | D22: =COUNTIFS($H:$H,D$15,$L:$L,$A22) -> 0 | E22: =SUM(B22:D22) -> 0
A25: Test case Id | B25: Test case Title | C25: Pre-conditions | D25: Test Step | E25: Test Datas | F25: Expected result | G25: Test Environment | H25: Priority | I25: Automation Status | J25: 1st Test Results | K25: 2nd Test Results | L25: 3rd Test Results | M25: BugID | N25: Notes
A26: TF_RP1_01 | B26: Kiểm tra tiêu chí đầu vào báo cáo và các nút chức năng
A27: TF_RP1_01_01 | B27: Kiểm tra hiển thị các trường tham số | D27: 1. Đăng nhập vào Oracle Analytics Server 2. Mở báo cáo "Báo cáo thống kê hit theo từng giao dịch" | F27: Người dùng xem được các trường thông tin: - Từ ngày - Đến ngày - Đơn vị - Mã giao dịch Các nút chức năng: - Apply - Reset | G27: SIT | H27: Medium | I27: Manual | J27: Untested | K27: Passed | L27: Untested
A28: TF_RP1_01_02 | B28: Kiểm tra tham số Từ ngày | D28: 1. Đăng nhập vào Oracle Analytics Server 2. Mở báo cáo "Báo cáo thống kê hit theo từng giao dịch" 3. Kiểm tra tham số Từ ngày | F28: Hệ thống cho người dùng chọn theo bảng lịch, hiển thị dạng dd/mm/yyyy | G28: SIT | H28: Medium | I28: Manual | J28: Untested | K28: Passed | L28: Untested
A29: TF_RP1_01_03 | B29: Kiểm tra tham số Đến ngày | D29: 1. Đăng nhập vào Oracle Analytics Server 2. Mở báo cáo "Báo cáo thống kê hit theo từng giao dịch" 3. Kiểm tra tham số Đến ngày | F29: Hệ thống cho người dùng chọn theo bảng lịch, hiển thị dạng dd/mm/yyyy | G29: SIT | H29: Medium | I29: Manual | J29: Untested | K29: Passed | L29: Untested
A30: TF_RP1_01_04 | B30: Kiểm tra tham số Đơn vị | D30: 1. Đăng nhập vào Oracle Analytics Server 2. Mở báo cáo "Báo cáo thống kê hit theo từng giao dịch" 3. Kiểm tra tham số Đơn vị | F30: Hệ thống hiển thị danh sách các chi nhánh/PGD, cho phép người dùng chọn một hoặc nhiều và không bắt buộc chọn | G30: SIT | H30: Medium | I30: Manual | J30: Untested | K30: Passed | L30: Untested
A31: TF_RP1_01_05 | B31: Kiểm tra tham số Mã giao dịch | D31: 1. Đăng nhập vào Oracle Analytics Server 2. Mở báo cáo "Báo cáo thống kê hit theo từng giao dịch" 3. Kiểm tra tham số Mã giao dịch | F31: Hệ thống cho phép người dùng nhập giá trị mã giao dịch và không bắt buộc nhập | G31: SIT | H31: Medium | I31: Manual | J31: Untested | K31: Passed | L31: Untested
A32: TF_RP1_01_06 | B32: Kiểm tra nút chức năng 'Apply' | D32: 1. Đăng nhập vào Oracle Analytics Server 2. Mở báo cáo "Báo cáo thống kê hit theo từng giao dịch" 3. Nhập/Chọn thông tin các trường: - Chọn ngày trong trường 'Từ ngày' - Chọn ngày trong trường 'Đến ngày' - Nhập giá trị trường Đơn vị - Chọn giá trị trường Mã giao dịch 4. Bấm nút chức năng 'Apply' | F32: Người dùng xem được kết quả báo cáo | G32: SIT | H32: Medium | I32: Manual | J32: Untested | K32: Passed | L32: Untested
A33: TF_RP1_01_07 | B33: Kiểm tra nút chức năng 'Reset' | D33: 1. Đăng nhập vào Oracle Analytics Server 2. Mở báo cáo "Báo cáo thống kê hit theo từng giao dịch" 3. Nhập/Chọn thông tin các trường: - Chọn ngày trong trường 'Từ ngày' - Chọn ngày trong trường 'Đến ngày' - Nhập giá trị trường Đơn vị - Chọn giá trị trường Mã giao dịch 4. Bấm nút chức năng 'Reset' | F33: Hệ thống đặt lại tiêu chí lọc của người dùng theo lựa chọn tương ứng: - Reset to last applied values: Đặt lại về giá trị lọc trước đó - Reset to default values: Đặt lại về giá trị lọc của báo cáo - Clear All: Đặt lại toàn bộ tiêu chí lọc | G33: SIT | H33: Medium | I33: Manual | J33: Untested | K33: Passed | L33: Untested
A34: TF_RP1_02 | B34: Kiểm tra tiêu chí đầu ra mong muốn
A35: TF_RP1_02_01 | B35: Kiểm tra hiển thị báo cáo | C35: 1. NSD có quyền truy cập báo cáo. 2. Đã tồn tại giao dịch phát sinh HIT/Knocked-out trong kỳ báo cáo thuộc phạm vi đơn vị được phân quyền. | D35: 1. Đăng nhập vào Oracle Analytics Server 2. Mở báo cáo "Báo cáo thống kê hit theo từng giao dịch" 3. Nhập các tiêu chí lọc và đảm bảo nhập đủ các tiêu chí bắt buộc nhập 4. Bấm nút chức năng 'Apply' | E35: --report 1 WITH DS_PARAMS AS( SELECT TO_DATE('20260917','YYYYMMDD') AS P_FROM_DATE, TO_DATE('20260917','YYYYMMDD') AS P_TO_DATE, '' AS P_BRANCH_CD, '' AS P_TRANSATION_ID FROM DUAL ), DS_REPORT_1 AS( SELECT RA.N_ALERT_ID AS N_ALERT_ID, JSON_VALUE(RD.C_EXT_DATA,'$.transactionId') AS TRANSACTION_ID, RD.V_GRP_MSG_TYPE AS GRP_MSG_TYPE, DS.V_SWIFT_WEBSERVICE_DESC AS WEBSERVICE_NAME, REGEXP_SUBSTR(ST.V_RULE,'\[([^]]+)\]',1,1,NULL,1) AS RULE_CODE, ST.N_SCORE AS N_SCORE, SS.V_SANCTION_STATUS_NAME AS STATUS_NAME, ST.V_MATCHED_LIST_NAME AS MATCHED_LIST_NAME, ST.V_MATCHED_SUBLIST_NAME AS MATCHED_SUBLIST_NAME, CAST(ST.C_INPUT_STR AS VARCHAR2(4000)) AS KEY_WORD, COALESCE( ST.V_MATCHED_ENTITY_NAME, ST.V_MATCHED_INDIVIDUAL_NAME, ST.V_MATCHED_COUNTRY, ST.V_MATCHED_CITY, ST.V_MATCHED_BIC ) AS WATCHlIST, ST.V_MATCHED_LIST_REC_ID AS MATCHED_LIST_REC_ID, NVL( ST.V_TAG_NAME, REGEXP_REPLACE(MX.X_PATH,'\[[0-9]+\]','') ) AS TAG_NAME FROM FSI_RT_ALERTS RA INNER JOIN FSI_RT_RAW_DATA RD ON RA.N_GRP_MSG_ID = RD.N_GRP_MSG_ID INNER JOIN FSI_RT_AL_WLS_RESPONSE ST ON ST.N_GRP_MSG_ID = RA.N_GRP_MSG_ID INNER JOIN DIM_SWIFT_WEBSERVICE DS ON ST.N_WEBSERVICE_ID = DS.N_SWIFT_WEBSERVICE_ID LEFT JOIN FSI_RT_XML_WLS_RESPONSE MX ON MX.N_GRP_MSG_ID = RA.N_GRP_MSG_ID JOIN DIM_SANCTIONS_STATUS SS ON ST.N_IS_ACCEPTED = SS.N_SANCTION_STATUS_CODE CROSS JOIN DS_PARAMS P WHERE 1 = 1 AND TRUNC(RD.D_RECEIVED) BETWEEN P.P_FROM_DATE AND P.P_TO_DATE ---- ADD THÊM, NẾU LỌC THÊM THEO CHI NHANH --AND JSON_VALUE(RD.C_EXT_DATA,'$.branchCd') = P.P_BRANCH_CD ---- ADD THÊM, NẾU LỌC THÊM THEO TRANSACTION --AND JSON_VALUE(RD.C_EXT_DATA,'$.transactionId') = P.P_TRANSATION_ID ), DS_END AS( SELECT N_ALERT_ID, TRANSACTION_ID, GRP_MSG_TYPE, WEBSERVICE_NAME, RULE_CODE, N_SCORE, STATUS_NAME, MATCHED_LIST_NAME, MATCHED_SUBLIST_NAME, KEY_WORD, WATCHlIST, MATCHED_LIST_REC_ID, TAG_NAME, ROW_NUMBER() OVER(PARTITION BY N_ALERT_ID, TRANSACTION_ID, GRP_MSG_TYPE, WEBSERVICE_NAME, RULE_CODE, N_SCORE, STATUS_NAME, MATCHED_LIST_NAME, MATCHED_SUBLIST_NAME, KEY_WORD, WATCHlIST, MATCHED_LIST_REC_ID, TAG_NAME ORDER BY N_ALERT_ID ) AS RN FROM DS_REPORT_1 ) SELECT N_ALERT_ID, TRANSACTION_ID, GRP_MSG_TYPE, WEBSERVICE_NAME, RULE_CODE, N_SCORE, STATUS_NAME, MATCHED_LIST_NAME, MATCHED_SUBLIST_NAME, KEY_WORD, WATCHlIST, MATCHED_LIST_REC_ID, TAG_NAME FROM DS_END WHERE RN = 1; WITH DS_PARAMS AS( SELECT TO_DATE('20260917','YYYYMMDD') AS P_FROM_DATE, TO_DATE('20260917','YYYYMMDD') AS P_TO_DATE, '' AS P_BRANCH_CD, '' AS P_TRANSATION_ID FROM DUAL ), DS_REPORT_1 AS( SELECT RA.N_ALERT_ID AS N_ALERT_ID, JSON_VALUE(RD.C_EXT_DATA,'$.transactionId') AS TRANSACTION_ID, JSON_VALUE(RD.C_EXT_DATA,'$.branchCd') AS BRANCH_CD, -- Thêm cột Chi nhánh RD.V_GRP_MSG_TYPE AS GRP_MSG_TYPE, DS.V_SWIFT_WEBSERVICE_DESC AS WEBSERVICE_NAME, REGEXP_SUBSTR(ST.V_RULE,'\[([^]]+)\]',1,1,NULL,1) AS RULE_CODE, ST.N_SCORE AS N_SCORE, SS.V_SANCTION_STATUS_NAME AS STATUS_NAME, ST.V_MATCHED_LIST_NAME AS MATCHED_LIST_NAME, ST.V_MATCHED_SUBLIST_NAME AS MATCHED_SUBLIST_NAME, CAST(ST.C_INPUT_STR AS VARCHAR2(4000)) AS KEY_WORD, COALESCE( ST.V_MATCHED_ENTITY_NAME, ST.V_MATCHED_INDIVIDUAL_NAME, ST.V_MATCHED_COUNTRY, ST.V_MATCHED_CITY, ST.V_MATCHED_BIC ) AS WATCHlIST, ST.V_MATCHED_LIST_REC_ID AS MATCHED_LIST_REC_ID, NVL( ST.V_TAG_NAME, REGEXP_REPLACE(MX.X_PATH,'\[[0-9]+\]','') ) AS TAG_NAME FROM FSI_RT_ALERTS RA INNER JOIN FSI_RT_RAW_DATA RD ON RA.N_GRP_MSG_ID = RD.N_GRP_MSG_ID INNER JOIN FSI_RT_AL_WLS_RESPONSE ST ON ST.N_GRP_MSG_ID = RA.N_GRP_MSG_ID INNER JOIN DIM_SWIFT_WEBSERVICE DS ON ST.N_WEBSERVICE_ID = DS.N_SWIFT_WEBSERVICE_ID LEFT JOIN FSI_RT_XML_WLS_RESPONSE MX ON MX.N_GRP_MSG_ID = RA.N_GRP_MSG_ID JOIN DIM_SANCTIONS_STATUS SS ON ST.N_IS_ACCEPTED = SS.N_SANCTION_STATUS_CODE CROSS JOIN DS_PARAMS P WHERE 1 = 1 AND TRUNC(RD.D_RECEIVED) BETWEEN P.P_FROM_DATE AND P.P_TO_DATE ---- Bỏ comment dòng dưới nếu bạn muốn lọc luôn theo tham số Chi nhánh truyền vào --AND JSON_VALUE(RD.C_EXT_DATA,'$.branchCd') = P.P_BRANCH_CD ---- ADD THÊM, NẾU LỌC THÊM THEO TRANSACTION --AND JSON_VALUE(RD.C_EXT_DATA,'$.transactionId') = P.P_TRANSATION_ID ), DS_END AS( SELECT N_ALERT_ID, TRANSACTION_ID, BRANCH_CD, -- Thêm vào danh sách chọn GRP_MSG_TYPE, WEBSERVICE_NAME, RULE_CODE, N_SCORE, STATUS_NAME, MATCHED_LIST_NAME, MATCHED_SUBLIST_NAME, KEY_WORD, WATCHlIST, MATCHED_LIST_REC_ID, TAG_NAME, ROW_NUMBER() OVER(PARTITION BY N_ALERT_ID, TRANSACTION_ID, BRANCH_CD, -- Thêm vào Partition by để tránh mất dữ liệu trùng lặp theo nhánh GRP_MSG_TYPE, WEBSERVICE_NAME, RULE_CODE, N_SCORE, STATUS_NAME, MATCHED_LIST_NAME, MATCHED_SUBLIST_NAME, KEY_WORD, WATCHlIST, MATCHED_LIST_REC_ID, TAG_NAME ORDER BY N_ALERT_ID ) AS RN FROM DS_REPORT_1 ) SELECT N_ALERT_ID, TRANSACTION_ID, BRANCH_CD, -- Thêm vào câu lệnh SELECT cuối cùng GRP_MSG_TYPE, WEBSERVICE_NAME, RULE_CODE, N_SCORE, STATUS_NAME, MATCHED_LIST_NAME, MATCHED_SUBLIST_NAME, KEY_WORD, WATCHlIST, MATCHED_LIST_REC_ID, TAG_NAME FROM DS_END WHERE RN = 1; WITH DS_PARAMS AS( SELECT TO_DATE('20260917','YYYYMMDD') AS P_FROM_DATE, TO_DATE('20260917','YYYYMMDD') AS P_TO_DATE, '' AS P_BRANCH_CD, '' AS P_TRANSATION_ID FROM DUAL ), DS_REPORT_1 AS( SELECT RA.N_ALERT_ID AS N_ALERT_ID, JSON_VALUE(RD.C_EXT_DATA,'$.transactionId') AS TRANSACTION_ID, COALESCE( TRIM(JSON_VALUE(RD.C_EXT_DATA,'$.branchCd')), MAP_BRANCH.V_BRANCH_CODES ) AS BRANCH_CD, -- Bổ sung fallback lấy chi nhánh từ mapping nếu cần RD.V_GRP_MSG_TYPE AS GRP_MSG_TYPE, DS.V_SWIFT_WEBSERVICE_DESC AS WEBSERVICE_NAME, REGEXP_SUBSTR(ST.V_RULE,'\[([^]]+)\]',1,1,NULL,1) AS RULE_CODE, ST.N_SCORE AS N_SCORE, SS.V_SANCTION_STATUS_NAME AS STATUS_NAME, ST.V_MATCHED_LIST_NAME AS MATCHED_LIST_NAME, ST.V_MATCHED_SUBLIST_NAME AS MATCHED_SUBLIST_NAME, CAST(ST.C_INPUT_STR AS VARCHAR2(4000)) AS KEY_WORD, COALESCE( ST.V_MATCHED_ENTITY_NAME, ST.V_MATCHED_INDIVIDUAL_NAME, ST.V_MATCHED_COUNTRY, ST.V_MATCHED_CITY, ST.V_MATCHED_BIC ) AS WATCHlIST, ST.V_MATCHED_LIST_REC_ID AS MATCHED_LIST_REC_ID, NVL( ST.V_TAG_NAME, REGEXP_REPLACE(MX.X_PATH,'\[[0-9]+\]','') ) AS TAG_NAME FROM FSI_RT_ALERTS RA INNER JOIN FSI_RT_RAW_DATA RD ON RA.N_GRP_MSG_ID = RD.N_GRP_MSG_ID INNER JOIN FSI_RT_AL_WLS_RESPONSE ST ON ST.N_GRP_MSG_ID = RA.N_GRP_MSG_ID INNER JOIN DIM_SWIFT_WEBSERVICE DS ON ST.N_WEBSERVICE_ID = DS.N_SWIFT_WEBSERVICE_ID -- Sửa lại JOIN bảng XML theo N_RESPONSE_ID để chuẩn xác 1-1 với response chi tiết LEFT JOIN FSI_RT_XML_WLS_RESPONSE MX ON MX.N_RESPONSE_ID = ST.N_RESPONSE_ID LEFT JOIN MSB_GRPMSGTY_BRANCH_MAP MAP_BRANCH ON MAP_BRANCH.V_GRP_MSG_TYPE = RD.V_GRP_MSG_TYPE JOIN DIM_SANCTIONS_STATUS SS ON ST.N_IS_ACCEPTED = SS.N_SANCTION_STATUS_CODE CROSS JOIN DS_PARAMS P WHERE 1 = 1 -- Thay đổi từ RD.D_RECEIVED thành RA.D_CREATED AND TRUNC(RA.D_CREATED) BETWEEN P.P_FROM_DATE AND P.P_TO_DATE ---- Bỏ comment dòng dưới nếu bạn muốn lọc luôn theo tham số Chi nhánh truyền vào --AND JSON_VALUE(RD.C_EXT_DATA,'$.branchCd') = P.P_BRANCH_CD ---- ADD THÊM, NẾU LỌC THÊM THEO TRANSACTION --AND JSON_VALUE(RD.C_EXT_DATA,'$.transactionId') = P.P_TRANSATION_ID ), DS_END AS( SELECT N_ALERT_ID, TRANSACTION_ID, BRANCH_CD, GRP_MSG_TYPE, WEBSERVICE_NAME, RULE_CODE, N_SCORE, STATUS_NAME, MATCHED_LIST_NAME, MATCHED_SUBLIST_NAME, KEY_WORD, WATCHlIST, MATCHED_LIST_REC_ID, TAG_NAME, ROW_NUMBER() OVER(PARTITION BY N_ALERT_ID, TRANSACTION_ID, BRANCH_CD, GRP_MSG_TYPE, WEBSERVICE_NAME, RULE_CODE, N_SCORE, STATUS_NAME, MATCHED_LIST_NAME, MATCHED_SUBLIST_NAME, KEY_WORD, WATCHlIST, MATCHED_LIST_REC_ID, TAG_NAME ORDER BY N_ALERT_ID ) AS RN FROM DS_REPORT_1 ) SELECT N_ALERT_ID, TRANSACTION_ID, BRANCH_CD, GRP_MSG_TYPE, WEBSERVICE_NAME, RULE_CODE, N_SCORE, STATUS_NAME, MATCHED_LIST_NAME, MATCHED_SUBLIST_NAME, KEY_WORD, WATCHlIST, MATCHED_LIST_REC_ID, TAG_NAME FROM DS_END WHERE RN = 1; | F35: Người dùng xem được báo cáo hiển thị kết quả đầu ra bao gồm các trường thông tin sau: - ID của cảnh báo (alert) - Mã giao dịch - Loại điện - Webservices - Mã quy tắc quét - Match Score - Trạng thái đánh giá HIT - Nguồn danh sách HIT - Danh sách trùng khớp - Từ khóa HIT - Đối tượng hit nằm trong watch list - ID của đối tượng trong watch list - Tên trường HIT | G35: SIT | H35: High | I35: Manual | J35: Untested | K35: Passed | L35: Untested
A36: TF_RP1_02_02 | B36: Kiểm tra giá trị trường ID của cảnh báo (alert) | C36: 1. NSD có quyền truy cập báo cáo. 2. Đã tồn tại giao dịch phát sinh HIT/Knocked-out trong kỳ báo cáo thuộc phạm vi đơn vị được phân quyền. | D36: 1. Đăng nhập vào Oracle Analytics Server 2. Mở báo cáo "Báo cáo thống kê hit theo từng giao dịch" 3. Nhập các tiêu chí lọc và đảm bảo nhập đủ các tiêu chí bắt buộc nhập 4. Bấm nút chức năng 'Apply' | F36: Hệ thống hiển thị giá trị trường ID của cảnh báo (alert) | G36: SIT | H36: Medium | I36: Manual | J36: Untested | K36: Passed | L36: Untested
A37: TF_RP1_02_03 | B37: Kiểm tra giá trị trường Mã giao dịch | C37: 1. NSD có quyền truy cập báo cáo. 2. Đã tồn tại giao dịch phát sinh HIT/Knocked-out trong kỳ báo cáo thuộc phạm vi đơn vị được phân quyền. | D37: 1. Đăng nhập vào Oracle Analytics Server 2. Mở báo cáo "Báo cáo thống kê hit theo từng giao dịch" 3. Nhập các tiêu chí lọc và đảm bảo nhập đủ các tiêu chí bắt buộc nhập 4. Bấm nút chức năng 'Apply' | F37: Hệ thống hiển thị giá trị trường Mã giao dịch | G37: SIT | H37: Medium | I37: Manual | J37: Untested | K37: Passed | L37: Untested
A38: TF_RP1_02_04 | B38: Kiểm tra giá trị trường Loại điện | C38: 1. NSD có quyền truy cập báo cáo. 2. Đã tồn tại giao dịch phát sinh HIT/Knocked-out trong kỳ báo cáo thuộc phạm vi đơn vị được phân quyền. | D38: 1. Đăng nhập vào Oracle Analytics Server 2. Mở báo cáo "Báo cáo thống kê hit theo từng giao dịch" 3. Nhập các tiêu chí lọc và đảm bảo nhập đủ các tiêu chí bắt buộc nhập 4. Bấm nút chức năng 'Apply' | F38: Hệ thống hiển thị giá trị trường Loại điện | G38: SIT | H38: Medium | I38: Manual | J38: Untested | K38: Passed | L38: Untested
A39: TF_RP1_02_05 | B39: Kiểm tra giá trị trường Webservices | C39: 1. NSD có quyền truy cập báo cáo. 2. Đã tồn tại giao dịch phát sinh HIT/Knocked-out trong kỳ báo cáo thuộc phạm vi đơn vị được phân quyền. | D39: 1. Đăng nhập vào Oracle Analytics Server 2. Mở báo cáo "Báo cáo thống kê hit theo từng giao dịch" 3. Nhập các tiêu chí lọc và đảm bảo nhập đủ các tiêu chí bắt buộc nhập 4. Bấm nút chức năng 'Apply' | F39: Hệ thống hiển thị giá trị trường Webservices | G39: SIT | H39: Medium | I39: Manual | J39: Untested | K39: Passed | L39: Untested
A40: TF_RP1_02_06 | B40: Kiểm tra giá trị trường Mã quy tắc quét | C40: 1. NSD có quyền truy cập báo cáo. 2. Đã tồn tại giao dịch phát sinh HIT/Knocked-out trong kỳ báo cáo thuộc phạm vi đơn vị được phân quyền. | D40: 1. Đăng nhập vào Oracle Analytics Server 2. Mở báo cáo "Báo cáo thống kê hit theo từng giao dịch" 3. Nhập các tiêu chí lọc và đảm bảo nhập đủ các tiêu chí bắt buộc nhập 4. Bấm nút chức năng 'Apply' | F40: Hệ thống hiển thị giá trị trường Mã quy tắc quét | G40: SIT | H40: Medium | I40: Manual | J40: Untested | K40: Passed | L40: Untested
A41: TF_RP1_02_07 | B41: Kiểm tra giá trị trường Match Score | C41: 1. NSD có quyền truy cập báo cáo. 2. Đã tồn tại giao dịch phát sinh HIT/Knocked-out trong kỳ báo cáo thuộc phạm vi đơn vị được phân quyền. | D41: 1. Đăng nhập vào Oracle Analytics Server 2. Mở báo cáo "Báo cáo thống kê hit theo từng giao dịch" 3. Nhập các tiêu chí lọc và đảm bảo nhập đủ các tiêu chí bắt buộc nhập 4. Bấm nút chức năng 'Apply' | F41: Hệ thống hiển thị giá trị trường Match Score | G41: SIT | H41: Medium | I41: Manual | J41: Untested | K41: Passed | L41: Untested
A42: TF_RP1_02_08 | B42: Kiểm tra giá trị trường Trạng thái đánh giá HIT | C42: 1. NSD có quyền truy cập báo cáo. 2. Đã tồn tại giao dịch phát sinh HIT/Knocked-out trong kỳ báo cáo thuộc phạm vi đơn vị được phân quyền. | D42: 1. Đăng nhập vào Oracle Analytics Server 2. Mở báo cáo "Báo cáo thống kê hit theo từng giao dịch" 3. Nhập các tiêu chí lọc và đảm bảo nhập đủ các tiêu chí bắt buộc nhập 4. Bấm nút chức năng 'Apply' | F42: Hệ thống hiển thị giá trị trường Trạng thái đánh giá HIT | G42: SIT | H42: Medium | I42: Manual | J42: Untested | K42: Passed | L42: Untested
A43: TF_RP1_02_09 | B43: Kiểm tra giá trị trường Nguồn danh sách HIT | C43: 1. NSD có quyền truy cập báo cáo. 2. Đã tồn tại giao dịch phát sinh HIT/Knocked-out trong kỳ báo cáo thuộc phạm vi đơn vị được phân quyền. | D43: 1. Đăng nhập vào Oracle Analytics Server 2. Mở báo cáo "Báo cáo thống kê hit theo từng giao dịch" 3. Nhập các tiêu chí lọc và đảm bảo nhập đủ các tiêu chí bắt buộc nhập 4. Bấm nút chức năng 'Apply' | F43: Hệ thống hiển thị giá trị trường Nguồn danh sách HIT | G43: SIT | H43: Medium | I43: Manual | J43: Untested | K43: Passed | L43: Untested
A44: TF_RP1_02_10 | B44: Kiểm tra giá trị trường Danh sách trùng khớp | C44: 1. NSD có quyền truy cập báo cáo. 2. Đã tồn tại giao dịch phát sinh HIT/Knocked-out trong kỳ báo cáo thuộc phạm vi đơn vị được phân quyền. | D44: 1. Đăng nhập vào Oracle Analytics Server 2. Mở báo cáo "Báo cáo thống kê hit theo từng giao dịch" 3. Nhập các tiêu chí lọc và đảm bảo nhập đủ các tiêu chí bắt buộc nhập 4. Bấm nút chức năng 'Apply' | F44: Hệ thống hiển thị giá trị trường Danh sách trùng khớp | G44: SIT | H44: Medium | I44: Manual | J44: Untested | K44: Passed | L44: Untested
...

Sheet Report_02
A1: Functions | B1: =Cover!E11 -> DỰ ÁN TRIỂN KHAI BẢN QUYỀN PHẦN MỀM HỆ THỐNG AML MỚI
A2: Build Version | B2: v1.0
A4: ROUND 2
B5: High | C5: Medium | D5: Low | E5: Total
B6: =SUM(B7:B11) -> 16 | C6: =SUM(C7:C11) -> 14 | D6: =SUM(D7:D11) -> 0 | E6: =SUM(B6:D6) -> 30
A7: Passed | B7: =COUNTIFS($H:$H,B$5,$K:$K,$A7) -> 16 | C7: =COUNTIFS($H:$H,C$5,$K:$K,$A7) -> 14 | D7: =COUNTIFS($H:$H,D$5,$K:$K,$A7) -> 0 | E7: =SUM(B7:D7) -> 30
A8: Failed | B8: =COUNTIFS($H:$H,B$5,$K:$K,$A8) -> 0 | C8: =COUNTIFS($H:$H,C$5,$K:$K,$A8) -> 0 | D8: =COUNTIFS($H:$H,D$5,$K:$K,$A8) -> 0 | E8: =SUM(B8:D8) -> 0
A9: Pending | B9: =COUNTIFS($H:$H,B$5,$K:$K,$A9) -> 0 | C9: =COUNTIFS($H:$H,C$5,$K:$K,$A9) -> 0 | D9: =COUNTIFS($H:$H,D$5,$K:$K,$A9) -> 0 | E9: =SUM(B9:D9) -> 0
A10: Cancel | B10: =COUNTIFS($H:$H,B$5,$K:$K,$A10) -> 0 | C10: =COUNTIFS($H:$H,C$5,$K:$K,$A10) -> 0 | D10: =COUNTIFS($H:$H,D$5,$K:$K,$A10) -> 0 | E10: =SUM(B10:D10) -> 0
A11: Untested | B11: =COUNTIFS($H:$H,B$5,$K:$K,$A11) -> 0 | C11: =COUNTIFS($H:$H,C$5,$K:$K,$A11) -> 0 | D11: =COUNTIFS($H:$H,D$5,$K:$K,$A11) -> 0 | E11: =SUM(B11:D11) -> 0
A12: Next | B12: =COUNTIFS($H:$H,B$5,$K:$K,$A12) -> 0 | C12: =COUNTIFS($H:$H,C$5,$K:$K,$A12) -> 0 | D12: =COUNTIFS($H:$H,D$5,$K:$K,$A12) -> 0 | E12: =SUM(B12:D12) -> 0
A14: ROUND 3
B15: High | C15: Medium | D15: Low | E15: Total
B16: =SUM(B17:B21) -> 16 | C16: =SUM(C17:C21) -> 14 | D16: =SUM(D17:D21) -> 0 | E16: =SUM(B16:D16) -> 30
A17: Passed | B17: =COUNTIFS($H:$H,B$15,$L:$L,$A17) -> 0 | C17: =COUNTIFS($H:$H,C$15,$L:$L,$A17) -> 0 | D17: =COUNTIFS($H:$H,D$15,$L:$L,$A17) -> 0 | E17: =SUM(B17:D17) -> 0
A18: Failed | B18: =COUNTIFS($H:$H,B$15,$L:$L,$A18) -> 0 | C18: =COUNTIFS($H:$H,C$15,$L:$L,$A18) -> 0 | D18: =COUNTIFS($H:$H,D$15,$L:$L,$A18) -> 0 | E18: =SUM(B18:D18) -> 0
A19: Pending | B19: =COUNTIFS($H:$H,B$15,$L:$L,$A19) -> 0 | C19: =COUNTIFS($H:$H,C$15,$L:$L,$A19) -> 0 | D19: =COUNTIFS($H:$H,D$15,$L:$L,$A19) -> 0 | E19: =SUM(B19:D19) -> 0
A20: Cancel | B20: =COUNTIFS($H:$H,B$15,$L:$L,$A20) -> 0 | C20: =COUNTIFS($H:$H,C$15,$L:$L,$A20) -> 0 | D20: =COUNTIFS($H:$H,D$15,$L:$L,$A20) -> 0 | E20: =SUM(B20:D20) -> 0
A21: Untested | B21: =COUNTIFS($H:$H,B$15,$L:$L,$A21) -> 16 | C21: =COUNTIFS($H:$H,C$15,$L:$L,$A21) -> 14 | D21: =COUNTIFS($H:$H,D$15,$L:$L,$A21) -> 0 | E21: =SUM(B21:D21) -> 30
A22: Next | B22: =COUNTIFS($H:$H,B$15,$L:$L,$A22) -> 0 | C22: =COUNTIFS($H:$H,C$15,$L:$L,$A22) -> 0 | D22: =COUNTIFS($H:$H,D$15,$L:$L,$A22) -> 0
A24: Test case Id | B24: Test case Title | C24: Pre-conditions | D24: Test Step | E24: Test Datas | F24: Expected result | G24: Test Environment | H24: Priority | I24: Automation Status | J24: 1st | K24: 2st Test Results | L24: 3nd Test Results | M24: BugID | N24: Notes
A25: TF_RP2_01 | B25: Kiểm tra tiêu chí đầu vào báo cáo và các nút chức năng
A26: TF_RP2_01_01 | B26: Kiểm tra hiển thị các trường tham số | D26: 1. Đăng nhập vào Oracle Analytics Server 2. Mở báo cáo "Báo cáo tỷ lệ cảnh báo hit theo nghiệp vụ" | F26: Người dùng xem được các trường thông tin: - Từ ngày - Đến ngày - Đơn vị Các nút chức năng: - Apply - Reset | G26: SIT | H26: Medium | I26: Manual | J26: Untested | K26: Passed | L26: Untested
A27: TF_RP2_01_02 | B27: Kiểm tra tham số Từ ngày | D27: 1. Đăng nhập vào Oracle Analytics Server 2. Mở báo cáo "Báo cáo tỷ lệ cảnh báo hit theo nghiệp vụ" 3. Kiểm tra tham số Từ ngày | F27: Hệ thống cho người dùng chọn theo bảng lịch, hiển thị dạng dd/mm/yyyy | G27: SIT | H27: Medium | I27: Manual | J27: Untested | K27: Passed | L27: Untested
A28: TF_RP2_01_03 | B28: Kiểm tra tham số Đến ngày | D28: 1. Đăng nhập vào Oracle Analytics Server 2. Mở báo cáo "Báo cáo tỷ lệ cảnh báo hit theo nghiệp vụ" 3. Kiểm tra tham số Đến ngày | F28: Hệ thống cho người dùng chọn theo bảng lịch, hiển thị dạng dd/mm/yyyy | G28: SIT | H28: Medium | I28: Manual | J28: Untested | K28: Passed | L28: Untested
A29: TF_RP2_01_04 | B29: Kiểm tra tham số Đơn vị | D29: 1. Đăng nhập vào Oracle Analytics Server 2. Mở báo cáo "Báo cáo tỷ lệ cảnh báo hit theo nghiệp vụ" 3. Kiểm tra tham số Đơn vị | F29: Hệ thống hiển thị danh sách các chi nhánh/PGD, cho phép người dùng chọn một hoặc nhiều và không bắt buộc chọn | G29: SIT | H29: Medium | I29: Manual | J29: Untested | K29: Passed | L29: Untested
A30: TF_RP2_01_05 | B30: Kiểm tra nút chức năng 'Apply' | D30: 1. Đăng nhập vào Oracle Analytics Server 2. Mở báo cáo "Báo cáo tỷ lệ cảnh báo hit theo nghiệp vụ" 3. Nhập/Chọn thông tin các trường: - Chọn ngày trong trường 'Từ ngày' - Chọn ngày trong trường 'Đến ngày' - Nhập giá trị trường Đơn vị 4. Bấm nút chức năng 'Apply' | F30: Người dùng xem được kết quả báo cáo | G30: SIT | H30: Medium | I30: Manual | J30: Untested | K30: Passed | L30: Untested
A31: TF_RP2_01_06 | B31: Kiểm tra nút chức năng 'Reset' | D31: 1. Đăng nhập vào Oracle Analytics Server 2. Mở báo cáo "Báo cáo tỷ lệ cảnh báo hit theo nghiệp vụ" 3. Nhập/Chọn thông tin các trường: - Chọn ngày trong trường 'Từ ngày' - Chọn ngày trong trường 'Đến ngày' - Nhập giá trị trường Đơn vị 4. Bấm nút chức năng 'Reset' | F31: Hệ thống đặt lại tiêu chí lọc của người dùng theo lựa chọn tương ứng: - Reset to last applied values: Đặt lại về giá trị lọc trước đó - Reset to default values: Đặt lại về giá trị lọc của báo cáo - Clear All: Đặt lại toàn bộ tiêu chí lọc | G31: SIT | H31: Medium | I31: Manual | J31: Untested | K31: Passed | L31: Untested
A32: TF_RP2_02 | B32: Kiểm tra tiêu chí đầu ra mong muốn | N32: Đã BỎ cột 'Tổng số lượng giao dịch có cảnh báo chính xác' theo ghi chú MSB (trùng với 'cảnh báo thật'). Header PL vẫn còn cột này -> cần chốt chính thức; nếu giữ lại phải bổ sung TC.
A33: TF_RP2_02_01 | B33: Kiểm tra hiển thị báo cáo | C33: 1. NSD có quyền truy cập báo cáo. 2. Đã có giao dịch được quét và cảnh báo đã được đánh giá (True/False) trong kỳ báo cáo. | D33: 1. Đăng nhập vào Oracle Analytics Server 2. Mở báo cáo "Báo cáo tỷ lệ cảnh báo hit theo nghiệp vụ" 3. Nhập các tiêu chí lọc và đảm bảo nhập đủ các tiêu chí bắt buộc nhập 4. Bấm nút chức năng 'Apply' | E33: WITH DS_PARAMS AS ( SELECT TO_DATE('20260828','YYYYMMDD') AS P_FROM_DATE, TO_DATE('20260828','YYYYMMDD') AS P_TO_DATE, '' AS P_BRANCH_CD -- điền mã đơn vị để lọc; '' = tất cả FROM DUAL ), DS_REPORT_2 AS ( SELECT JSON_VALUE(RD.C_EXT_DATA,'$.branchCd') AS BRANCH_CD, COUNT(DISTINCT RD.N_GRP_MSG_ID) AS TOTAL_SCANNED, COUNT(DISTINCT RA.N_GRP_MSG_ID) AS TOTAL_HIT, COUNT(DISTINCT CASE WHEN RA.N_STATUS_CD IN (126,127,128,130,131,134,135) THEN RA.N_GRP_MSG_ID END) AS TOTAL_RATED, COUNT(DISTINCT CASE WHEN RA.N_STATUS_CD IN (127,130,134) THEN RA.N_GRP_MSG_ID END) AS TOTAL_FALSE, COUNT(DISTINCT CASE WHEN RA.N_STATUS_CD IN (126,128,131,135) THEN RA.N_GRP_MSG_ID END) AS TOTAL_TRUE FROM FSI_RT_RAW_DATA RD LEFT JOIN FSI_RT_ALERTS RA ON RA.N_GRP_MSG_ID = RD.N_GRP_MSG_ID CROSS JOIN DS_PARAMS P WHERE 1 = 1 AND TRUNC(RD.D_RECEIVED) BETWEEN P.P_FROM_DATE AND P.P_TO_DATE ---- LỌC THEO CHI NHÁNH (bỏ -- và điền P_BRANCH_CD để bật) --AND JSON_VALUE(RD.C_EXT_DATA,'$.branchCd') = P.P_BRANCH_CD GROUP BY JSON_VALUE(RD.C_EXT_DATA,'$.branchCd') ) SELECT BRANCH_CD AS "Đơn vị", TOTAL_SCANNED AS "Tổng GD được quét", TOTAL_HIT AS "Tổng GD bị hit rule", TOTAL_RATED AS "Tổng GD đã đánh giá", TOTAL_FALSE AS "Tổng GD cảnh báo giả", TOTAL_TRUE AS "Tổng GD cảnh báo thật", ROUND(TOTAL_FALSE / GREATEST(TOTAL_RATED,1) * 100, 2) AS "Tỷ lệ cảnh báo giả (%)", ROUND(TOTAL_TRUE / GREATEST(TOTAL_RATED,1) * 100, 2) AS "Tỷ lệ cảnh báo thật (%)" FROM DS_REPORT_2 ORDER BY BRANCH_CD; | F33: Người dùng xem được báo cáo hiển thị kết quả đầu ra bao gồm các trường thông tin sau: - Đơn vị - Tổng số lượng giao dịch được quét - Tổng số giao dịch bị hit rule sàng lọc giao dịch - Tổng số lượng giao dịch đánh giá - Tổng số lượng giao dịch có cảnh báo giả - Tổng số lượng giao dịch có cảnh báo thật - Tỷ lệ cảnh báo giả - Tỷ lệ cảnh báo thật | G33: SIT | H33: High | I33: Manual | J33: Untested | K33: Passed | L33: Untested
A34: TF_RP2_02_02 | B34: Kiểm tra giá trị trường Đơn vị | C34: 1. NSD có quyền truy cập báo cáo. 2. Đã có giao dịch được quét và cảnh báo đã được đánh giá (True/False) trong kỳ báo cáo. | D34: 1. Đăng nhập vào Oracle Analytics Server 2. Mở báo cáo "Báo cáo tỷ lệ cảnh báo hit theo nghiệp vụ" 3. Nhập các tiêu chí lọc và đảm bảo nhập đủ các tiêu chí bắt buộc nhập 4. Bấm nút chức năng 'Apply' | F34: Hệ thống hiển thị giá trị trường Đơn vị | G34: SIT | H34: Medium | I34: Manual | J34: Untested | K34: Passed | L34: Untested
A35: TF_RP2_02_03 | B35: Kiểm tra giá trị trường Tổng số lượng giao dịch được quét | C35: 1. NSD có quyền truy cập báo cáo. 2. Đã có giao dịch được quét và cảnh báo đã được đánh giá (True/False) trong kỳ báo cáo. | D35: 1. Đăng nhập vào Oracle Analytics Server 2. Mở báo cáo "Báo cáo tỷ lệ cảnh báo hit theo nghiệp vụ" 3. Nhập các tiêu chí lọc và đảm bảo nhập đủ các tiêu chí bắt buộc nhập 4. Bấm nút chức năng 'Apply' | F35: Hệ thống hiển thị giá trị trường Tổng số lượng giao dịch được quét | G35: SIT | H35: Medium | I35: Manual | J35: Untested | K35: Passed | L35: Untested
A36: TF_RP2_02_04 | B36: Kiểm tra giá trị trường Tổng số giao dịch bị hit rule sàng lọc giao dịch | C36: 1. NSD có quyền truy cập báo cáo. 2. Đã có giao dịch được quét và cảnh báo đã được đánh giá (True/False) trong kỳ báo cáo. | D36: 1. Đăng nhập vào Oracle Analytics Server 2. Mở báo cáo "Báo cáo tỷ lệ cảnh báo hit theo nghiệp vụ" 3. Nhập các tiêu chí lọc và đảm bảo nhập đủ các tiêu chí bắt buộc nhập 4. Bấm nút chức năng 'Apply' | F36: Hệ thống hiển thị giá trị trường Tổng số giao dịch bị hit rule sàng lọc giao dịch | G36: SIT | H36: Medium | I36: Manual | J36: Untested | K36: Passed | L36: Untested
A37: TF_RP2_02_05 | B37: Kiểm tra giá trị trường Tổng số lượng giao dịch đánh giá | C37: 1. NSD có quyền truy cập báo cáo. 2. Đã có giao dịch được quét và cảnh báo đã được đánh giá (True/False) trong kỳ báo cáo. | D37: 1. Đăng nhập vào Oracle Analytics Server 2. Mở báo cáo "Báo cáo tỷ lệ cảnh báo hit theo nghiệp vụ" 3. Nhập các tiêu chí lọc và đảm bảo nhập đủ các tiêu chí bắt buộc nhập 4. Bấm nút chức năng 'Apply' | F37: Hệ thống hiển thị giá trị trường Tổng số lượng giao dịch đánh giá | G37: SIT | H37: Medium | I37: Manual | J37: Untested | K37: Passed | L37: Untested
A38: TF_RP2_02_06 | B38: Kiểm tra giá trị trường Tổng số lượng giao dịch có cảnh báo giả | C38: 1. NSD có quyền truy cập báo cáo. 2. Đã có giao dịch được quét và cảnh báo đã được đánh giá (True/False) trong kỳ báo cáo. | D38: 1. Đăng nhập vào Oracle Analytics Server 2. Mở báo cáo "Báo cáo tỷ lệ cảnh báo hit theo nghiệp vụ" 3. Nhập các tiêu chí lọc và đảm bảo nhập đủ các tiêu chí bắt buộc nhập 4. Bấm nút chức năng 'Apply' | F38: Hệ thống hiển thị giá trị trường Tổng số lượng giao dịch có cảnh báo giả | G38: SIT | H38: Medium | I38: Manual | J38: Untested | K38: Passed | L38: Untested
A39: TF_RP2_02_07 | B39: Kiểm tra giá trị trường Tổng số lượng giao dịch có cảnh báo thật | C39: 1. NSD có quyền truy cập báo cáo. 2. Đã có giao dịch được quét và cảnh báo đã được đánh giá (True/False) trong kỳ báo cáo. | D39: 1. Đăng nhập vào Oracle Analytics Server 2. Mở báo cáo "Báo cáo tỷ lệ cảnh báo hit theo nghiệp vụ" 3. Nhập các tiêu chí lọc và đảm bảo nhập đủ các tiêu chí bắt buộc nhập 4. Bấm nút chức năng 'Apply' | F39: Hệ thống hiển thị giá trị trường Tổng số lượng giao dịch có cảnh báo thật | G39: SIT | H39: Medium | I39: Manual | J39: Untested | K39: Passed | L39: Untested
A40: TF_RP2_02_08 | B40: Kiểm tra giá trị trường Tỷ lệ cảnh báo giả | C40: 1. NSD có quyền truy cập báo cáo. 2. Đã có giao dịch được quét và cảnh báo đã được đánh giá (True/False) trong kỳ báo cáo. | D40: 1. Đăng nhập vào Oracle Analytics Server 2. Mở báo cáo "Báo cáo tỷ lệ cảnh báo hit theo nghiệp vụ" 3. Nhập các tiêu chí lọc và đảm bảo nhập đủ các tiêu chí bắt buộc nhập 4. Bấm nút chức năng 'Apply' | F40: Hệ thống hiển thị giá trị trường Tỷ lệ cảnh báo giả | G40: SIT | H40: Medium | I40: Manual | J40: Untested | K40: Passed | L40: Untested
A41: TF_RP2_02_09 | B41: Kiểm tra giá trị trường Tỷ lệ cảnh báo thật | C41: 1. NSD có quyền truy cập báo cáo. 2. Đã có giao dịch được quét và cảnh báo đã được đánh giá (True/False) trong kỳ báo cáo. | D41: 1. Đăng nhập vào Oracle Analytics Server 2. Mở báo cáo "Báo cáo tỷ lệ cảnh báo hit theo nghiệp vụ" 3. Nhập các tiêu chí lọc và đảm bảo nhập đủ các tiêu chí bắt buộc nhập 4. Bấm nút chức năng 'Apply' | F41: Hệ thống hiển thị giá trị trường Tỷ lệ cảnh báo thật | G41: SIT | H41: Medium | I41: Manual | J41: Untested | K41: Passed | L41: Untested
A42: TF_RP2_03 | B42: Kiểm tra tính năng trích xuất dữ liệu báo cáo
A43: TF_RP2_03_01 | B43: Kiểm tra tính năng cho phép xuất báo cáo theo định dạng file excel | D43: 1. Đăng nhập vào Oracle Analytics Server 2. Mở báo cáo "Báo cáo tỷ lệ cảnh báo hit theo nghiệp vụ" 3. Trên màn hình báo cáo, người dùng click vào chữ Export ở cuối màn hình -> chọn Formatted -> Excel | F43: 1. Người dùng xuất được báo cáo theo định dạng file excel 2. Báo cáo xuất ra hiển thị thông tin trùng khớp với template | G43: SIT | H43: High | I43: Manual | J43: Untested | K43: Passed | L43: Untested
...

Sheet Report_03
A1: Functions | B1: =Cover!E11 -> DỰ ÁN TRIỂN KHAI BẢN QUYỀN PHẦN MỀM HỆ THỐNG AML MỚI
A2: Build Version | B2: v1.0
A4: ROUND 2
B5: High | C5: Medium | D5: Low | E5: Total
B6: =SUM(B7:B11) -> 13 | C6: =SUM(C7:C11) -> 15 | D6: =SUM(D7:D11) -> 0 | E6: =SUM(B6:D6) -> 28
A7: Passed | B7: =COUNTIFS($J:$J,$A7,$H:$H,B$5) -> 13 | C7: =COUNTIFS($J:$J,$A7,$H:$H,C$5) -> 15 | D7: =COUNTIFS($J:$J,$A7,$H:$H,D$5) -> 0 | E7: =SUM(B7:D7) -> 28
A8: Failed | B8: =COUNTIFS($J:$J,$A8,$H:$H,B$5) -> 0 | C8: =COUNTIFS($J:$J,$A8,$H:$H,C$5) -> 0 | D8: =COUNTIFS($J:$J,$A8,$H:$H,D$5) -> 0 | E8: =SUM(B8:D8) -> 0
A9: Pending | B9: =COUNTIFS($J:$J,$A9,$H:$H,B$5) -> 0 | C9: =COUNTIFS($J:$J,$A9,$H:$H,C$5) -> 0 | D9: =COUNTIFS($J:$J,$A9,$H:$H,D$5) -> 0 | E9: =SUM(B9:D9) -> 0
A10: Cancel | B10: =COUNTIFS($J:$J,$A10,$H:$H,B$5) -> 0 | C10: =COUNTIFS($J:$J,$A10,$H:$H,C$5) -> 0 | D10: =COUNTIFS($J:$J,$A10,$H:$H,D$5) -> 0 | E10: =SUM(B10:D10) -> 0
A11: Untested | B11: =COUNTIFS($J:$J,$A11,$H:$H,B$5) -> 0 | C11: =COUNTIFS($J:$J,$A11,$H:$H,C$5) -> 0 | D11: =COUNTIFS($J:$J,$A11,$H:$H,D$5) -> 0 | E11: =SUM(B11:D11) -> 0
A12: Next | B12: =COUNTIFS($J:$J,$A12,$H:$H,B$5) -> 0 | C12: =COUNTIFS($J:$J,$A12,$H:$H,C$5) -> 0 | D12: =COUNTIFS($J:$J,$A12,$H:$H,D$5) -> 0 | E12: =SUM(B12:D12) -> 0
A14: ROUND 3
B15: High | C15: Medium | D15: Low | E15: Total
B16: =SUM(B17:B21) -> 13 | C16: =SUM(C17:C21) -> 15 | D16: =SUM(D17:D21) -> 0 | E16: =SUM(B16:D16) -> 28
A17: Passed | B17: =COUNTIFS($K:$K,$A17,$H:$H,B$15) -> 0 | C17: =COUNTIFS($K:$K,$A17,$H:$H,C$15) -> 0 | D17: =COUNTIFS($K:$K,$A17,$H:$H,D$15) -> 0 | E17: =SUM(B17:D17) -> 0
A18: Failed | B18: =COUNTIFS($K:$K,$A18,$H:$H,B$15) -> 0 | C18: =COUNTIFS($K:$K,$A18,$H:$H,C$15) -> 0 | D18: =COUNTIFS($K:$K,$A18,$H:$H,D$15) -> 0 | E18: =SUM(B18:D18) -> 0
A19: Pending | B19: =COUNTIFS($K:$K,$A19,$H:$H,B$15) -> 0 | C19: =COUNTIFS($K:$K,$A19,$H:$H,C$15) -> 0 | D19: =COUNTIFS($K:$K,$A19,$H:$H,D$15) -> 0 | E19: =SUM(B19:D19) -> 0
A20: Cancel | B20: =COUNTIFS($K:$K,$A20,$H:$H,B$15) -> 0 | C20: =COUNTIFS($K:$K,$A20,$H:$H,C$15) -> 0 | D20: =COUNTIFS($K:$K,$A20,$H:$H,D$15) -> 0 | E20: =SUM(B20:D20) -> 0
A21: Untested | B21: =COUNTIFS($K:$K,$A21,$H:$H,B$15) -> 13 | C21: =COUNTIFS($K:$K,$A21,$H:$H,C$15) -> 15 | D21: =COUNTIFS($K:$K,$A21,$H:$H,D$15) -> 0 | E21: =SUM(B21:D21) -> 28
A22: Next | B22: =COUNTIFS($K:$K,$A22,$H:$H,B$15) -> 0 | C22: =COUNTIFS($K:$K,$A22,$H:$H,C$15) -> 0 | D22: =COUNTIFS($K:$K,$A22,$H:$H,D$15) -> 0 | E22: =SUM(B22:D22) -> 0
A24: Test case Id | B24: Test case Title | C24: Pre-conditions | D24: Test Step | E24: Test Datas | F24: Expected result | G24: Test Environment | H24: Priority | I24: Automation Status | J24: 2st Test Results | K24: 3nd Test Results | L24: BugID | M24: Notes
A25: TF_RP3_01 | B25: Kiểm tra tiêu chí đầu vào báo cáo và các nút chức năng
A26: TF_RP3_01_01 | B26: Kiểm tra hiển thị các trường tham số | D26: 1. Đăng nhập vào Oracle Analytics Server 2. Mở báo cáo "Báo cáo tỷ lệ cảnh báo theo rule quét sàng lọc " | F26: Người dùng xem được các trường thông tin: - Từ ngày - Đến ngày - Loại Webservice Các nút chức năng: - Apply - Reset | G26: SIT | H26: Medium | I26: Manual | J26: Passed | K26: Untested
A27: TF_RP3_01_02 | B27: Kiểm tra tham số Từ ngày | D27: 1. Đăng nhập vào Oracle Analytics Server 2. Mở báo cáo "Báo cáo tỷ lệ cảnh báo theo rule quét sàng lọc " 3. Kiểm tra tham số Từ ngày | F27: Hệ thống cho người dùng chọn theo bảng lịch, hiển thị dạng dd/mm/yyyy | G27: SIT | H27: Medium | I27: Manual | J27: Passed | K27: Untested
A28: TF_RP3_01_03 | B28: Kiểm tra tham số Đến ngày | D28: 1. Đăng nhập vào Oracle Analytics Server 2. Mở báo cáo "Báo cáo tỷ lệ cảnh báo theo rule quét sàng lọc " 3. Kiểm tra tham số Đến ngày | F28: Hệ thống cho người dùng chọn theo bảng lịch, hiển thị dạng dd/mm/yyyy | G28: SIT | H28: Medium | I28: Manual | J28: Passed | K28: Untested
A29: TF_RP3_01_04 | B29: Kiểm tra tham số Webservice | D29: 1. Đăng nhập vào Oracle Analytics Server 2. Mở báo cáo "Báo cáo tỷ lệ cảnh báo theo rule quét sàng lọc " 3. Kiểm tra tham số Webservice | F29: Hệ thống hiển thị danh sách các Webservice, cho phép người dùng chọn một hoặc nhiều và không bắt buộc chọn | G29: SIT | H29: Medium | I29: Manual | J29: Passed | K29: Untested
A30: TF_RP3_01_05 | B30: Kiểm tra nút chức năng 'Apply' | D30: 1. Đăng nhập vào Oracle Analytics Server 2. Mở báo cáo "Báo cáo tỷ lệ cảnh báo theo rule quét sàng lọc " 3. Nhập/Chọn thông tin các trường: - Chọn ngày trong trường 'Từ ngày' - Chọn ngày trong trường 'Đến ngày' - Nhập giá trị trường Webservice 4. Bấm nút chức năng 'Apply' | F30: Người dùng xem được kết quả báo cáo | G30: SIT | H30: Medium | I30: Manual | J30: Passed | K30: Untested
A31: TF_RP3_01_06 | B31: Kiểm tra nút chức năng 'Reset' | D31: 1. Đăng nhập vào Oracle Analytics Server 2. Mở báo cáo "Báo cáo tỷ lệ cảnh báo theo rule quét sàng lọc " 3. Nhập/Chọn thông tin các trường: - Chọn ngày trong trường 'Từ ngày' - Chọn ngày trong trường 'Đến ngày' - Nhập giá trị trường Webservice 4. Bấm nút chức năng 'Reset' | F31: Hệ thống đặt lại tiêu chí lọc của người dùng theo lựa chọn tương ứng: - Reset to last applied values: Đặt lại về giá trị lọc trước đó - Reset to default values: Đặt lại về giá trị lọc của báo cáo - Clear All: Đặt lại toàn bộ tiêu chí lọc | G31: SIT | H31: Medium | I31: Manual | J31: Passed | K31: Untested
A32: TF_RP3_02 | B32: Kiểm tra tiêu chí đầu ra mong muốn
A33: TF_RP3_02_01 | B33: Kiểm tra hiển thị báo cáo | C33: 1. NSD có quyền truy cập báo cáo. 2. Đã có giao dịch được quét qua các rule/Webservice và có Event đã đánh giá trong kỳ báo cáo. | D33: 1. Đăng nhập vào Oracle Analytics Server 2. Mở báo cáo "Báo cáo tỷ lệ cảnh báo theo rule quét sàng lọc " 3. Nhập các tiêu chí lọc và đảm bảo nhập đủ các tiêu chí bắt buộc nhập 4. Bấm nút chức năng 'Apply' | F33: Người dùng xem được báo cáo hiển thị kết quả đầu ra bao gồm các trường thông tin sau: - Loại Webservice - Phương thức quét - Mã rule quét sàng lọc giao dịch - Tên Rule quét sàng lọc giao dịch - Tổng số lần hit - Tổng số lần hit đã đánh giá - Tổng số lần hit giả - Tổng số lần hit thật - Tỷ lệ hit thật | G33: SIT | H33: High | I33: Manual | J33: Passed | K33: Untested
A34: TF_RP3_02_02 | B34: Kiểm tra giá trị trường Loại Webservice | C34: 1. NSD có quyền truy cập báo cáo. 2. Đã có giao dịch được quét qua các rule/Webservice và có Event đã đánh giá trong kỳ báo cáo. | D34: 1. Đăng nhập vào Oracle Analytics Server 2. Mở báo cáo "Báo cáo tỷ lệ cảnh báo theo rule quét sàng lọc " 3. Nhập các tiêu chí lọc và đảm bảo nhập đủ các tiêu chí bắt buộc nhập 4. Bấm nút chức năng 'Apply' | F34: Hệ thống hiển thị giá trị trường Webservice | G34: SIT | H34: Medium | I34: Manual | J34: Passed | K34: Untested
A35: TF_RP3_02_03 | B35: Kiểm tra giá trị trường Phương thức quét | C35: 1. NSD có quyền truy cập báo cáo. 2. Đã có giao dịch được quét qua các rule/Webservice và có Event đã đánh giá trong kỳ báo cáo. | D35: 1. Đăng nhập vào Oracle Analytics Server 2. Mở báo cáo "Báo cáo tỷ lệ cảnh báo theo rule quét sàng lọc " 3. Nhập các tiêu chí lọc và đảm bảo nhập đủ các tiêu chí bắt buộc nhập 4. Bấm nút chức năng 'Apply' | F35: Hệ thống hiển thị giá trị trường Phương thức quét | G35: SIT | H35: Medium | I35: Manual | J35: Passed | K35: Untested
A36: TF_RP3_02_04 | B36: Kiểm tra giá trị trường Mã rule quét sàng lọc giao dịch | C36: 1. NSD có quyền truy cập báo cáo. 2. Đã có giao dịch được quét qua các rule/Webservice và có Event đã đánh giá trong kỳ báo cáo. | D36: 1. Đăng nhập vào Oracle Analytics Server 2. Mở báo cáo "Báo cáo tỷ lệ cảnh báo theo rule quét sàng lọc " 3. Nhập các tiêu chí lọc và đảm bảo nhập đủ các tiêu chí bắt buộc nhập 4. Bấm nút chức năng 'Apply' | F36: Hệ thống hiển thị giá trị trường Mã rule quét sàng lọc giao dịch | G36: SIT | H36: Medium | I36: Manual | J36: Passed | K36: Untested
A37: TF_RP3_02_05 | B37: Kiểm tra giá trị trường Tên Rule quét sàng lọc giao dịch | C37: 1. NSD có quyền truy cập báo cáo. 2. Đã có giao dịch được quét qua các rule/Webservice và có Event đã đánh giá trong kỳ báo cáo. | D37: 1. Đăng nhập vào Oracle Analytics Server 2. Mở báo cáo "Báo cáo tỷ lệ cảnh báo theo rule quét sàng lọc " 3. Nhập các tiêu chí lọc và đảm bảo nhập đủ các tiêu chí bắt buộc nhập 4. Bấm nút chức năng 'Apply' | F37: Hệ thống hiển thị giá trị trường Tên Rule quét sàng lọc giao dịch | G37: SIT | H37: Medium | I37: Manual | J37: Passed | K37: Untested
A38: TF_RP3_02_07 | B38: Kiểm tra giá trị trường Tổng số lần hit | C38: 1. NSD có quyền truy cập báo cáo. 2. Đã có giao dịch được quét qua các rule/Webservice và có Event đã đánh giá trong kỳ báo cáo. | D38: 1. Đăng nhập vào Oracle Analytics Server 2. Mở báo cáo "Báo cáo tỷ lệ cảnh báo theo rule quét sàng lọc " 3. Nhập các tiêu chí lọc và đảm bảo nhập đủ các tiêu chí bắt buộc nhập 4. Bấm nút chức năng 'Apply' | F38: Hệ thống hiển thị giá trị trường Tổng số lần hit | G38: SIT | H38: Medium | I38: Manual | J38: Passed | K38: Untested
A39: TF_RP3_02_08 | B39: Kiểm tra giá trị trường Tổng số lần hit đã đánh giá | C39: 1. NSD có quyền truy cập báo cáo. 2. Đã có giao dịch được quét qua các rule/Webservice và có Event đã đánh giá trong kỳ báo cáo. | D39: 1. Đăng nhập vào Oracle Analytics Server 2. Mở báo cáo "Báo cáo tỷ lệ cảnh báo theo rule quét sàng lọc " 3. Nhập các tiêu chí lọc và đảm bảo nhập đủ các tiêu chí bắt buộc nhập 4. Bấm nút chức năng 'Apply' | F39: Hệ thống hiển thị giá trị trường Tổng số lần hit đã đánh giá | G39: SIT | H39: Medium | I39: Manual | J39: Passed | K39: Untested
A40: TF_RP3_02_09 | B40: Kiểm tra giá trị trường Tổng số lần hit giả | C40: 1. NSD có quyền truy cập báo cáo. 2. Đã có giao dịch được quét qua các rule/Webservice và có Event đã đánh giá trong kỳ báo cáo. | D40: 1. Đăng nhập vào Oracle Analytics Server 2. Mở báo cáo "Báo cáo tỷ lệ cảnh báo theo rule quét sàng lọc " 3. Nhập các tiêu chí lọc và đảm bảo nhập đủ các tiêu chí bắt buộc nhập 4. Bấm nút chức năng 'Apply' | F40: Hệ thống hiển thị giá trị trường Tổng số lần hit giả | G40: SIT | H40: Medium | I40: Manual | J40: Passed | K40: Untested
A41: TF_RP3_02_10 | B41: Kiểm tra giá trị trường Tổng số lần hit thật | C41: 1. NSD có quyền truy cập báo cáo. 2. Đã có giao dịch được quét qua các rule/Webservice và có Event đã đánh giá trong kỳ báo cáo. | D41: 1. Đăng nhập vào Oracle Analytics Server 2. Mở báo cáo "Báo cáo tỷ lệ cảnh báo theo rule quét sàng lọc " 3. Nhập các tiêu chí lọc và đảm bảo nhập đủ các tiêu chí bắt buộc nhập 4. Bấm nút chức năng 'Apply' | F41: Hệ thống hiển thị giá trị trường Tổng số lần hit thật đã đánh giá | G41: SIT | H41: Medium | I41: Manual | J41: Passed | K41: Untested
A42: TF_RP3_02_12 | B42: Kiểm tra giá trị trường Tỷ lệ hit thật | C42: 1. NSD có quyền truy cập báo cáo. 2. Đã có giao dịch được quét qua các rule/Webservice và có Event đã đánh giá trong kỳ báo cáo. | D42: 1. Đăng nhập vào Oracle Analytics Server 2. Mở báo cáo "Báo cáo tỷ lệ cảnh báo theo rule quét sàng lọc " 3. Nhập các tiêu chí lọc và đảm bảo nhập đủ các tiêu chí bắt buộc nhập 4. Bấm nút chức năng 'Apply' | F42: Hệ thống hiển thị giá trị trường Tỷ lệ hit thật | G42: SIT | H42: Medium | I42: Manual | J42: Passed | K42: Untested
A43: TF_RP3_03 | B43: Kiểm tra tính năng trích xuất dữ liệu báo cáo
...

Sheet Report_04
A1: Functions | B1: =Cover!E11 -> DỰ ÁN TRIỂN KHAI BẢN QUYỀN PHẦN MỀM HỆ THỐNG AML MỚI
A2: Build Version | B2: v1.0
A4: ROUND 2
B5: High | C5: Medium | D5: Low | E5: Total
B6: =SUM(B7:B11) -> 8 | C6: =SUM(C7:C11) -> 10 | D6: =SUM(D7:D11) -> 0 | E6: =SUM(B6:D6) -> 18
A7: Passed | B7: =COUNTIFS($J:$J,$A7,$H:$H,B$5) -> 8 | C7: =COUNTIFS($J:$J,$A7,$H:$H,C$5) -> 10 | D7: =COUNTIFS($J:$J,$A7,$H:$H,D$5) -> 0 | E7: =SUM(B7:D7) -> 18
A8: Failed | B8: =COUNTIFS($J:$J,$A8,$H:$H,B$5) -> 0 | C8: =COUNTIFS($J:$J,$A8,$H:$H,C$5) -> 0 | D8: =COUNTIFS($J:$J,$A8,$H:$H,D$5) -> 0 | E8: =SUM(B8:D8) -> 0
A9: Pending | B9: =COUNTIFS($J:$J,$A9,$H:$H,B$5) -> 0 | C9: =COUNTIFS($J:$J,$A9,$H:$H,C$5) -> 0 | D9: =COUNTIFS($J:$J,$A9,$H:$H,D$5) -> 0 | E9: =SUM(B9:D9) -> 0
A10: Cancel | B10: =COUNTIFS($J:$J,$A10,$H:$H,B$5) -> 0 | C10: =COUNTIFS($J:$J,$A10,$H:$H,C$5) -> 0 | D10: =COUNTIFS($J:$J,$A10,$H:$H,D$5) -> 0 | E10: =SUM(B10:D10) -> 0
A11: Untested | B11: =COUNTIFS($J:$J,$A11,$H:$H,B$5) -> 0 | C11: =COUNTIFS($J:$J,$A11,$H:$H,C$5) -> 0 | D11: =COUNTIFS($J:$J,$A11,$H:$H,D$5) -> 0 | E11: =SUM(B11:D11) -> 0
A12: Next | B12: =COUNTIFS($J:$J,$A12,$H:$H,B$5) -> 0 | C12: =COUNTIFS($J:$J,$A12,$H:$H,C$5) -> 0 | D12: =COUNTIFS($J:$J,$A12,$H:$H,D$5) -> 0 | E12: =SUM(B12:D12) -> 0
A14: ROUND 3
B15: High | C15: Medium | D15: Low | E15: Total
B16: =SUM(B17:B21) -> 8 | C16: =SUM(C17:C21) -> 10 | D16: =SUM(D17:D21) -> 0 | E16: =SUM(B16:D16) -> 18
A17: Passed | B17: =COUNTIFS($K:$K,$A17,$H:$H,B$15) -> 0 | C17: =COUNTIFS($K:$K,$A17,$H:$H,C$15) -> 0 | D17: =COUNTIFS($K:$K,$A17,$H:$H,D$15) -> 0 | E17: =SUM(B17:D17) -> 0
A18: Failed | B18: =COUNTIFS($K:$K,$A18,$H:$H,B$15) -> 0 | C18: =COUNTIFS($K:$K,$A18,$H:$H,C$15) -> 0 | D18: =COUNTIFS($K:$K,$A18,$H:$H,D$15) -> 0 | E18: =SUM(B18:D18) -> 0
A19: Pending | B19: =COUNTIFS($K:$K,$A19,$H:$H,B$15) -> 0 | C19: =COUNTIFS($K:$K,$A19,$H:$H,C$15) -> 0 | D19: =COUNTIFS($K:$K,$A19,$H:$H,D$15) -> 0 | E19: =SUM(B19:D19) -> 0
A20: Cancel | B20: =COUNTIFS($K:$K,$A20,$H:$H,B$15) -> 0 | C20: =COUNTIFS($K:$K,$A20,$H:$H,C$15) -> 0 | D20: =COUNTIFS($K:$K,$A20,$H:$H,D$15) -> 0 | E20: =SUM(B20:D20) -> 0
A21: Untested | B21: =COUNTIFS($K:$K,$A21,$H:$H,B$15) -> 8 | C21: =COUNTIFS($K:$K,$A21,$H:$H,C$15) -> 10 | D21: =COUNTIFS($K:$K,$A21,$H:$H,D$15) -> 0 | E21: =SUM(B21:D21) -> 18
A22: Next | B22: =COUNTIFS($K:$K,$A22,$H:$H,B$15) -> 0 | C22: =COUNTIFS($K:$K,$A22,$H:$H,C$15) -> 0 | D22: =COUNTIFS($K:$K,$A22,$H:$H,D$15) -> 0 | E22: =SUM(B22:D22) -> 0
A24: Test case Id | B24: Test case Title | C24: Pre-conditions | D24: Test Step | E24: Test Datas | F24: Expected result | G24: Test Environment | H24: Priority | I24: Automation Status | J24: 2st Test Results | K24: 3nd Test Results | L24: BugID | M24: Notes
A25: TF_RP4_01 | B25: Kiểm tra tiêu chí đầu vào báo cáo và các nút chức năng
A26: TF_RP4_01_01 | B26: Kiểm tra hiển thị các trường tham số | D26: 1. Đăng nhập vào Oracle Analytics Server 2. Mở báo cáo "Báo cáo theo dõi Danh sách Good Guy sắp đến ngày hạn" | F26: Người dùng xem được các trường thông tin: Expiry Date Các nút chức năng: - Apply - Reset | G26: SIT | H26: Medium | I26: Manual | J26: Passed | K26: Untested
A27: TF_RP4_01_02 | B27: Kiểm tra tham số Expiry Date | D27: 1. Đăng nhập vào Oracle Analytics Server 2. Mở báo cáo "Báo cáo theo dõi Danh sách Good Guy sắp đến ngày hạn" 3. Kiểm tra tham số Webservice | F27: Hệ thống cho người dùng chọn theo bảng lịch, hiển thị dạng dd/mm/yyyy | G27: SIT | H27: Medium | I27: Manual | J27: Passed | K27: Untested | M27: Sai định dạng ngày Act: dd.mm.yyyy
A28: TF_RP4_01_03 | B28: Kiểm tra nút chức năng 'Apply' | D28: 1. Đăng nhập vào Oracle Analytics Server 2. Mở báo cáo "Báo cáo theo dõi Danh sách Good Guy sắp đến ngày hạn" 3. Nhập/Chọn thông tin các trường: - Chọn ngày trong trường 'Expiry Date' 4. Bấm nút chức năng 'Apply' | F28: Người dùng xem được kết quả báo cáo | G28: SIT | H28: Medium | I28: Manual | J28: Passed | K28: Untested | M28: Không hiển thị dữ liệu báo cáo
A29: TF_RP4_01_04 | B29: Kiểm tra nút chức năng 'Reset' | D29: 1. Đăng nhập vào Oracle Analytics Server 2. Mở báo cáo "Báo cáo theo dõi Danh sách Good Guy sắp đến ngày hạn" 3. Nhập/Chọn thông tin các trường: - Chọn ngày trong trường 'Expiry Date' 4. Bấm nút chức năng 'Reset' | F29: Hệ thống đặt lại tiêu chí lọc của người dùng theo lựa chọn tương ứng: - Reset to last applied values: Đặt lại về giá trị lọc trước đó - Reset to default values: Đặt lại về giá trị lọc của báo cáo - Clear All: Đặt lại toàn bộ tiêu chí lọc | G29: SIT | H29: Medium | I29: Manual | J29: Passed | K29: Untested
A30: TF_RP4_02 | B30: Kiểm tra tiêu chí đầu ra mong muốn
A31: TF_RP4_02_01 | B31: Kiểm tra hiển thị báo cáo | D31: 1. Đăng nhập vào Oracle Analytics Server 2. Mở báo cáo "Báo cáo theo dõi Danh sách Good Guy sắp đến ngày hạn" 3. Nhập các tiêu chí lọc và đảm bảo nhập đủ các tiêu chí bắt buộc nhập 4. Bấm nút chức năng 'Apply' | E31: SELECT W.N_WHITELIST_ID AS ID_DOI_TUONG_GOOD_GUY, W.D_EXPIRE_ON AS THOI_GIAN_HET_HAN_CUA_BAN_GHI, W.V_WHITE_NAME AS TEN_DOI_TUONG, W.V_ORIGIN AS TEN_DANH_SACH_THEO_DOI, -- W.N_STATUS_CD AS TRANG_THAI, W.V_WHITE_ENTITY_NAME AS DOI_TUONG_THUOC_DANH_SACH_THEO_DOI, W.V_RECORD_ID AS MA_BAN_GHI_DANH_SACH_THEO_DOI FROM FCC_WHITELIST W WHERE W.D_EXPIRE_ON IS NOT NULL AND TRUNC(W.D_EXPIRE_ON) BETWEEN TO_DATE(:FROM_DATE, 'DD/MM/YYYY') AND TO_DATE(:TO_DATE, 'DD/MM/YYYY') AND W.N_STATUS_CD = 22 ORDER BY W.D_EXPIRE_ON, W.N_WHITELIST_ID; | F31: Người dùng xem được báo cáo hiển thị kết quả đầu ra bao gồm các trường thông tin sau: - ID đối tượng good guy - Thời gian hết hạn của bản ghi - Tên đối tượng - Tên danh sách theo dõi - Đối tượng thuộc danh sách theo dõi - Mã bản ghi danh sách theo dõi | G31: SIT | H31: High | I31: Manual | J31: Passed | K31: Untested
A32: TF_RP4_02_02 | B32: Kiểm tra giá trị trường ID đối tượng good guy | D32: 1. Đăng nhập vào Oracle Analytics Server 2. Mở báo cáo "Báo cáo theo dõi Danh sách Good Guy sắp đến ngày hạn" 3. Nhập các tiêu chí lọc và đảm bảo nhập đủ các tiêu chí bắt buộc nhập 4. Bấm nút chức năng 'Apply' | F32: Hệ thống hiển thị giá trị trường ID đối tượng good guy | G32: SIT | H32: Medium | I32: Manual | J32: Passed | K32: Untested
A33: TF_RP4_02_03 | B33: Kiểm tra giá trị trường Thời gian hết hạn của bản ghi | D33: 1. Đăng nhập vào Oracle Analytics Server 2. Mở báo cáo "Báo cáo theo dõi Danh sách Good Guy sắp đến ngày hạn" 3. Nhập các tiêu chí lọc và đảm bảo nhập đủ các tiêu chí bắt buộc nhập 4. Bấm nút chức năng 'Apply' | F33: Hệ thống hiển thị giá trị trường Thời gian hết hạn của bản ghi | G33: SIT | H33: Medium | I33: Manual | J33: Passed | K33: Untested
A34: TF_RP4_02_04 | B34: Kiểm tra giá trị trường Tên đối tượng | D34: 1. Đăng nhập vào Oracle Analytics Server 2. Mở báo cáo "Báo cáo theo dõi Danh sách Good Guy sắp đến ngày hạn" 3. Nhập các tiêu chí lọc và đảm bảo nhập đủ các tiêu chí bắt buộc nhập 4. Bấm nút chức năng 'Apply' | F34: Hệ thống hiển thị giá trị trường Tên đối tượng | G34: SIT | H34: Medium | I34: Manual | J34: Passed | K34: Untested
A35: TF_RP4_02_05 | B35: Kiểm tra giá trị trường Tên danh sách theo dõi | D35: 1. Đăng nhập vào Oracle Analytics Server 2. Mở báo cáo "Báo cáo theo dõi Danh sách Good Guy sắp đến ngày hạn" 3. Nhập các tiêu chí lọc và đảm bảo nhập đủ các tiêu chí bắt buộc nhập 4. Bấm nút chức năng 'Apply' | F35: Hệ thống hiển thị giá trị trường Tên danh sách theo dõi | G35: SIT | H35: Medium | I35: Manual | J35: Passed | K35: Untested
A36: TF_RP4_02_06 | B36: Kiểm tra giá trị trường Đối tượng thuộc danh sách theo dõi | D36: 1. Đăng nhập vào Oracle Analytics Server 2. Mở báo cáo "Báo cáo theo dõi Danh sách Good Guy sắp đến ngày hạn" 3. Nhập các tiêu chí lọc và đảm bảo nhập đủ các tiêu chí bắt buộc nhập 4. Bấm nút chức năng 'Apply' | F36: Hệ thống hiển thị giá trị trường Đối tượng thuộc danh sách theo dõi | G36: SIT | H36: Medium | I36: Manual | J36: Passed | K36: Untested
A37: TF_RP4_02_07 | B37: Kiểm tra giá trị trường Mã bản ghi danh sách theo dõi | D37: 1. Đăng nhập vào Oracle Analytics Server 2. Mở báo cáo "Báo cáo theo dõi Danh sách Good Guy sắp đến ngày hạn" 3. Nhập các tiêu chí lọc và đảm bảo nhập đủ các tiêu chí bắt buộc nhập 4. Bấm nút chức năng 'Apply' | F37: Hệ thống hiển thị giá trị trường Mã bản ghi danh sách theo dõi tham số NSD đã nhập | G37: SIT | H37: Medium | I37: Manual | J37: Passed | K37: Untested
A38: TF_RP4_03 | B38: Kiểm tra tính năng trích xuất dữ liệu báo cáo
