Workbook

Sheet Cover
E8: Test Report
C11: Project Name: | E11: DỰ ÁN TRIỂN KHAI BẢN QUYỀN PHẦN MỀM HỆ THỐNG AML MỚI | G11: Reviewer:
C12: Document Code: | E12: MSB_AML_TM_Create_Case | G12: Position:
C13: Originator: | G13: Reviewed Date:
C14: Position: | G14: Approver:
C15: Created Date: | E15: 46279 | G15: Position:
C16: Version: | E16: 1.2 | G16: Approved Date:

Sheet Records
A1: TABLE OF CONTENT
A3: No | B3: Items | C3: Content
A4: 1 | B4: Cover | C4: Cover
A5: 2 | B5: Records | C5: Record of changes
A6: 3 | B6: Test Report | C6: This test report is used to summarize the testing status of the test case set
A7: 4 | B7: Create Case | C7: Testcase chức năng khởi tạo case thủ công (Create Case) và gán giao dịch vào case (Add Transaction) - theo BRD MSB TM v1.8, mục CM-1.2
A8: 5 | B8: Legend | C8: Chú giải các giá trị sử dụng trong tài liệu
A11: Effective Date | B11: A, M, D | C11: Change Description | F11: New Version | G11: Author
A12: 46279 | B12: A | C12: Tạo mới testcase Create Case (khởi tạo case thủ công) | F12: 1.0
A13: 46279 | B13: M | C13: Bổ sung nhóm TM_CC_5 - Add Transaction | F13: 1.1
A14: 46279 | B14: M | C14: Bỏ nhóm kiểm tra phân quyền & gán Assignee (chuyển sang bộ testcase MTPQ - Ma trận phân quyền); đánh số lại nhóm Add Transaction thành TM_CC_3 | F14: 1.2

Sheet Test Report
B2: SYSTEM TEST REPORT
A5: Project | B5: DỰ ÁN TRIỂN KHAI BẢN QUYỀN PHẦN MỀM HỆ THỐNG AML MỚI | D5: Project manager
A6: Application | B6: AML Transaction Monitoring - Create Case | D6: Approved Date
A7: Consolidated By | D7: Reviewed By
A8: Build Versions | D8: Reviewed date
A9: Test Environment | B9: SIT
A10: Last Updated Date
A11: Test Execution Summary
A12: Reported by
A13: Date
A14: Test Results (Round1) | B14: Passed | C14: Failed | D14: Untested | E14: Accepted | F14: Pending | G14: Cancel | H14: Total
B15: =B16 -> 0 | C15: =C16 -> 0 | D15: =D16 -> 28 | E15: =E16 -> 0 | F15: =F16 -> 0 | H15: =SUM(B15:F15) -> 28
A16: Test cases | B16: =COUNTIF('Create Case'!K:K,"Passed") -> 0 | C16: =COUNTIF('Create Case'!K:K,"Failed") -> 0 | D16: =COUNTIF('Create Case'!K:K,"Untested") -> 28 | E16: =COUNTIF('Create Case'!K:K,"Accepted") -> 0 | F16: =COUNTIF('Create Case'!K:K,"Pending") -> 0 | G16: =COUNTIF('Create Case'!K:K,"Cancel") -> 0
A18: Test Results (Round2) | B18: =B19 -> 0 | C18: =C19 -> 0 | D18: =D19 -> 28 | E18: =E19 -> 0 | F18: =F19 -> 0 | H18: =SUM(B18:F18) -> 28
A19: Test cases | B19: =COUNTIF('Create Case'!L:L,"Passed") -> 0 | C19: =COUNTIF('Create Case'!L:L,"Failed") -> 0 | D19: =COUNTIF('Create Case'!L:L,"Untested") -> 28 | E19: =COUNTIF('Create Case'!L:L,"Accepted") -> 0 | F19: =COUNTIF('Create Case'!L:L,"Pending") -> 0 | G19: =COUNTIF('Create Case'!L:L,"Cancel") -> 0
A20: Test coverage
A21: Test coverage
A22: Test successful coverage
A23: Issues
A24: 1. Block testing issue
A25: 2. Critical defects

Sheet Create Case
B1: Functions | C1: DỰ ÁN TRIỂN KHAI BẢN QUYỀN PHẦN MỀM HỆ THỐNG AML MỚI
B2: Build Version | C2: v1.2
B3: ROUND 1
C4: High | D4: Medium | E4: Low | F4: Total
C5: =SUM(C6:C10) -> 17 | D5: =SUM(D6:D10) -> 11 | E5: =SUM(E6:E10) -> 0 | F5: =SUM(C5:E5) -> 28
B6: Passed | C6: =COUNTIFS($K:$K, $B6,$I:$I,C$4) -> 0 | D6: =COUNTIFS($K:$K, $B6,$I:$I,D$4) -> 0 | E6: =COUNTIFS($K:$K, $B6,$I:$I,E$4) -> 0 | F6: =SUM(C6:E6) -> 0
B7: Failed | C7: =COUNTIFS($K:$K, $B7,$I:$I,C$4) -> 0 | D7: =COUNTIFS($K:$K, $B7,$I:$I,D$4) -> 0 | E7: =COUNTIFS($K:$K, $B7,$I:$I,E$4) -> 0 | F7: =SUM(C7:E7) -> 0
B8: Untested | C8: =COUNTIFS($K:$K, $B8,$I:$I,C$4) -> 17 | D8: =COUNTIFS($K:$K, $B8,$I:$I,D$4) -> 11 | E8: =COUNTIFS($K:$K, $B8,$I:$I,E$4) -> 0 | F8: =SUM(C8:E8) -> 28
B9: Accepted | C9: =COUNTIFS($K:$K, $B9,$I:$I,C$4) -> 0 | D9: =COUNTIFS($K:$K, $B9,$I:$I,D$4) -> 0 | E9: =COUNTIFS($K:$K, $B9,$I:$I,E$4) -> 0 | F9: =SUM(C9:E9) -> 0
B10: Pending | C10: =COUNTIFS($K:$K, $B10,$I:$I,C$4) -> 0 | D10: =COUNTIFS($K:$K, $B10,$I:$I,D$4) -> 0 | E10: =COUNTIFS($K:$K, $B10,$I:$I,E$4) -> 0 | F10: =SUM(C10:E10) -> 0
B11: Cancel | C11: =COUNTIFS($K:$K, $B11,$I:$I,C$4) -> 0 | D11: =COUNTIFS($K:$K, $B11,$I:$I,D$4) -> 0 | E11: =COUNTIFS($K:$K, $B11,$I:$I,E$4) -> 0 | F11: =SUM(C11:E11) -> 0
B12: ROUND2
C13: High | D13: Medium | E13: Low | F13: Total
C14: =SUM(C15:C19) -> 17 | D14: =SUM(D15:D19) -> 11 | E14: =SUM(E15:E19) -> 0 | F14: =SUM(C14:E14) -> 28
B15: Passed | C15: =COUNTIFS($L:$L, $B15,$I:$I,C$4) -> 0 | D15: =COUNTIFS($L:$L, $B15,$I:$I,D$4) -> 0 | E15: =COUNTIFS($L:$L, $B15,$I:$I,E$4) -> 0 | F15: =SUM(C15:E15) -> 0
B16: Failed | C16: =COUNTIFS($L:$L, $B16,$I:$I,C$4) -> 0 | D16: =COUNTIFS($L:$L, $B16,$I:$I,D$4) -> 0 | E16: =COUNTIFS($L:$L, $B16,$I:$I,E$4) -> 0 | F16: =SUM(C16:E16) -> 0
B17: Untested | C17: =COUNTIFS($L:$L, $B17,$I:$I,C$4) -> 17 | D17: =COUNTIFS($L:$L, $B17,$I:$I,D$4) -> 11 | E17: =COUNTIFS($L:$L, $B17,$I:$I,E$4) -> 0 | F17: =SUM(C17:E17) -> 28
B18: Accepted | C18: =COUNTIFS($L:$L, $B18,$I:$I,C$4) -> 0 | D18: =COUNTIFS($L:$L, $B18,$I:$I,D$4) -> 0 | E18: =COUNTIFS($L:$L, $B18,$I:$I,E$4) -> 0 | F18: =SUM(C18:E18) -> 0
B19: Pending | C19: =COUNTIFS($L:$L, $B19,$I:$I,C$4) -> 0 | D19: =COUNTIFS($L:$L, $B19,$I:$I,D$4) -> 0 | E19: =COUNTIFS($L:$L, $B19,$I:$I,E$4) -> 0 | F19: =SUM(C19:E19) -> 0
B20: Cancel | C20: =COUNTIFS($L:$L, $B20,$I:$I,C$4) -> 0 | D20: =COUNTIFS($L:$L, $B20,$I:$I,D$4) -> 0 | E20: =COUNTIFS($L:$L, $B20,$I:$I,E$4) -> 0 | F20: =SUM(C20:E20) -> 0
A21: STT | B21: Test case Id | C21: Test case Title | D21: Pre-conditions | E21: Test Steps | F21: Test Datas | G21: Expected result | H21: Test Environment | I21: Priority | J21: Automation Status | K21: 1st Test Results | L21: 2nd Test Results | M21: 3rd Test Results | N21: BugID | O21: Notes
A22: =ROW()-21 -> 1 | B22: TM_CC | C22: Màn hình khởi tạo case thủ công
A23: =ROW()-21 -> 2 | B23: TM_CC_1 | C23: Kiểm tra giao diện hiển thị
A24: =ROW()-21 -> 3 | B24: =$B$23&"."&COUNTA($B$23:B23) -> TM_CC_1.1 | C24: Kiểm tra giao diện hiển thị màn hình khởi tạo case thủ công | D24: User đã đăng nhập hệ thống và được phân quyền xử lý case nghiệp vụ TM | E24: 1. Truy cập chức năng khởi tạo case thủ công (Create Case) 2. Chọn Type = AML_MN 3. Kiểm tra các trường hiển thị trên màn hình | G24: Màn hình hiển thị đầy đủ các trường theo đúng yêu cầu: - Type - Title - Jurisdiction - Business Domain - Priority - Due - Owner - Assignee - Created By - Description Các nút chức năng: - Reset - Create | H24: SIT | I24: High | J24: N | K24: Untested | L24: Untested
A25: =ROW()-21 -> 4 | B25: TM_CC_2 | C25: Kiểm tra chức năng tạo mới case thủ công
A26: =ROW()-21 -> 5 | B26: =$B$25&"."&COUNTA($B$25:B25) -> TM_CC_2.1 | C26: Tạo mới case thủ công thành công khi nhập đầy đủ thông tin bắt buộc | D26: User đã đăng nhập hệ thống và được phân quyền xử lý case nghiệp vụ TM | E26: 1. Truy cập chức năng khởi tạo case thủ công (Create Case) 2. Chọn Type = AML_MN 3. Nhập/chọn đầy đủ các trường bắt buộc (*): Type, Jurisdiction, Business Domain, Owner, Assignee, Created By, Description 4. Nhấn nút Create | G26: Hệ thống tạo case thành công, tự động sinh Case ID cho case vừa tạo và hiển thị thông báo tạo case thành công | H26: SIT | I26: High | J26: N | K26: Untested | L26: Untested
A27: =ROW()-21 -> 6 | B27: =$B$25&"."&COUNTA($B$25:B26) -> TM_CC_2.2 | C27: Kiểm tra Case ID được hệ thống tự động sinh khi tạo case thủ công | D27: User đã đăng nhập hệ thống và được phân quyền xử lý case nghiệp vụ TM | E27: 1. Truy cập chức năng khởi tạo case thủ công (Create Case) 2. Nhập/chọn đầy đủ các trường bắt buộc 3. Nhấn nút Create 4. Kiểm tra Case ID của case vừa được tạo | G27: Hệ thống tự động sinh Case ID cho case vừa tạo. Người dùng không tự nhập/chỉnh sửa được Case ID trên màn hình khởi tạo | H27: SIT | I27: High | J27: N | K27: Untested | L27: Untested
A28: =ROW()-21 -> 7 | B28: =$B$25&"."&COUNTA($B$25:B27) -> TM_CC_2.3 | C28: Kiểm tra chức năng Reset | E28: 1. Truy cập chức năng khởi tạo case thủ công (Create Case) 2. Nhập/chọn giá trị bất kỳ vào các trường trên màn hình 3. Nhấn nút Reset | G28: Hệ thống xóa sạch dữ liệu người dùng đã nhập, các trường trở về trạng thái mặc định ban đầu, cho phép người dùng nhập lại từ đầu | H28: SIT | I28: Medium | J28: N | K28: Untested | L28: Untested
A29: =ROW()-21 -> 8 | B29: =$B$25&"."&COUNTA($B$25:B28) -> TM_CC_2.4 | C29: Kiểm tra tạo case thủ công không thành công khi bỏ trống trường bắt buộc | E29: 1. Truy cập chức năng khởi tạo case thủ công (Create Case) 2. Bỏ trống 1 trong các trường bắt buộc (Type/Jurisdiction/Business Domain/Owner/Assignee/Created By/Description) 3. Nhấn nút Create | G29: Hệ thống hiển thị thông báo yêu cầu nhập đầy đủ các trường bắt buộc, không tạo case | H29: SIT | I29: High | J29: N | K29: Untested | L29: Untested | O29: [Inference] BRD chưa mô tả nội dung message lỗi cụ thể; test case được bổ sung theo nguyên tắc validate trường bắt buộc (M) tại mục CM-1.2. Cần xác nhận nội dung thông báo khi SIT/UAT.
A30: =ROW()-21 -> 9 | B30: =$B$25&"."&COUNTA($B$25:B29) -> TM_CC_2.5 | C30: ="Kiểm tra trường "&F30 -> Kiểm tra trường Type | E30: 1. Truy cập chức năng khởi tạo case thủ công (Create Case) 2. Kiểm tra/chỉnh sửa trường Type | F30: Type | G30: Hệ thống hiển thị giá trị drop-down list, bắt buộc chọn, gồm giá trị: - AML_MN | H30: SIT | I30: High | J30: N | K30: Untested | L30: Untested
A31: =ROW()-21 -> 10 | B31: =$B$25&"."&COUNTA($B$25:B30) -> TM_CC_2.6 | C31: ="Kiểm tra trường "&F31 -> Kiểm tra trường Title | E31: 1. Truy cập chức năng khởi tạo case thủ công (Create Case) 2. Kiểm tra/chỉnh sửa trường Title | F31: Title | G31: Hệ thống cho phép nhập tự do (free text), không bắt buộc nhập | H31: SIT | I31: Medium | J31: N | K31: Untested | L31: Untested | O31: [Unverified] BRD không quy định giới hạn ký tự cụ thể cho trường Title - cần xác nhận thêm.
A32: =ROW()-21 -> 11 | B32: =$B$25&"."&COUNTA($B$25:B31) -> TM_CC_2.7 | C32: ="Kiểm tra trường "&F32 -> Kiểm tra trường Jurisdiction | E32: 1. Truy cập chức năng khởi tạo case thủ công (Create Case) 2. Kiểm tra/chỉnh sửa trường Jurisdiction | F32: Jurisdiction | G32: Hệ thống hiển thị giá trị drop-down list, bắt buộc chọn, mặc định (default): All | H32: SIT | I32: High | J32: N | K32: Untested | L32: Untested
A33: =ROW()-21 -> 12 | B33: =$B$25&"."&COUNTA($B$25:B32) -> TM_CC_2.8 | C33: ="Kiểm tra trường "&F33 -> Kiểm tra trường Business Domain | E33: 1. Truy cập chức năng khởi tạo case thủ công (Create Case) 2. Kiểm tra/chỉnh sửa trường Business Domain | F33: Business Domain | G33: Hệ thống hiển thị giá trị drop-down list, bắt buộc chọn, mặc định (default): All | H33: SIT | I33: High | J33: N | K33: Untested | L33: Untested
A34: =ROW()-21 -> 13 | B34: =$B$25&"."&COUNTA($B$25:B33) -> TM_CC_2.9 | C34: ="Kiểm tra trường "&F34 -> Kiểm tra trường Priority | E34: 1. Truy cập chức năng khởi tạo case thủ công (Create Case) 2. Kiểm tra/chỉnh sửa trường Priority | F34: Priority | G34: Hệ thống hiển thị giá trị drop-down list, không bắt buộc chọn, gồm 3 giá trị: - High - Medium - Low | H34: SIT | I34: Medium | J34: N | K34: Untested | L34: Untested
A35: =ROW()-21 -> 14 | B35: =$B$25&"."&COUNTA($B$25:B34) -> TM_CC_2.10 | C35: ="Kiểm tra trường "&F35 -> Kiểm tra trường Due | E35: 1. Truy cập chức năng khởi tạo case thủ công (Create Case) 2. Kiểm tra/chỉnh sửa trường Due | F35: Due | G35: Hệ thống cho phép nhập theo định dạng ngày MM/DD/YYYY, không bắt buộc nhập | H35: SIT | I35: Medium | J35: N | K35: Untested | L35: Untested
A36: =ROW()-21 -> 15 | B36: =$B$25&"."&COUNTA($B$25:B35) -> TM_CC_2.11 | C36: ="Kiểm tra trường "&F36 -> Kiểm tra trường Owner | E36: 1. Truy cập chức năng khởi tạo case thủ công (Create Case) 2. Kiểm tra/chỉnh sửa trường Owner | F36: Owner | G36: Hệ thống hiển thị giá trị drop-down list là danh sách user được phân quyền xử lý case nghiệp vụ TM, bắt buộc chọn | H36: SIT | I36: High | J36: N | K36: Untested | L36: Untested
A37: =ROW()-21 -> 16 | B37: =$B$25&"."&COUNTA($B$25:B36) -> TM_CC_2.12 | C37: ="Kiểm tra trường "&F37 -> Kiểm tra trường Assignee | E37: 1. Truy cập chức năng khởi tạo case thủ công (Create Case) 2. Kiểm tra/chỉnh sửa trường Assignee | F37: Assignee | G37: Hệ thống hiển thị giá trị drop-down list là danh sách user được phân quyền xử lý case nghiệp vụ TM, bắt buộc chọn | H37: SIT | I37: High | J37: N | K37: Untested | L37: Untested
A38: =ROW()-21 -> 17 | B38: =$B$25&"."&COUNTA($B$25:B37) -> TM_CC_2.13 | C38: ="Kiểm tra trường "&F38 -> Kiểm tra trường Created By | E38: 1. Truy cập chức năng khởi tạo case thủ công (Create Case) 2. Kiểm tra/chỉnh sửa trường Created By | F38: Created By | G38: Hệ thống hiển thị giá trị drop-down list là danh sách user được phân quyền xử lý case nghiệp vụ TM, bắt buộc chọn | H38: SIT | I38: High | J38: N | K38: Untested | L38: Untested
A39: =ROW()-21 -> 18 | B39: =$B$25&"."&COUNTA($B$25:B38) -> TM_CC_2.14 | C39: ="Kiểm tra trường "&F39 -> Kiểm tra trường Description | E39: 1. Truy cập chức năng khởi tạo case thủ công (Create Case) 2. Kiểm tra/chỉnh sửa trường Description | F39: Description | G39: Hệ thống cho phép nhập tự do (free text), bắt buộc nhập | H39: SIT | I39: High | J39: N | K39: Untested | L39: Untested | O39: [Unverified] BRD không quy định giới hạn ký tự cụ thể cho trường Description - cần xác nhận thêm.
A40: =ROW()-21 -> 19 | B40: TM_CC_3 | C40: Kiểm tra chức năng tìm kiếm/gán thông tin giao dịch vào case thủ công (Add Transaction)
...

Sheet Legend
A1: Giai đoạn kiểm thử
A2: Test Level
A3: Giá trị | B3: Giải thích
A4: Value | B4: Description
A5: UT | B5: Kiểm thử kỹ thuật (Unit Test) (IT thực hiện)
A6: SIT | B6: Kiểm thử tích hợp hệ thống (System Integration Test) (IT thực hiện)
A7: OAT | B7: Kiểm thử vận hành (Operation Acceptance Test) (IT thực hiện)
A8: ST | B8: Kiểm thử an ninh thông tin (Security Test) (IT thực hiện)
A9: UAT | B9: Kiểm thử người dùng cuối (User Acceptance Test) (ĐVNV thực hiện)
A12: Độ ưu tiên
A13: Priority
A14: Giá trị | B14: Giải thích
A15: Value | B15: Description
A16: High | B16: Ưu tiên cao
A17: Medium | B17: Ưu tiên trung bình
A18: Low | B18: Ưu tiên thấp/không ưu tiên
A20: Cách thực hiện test | F20: Passed
A21: Automation Status | F21: Failed
A22: Giá trị | B22: Giải thích | F22: Untested
A23: Value | B23: Description | F23: Accepted
A24: Y | B24: Thực hiện Auto test | F24: Pending
A25: N | B25: Thực hiện Manual test | F25: Cancel
A27: Trạng thái
A28: Status
A29: Giá trị | B29: Giải thích
A30: Value | B30: Description
A31: Untested | B31: Chưa thực hiện
A32: Passed | B32: Đạt yêu cầu
A33: Failed | B33: Không đạt yêu cầu
A34: Pending | B34: Pending
B35: Một testcase tạm dừng thực hiện do ảnh hưởng bởi testcase khác fail hoặc cần xác nhận từ các bên liên quan.
A36: Cancel | B36: Không thực hiện
A37: Total | B37: Total = 'Untested' + 'Passed' + 'Failed' + 'Pending' + 'Cancel
A38: % Executed | B38: % Executed = ('Total' - 'Todo' - 'Un-executed')/'Total'
A39: % Pass | B39: % Pass = 'Pass'/'Total'
