Workbook

Sheet Cover
E8: Test Report
C11: Project Name: | E11: DỰ ÁN TRIỂN KHAI BẢN QUYỀN PHẦN MỀM HỆ THỐNG AML MỚI | G11: Reviewer:
C12: Document Code: | G12: Position:
C13: Originator: | G13: Reviewed Date:
C14: Position: | G14: Approver:
C15: Created Date: | E15: 46157 | G15: Position:
C16: Version: | E16: 1.0 | G16: Approved Date:

Sheet Records
A1: TABLE OF CONTENT
A3: No | B3: Items | C3: Content
A4: 1 | B4: Cover | C4: Cover
A5: 2 | B5: Records | C5: Record of changes
A6: 3 | B6: Test Report | C6: This test report is used to summarize the testing status of the project
A7: 4 | B7: ETL | C7: Testcase kiểm tra ETL (STG Batch) — đối chiếu dữ liệu core banking MSB với các bảng STG_* theo MSB_TM_DataMapping_STG_Batch v1.0
A9: Effective Date | B9: A, M, D | C9: Change Description | F9: New Version | G9: Author
A10: 46273 | B10: A | C10: Create new TC | F10: 1

Sheet Test Report
B2: SYSTEM TEST REPORT
A5: Project | B5: =Cover!E11 -> DỰ ÁN TRIỂN KHAI BẢN QUYỀN PHẦN MỀM HỆ THỐNG AML MỚI | D5: Project manager
A6: Application | D6: Approved Date
A7: Consolidated By | D7: Reviewed By
A8: Build Versions | B8: =Cover!E16 -> 1.0 | D8: Reviewed date
A9: Test Environment | B9: SIT
A10: Last Updated Date | B10: =TODAY() -> 46287
A11: Test Execution Summary
A12: Reported by
A13: Date
A14: Test Results (Round1) | B14: Passed | C14: Failed | D14: Untested | E14: Accepted | F14: Pending | G14: Cancel | H14: Total
B15: =B16 -> 0 | C15: =C16 -> 0 | D15: =D16 -> 54 | E15: =E16 -> 0 | F15: =F16 -> 0 | G15: =G16 -> 0 | H15: =SUM(B15:F15) -> 54
A16: Test cases | B16: =ETL!F6 -> 0 | C16: =ETL!F7 -> 0 | D16: =ETL!F8 -> 54 | E16: =ETL!F9 -> 0 | F16: =ETL!F10 -> 0 | G16: =ETL!F11 -> 0 | H16: =SUM(B16:G16) -> 54
A18: Test Results (Round2) | B18: =B19 -> 0 | C18: =C19 -> 0 | D18: =D19 -> 54 | E18: =E19 -> 0 | F18: =F19 -> 0 | G18: =G19 -> 0 | H18: =SUM(B18:F18) -> 54
A19: Test cases | B19: =ETL!F15 -> 0 | C19: =ETL!F16 -> 0 | D19: =ETL!F17 -> 54 | E19: =ETL!F18 -> 0 | F19: =ETL!F19 -> 0 | G19: =ETL!F20 -> 0 | H19: =SUM(B19:G19) -> 54
A20: Test coverage
A21: Test coverage | H21: =IF(H18=0, IF(H15=0,0,(H15-D15)/H15), (H18-D18)/H18) -> 0
A22: Test successful coverage | H22: =IF(H18=0, IF(H15=0,0,B15/H15), B18/H18) -> 0
A23: Issues
A24: 1. Block testing issue
A25: 2. Critical defects

Sheet ETL
B1: Functions | C1: DỰ ÁN TRIỂN KHAI BẢN QUYỀN PHẦN MỀM HỆ THỐNG AML MỚI
B2: Build Version | C2: v1.0
B3: ROUND 1
C4: High | D4: Medium | E4: Low | F4: Total
C5: =SUM(C6:C10) -> 54 | D5: =SUM(D6:D10) -> 0 | E5: =SUM(E6:E10) -> 0 | F5: =SUM(C5:E5) -> 54
B6: Passed | C6: =COUNTIFS($K:$K, $B6,$I:$I,C$4) -> 0 | D6: =COUNTIFS($K:$K, $B6,$I:$I,D$4) -> 0 | E6: =COUNTIFS($K:$K, $B6,$I:$I,E$4) -> 0 | F6: =SUM(C6:E6) -> 0
B7: Failed | C7: =COUNTIFS($K:$K, $B7,$I:$I,C$4) -> 0 | D7: =COUNTIFS($K:$K, $B7,$I:$I,D$4) -> 0 | E7: =COUNTIFS($K:$K, $B7,$I:$I,E$4) -> 0 | F7: =SUM(C7:E7) -> 0
B8: Untested | C8: =COUNTIFS($K:$K, $B8,$I:$I,C$4) -> 54 | D8: =COUNTIFS($K:$K, $B8,$I:$I,D$4) -> 0 | E8: =COUNTIFS($K:$K, $B8,$I:$I,E$4) -> 0 | F8: =SUM(C8:E8) -> 54
B9: Accepted | C9: =COUNTIFS($K:$K, $B9,$I:$I,C$4) -> 0 | D9: =COUNTIFS($K:$K, $B9,$I:$I,D$4) -> 0 | E9: =COUNTIFS($K:$K, $B9,$I:$I,E$4) -> 0 | F9: =SUM(C9:E9) -> 0
B10: Pending | C10: =COUNTIFS($K:$K, $B10,$I:$I,C$4) -> 0 | D10: =COUNTIFS($K:$K, $B10,$I:$I,D$4) -> 0 | E10: =COUNTIFS($K:$K, $B10,$I:$I,E$4) -> 0 | F10: =SUM(C10:E10) -> 0
B11: Cancel | C11: =COUNTIFS($K:$K, $B11,$I:$I,C$4) -> 0 | D11: =COUNTIFS($K:$K, $B11,$I:$I,D$4) -> 0 | E11: =COUNTIFS($K:$K, $B11,$I:$I,E$4) -> 0 | F11: =SUM(C11:E11) -> 0
B12: ROUND2
C13: High | D13: Medium | E13: Low | F13: Total
C14: =SUM(C15:C19) -> 54 | D14: =SUM(D15:D19) -> 0 | E14: =SUM(E15:E19) -> 0 | F14: =SUM(C14:E14) -> 54
B15: Passed | C15: =COUNTIFS($L:$L, $B15,$I:$I,C$4) -> 0 | D15: =COUNTIFS($L:$L, $B15,$I:$I,D$4) -> 0 | E15: =COUNTIFS($L:$L, $B15,$I:$I,E$4) -> 0 | F15: =SUM(C15:E15) -> 0
B16: Failed | C16: =COUNTIFS($L:$L, $B16,$I:$I,C$4) -> 0 | D16: =COUNTIFS($L:$L, $B16,$I:$I,D$4) -> 0 | E16: =COUNTIFS($L:$L, $B16,$I:$I,E$4) -> 0 | F16: =SUM(C16:E16) -> 0
B17: Untested | C17: =COUNTIFS($L:$L, $B17,$I:$I,C$4) -> 54 | D17: =COUNTIFS($L:$L, $B17,$I:$I,D$4) -> 0 | E17: =COUNTIFS($L:$L, $B17,$I:$I,E$4) -> 0 | F17: =SUM(C17:E17) -> 54
B18: Accepted | C18: =COUNTIFS($L:$L, $B18,$I:$I,C$4) -> 0 | D18: =COUNTIFS($L:$L, $B18,$I:$I,D$4) -> 0 | E18: =COUNTIFS($L:$L, $B18,$I:$I,E$4) -> 0 | F18: =SUM(C18:E18) -> 0
B19: Pending | C19: =COUNTIFS($L:$L, $B19,$I:$I,C$4) -> 0 | D19: =COUNTIFS($L:$L, $B19,$I:$I,D$4) -> 0 | E19: =COUNTIFS($L:$L, $B19,$I:$I,E$4) -> 0 | F19: =SUM(C19:E19) -> 0
B20: Cancel | C20: =COUNTIFS($L:$L, $B20,$I:$I,C$4) -> 0 | D20: =COUNTIFS($L:$L, $B20,$I:$I,D$4) -> 0 | E20: =COUNTIFS($L:$L, $B20,$I:$I,E$4) -> 0 | F20: =SUM(C20:E20) -> 0
A21: STT | B21: Test case Id | C21: Test case Title | D21: Pre-conditions | E21: Test Steps | F21: Test Datas | G21: Expected result | H21: Test Environment | I21: Priority | J21: Automation Status | K21: 1st Test Results | L21: 2nd Test Results | M21: 3rd Test Results | N21: BugID | O21: Notes
A22: I. CU — Nhóm bảng chứa thông tin Khách hàng (Customer) (11 bảng / 33 testcase)
A23: I.1 STG_PARTY_MASTER — KH – thông tin định danh/nhân khẩu/tổ chức
A24: 1 | B24: TM_ETL_CU_CUS_001 | C24: Kiểm tra số lượng bản ghi | D24: Batch/job ETL đã chạy xong cho ngày dữ liệu kiểm thử (FIC_MIS_DATE = &TEST_DATE). | E24: - Đếm số bản ghi bảng nguồn (hệ thống nguồn/bảng nguồn MSB (CHƯA xác định)) theo ngày dữ liệu kiểm thử - Đếm số bản ghi bảng đích STG_PARTY_MASTER theo FIC_MIS_DATE - So sánh 2 kết quả | G24: Số bản ghi của bảng nguồn = Số bản ghi của bảng đích STG_PARTY_MASTER, đã lọc theo điều kiện FIC_MIS_DATE = &TEST_DATE | H24: SIT | I24: High | J24: N | K24: Untested | L24: Untested | M24: Untested | O24: [Unverified] MSB chưa cung cấp bảng/trường nguồn (cột 'Bảng nguồn'/'Trường nguồn' trong file MSB_TM_DataMapping_STG_Batch_V1_0.xlsx còn trống cho bảng này) — xem AT-02 (nguồn FIC_MIS_DATE + dấu hiệu bản ghi mới/cập nhật, đăng ký V_DATA_ORIGIN); AT-09 (thống nhất danh mục codeset); AT-10 (nguồn quốc gia/quốc tịch ISO2 + bảng map) trong sheet '★ Action Tracker (MSB)' của file đó. Cập nhật cột 'Test Datas' sau khi có mapping.
A25: 2 | B25: TM_ETL_CU_CUS_002 | C25: Kiểm tra bản ghi trùng lặp | D25: Batch/job ETL đã chạy xong cho ngày dữ liệu kiểm thử (FIC_MIS_DATE = &TEST_DATE). | E25: Kiểm tra key tất cả các bản ghi trong bảng đích STG_PARTY_MASTER theo tổ hợp khóa chính (V_PARTY_ID, FIC_MIS_DATE), lọc theo FIC_MIS_DATE | F25: SELECT V_PARTY_ID, FIC_MIS_DATE, COUNT(*) AS SL FROM STG_PARTY_MASTER WHERE FIC_MIS_DATE = DATE '&TEST_DATE' GROUP BY V_PARTY_ID, FIC_MIS_DATE HAVING COUNT(*) > 1; | G25: Không có bản ghi nào trùng key (câu SQL trả về 0 dòng) | H25: SIT | I25: High | J25: N | K25: Untested | L25: Untested | M25: Untested | O25: PK theo mapping v1.0.
A26: 3 | B26: TM_ETL_CU_CUS_003 | C26: Kiểm tra tính đồng nhất của các trường dữ liệu | D26: Batch/job ETL đã chạy xong cho ngày dữ liệu kiểm thử (FIC_MIS_DATE = &TEST_DATE). | E26: Check toàn bộ dữ liệu các trường trong bảng đích STG_PARTY_MASTER so với các trường trong bảng nguồn theo logic mapping (nguồn: hệ thống nguồn/bảng nguồn MSB (CHƯA xác định)) | G26: Tất cả các trường có dữ liệu trong bảng nguồn theo logic mapping và bảng đích STG_PARTY_MASTER giống nhau (câu lệnh MINUS trả về 0 dòng). Các cột đích cần đối chiếu (35): FIC_MIS_DATE, V_DATA_JURISDICTION, V_BUSINESS_DOMAIN, V_PARTY_ID, V_PARTY_NAME, V_DISPLAY_NM, V_PARTY_TYPE, D_DATE_OF_BIRTH, V_GENDER, V_NATIONALITY_COUNTRY, V_DOMICILE_COUNTRY, V_PROFESSION, V_ORG_CONSTITUENT_TYPE, V_INDUSTRY_CODE, D_INCORPORATION_DATE, V_PARTY_TAX_ID, V_BUSS_SEGMENT, N_KYC_RISK, D_START_DATE, V_DATA_ORIGIN, V_INCORPORATION_COUNTRY_CD, V_CITIZENSHIP_TYPE, V_BENEFICIAL_OWNER_CATEGORY, V_EMP_COMPANY, V_OCCUPATION_STATUS, V_EDUCATION, V_RESIDENCY_STATUS_INDICATOR, V_ADDRESS_OFF_FAX_NO, V_WEBSITE, V_BRANCH_CODE, V_JOB_TITLE, V_PARTY_FULL_NAME, V_PARTY_ALIAS, V_SECONDARY_CITIZENSHIP, F_SAR_STR_FLAG | H26: SIT | I26: High | J26: N | K26: Untested | L26: Untested | M26: Untested | O26: [Unverified] MSB chưa cung cấp bảng/trường nguồn (cột 'Bảng nguồn'/'Trường nguồn' trong file MSB_TM_DataMapping_STG_Batch_V1_0.xlsx còn trống cho bảng này) — xem AT-02 (nguồn FIC_MIS_DATE + dấu hiệu bản ghi mới/cập nhật, đăng ký V_DATA_ORIGIN); AT-09 (thống nhất danh mục codeset); AT-10 (nguồn quốc gia/quốc tịch ISO2 + bảng map) trong sheet '★ Action Tracker (MSB)' của file đó. Cập nhật cột 'Test Datas' (câu lệnh MINUS) sau khi có mapping.
A27: I.2 STG_ADDRESS_MASTER — Nội dung địa chỉ (mô hình OFSAA)
A28: 4 | B28: TM_ETL_CU_ADR_001 | C28: Kiểm tra số lượng bản ghi | D28: Batch/job ETL đã chạy xong cho ngày dữ liệu kiểm thử (FIC_MIS_DATE = &TEST_DATE). | E28: - Đếm số bản ghi bảng nguồn (hệ thống nguồn/bảng nguồn MSB (CHƯA xác định)) theo ngày dữ liệu kiểm thử - Đếm số bản ghi bảng đích STG_ADDRESS_MASTER theo FIC_MIS_DATE - So sánh 2 kết quả | G28: Số bản ghi của bảng nguồn = Số bản ghi của bảng đích STG_ADDRESS_MASTER, đã lọc theo điều kiện FIC_MIS_DATE = &TEST_DATE | H28: SIT | I28: High | J28: N | K28: Untested | L28: Untested | M28: Untested | O28: [Unverified] MSB chưa cung cấp bảng/trường nguồn (cột 'Bảng nguồn'/'Trường nguồn' trong file MSB_TM_DataMapping_STG_Batch_V1_0.xlsx còn trống cho bảng này) — xem AT-02 (nguồn FIC_MIS_DATE + dấu hiệu bản ghi mới/cập nhật, đăng ký V_DATA_ORIGIN) trong sheet '★ Action Tracker (MSB)' của file đó. Cập nhật cột 'Test Datas' sau khi có mapping.
A29: 5 | B29: TM_ETL_CU_ADR_002 | C29: Kiểm tra bản ghi trùng lặp | D29: Batch/job ETL đã chạy xong cho ngày dữ liệu kiểm thử (FIC_MIS_DATE = &TEST_DATE). | E29: Kiểm tra key tất cả các bản ghi trong bảng đích STG_ADDRESS_MASTER theo tổ hợp khóa chính (FIC_MIS_DATE, V_ADDRESS_ID), lọc theo FIC_MIS_DATE | F29: SELECT FIC_MIS_DATE, V_ADDRESS_ID, COUNT(*) AS SL FROM STG_ADDRESS_MASTER WHERE FIC_MIS_DATE = DATE '&TEST_DATE' GROUP BY FIC_MIS_DATE, V_ADDRESS_ID HAVING COUNT(*) > 1; | G29: Không có bản ghi nào trùng key (câu SQL trả về 0 dòng) | H29: SIT | I29: High | J29: N | K29: Untested | L29: Untested | M29: Untested | O29: PK theo mapping v1.0.
A30: 6 | B30: TM_ETL_CU_ADR_003 | C30: Kiểm tra tính đồng nhất của các trường dữ liệu | D30: Batch/job ETL đã chạy xong cho ngày dữ liệu kiểm thử (FIC_MIS_DATE = &TEST_DATE). | E30: Check toàn bộ dữ liệu các trường trong bảng đích STG_ADDRESS_MASTER so với các trường trong bảng nguồn theo logic mapping (nguồn: hệ thống nguồn/bảng nguồn MSB (CHƯA xác định)) | G30: Tất cả các trường có dữ liệu trong bảng nguồn theo logic mapping và bảng đích STG_ADDRESS_MASTER giống nhau (câu lệnh MINUS trả về 0 dòng). Các cột đích cần đối chiếu (7): FIC_MIS_DATE, V_ADDRESS_ID, V_ADDRESS_LINE1, V_ADDRESS_LINE2, V_CITY, V_COUNTRY_CODE, V_DATA_ORIGIN Các trường gán mặc định đã xác nhận (sheet '1. Cơ chế Load' / mapping): V_ADDRESS_ID=Sinh mã địa chỉ (PK) để liên kết STG_PARTY_ADDRESS_MAP; V_DATA_ORIGIN=Gán mặc định = 'MSB'. | H30: SIT | I30: High | J30: N | K30: Untested | L30: Untested | M30: Untested | O30: [Unverified] MSB chưa cung cấp bảng/trường nguồn (cột 'Bảng nguồn'/'Trường nguồn' trong file MSB_TM_DataMapping_STG_Batch_V1_0.xlsx còn trống cho bảng này) — xem AT-02 (nguồn FIC_MIS_DATE + dấu hiệu bản ghi mới/cập nhật, đăng ký V_DATA_ORIGIN) trong sheet '★ Action Tracker (MSB)' của file đó. Cập nhật cột 'Test Datas' (câu lệnh MINUS) sau khi có mapping.
A31: I.3 STG_PARTY_ADDRESS_MAP — Liên kết KH–địa chỉ + mục đích địa chỉ
A32: 7 | B32: TM_ETL_CU_PAD_001 | C32: Kiểm tra số lượng bản ghi | D32: Batch/job ETL đã chạy xong cho ngày dữ liệu kiểm thử (FIC_MIS_DATE = &TEST_DATE). | E32: - Đếm số bản ghi bảng nguồn (hệ thống nguồn/bảng nguồn MSB (CHƯA xác định)) theo ngày dữ liệu kiểm thử - Đếm số bản ghi bảng đích STG_PARTY_ADDRESS_MAP theo FIC_MIS_DATE - So sánh 2 kết quả | G32: Số bản ghi của bảng nguồn = Số bản ghi của bảng đích STG_PARTY_ADDRESS_MAP, đã lọc theo điều kiện FIC_MIS_DATE = &TEST_DATE | H32: SIT | I32: High | J32: N | K32: Untested | L32: Untested | M32: Untested | O32: [Unverified] MSB chưa cung cấp bảng/trường nguồn (cột 'Bảng nguồn'/'Trường nguồn' trong file MSB_TM_DataMapping_STG_Batch_V1_0.xlsx còn trống cho bảng này) — xem AT-02 (nguồn FIC_MIS_DATE + dấu hiệu bản ghi mới/cập nhật, đăng ký V_DATA_ORIGIN) trong sheet '★ Action Tracker (MSB)' của file đó. Cập nhật cột 'Test Datas' sau khi có mapping.
A33: 8 | B33: TM_ETL_CU_PAD_002 | C33: Kiểm tra bản ghi trùng lặp | D33: Batch/job ETL đã chạy xong cho ngày dữ liệu kiểm thử (FIC_MIS_DATE = &TEST_DATE). | E33: Kiểm tra key tất cả các bản ghi trong bảng đích STG_PARTY_ADDRESS_MAP theo tổ hợp khóa chính (FIC_MIS_DATE, V_ADDRESS_ID, V_ADDRESS_PURPOSE_TYPE_CD, V_PARTY_ID), lọc theo FIC_MIS_DATE | F33: SELECT FIC_MIS_DATE, V_ADDRESS_ID, V_ADDRESS_PURPOSE_TYPE_CD, V_PARTY_ID, COUNT(*) AS SL FROM STG_PARTY_ADDRESS_MAP WHERE FIC_MIS_DATE = DATE '&TEST_DATE' GROUP BY FIC_MIS_DATE, V_ADDRESS_ID, V_ADDRESS_PURPOSE_TYPE_CD, V_PARTY_ID HAVING COUNT(*) > 1; | G33: Không có bản ghi nào trùng key (câu SQL trả về 0 dòng) | H33: SIT | I33: High | J33: N | K33: Untested | L33: Untested | M33: Untested | O33: PK theo mapping v1.0.
A34: 9 | B34: TM_ETL_CU_PAD_003 | C34: Kiểm tra tính đồng nhất của các trường dữ liệu | D34: Batch/job ETL đã chạy xong cho ngày dữ liệu kiểm thử (FIC_MIS_DATE = &TEST_DATE). | E34: Check toàn bộ dữ liệu các trường trong bảng đích STG_PARTY_ADDRESS_MAP so với các trường trong bảng nguồn theo logic mapping (nguồn: hệ thống nguồn/bảng nguồn MSB (CHƯA xác định)) | G34: Tất cả các trường có dữ liệu trong bảng nguồn theo logic mapping và bảng đích STG_PARTY_ADDRESS_MAP giống nhau (câu lệnh MINUS trả về 0 dòng). Các cột đích cần đối chiếu (5): FIC_MIS_DATE, V_ADDRESS_ID, V_ADDRESS_PURPOSE_TYPE_CD, V_PARTY_ID, N_SEQUENCE_NUMBER | H34: SIT | I34: High | J34: N | K34: Untested | L34: Untested | M34: Untested | O34: [Unverified] MSB chưa cung cấp bảng/trường nguồn (cột 'Bảng nguồn'/'Trường nguồn' trong file MSB_TM_DataMapping_STG_Batch_V1_0.xlsx còn trống cho bảng này) — xem AT-02 (nguồn FIC_MIS_DATE + dấu hiệu bản ghi mới/cập nhật, đăng ký V_DATA_ORIGIN) trong sheet '★ Action Tracker (MSB)' của file đó. Cập nhật cột 'Test Datas' (câu lệnh MINUS) sau khi có mapping.
A35: I.4 STG_PARTY_PHONE_MAP — Số điện thoại / fax của KH
A36: 10 | B36: TM_ETL_CU_PHO_001 | C36: Kiểm tra số lượng bản ghi | D36: Batch/job ETL đã chạy xong cho ngày dữ liệu kiểm thử (FIC_MIS_DATE = &TEST_DATE). | E36: - Đếm số bản ghi bảng nguồn (hệ thống nguồn/bảng nguồn MSB (CHƯA xác định)) theo ngày dữ liệu kiểm thử - Đếm số bản ghi bảng đích STG_PARTY_PHONE_MAP theo FIC_MIS_DATE - So sánh 2 kết quả | G36: Số bản ghi của bảng nguồn = Số bản ghi của bảng đích STG_PARTY_PHONE_MAP, đã lọc theo điều kiện FIC_MIS_DATE = &TEST_DATE | H36: SIT | I36: High | J36: N | K36: Untested | L36: Untested | M36: Untested | O36: [Unverified] MSB chưa cung cấp bảng/trường nguồn (cột 'Bảng nguồn'/'Trường nguồn' trong file MSB_TM_DataMapping_STG_Batch_V1_0.xlsx còn trống cho bảng này) — xem AT-01 (quy tắc UNPIVOT SĐT/email + sinh V_PHONE_ID/V_EMAIL_ID) trong sheet '★ Action Tracker (MSB)' của file đó. Cập nhật cột 'Test Datas' sau khi có mapping.
A37: 11 | B37: TM_ETL_CU_PHO_002 | C37: Kiểm tra bản ghi trùng lặp | D37: Batch/job ETL đã chạy xong cho ngày dữ liệu kiểm thử (FIC_MIS_DATE = &TEST_DATE). | E37: Kiểm tra key tất cả các bản ghi trong bảng đích STG_PARTY_PHONE_MAP theo tổ hợp khóa chính (FIC_MIS_DATE, V_PARTY_ID, V_PHONE_ID, V_PHONE_PURPOSE_TYPE_CD), lọc theo FIC_MIS_DATE | F37: SELECT FIC_MIS_DATE, V_PARTY_ID, V_PHONE_ID, V_PHONE_PURPOSE_TYPE_CD, COUNT(*) AS SL FROM STG_PARTY_PHONE_MAP WHERE FIC_MIS_DATE = DATE '&TEST_DATE' GROUP BY FIC_MIS_DATE, V_PARTY_ID, V_PHONE_ID, V_PHONE_PURPOSE_TYPE_CD HAVING COUNT(*) > 1; | G37: Không có bản ghi nào trùng key (câu SQL trả về 0 dòng) | H37: SIT | I37: High | J37: N | K37: Untested | L37: Untested | M37: Untested | O37: PK theo mapping v1.0.
A38: 12 | B38: TM_ETL_CU_PHO_003 | C38: Kiểm tra tính đồng nhất của các trường dữ liệu | D38: Batch/job ETL đã chạy xong cho ngày dữ liệu kiểm thử (FIC_MIS_DATE = &TEST_DATE). | E38: Check toàn bộ dữ liệu các trường trong bảng đích STG_PARTY_PHONE_MAP so với các trường trong bảng nguồn theo logic mapping (nguồn: hệ thống nguồn/bảng nguồn MSB (CHƯA xác định)) | G38: Tất cả các trường có dữ liệu trong bảng nguồn theo logic mapping và bảng đích STG_PARTY_PHONE_MAP giống nhau (câu lệnh MINUS trả về 0 dòng). Các cột đích cần đối chiếu (6): FIC_MIS_DATE, V_PARTY_ID, V_PHONE_ID, V_PHONE_PURPOSE_TYPE_CD, N_SEQUENCE_NUMBER, V_PHONE_NUMBER | H38: SIT | I38: High | J38: N | K38: Untested | L38: Untested | M38: Untested | O38: [Unverified] MSB chưa cung cấp bảng/trường nguồn (cột 'Bảng nguồn'/'Trường nguồn' trong file MSB_TM_DataMapping_STG_Batch_V1_0.xlsx còn trống cho bảng này) — xem AT-01 (quy tắc UNPIVOT SĐT/email + sinh V_PHONE_ID/V_EMAIL_ID) trong sheet '★ Action Tracker (MSB)' của file đó. Cập nhật cột 'Test Datas' (câu lệnh MINUS) sau khi có mapping.
A39: I.5 STG_PARTY_EMAIL_MAP — Email của KH
A40: 13 | B40: TM_ETL_CU_EML_001 | C40: Kiểm tra số lượng bản ghi | D40: Batch/job ETL đã chạy xong cho ngày dữ liệu kiểm thử (FIC_MIS_DATE = &TEST_DATE). | E40: - Đếm số bản ghi bảng nguồn (hệ thống nguồn/bảng nguồn MSB (CHƯA xác định)) theo ngày dữ liệu kiểm thử - Đếm số bản ghi bảng đích STG_PARTY_EMAIL_MAP theo FIC_MIS_DATE - So sánh 2 kết quả | G40: Số bản ghi của bảng nguồn = Số bản ghi của bảng đích STG_PARTY_EMAIL_MAP, đã lọc theo điều kiện FIC_MIS_DATE = &TEST_DATE | H40: SIT | I40: High | J40: N | K40: Untested | L40: Untested | M40: Untested | O40: [Unverified] MSB chưa cung cấp bảng/trường nguồn (cột 'Bảng nguồn'/'Trường nguồn' trong file MSB_TM_DataMapping_STG_Batch_V1_0.xlsx còn trống cho bảng này) — xem AT-01 (quy tắc UNPIVOT SĐT/email + sinh V_PHONE_ID/V_EMAIL_ID) trong sheet '★ Action Tracker (MSB)' của file đó. Cập nhật cột 'Test Datas' sau khi có mapping.
...

Sheet Legend
A1: Giai đoạn kiểm thử
A2: Test Level
A3: Giá trị | B3: Giải thích
A4: Value | B4: Description
A5: UT | B5: Kiểm thử kỹ thuật (Unit Test) (IT thực hiện)
A6: SIT | B6: Kiểm thử tích hợp hệ thống (System Integration Test) (IT thực hiện)
A7: OAT | B7: Kiểm thử vận hành (Operation Acceptance Test) (IT thực hiện)
A8: ST | B8: Kiểm thử an ninh thông tin (Security Test) (IT thực hiện)
A9: UAT | B9: Kiểm thử người dùng cuối (User Acceptance Test) (ĐVNV thực hiện)
A12: Độ ưu tiên
A13: Priority
A14: Giá trị | B14: Giải thích
A15: Value | B15: Description
A16: High | B16: Ưu tiên cao
A17: Medium | B17: Ưu tiên trung bình
A18: Low | B18: Ưu tiên thấp/không ưu tiên
A20: Cách thực hiện test | F20: Passed
A21: Automation Status | F21: Failed
A22: Giá trị | B22: Giải thích | F22: Untested
A23: Value | B23: Description | F23: Accepted
A24: Y | B24: Thực hiện Auto test | F24: Pending
A25: N | B25: Thực hiện Manual test | F25: Cancel
A27: Trạng thái
A28: Status
A29: Giá trị | B29: Giải thích
A30: Value | B30: Description
A31: Untested | B31: Chưa thực hiện
A32: Passed | B32: Đạt yêu cầu
A33: Failed | B33: Không đạt yêu cầu
A34: Pending | B34: Pending
B35: Một testcase tạm dừng thực hiện do ảnh hưởng bởi testcase khác fail hoặc cần xác nhận từ các bên liên quan.
A36: Cancel | B36: Không thực hiện
A37: Total | B37: Total = 'Untested' + 'Passed' + 'Failed' + 'Pending' + 'Cancel
A38: % Executed | B38: % Executed = ('Total' - 'Todo' - 'Un-executed')/'Total'
A39: % Pass | B39: % Pass = 'Pass'/'Total'
