Workbook

Sheet Cover
E8: Test Report
C11: Project Name: | E11: DỰ ÁN TRIỂN KHAI BẢN QUYỀN PHẦN MỀM HỆ THỐNG AML MỚI | G11: Reviewer:
C12: Document Code: | E12: MSB_AML_TM_Testcase_Whitelist | G12: Position:
C13: Originator: | G13: Reviewed Date:
C14: Position: | G14: Approver:
C15: Created Date: | E15: 46157 | G15: Position:
C16: Version: | E16: 1.0 | G16: Approved Date:

Sheet Records
A1: TABLE OF CONTENT
A3: No | B3: Items | C3: Content
A4: 1 | B4: Cover | C4: Cover
A5: 2 | B5: Records | C5: Record of changes
A6: 3 | B6: Test Report | C6: Báo cáo tổng hợp tình trạng kiểm thử của module TM - Whitelist
A7: 4 | B7: Testcase Whitelist | C7: Danh sách testcase chức năng Whitelist (Module TM)
A8: 5 | B8: Legend | C8: Chú thích các giá trị dùng trong bộ testcase
A11: Effective Date | B11: A, M, D | C11: Change Description | F11: New Version | G11: Author
A12: 46157 | B12: A | C12: Tạo mới bộ testcase Whitelist (Module TM) | F12: 1

Sheet Test Report
B2: SYSTEM TEST REPORT
A5: Project | B5: DỰ ÁN TRIỂN KHAI BẢN QUYỀN PHẦN MỀM HỆ THỐNG AML MỚI | D5: Project manager
A6: Application | B6: Module TM - Whitelist | D6: Approved Date
A7: Consolidated By | D7: Reviewed By
A8: Build Versions | B8: v1.0 | D8: Reviewed date
A9: Test Environment | B9: SIT
A10: Last Updated Date
A11: Test Execution Summary
A12: Reported by
A13: Date
A14: Test Results (Round1) | B14: Passed | C14: Failed | D14: Untested | E14: Accepted | F14: Pending | G14: Cancel | H14: Total
B15: =B16 -> 0 | C15: =C16 -> 0 | D15: =D16 -> 99 | E15: =E16 -> 0 | F15: =F16 -> 0 | H15: =SUM(B15:F15) -> 99
A16: Test cases | B16: =DEF_Whitelist!F6 -> 0 | C16: =DEF_Whitelist!F7 -> 0 | D16: =DEF_Whitelist!F8 -> 99 | E16: =DEF_Whitelist!F9 -> 0 | F16: =DEF_Whitelist!F10 -> 0 | G16: =DEF_Whitelist!F11 -> 0 | H16: =SUM(B16:G16) -> 99
A18: Test Results (Round2) | B18: =B19 -> 0 | C18: =C19 -> 0 | D18: =D19 -> 99 | E18: =E19 -> 0 | F18: =F19 -> 0 | H18: =SUM(B18:F18) -> 99
A19: Test cases | B19: =DEF_Whitelist!F15 -> 0 | C19: =DEF_Whitelist!F16 -> 0 | D19: =DEF_Whitelist!F17 -> 99 | E19: =DEF_Whitelist!F18 -> 0 | F19: =DEF_Whitelist!F19 -> 0 | G19: =DEF_Whitelist!F20 -> 0 | H19: =SUM(B19:G19) -> 99
A20: Test coverage
A21: Test coverage | B21: =IFERROR((H15-D15)/H15,0) -> 0
A22: Test successful coverage | B22: =IFERROR(B15/H15,0) -> 0
A23: Issues
A24: 1. Block testing issue
A25: 2. Critical defects

Sheet DEF_Whitelist
B1: Functions | C1: DỰ ÁN TRIỂN KHAI BẢN QUYỀN PHẦN MỀM HỆ THỐNG AML MỚI
B2: Build Version | C2: v1.0 - Whitelist (Module TM)
B3: ROUND 1
C4: High | D4: Medium | E4: Low | F4: Total
C5: =SUM(C6:C10) -> 41 | D5: =SUM(D6:D10) -> 43 | E5: =SUM(E6:E10) -> 15 | F5: =SUM(C5:E5) -> 99
B6: Passed | C6: =COUNTIFS($K:$K, $B6,$I:$I,C$4) -> 0 | D6: =COUNTIFS($K:$K, $B6,$I:$I,D$4) -> 0 | E6: =COUNTIFS($K:$K, $B6,$I:$I,E$4) -> 0 | F6: =SUM(C6:E6) -> 0
B7: Failed | C7: =COUNTIFS($K:$K, $B7,$I:$I,C$4) -> 0 | D7: =COUNTIFS($K:$K, $B7,$I:$I,D$4) -> 0 | E7: =COUNTIFS($K:$K, $B7,$I:$I,E$4) -> 0 | F7: =SUM(C7:E7) -> 0
B8: Untested | C8: =COUNTIFS($K:$K, $B8,$I:$I,C$4) -> 41 | D8: =COUNTIFS($K:$K, $B8,$I:$I,D$4) -> 43 | E8: =COUNTIFS($K:$K, $B8,$I:$I,E$4) -> 15 | F8: =SUM(C8:E8) -> 99
B9: Accepted | C9: =COUNTIFS($K:$K, $B9,$I:$I,C$4) -> 0 | D9: =COUNTIFS($K:$K, $B9,$I:$I,D$4) -> 0 | E9: =COUNTIFS($K:$K, $B9,$I:$I,E$4) -> 0 | F9: =SUM(C9:E9) -> 0
B10: Pending | C10: =COUNTIFS($K:$K, $B10,$I:$I,C$4) -> 0 | D10: =COUNTIFS($K:$K, $B10,$I:$I,D$4) -> 0 | E10: =COUNTIFS($K:$K, $B10,$I:$I,E$4) -> 0 | F10: =SUM(C10:E10) -> 0
B11: Cancel | C11: =COUNTIFS($K:$K, $B11,$I:$I,C$4) -> 0 | D11: =COUNTIFS($K:$K, $B11,$I:$I,D$4) -> 0 | E11: =COUNTIFS($K:$K, $B11,$I:$I,E$4) -> 0 | F11: =SUM(C11:E11) -> 0
B12: ROUND2
C13: High | D13: Medium | E13: Low | F13: Total
C14: =SUM(C15:C19) -> 41 | D14: =SUM(D15:D19) -> 43 | E14: =SUM(E15:E19) -> 15 | F14: =SUM(C14:E14) -> 99
B15: Passed | C15: =COUNTIFS($L:$L, $B15,$I:$I,C$4) -> 0 | D15: =COUNTIFS($L:$L, $B15,$I:$I,D$4) -> 0 | E15: =COUNTIFS($L:$L, $B15,$I:$I,E$4) -> 0 | F15: =SUM(C15:E15) -> 0
B16: Failed | C16: =COUNTIFS($L:$L, $B16,$I:$I,C$4) -> 0 | D16: =COUNTIFS($L:$L, $B16,$I:$I,D$4) -> 0 | E16: =COUNTIFS($L:$L, $B16,$I:$I,E$4) -> 0 | F16: =SUM(C16:E16) -> 0
B17: Untested | C17: =COUNTIFS($L:$L, $B17,$I:$I,C$4) -> 41 | D17: =COUNTIFS($L:$L, $B17,$I:$I,D$4) -> 43 | E17: =COUNTIFS($L:$L, $B17,$I:$I,E$4) -> 15 | F17: =SUM(C17:E17) -> 99
B18: Accepted | C18: =COUNTIFS($L:$L, $B18,$I:$I,C$4) -> 0 | D18: =COUNTIFS($L:$L, $B18,$I:$I,D$4) -> 0 | E18: =COUNTIFS($L:$L, $B18,$I:$I,E$4) -> 0 | F18: =SUM(C18:E18) -> 0
B19: Pending | C19: =COUNTIFS($L:$L, $B19,$I:$I,C$4) -> 0 | D19: =COUNTIFS($L:$L, $B19,$I:$I,D$4) -> 0 | E19: =COUNTIFS($L:$L, $B19,$I:$I,E$4) -> 0 | F19: =SUM(C19:E19) -> 0
B20: Cancel | C20: =COUNTIFS($L:$L, $B20,$I:$I,C$4) -> 0 | D20: =COUNTIFS($L:$L, $B20,$I:$I,D$4) -> 0 | E20: =COUNTIFS($L:$L, $B20,$I:$I,E$4) -> 0 | F20: =SUM(C20:E20) -> 0
A21: STT | B21: Test case Id | C21: Test case Title | D21: Pre-conditions | E21: Test Steps | F21: Test Datas | G21: Expected result | H21: Test Environment | I21: Priority | J21: Automation Status | K21: 1st Test Results | L21: 2nd Test Results | M21: 3rd Test Results | N21: BugID | O21: Notes | P21: abc
A22: 1. Kiểm tra giao diện hiển thị và Tìm kiếm
A23: =COUNTA($C$22:C23) -> 1 | B23: ="TM_DEF_"&$P23&"_"&TEXT(COUNTIF($P$22:$P23,$P23),"000") -> TM_DEF_UI_001 | C23: Kiểm tra giao diện hiển thị chức năng View | D23: User đăng nhập đã được phân quyền role maker/checker sử dụng chức năng cho form nhập liệu | E23: 1. Truy cập màn hình Data Entry Form and Query Forms, chọn form Whitelist 2. Kiểm tra các trường hiển thị trên màn hình | G23: Màn hình hiển thị các trường trên form đúng và đủ theo yêu cầu: - List Code * (tự sinh) - ID * - ID Type * - Application scenario * - Status * - Reason Added - Effective date (tự sinh, chỉ đọc) - Description - Comment - Trạng thái phê duyệt - Người tạo - Ngày tạo - Người kiểm tra - Ngày kiểm tra | H23: SIT | I23: High | J23: N | K23: Untested | L23: Untested | M23: Untested | P23: UI
A24: =COUNTA($C$22:C24) -> 2 | B24: ="TM_DEF_"&$P24&"_"&TEXT(COUNTIF($P$22:$P24,$P24),"000") -> TM_DEF_UI_002 | C24: Kiểm tra chức năng tìm kiếm cơ bản theo List Code thỏa mãn | D24: Form đã có dữ liệu Giá trị List Code nhập tìm kiếm tồn tại trong hệ thống User đăng nhập đã được phân quyền role maker/checker sử dụng chức năng cho form nhập liệu | E24: 1. Truy cập màn hình Data Entry Form and Query Forms, chọn form Whitelist 2. Chọn chức năng Search 3. Chọn trường List Code 4. Nhập/Chọn giá trị cần tìm kiếm tồn tại 5. Nhấn nút Go | F24: List Code: <giá trị tồn tại> | G24: Màn hình hiển thị các bản ghi thỏa mãn điều kiện tìm kiếm script SQL check: select "List Code", "ID", "ID Type", "Application scenario", "Status", "Reason Added", "Effective date", "Description", "Comment", "Trạng thái phê duyệt", "Người tạo", "Ngày tạo", "Người kiểm tra", "Ngày kiểm tra" from Whitelist where upper("List Code") like upper('%xâu%') | H24: SIT | I24: High | J24: N | K24: Untested | L24: Untested | M24: Untested | P24: UI
A25: =COUNTA($C$22:C25) -> 3 | B25: ="TM_DEF_"&$P25&"_"&TEXT(COUNTIF($P$22:$P25,$P25),"000") -> TM_DEF_UI_003 | C25: Kiểm tra chức năng tìm kiếm cơ bản theo List Code tồn tại nhưng phân biệt hoa thường | D25: Form đã có dữ liệu Giá trị List Code tồn tại nhưng nhập khác kiểu hoa thường User đăng nhập đã được phân quyền role maker/checker sử dụng chức năng cho form nhập liệu | E25: 1. Truy cập màn hình Data Entry Form and Query Forms, chọn form Whitelist 2. Chọn chức năng Search 3. Chọn trường List Code 4. Nhập giá trị tồn tại nhưng nhập kí tự hoa thường khác với dữ liệu gốc 5. Nhấn nút Go | F25: List Code: <giá trị tồn tại, đảo hoa/thường> | G25: Màn hình hiển thị các bản ghi chứa xâu tìm kiếm không phân biệt hoa thường | H25: SIT | I25: Medium | J25: N | K25: Untested | L25: Untested | M25: Untested | P25: UI
A26: =COUNTA($C$22:C26) -> 4 | B26: ="TM_DEF_"&$P26&"_"&TEXT(COUNTIF($P$22:$P26,$P26),"000") -> TM_DEF_UI_004 | C26: Kiểm tra chức năng tìm kiếm cơ bản theo List Code nhập kí tự đặc biệt | D26: Form đã có dữ liệu User đăng nhập đã được phân quyền role maker/checker sử dụng chức năng cho form nhập liệu | E26: 1. Truy cập màn hình Data Entry Form and Query Forms, chọn form Whitelist 2. Chọn chức năng Search 3. Chọn trường List Code 4. Nhập giá trị là các kí tự đặc biệt(@, #, $, %, ^, *...) có thể tồn tại hoặc không tồn tại 5. Nhấn nút Go | F26: List Code: @#$% | G26: Trả về thông báo không có dữ liệu [6997] No match found for the current search (nếu không tồn tại giá trị) hoặc hiển thị đúng kết quả chứa giá trị nhập (nếu tồn tại) | H26: SIT | I26: Low | J26: N | K26: Untested | L26: Untested | M26: Untested | P26: UI
A27: =COUNTA($C$22:C27) -> 5 | B27: ="TM_DEF_"&$P27&"_"&TEXT(COUNTIF($P$22:$P27,$P27),"000") -> TM_DEF_UI_005 | C27: Kiểm tra chức năng tìm kiếm cơ bản theo ID thỏa mãn | D27: Form đã có dữ liệu Giá trị ID nhập tìm kiếm tồn tại trong hệ thống User đăng nhập đã được phân quyền role maker/checker sử dụng chức năng cho form nhập liệu | E27: 1. Truy cập màn hình Data Entry Form and Query Forms, chọn form Whitelist 2. Chọn chức năng Search 3. Chọn trường ID 4. Nhập/Chọn giá trị cần tìm kiếm tồn tại 5. Nhấn nút Go | F27: ID: <giá trị tồn tại> | G27: Màn hình hiển thị các bản ghi thỏa mãn điều kiện tìm kiếm script SQL check: select "List Code", "ID", "ID Type", "Application scenario", "Status", "Reason Added", "Effective date", "Description", "Comment", "Trạng thái phê duyệt", "Người tạo", "Ngày tạo", "Người kiểm tra", "Ngày kiểm tra" from Whitelist where upper("ID") like upper('%xâu%') | H27: SIT | I27: High | J27: N | K27: Untested | L27: Untested | M27: Untested | P27: UI
A28: =COUNTA($C$22:C28) -> 6 | B28: ="TM_DEF_"&$P28&"_"&TEXT(COUNTIF($P$22:$P28,$P28),"000") -> TM_DEF_UI_006 | C28: Kiểm tra chức năng tìm kiếm cơ bản theo ID tồn tại nhưng phân biệt hoa thường | D28: Form đã có dữ liệu Giá trị ID tồn tại nhưng nhập khác kiểu hoa thường User đăng nhập đã được phân quyền role maker/checker sử dụng chức năng cho form nhập liệu | E28: 1. Truy cập màn hình Data Entry Form and Query Forms, chọn form Whitelist 2. Chọn chức năng Search 3. Chọn trường ID 4. Nhập giá trị tồn tại nhưng nhập kí tự hoa thường khác với dữ liệu gốc 5. Nhấn nút Go | F28: ID: <giá trị tồn tại, đảo hoa/thường> | G28: Màn hình hiển thị các bản ghi chứa xâu tìm kiếm không phân biệt hoa thường | H28: SIT | I28: Medium | J28: N | K28: Untested | L28: Untested | M28: Untested | P28: UI
A29: =COUNTA($C$22:C29) -> 7 | B29: ="TM_DEF_"&$P29&"_"&TEXT(COUNTIF($P$22:$P29,$P29),"000") -> TM_DEF_UI_007 | C29: Kiểm tra chức năng tìm kiếm cơ bản theo ID nhập kí tự đặc biệt | D29: Form đã có dữ liệu User đăng nhập đã được phân quyền role maker/checker sử dụng chức năng cho form nhập liệu | E29: 1. Truy cập màn hình Data Entry Form and Query Forms, chọn form Whitelist 2. Chọn chức năng Search 3. Chọn trường ID 4. Nhập giá trị là các kí tự đặc biệt(@, #, $, %, ^, *...) có thể tồn tại hoặc không tồn tại 5. Nhấn nút Go | F29: ID: @#$% | G29: Trả về thông báo không có dữ liệu [6997] No match found for the current search (nếu không tồn tại giá trị) hoặc hiển thị đúng kết quả chứa giá trị nhập (nếu tồn tại) | H29: SIT | I29: Low | J29: N | K29: Untested | L29: Untested | M29: Untested | P29: UI
A30: =COUNTA($C$22:C30) -> 8 | B30: ="TM_DEF_"&$P30&"_"&TEXT(COUNTIF($P$22:$P30,$P30),"000") -> TM_DEF_UI_008 | C30: Kiểm tra chức năng tìm kiếm cơ bản theo ID Type thỏa mãn | D30: Form đã có dữ liệu Giá trị ID Type nhập tìm kiếm tồn tại trong hệ thống User đăng nhập đã được phân quyền role maker/checker sử dụng chức năng cho form nhập liệu | E30: 1. Truy cập màn hình Data Entry Form and Query Forms, chọn form Whitelist 2. Chọn chức năng Search 3. Chọn trường ID Type 4. Nhập/Chọn giá trị cần tìm kiếm tồn tại 5. Nhấn nút Go | F30: ID Type: <giá trị tồn tại> | G30: Màn hình hiển thị các bản ghi thỏa mãn điều kiện tìm kiếm script SQL check: select "List Code", "ID", "ID Type", "Application scenario", "Status", "Reason Added", "Effective date", "Description", "Comment", "Trạng thái phê duyệt", "Người tạo", "Ngày tạo", "Người kiểm tra", "Ngày kiểm tra" from Whitelist where upper("ID Type") like upper('%xâu%') | H30: SIT | I30: High | J30: N | K30: Untested | L30: Untested | M30: Untested | P30: UI
A31: =COUNTA($C$22:C31) -> 9 | B31: ="TM_DEF_"&$P31&"_"&TEXT(COUNTIF($P$22:$P31,$P31),"000") -> TM_DEF_UI_009 | C31: Kiểm tra chức năng tìm kiếm cơ bản theo ID Type tồn tại nhưng phân biệt hoa thường | D31: Form đã có dữ liệu Giá trị ID Type tồn tại nhưng nhập khác kiểu hoa thường User đăng nhập đã được phân quyền role maker/checker sử dụng chức năng cho form nhập liệu | E31: 1. Truy cập màn hình Data Entry Form and Query Forms, chọn form Whitelist 2. Chọn chức năng Search 3. Chọn trường ID Type 4. Nhập giá trị tồn tại nhưng nhập kí tự hoa thường khác với dữ liệu gốc 5. Nhấn nút Go | F31: ID Type: <giá trị tồn tại, đảo hoa/thường> | G31: Màn hình hiển thị các bản ghi chứa xâu tìm kiếm không phân biệt hoa thường | H31: SIT | I31: Medium | J31: N | K31: Untested | L31: Untested | M31: Untested | P31: UI
A32: =COUNTA($C$22:C32) -> 10 | B32: ="TM_DEF_"&$P32&"_"&TEXT(COUNTIF($P$22:$P32,$P32),"000") -> TM_DEF_UI_010 | C32: Kiểm tra chức năng tìm kiếm cơ bản theo ID Type nhập kí tự đặc biệt | D32: Form đã có dữ liệu User đăng nhập đã được phân quyền role maker/checker sử dụng chức năng cho form nhập liệu | E32: 1. Truy cập màn hình Data Entry Form and Query Forms, chọn form Whitelist 2. Chọn chức năng Search 3. Chọn trường ID Type 4. Nhập giá trị là các kí tự đặc biệt(@, #, $, %, ^, *...) có thể tồn tại hoặc không tồn tại 5. Nhấn nút Go | F32: ID Type: @#$% | G32: Trả về thông báo không có dữ liệu [6997] No match found for the current search (nếu không tồn tại giá trị) hoặc hiển thị đúng kết quả chứa giá trị nhập (nếu tồn tại) | H32: SIT | I32: Low | J32: N | K32: Untested | L32: Untested | M32: Untested | P32: UI
A33: =COUNTA($C$22:C33) -> 11 | B33: ="TM_DEF_"&$P33&"_"&TEXT(COUNTIF($P$22:$P33,$P33),"000") -> TM_DEF_UI_011 | C33: Kiểm tra chức năng tìm kiếm cơ bản theo Application scenario thỏa mãn | D33: Form đã có dữ liệu Giá trị Application scenario nhập tìm kiếm tồn tại trong hệ thống User đăng nhập đã được phân quyền role maker/checker sử dụng chức năng cho form nhập liệu | E33: 1. Truy cập màn hình Data Entry Form and Query Forms, chọn form Whitelist 2. Chọn chức năng Search 3. Chọn trường Application scenario 4. Nhập/Chọn giá trị cần tìm kiếm tồn tại 5. Nhấn nút Go | F33: Application scenario: <giá trị tồn tại> | G33: Màn hình hiển thị các bản ghi thỏa mãn điều kiện tìm kiếm script SQL check: select "List Code", "ID", "ID Type", "Application scenario", "Status", "Reason Added", "Effective date", "Description", "Comment", "Trạng thái phê duyệt", "Người tạo", "Ngày tạo", "Người kiểm tra", "Ngày kiểm tra" from Whitelist where upper("Application scenario") like upper('%xâu%') | H33: SIT | I33: High | J33: N | K33: Untested | L33: Untested | M33: Untested | P33: UI
A34: =COUNTA($C$22:C34) -> 12 | B34: ="TM_DEF_"&$P34&"_"&TEXT(COUNTIF($P$22:$P34,$P34),"000") -> TM_DEF_UI_012 | C34: Kiểm tra chức năng tìm kiếm cơ bản theo Application scenario tồn tại nhưng phân biệt hoa thường | D34: Form đã có dữ liệu Giá trị Application scenario tồn tại nhưng nhập khác kiểu hoa thường User đăng nhập đã được phân quyền role maker/checker sử dụng chức năng cho form nhập liệu | E34: 1. Truy cập màn hình Data Entry Form and Query Forms, chọn form Whitelist 2. Chọn chức năng Search 3. Chọn trường Application scenario 4. Nhập giá trị tồn tại nhưng nhập kí tự hoa thường khác với dữ liệu gốc 5. Nhấn nút Go | F34: Application scenario: <giá trị tồn tại, đảo hoa/thường> | G34: Màn hình hiển thị các bản ghi chứa xâu tìm kiếm không phân biệt hoa thường | H34: SIT | I34: Medium | J34: N | K34: Untested | L34: Untested | M34: Untested | P34: UI
A35: =COUNTA($C$22:C35) -> 13 | B35: ="TM_DEF_"&$P35&"_"&TEXT(COUNTIF($P$22:$P35,$P35),"000") -> TM_DEF_UI_013 | C35: Kiểm tra chức năng tìm kiếm cơ bản theo Application scenario nhập kí tự đặc biệt | D35: Form đã có dữ liệu User đăng nhập đã được phân quyền role maker/checker sử dụng chức năng cho form nhập liệu | E35: 1. Truy cập màn hình Data Entry Form and Query Forms, chọn form Whitelist 2. Chọn chức năng Search 3. Chọn trường Application scenario 4. Nhập giá trị là các kí tự đặc biệt(@, #, $, %, ^, *...) có thể tồn tại hoặc không tồn tại 5. Nhấn nút Go | F35: Application scenario: @#$% | G35: Trả về thông báo không có dữ liệu [6997] No match found for the current search (nếu không tồn tại giá trị) hoặc hiển thị đúng kết quả chứa giá trị nhập (nếu tồn tại) | H35: SIT | I35: Low | J35: N | K35: Untested | L35: Untested | M35: Untested | P35: UI
... A48: =COUNTA($C$22:C48) -> 26 | B48: ="TM_DEF_"&$P48&"_"&TEXT(COUNTIF($P$22:$P48,$P48),"000") -> TM_DEF_UI_026 | C48: Kiểm tra chức năng tìm kiếm kết hợp nhiều tiêu chí | D48: Form đã có dữ liệu User đăng nhập đã được phân quyền role maker/checker sử dụng chức năng cho form nhập liệu | E48: 1. Truy cập màn hình Data Entry Form and Query Forms, chọn form Whitelist 2. Chọn chức năng Search 3. Nhập đồng thời nhiều trường tìm kiếm (Application scenario, ID Type, Status) 4. Nhấn nút Go | F48: Application scenario: AML-01; ID Type: Customer; Status: Active | G48: Màn hình hiển thị các bản ghi thỏa mãn đồng thời tất cả tiêu chí tìm kiếm (điều kiện AND) | H48: SIT | I48: Medium | J48: N | K48: Untested | L48: Untested | M48: Untested | P48: UI
A49: =COUNTA($C$22:C49) -> 27 | B49: ="TM_DEF_"&$P49&"_"&TEXT(COUNTIF($P$22:$P49,$P49),"000") -> TM_DEF_UI_027 | C49: Kiểm tra chức năng tìm kiếm khi bỏ trống toàn bộ tiêu chí | D49: Form đã có dữ liệu User đăng nhập đã được phân quyền role maker/checker sử dụng chức năng cho form nhập liệu | E49: 1. Truy cập màn hình Data Entry Form and Query Forms, chọn form Whitelist 2. Chọn chức năng Search 3. Không nhập tiêu chí nào 4. Nhấn nút Go | G49: Màn hình hiển thị toàn bộ danh sách bản ghi whitelist đang tồn tại | H49: SIT | I49: Low | J49: N | K49: Untested | L49: Untested | M49: Untested | P49: UI
A50: 2. Kiểm tra chức năng Upload Excel
A51: 2.1. Kiểm tra Template Upload
A52: =COUNTA($C$22:C52) -> 28 | B52: ="TM_DEF_"&$P52&"_"&TEXT(COUNTIF($P$22:$P52,$P52),"000") -> TM_DEF_UPL_001 | C52: Kiểm tra template Excel upload đúng cấu trúc cột | D52: User đăng nhập đã được phân quyền role maker sử dụng chức năng cho form nhập liệu | E52: 1. NSD vào Data Entry Forms and Queries, chọn Excel upload 2. Trong mục Excel-Entity Mapping, Select Mapping bấm <mũi tên> 3. Chọn Download Excel của Whitelist | G52: Template tải về có đầy đủ các cột theo BRD: ID, ID Type, Application scenario, Status, Reason Added, Description, Comment (List Code và Effective date do hệ thống tự sinh, không có trong file nhập) | H52: SIT | I52: High | J52: N | K52: Untested | L52: Untested | M52: Untested | P52: UPL
...

Sheet Legend
A1: Giai đoạn kiểm thử
A2: Test Level
A3: Giá trị | B3: Giải thích
A4: Value | B4: Description
A5: UT | B5: Kiểm thử kỹ thuật (Unit Test) (IT thực hiện)
A6: SIT | B6: Kiểm thử tích hợp hệ thống (System Integration Test) (IT thực hiện)
A7: OAT | B7: Kiểm thử vận hành (Operation Acceptance Test) (IT thực hiện)
A8: ST | B8: Kiểm thử an ninh thông tin (Security Test) (IT thực hiện)
A9: UAT | B9: Kiểm thử người dùng cuối (User Acceptance Test) (ĐVNV thực hiện)
A12: Độ ưu tiên
A13: Priority
A14: Giá trị | B14: Giải thích
A15: Value | B15: Description
A16: High | B16: Ưu tiên cao
A17: Medium | B17: Ưu tiên trung bình
A18: Low | B18: Ưu tiên thấp/không ưu tiên
A20: Cách thực hiện test | F20: Passed
A21: Automation Status | F21: Failed
A22: Giá trị | B22: Giải thích | F22: Untested
A23: Value | B23: Description | F23: Accepted
A24: Y | B24: Thực hiện Auto test | F24: Pending
A25: N | B25: Thực hiện Manual test | F25: Cancel
A27: Trạng thái
A28: Status
A29: Giá trị | B29: Giải thích
A30: Value | B30: Description
A31: Untested | B31: Chưa thực hiện
A32: Passed | B32: Đạt yêu cầu
A33: Failed | B33: Không đạt yêu cầu
A34: Pending | B34: Pending
B35: Một testcase tạm dừng thực hiện do ảnh hưởng bởi testcase khác fail hoặc cần xác nhận từ các bên liên quan.
A36: Cancel | B36: Không thực hiện
A37: Total | B37: Total = 'Untested' + 'Passed' + 'Failed' + 'Pending' + 'Cancel
A38: % Executed | B38: % Executed = ('Total' - 'Todo' - 'Un-executed')/'Total'
A39: % Pass | B39: % Pass = 'Pass'/'Total'
