Workbook
Name AUTO: #REF!
Name nj: #REF!
Name PRIORITY: #REF!
Name STATUS: #REF!

Sheet Report
B2: Pass | C2: Fail | D2: Pending | E2: Cancel | F2: Untested | G2: Next
A3: API Sàng Lọc | B3: =COUNTIF('API Sàng Lọc'!$K:$K,Report!B2) -> 208 | C3: =COUNTIF('API Sàng Lọc'!$K:$K,Report!C2) -> 0 | D3: =COUNTIF('API Sàng Lọc'!$K:$K,Report!D2) -> 95 | E3: =COUNTIF('API Sàng Lọc'!$K:$K,Report!E2) -> 0 | F3: =COUNTIF('API Sàng Lọc'!$K:$K,Report!F2) -> 0 | G3: =COUNTIF('API Sàng Lọc'!$K:$K,Report!G2) -> 0 | H3: =SUM(B3:G3) -> 303
A4: API Search | B4: =COUNTIF('API Search'!$K:$K,Report!B2) -> 0 | C4: =COUNTIF('API Search'!$K:$K,Report!C2) -> 0 | D4: =COUNTIF('API Search'!$K:$K,Report!D2) -> 0 | E4: =COUNTIF('API Search'!$K:$K,Report!E2) -> 0 | F4: =COUNTIF('API Search'!$K:$K,Report!F2) -> 1 | G4: =COUNTIF('API Search'!$K:$K,Report!G2) -> 0 | H4: =SUM(B4:G4) -> 1
A5: API Callback | B5: =COUNTIF('API Callback'!$K:$K,Report!B2) -> 1 | C5: =COUNTIF('API Callback'!$K:$K,Report!C2) -> 0 | D5: =COUNTIF('API Callback'!$K:$K,Report!D2) -> 0 | E5: =COUNTIF('API Callback'!$K:$K,Report!E2) -> 0 | F5: =COUNTIF('API Callback'!$K:$K,Report!F2) -> 18 | G5: =COUNTIF('API Callback'!$K:$K,Report!G2) -> 0 | H5: =SUM(B5:G5) -> 19
A6: Tổng | B6: =SUM(B3:B5) -> 209 | C6: =SUM(C3:C5) -> 0 | D6: =SUM(D3:D5) -> 95 | E6: =SUM(E3:E5) -> 0 | F6: =SUM(F3:F5) -> 19 | G6: =SUM(G3:G5) -> 0 | H6: =SUM(B6:G6) -> 323
B7: =B6/$H$6 -> 0.64705882 | C7: =C6/$H$6 -> 0 | D7: =D6/$H$6 -> 0.29411765 | E7: =E6/$H$6 -> 0 | F7: =F6/$H$6 -> 0.058823529 | G7: =G6/$H$6 -> 0 | H7: =H6/$H$6 -> 1

Sheet API Sàng Lọc
A1: DỰ ÁN TRIỂN KHAI BẢN QUYỀN PHẦN MỀM HỆ THỐNG AML MỚI
B2: High | C2: Medium | D2: Low | E2: Total R1
A3: Pass | B3: =COUNTIFS($K$12:$K$389,A3,$H$12:$H$389,$B$2) -> 44 | C3: =COUNTIFS($K$12:$K$389,A3,$H$12:$H$389,$C$2) -> 162 | D3: =COUNTIFS($K$12:$K$389,A3,$H$12:$H$389,$D$2) -> 2 | E3: =SUM(B3:D3) -> 208
A4: Fail | B4: =COUNTIFS($K$12:$K$389,A4,$H$12:$H$389,$B$2) -> 0 | C4: =COUNTIFS($K$12:$K$389,A4,$H$12:$H$389,$C$2) -> 0 | D4: =COUNTIFS($K$12:$K$389,A4,$H$12:$H$389,$D$2) -> 0 | E4: =SUM(B4:D4) -> 0 | F4: đang retest
A5: Pending | B5: =COUNTIFS($K$12:$K$389,A5,$H$12:$H$389,$B$2) -> 9 | C5: =COUNTIFS($K$12:$K$389,A5,$H$12:$H$389,$C$2) -> 86 | D5: =COUNTIFS($K$12:$K$389,A5,$H$12:$H$389,$D$2) -> 0 | E5: =SUM(B5:D5) -> 95 | F5: Liên quan đến điện customize
A6: Cancel | B6: =COUNTIFS($K$12:$K$389,A6,$H$12:$H$389,$B$2) -> 0 | C6: =COUNTIFS($K$12:$K$389,A6,$H$12:$H$389,$C$2) -> 0 | D6: =COUNTIFS($K$12:$K$389,A6,$H$12:$H$389,$D$2) -> 0 | E6: =SUM(B6:D6) -> 0
A7: Untested | B7: =COUNTIFS($K$12:$K$389,A7,$H$12:$H$389,$B$2) -> 0 | C7: =COUNTIFS($K$12:$K$389,A7,$H$12:$H$389,$C$2) -> 0 | D7: =COUNTIFS($K$12:$K$389,A7,$H$12:$H$389,$D$2) -> 0 | E7: =SUM(B7:D7) -> 0
A8: Next | B8: =COUNTIFS($K$12:$K$389,A8,$H$12:$H$389,$B$2) -> 0 | C8: =COUNTIFS($K$12:$K$389,A8,$H$12:$H$389,$C$2) -> 0 | D8: =COUNTIFS($K$12:$K$389,A8,$H$12:$H$389,$D$2) -> 0 | E8: =SUM(B8:D8) -> 0
E9: =SUM(E3:E7) -> 303
A11: ID Testcase | B11: Test case Title | C11: Pre-conditions | D11: Test Steps | E11: Test Datas | F11: Expected result | G11: Test Environment | H11: Priority | I11: Automation Status | J11: 1st Test Results | K11: 2st Test Results
A12: II. Endpoint & HTTP Method
A13: AML_API_EP Kiểm tra endpoint và phương thức HTTP
A14: AML_API_EP_01 | B14: Kiểm tra thông tin API khi gọi đúng endpoint với method POST | C14: Server đang chạy; Auth hợp lệ | D14: 1. Gửi POST request đến: https://10.0.137.75:7001/transaction-screening/v1/transaction-screening 2. Body là điện MT hợp lệ 3. Kiểm tra HTTP 200 và response body | E14: Headers: Authorization: Basic a3ljYWRtbjphYmMxMjM= (Username and password to login) Content-Type: application/json transactionId: TF_EP_001 requestId: REQ_TF_EP_001 transactionType: MT branchCd: HN channel: T24 isCallBack: N Body: {1:F01BFICCUHHAXXX0000000000} {2:I195BFICCUHHXXXXN} {3:{108:MT195TEST0001}} {4: :20:QRY2607240001 :21:NONREF :75:PLEASE CONFIRM -}{5:{MAC:00000000}{CHK:1A2B3C4D5E6F}} | F14: Kiểm tra thông tin HTTP Status trả về : 200 OK "result": No-HIT hoặc HIT "transactionType": "transactionType", "score": score, "groupMessageId": "groupMessageId", "requestId": "requestId", "processDate": "processDate", "channel": "channel", "errorCode": null, "errorDetail": null, "alertId": "alertId", "transactionId": "transactionId", "branchCd": "branchCd" | G14: SIT | H14: High | I14: Manual | J14: Untested | K14: Pass
A15: AML_API_EP_02 | B15: Kiểm tra thông tin API khi gọi sai endpoint URL | C15: Server đang chạy; Auth hợp lệ | D15: 1. Gửi POST request đến URL sai: /wrong-path/v1/transaction-screening 2. Kiểm tra HTTP status trả về | E15: POST https://10.0.137.75:7001/transaction-screening/v1/transaction-screening Authorization: Basic a3ljYWRtbjphYmMxMjM= (Username and password to login) Content-Type: application/json | F15: Kiểm tra thông tin HTTP Status trả về : 404 Not Found | G15: SIT | H15: High | I15: Manual | J15: Untested | K15: Pass
A16: AML_API_EP_03 | B16: Kiểm tra thông tin API khi gọi đúng endpoint nhưng dùng method GET | C16: Server đang chạy; Auth hợp lệ | D16: 1. Gửi GET request đến đúng endpoint 2. Không có body 3. Kiểm tra HTTP status trả về | E16: GET https://10.0.137.75:7001/transaction-screening/v1/transaction-screening Authorization: Basic a3ljYWRtbjphYmMxMjM= (Username and password to login) Content-Type: application/json | F16: Kiểm tra thông tin HTTP Status trả về : 405 Method Not Allowed (Không có body nghiệp vụ) | G16: SIT | H16: Medium | I16: Manual | J16: Untested | K16: Pass
A17: III. Validation - Header Parameters
A18: AML_API_HDR Kiểm tra các trường bắt buộc / optional trong request params
A19: AML_API_HDR_01 | B19: Request đầy đủ tất cả field bắt buộc | C19: Auth hợp lệ; MT body đúng format | D19: 1. Gửi POST với đủ 7 fields: transactionId, requestId, transactionType=MT, branchCd, channel, isCallBack, requestUserId 2. Kiểm tra xử lý thành công | E19: Headers: Authorization: Basic a3ljYWRtbjphYmMxMjM= (Username and password to login) Content-Type: application/json transactionId: TF_HDR_001 requestId: REQ_TF_HDR_001 transactionType: MT branchCd: HN channel: T24 isCallBack: N Body: {1:F01BFICCUHHAXXX0000000000} {2:I195BFICCUHHXXXXN} {3:{108:MT195TEST0001}} {4: :20:QRY2607240001 :21:NONREF :75:PLEASE CONFIRM -}{5:{MAC:00000000}{CHK:1A2B3C4D5E6F}} | F19: Kiểm tra thông tin HTTP Status trả về : 200 OK "result": No-HIT hoặc HIT "transactionType": "transactionType", "score": score, "groupMessageId": "groupMessageId", "requestId": "requestId", "processDate": "processDate", "channel": "channel", "errorCode": null, "errorDetail": null, "alertId": "alertId", "transactionId": "transactionId", "branchCd": "branchCd" | G19: SIT | H19: High | I19: Manual | J19: Untested | K19: Pass
A20: AML_API_HDR_02 | B20: Thiếu transactionId (Mandatory) | C20: Auth hợp lệ | D20: 1. Gửi POST KHÔNG có transactionId 2. Các field khác đầy đủ 3. Kiểm tra errorCode trong response | E20: Headers: Authorization: Basic a3ljYWRtbjphYmMxMjM= (Username and password to login) Content-Type: application/json requestId: REQ_HDR_002 transactionType: MT branchCd: HN channel: T24 isCallBack: N Body: {1:F01BFICCUHHAXXX0000000000} {2:I195BFICCUHHXXXXN} {3:{108:MT195TEST0001}} {4: :20:QRY2607240001 :21:NONREF :75:PLEASE CONFIRM -}{5:{MAC:00000000}{CHK:1A2B3C4D5E6F}} | F20: Kiểm tra thông tin HTTP Status trả về : 200 OK "transactionType": "transactionType", "result": null, "score": null, "groupMessageId": null, "requestId": "requestId", "processDate": null, "channel": "channel", "errorCode": "01", "errorDetail": "Missing Parameter", "alertId": null, "transactionId": "", "branchCd": "branchCd" | G20: SIT | H20: High | I20: Manual | J20: Untested | K20: Pass
A21: AML_API_HDR_03 | B21: Thiếu requestId (Mandatory) | C21: Auth hợp lệ | D21: 1. Gửi POST KHÔNG có requestId 2. Các field khác đầy đủ 3. Kiểm tra errorCode | E21: Headers: Authorization: Basic a3ljYWRtbjphYmMxMjM= (Username and password to login) Content-Type: application/json transactionId: TF_HDR_003 transactionType: MT branchCd: HN channel: T24 isCallBack: N Body: {1:F01BFICCUHHAXXX0000000000} {2:I195BFICCUHHXXXXN} {3:{108:MT195TEST0001}} {4: :20:QRY2607240001 :21:NONREF :75:PLEASE CONFIRM -}{5:{MAC:00000000}{CHK:1A2B3C4D5E6F}} | F21: Kiểm tra thông tin HTTP Status trả về : 200 OK "transactionType": "transactionType", "result": null, "score": null, "groupMessageId": null, "requestId": "", "processDate": null, "channel": "channel", "errorCode": "01", "errorDetail": "Missing Parameter", "alertId": null, "transactionId": "transactionId", "branchCd": "branchCd" | G21: SIT | H21: High | I21: Manual | J21: Untested | K21: Pass
A22: AML_API_HDR_04 | B22: Thiếu transactionType (Mandatory) | C22: Auth hợp lệ | D22: 1. Gửi POST KHÔNG có transactionType 2. Các field khác đầy đủ 3. Kiểm tra errorCode | E22: Headers: Authorization: Basic a3ljYWRtbjphYmMxMjM= (Username and password to login) Content-Type: application/json transactionId: TF_HDR_004 requestId: REQ_HDR_004 branchCd: HN channel: T24 isCallBack: N Body: {1:F01BFICCUHHAXXX0000000000} {2:I195BFICCUHHXXXXN} {3:{108:MT195TEST0001}} {4: :20:QRY2607240001 :21:NONREF :75:PLEASE CONFIRM -}{5:{MAC:00000000}{CHK:1A2B3C4D5E6F}} | F22: Kiểm tra thông tin HTTP Status trả về : 200 OK "transactionType": "", "result": null, "score": null, "groupMessageId": null, "requestId": "requestId", "processDate": null, "channel": "channel", "errorCode": "01", "errorDetail": "Missing Parameter", "alertId": null, "transactionId": "transactionId", "branchCd": "branchCd" | G22: SIT | H22: High | I22: Manual | J22: Untested | K22: Pass
A23: AML_API_HDR_05 | B23: Thiếu branchCd (Mandatory) | C23: Auth hợp lệ | D23: 1. Gửi POST KHÔNG có branchCd 2. Các field khác đầy đủ 3. Kiểm tra errorCode | E23: Headers: Authorization: Basic a3ljYWRtbjphYmMxMjM= (Username and password to login) Content-Type: application/json transactionId: TF_HDR_005 requestId: REQ_HDR_005 transactionType: MT channel: T24 isCallBack: N Body: {1:F01BFICCUHHAXXX0000000000} {2:I195BFICCUHHXXXXN} {3:{108:MT195TEST0001}} {4: :20:QRY2607240001 :21:NONREF :75:PLEASE CONFIRM -}{5:{MAC:00000000}{CHK:1A2B3C4D5E6F}} | F23: Kiểm tra thông tin HTTP Status trả về : 200 OK "transactionType": "transactionType", "result": null, "score": null, "groupMessageId": null, "requestId": "requestId", "processDate": null, "channel": "channel", "errorCode": "01", "errorDetail": "Missing Parameter", "alertId": null, "transactionId": "transactionId", "branchCd": "" | G23: SIT | H23: High | I23: Manual | J23: Untested | K23: Pass
A24: AML_API_HDR_06 | B24: Thiếu channel (Mandatory) | C24: Auth hợp lệ | D24: 1. Gửi POST KHÔNG có channel 2. Các field khác đầy đủ 3. Kiểm tra errorCode | E24: Headers: Authorization: Basic a3ljYWRtbjphYmMxMjM= (Username and password to login) Content-Type: application/json transactionId: TF_HDR_006 requestId: REQ_HDR_006 transactionType: MT branchCd: HN isCallBack: N Body: {1:F01BFICCUHHAXXX0000000000} {2:I195BFICCUHHXXXXN} {3:{108:MT195TEST0001}} {4: :20:QRY2607240001 :21:NONREF :75:PLEASE CONFIRM -}{5:{MAC:00000000}{CHK:1A2B3C4D5E6F}} | F24: Kiểm tra thông tin HTTP Status trả về : 200 OK "transactionType": "transactionType", "result": null, "score": null, "groupMessageId": null, "requestId": "requestId", "processDate": null, "channel": "", "errorCode": "01", "errorDetail": "Missing Parameter", "alertId": null, "transactionId": "transactionId", "branchCd": "branchCd" | G24: SIT | H24: High | I24: Manual | J24: Untested | K24: Pass
A25: AML_API_HDR_07 | B25: Thiếu isCallBack (Mandatory) | C25: Auth hợp lệ | D25: 1. Gửi POST KHÔNG có isCallBack 2. Các field khác đầy đủ 3. Kiểm tra errorCode | E25: Headers: Authorization: Basic a3ljYWRtbjphYmMxMjM= (Username and password to login) Content-Type: application/json transactionId: TF_HDR_007 requestId: REQ_HDR_007 transactionType: MT branchCd: HN channel: T24 Body: {1:F01BFICCUHHAXXX0000000000} {2:I195BFICCUHHXXXXN} {3:{108:MT195TEST0001}} {4: :20:QRY2607240001 :21:NONREF :75:PLEASE CONFIRM -}{5:{MAC:00000000}{CHK:1A2B3C4D5E6F}} | F25: Kiểm tra thông tin HTTP Status trả về : 200 OK result: ERROR errorCode: 01 errorDetail: Missing parameter score: (rỗng) alertId: (rỗng) processDate: null | G25: SIT | H25: High | I25: Manual | J25: Untested | K25: Pass
A26: AML_API_HDR_08 | B26: requestUserId là Optional – không truyền vẫn hợp lệ | C26: Auth hợp lệ; Không truyền requestUserId | D26: 1. Gửi POST đầy đủ 6 fields bắt buộc 2. Không có requestUserId (Optional) 3. Kiểm tra xử lý thành công | E26: Headers: Authorization: Basic a3ljYWRtbjphYmMxMjM= (Username and password to login) Content-Type: application/json transactionId: TF_HDR_008 requestId: REQ_TF_HDR_008 transactionType: MT branchCd: HN channel: T24 isCallBack: N Body: {1:F01BFICCUHHAXXX0000000000} {2:I195BFICCUHHXXXXN} {3:{108:MT195TEST0001}} {4: :20:QRY2607240001 :21:NONREF :75:PLEASE CONFIRM -}{5:{MAC:00000000}{CHK:1A2B3C4D5E6F}} | F26: Kiểm tra thông tin HTTP Status trả về : 200 OK "result": No-HIT hoặc HIT "transactionType": "transactionType", "score": score, "groupMessageId": "groupMessageId", "requestId": "requestId", "processDate": "processDate", "channel": "channel", "errorCode": null, "errorDetail": null, "alertId": "alertId", "transactionId": "transactionId", "branchCd": "branchCd" | G26: SIT | H26: Medium | I26: Manual | J26: Untested | K26: Pass
A27: AML_API_HDR_09 | B27: isCallBack = Y – AML cần callback sau khi Alert hoàn thành | C27: Auth hợp lệ; Hệ thống có endpoint nhận callback | D27: 1. Gửi POST với isCallBack=Y 2. Body là điện MT có HIT 3. Kiểm tra: a. Response trả ngay (HTTP 200) b. Sau khi Alert xử lý xong: AML callback về hệ thống | E27: Headers: Authorization: Basic a3ljYWRtbjphYmMxMjM= (Username and password to login) Content-Type: application/json transactionId: TF_HDR_009 requestId: REQ_TF_HDR_009 transactionType: MT branchCd: HN channel: T24 isCallBack: Y Body: {1:F01BFICCUHHAXXX0000000000} {2:I195BFICCUHHXXXXN} {3:{108:MT195TEST0001}} {4: :20:QRY2607240001 :21:NONREF :75:PLEASE CONFIRM -}{5:{MAC:00000000}{CHK:1A2B3C4D5E6F}} | F27: Kiểm tra thông tin HTTP Status trả về : 200 OK result: HIT hoặc No-HIT errorCode: 00 Verify callback: - AML gọi callback URL với alertId và kết quả - Hệ thống nguồn nhận được callback | G27: SIT | H27: High | I27: Manual | J27: Untested | K27: Pass
A28: AML_API_HDR_10 | B28: isCallBack = N – AML không callback | C28: Auth hợp lệ | D28: 1. Gửi POST với isCallBack=N 2. Body là điện MT 3. Kiểm tra không có callback | E28: Headers: Authorization: Basic a3ljYWRtbjphYmMxMjM= (Username and password to login) Content-Type: application/json transactionId: TF_HDR_010 requestId: REQ_TF_HDR_010 transactionType: MT branchCd: HN channel: T24 isCallBack: N Body: {1:F01BFICCUHHAXXX0000000000} {2:I195BFICCUHHXXXXN} {3:{108:MT195TEST0001}} {4: :20:QRY2607240001 :21:NONREF :75:PLEASE CONFIRM -}{5:{MAC:00000000}{CHK:1A2B3C4D5E6F}} | F28: Kiểm tra thông tin HTTP Status trả về : 200 OK "result": No-HIT hoặc HIT "transactionType": "transactionType", "score": score, "groupMessageId": "groupMessageId", "requestId": "requestId", "processDate": "processDate", "channel": "channel", "errorCode": null, "errorDetail": null, "alertId": "alertId", "transactionId": "transactionId", "branchCd": "branchCd" | G28: SIT | H28: Medium | I28: Manual | J28: Untested | K28: Pass
A29: AML_API_HDR_11 | B29: isCallBack giá trị không hợp lệ (khác Y/N) | C29: Auth hợp lệ | D29: 1. Gửi POST với isCallBack='X' 2. Kiểm tra response lỗi | E29: Headers: Authorization: Basic a3ljYWRtbjphYmMxMjM= (Username and password to login) Content-Type: application/json transactionId: TF_HDR_011 requestId: REQ_TF_HDR_011 transactionType: MT branchCd: HN channel: T24 isCallBack: X Body: {1:F01BFICCUHHAXXX0000000000} {2:I195BFICCUHHXXXXN} {3:{108:MT195TEST0001}} {4: :20:QRY2607240001 :21:NONREF :75:PLEASE CONFIRM -}{5:{MAC:00000000}{CHK:1A2B3C4D5E6F}} | F29: Kiểm tra thông tin HTTP Status trả về : 200 OK "transactionType": "transactionType", "result": null, "score": null, "groupMessageId": null, "requestId": "requestId", "processDate": null, "channel": "channel", "errorCode": "01", "errorDetail": "Missing Parameter", "alertId": null, "transactionId": "transactionId", "branchCd": "branchCd" | G29: SIT | H29: Medium | I29: Manual | J29: Untested | K29: Pass
A30: AML_API_HDR_12 | B30: transactionId vượt độ dài tối đa (>100 ký tự) | C30: Auth hợp lệ | D30: 1. Gửi POST với transactionId dài 101 ký tự 2. Kiểm tra response lỗi | E30: transactionId: TF_AAAAAAAAAAAAAAAAAAAAAAAAAAAAAAAAAAAAAAAAAAAAAAAAAAAAAAAAAAAAAAAAAAAAAAAAAAAAAAAAAAAAAAAAAAAAAAAAA (độ dài=101, vượt varchar2(100)) | F30: Kiểm tra thông tin HTTP Status trả về : 200 OK "transactionType": "transactionType", "result": null, "score": null, "groupMessageId": null, "requestId": "requestId", "processDate": null, "channel": "channel", "errorCode": "01", "errorDetail": "Missing Parameter", "alertId": null, "transactionId": "transactionId", "branchCd": "branchCd" | G30: SIT | H30: Medium | I30: Manual | J30: Untested | K30: Pass
A31: AML_API_HDR_13 | B31: transactionType không hợp lệ (giá trị không được hỗ trợ) | C31: Auth hợp lệ | D31: 1. Gửi POST với transactionType='UNKNOWN_TYPE' 2. Kiểm tra response lỗi | E31: Headers: Authorization: Basic a3ljYWRtbjphYmMxMjM= (Username and password to login) Content-Type: application/json transactionId: TF_HDR_013 requestId: REQ_TF_HDR_013 transactionType: UNKNOWN_TYPE branchCd: HN channel: T24 isCallBack: N Body: {1:F01BFICCUHHAXXX0000000000} {2:I195BFICCUHHXXXXN} {3:{108:MT195TEST0001}} {4: :20:QRY2607240001 :21:NONREF :75:PLEASE CONFIRM -}{5:{MAC:00000000}{CHK:1A2B3C4D5E6F}} | F31: Kiểm tra thông tin HTTP Status trả về : 200 OK "transactionType": "transactionType", "result": null, "score": null, "groupMessageId": null, "requestId": "requestId", "processDate": null, "channel": "channel", "errorCode": "01", "errorDetail": "Missing Parameter", "alertId": null, "transactionId": "transactionId", "branchCd": "branchCd" | G31: SIT | H31: Medium | I31: Manual | J31: Untested | K31: Pass
A32: IV. Sàng lọc điện MT Standard
A33: AML_API_MT Kiểm tra sàng lọc với điện SWIFT MT Standard
A34: AML_API_MT_01 | B34: MT hợp lệ – kết quả No-HIT | C34: Auth hợp lệ; Body MT đúng format SWIFT; Thông tin điện không có match cấm vận | D34: 1. Gửi POST với transactionType=MT 2. Body là điện SWIFT MT chuẩn 3. Kiểm tra result=No-HIT 4. Verify các fields response | E34: Headers: Authorization: Basic a3ljYWRtbjphYmMxMjM= (Username and password to login) Content-Type: application/json transactionId: TF_MT_001 requestId: REQ_TF_MT_001 transactionType: MT branchCd: HN channel: T24 isCallBack: N Body: {1:F01SCBLSGSGAXXX0000000000} {2:I196MCOBVNVXXXXXN} {3:{108:MT196TEST0002}} {4: :20:ANS2607240002 :21:NONREF :76:00998877663 :77A:00998877663 :79:00998877663 -}{5:{MAC:00000000}{CHK:1A2B3C4D5E6F}} | F34: { "transactionType": "transactionType", "result": "NO HIT", "score": 0, "groupMessageId": "groupMessageId", "requestId": "requestId", "processDate": dd-mm-yyyy hh:mi:ss, "channel": "channel", "errorCode": null, "errorDetail": null, "alertId": "alertId", "transactionId": "transactionId", "branchCd": "branchCd" | G34: SIT | H34: High | I34: Manual | J34: Untested | K34: Pass
A35: AML_API_MT_02 | B35: MT hợp lệ – kết quả HIT (có match cấm vận) | C35: Auth hợp lệ; Body MT có tên/thông tin nằm trong danh sách cấm vận; (Không phải Knock-out country) | D35: 1. Gửi POST với transactionType=MT 2. Body điện MT có tên match danh sách cấm vận 3. Kiểm tra result=HIT 4. Verify alertId được sinh | E35: Headers: Authorization: Basic a3ljYWRtbjphYmMxMjM= (Username and password to login) Content-Type: application/json transactionId: TF_MT_002 requestId: REQ_TF_MT_002 transactionType: MT branchCd: HN channel: T24 isCallBack: N Body: {1:F01SCBLSGSGAXXX0000000000} {2:I196MCOBIRVXXXXXN} {3:{108:MT196TEST0002}} {4: :20:ANS2607240002 :21:NONREF :76:00998877663 :77A:00998877663 :79:00998877663 -}{5:{MAC:00000000}{CHK:1A2B3C4D5E6F}} | F35: { "transactionType": "transactionType", "result": "HIT", "score": score, "groupMessageId": "groupMessageId", "requestId": "requestId", "processDate": dd-mm-yyyy hh:mi:ss, "channel": "channel", "errorCode": null, "errorDetail": null, "alertId": "alertId", "transactionId": "transactionId", "branchCd": "branchCd" | G35: SIT | H35: High | I35: Manual | J35: Untested | K35: Pass
A36: AML_API_MT_03 | B36: MT hợp lệ – kết quả KNOCKED-OUT (quốc gia Knock-out) | C36: Auth hợp lệ; Body MT có quốc gia nằm trong danh sách Knock-out; (Ví dụ: CUBA trong :58D) | D36: 1. Gửi POST với transactionType=MT 2. Body điện MT có quốc gia Knock-out (vd: CUBA) 3. Kiểm tra result=KNOCKED-OUT | E36: Headers: Authorization: Basic a3ljYWRtbjphYmMxMjM= (Username and password to login) Content-Type: application/json transactionId: TF_MT_003 requestId: REQ_TF_MT_003 transactionType: MT branchCd: HN channel: T24 isCallBack: N Body: {1:F01SIIBSYDAXXXX0000000000} {2:I202ESSESESSXXXXN} {4: :20:MT202 :21:SENDEREFERENC001 :32A:170623CNY5000 :58D:/B/BENEFICIARYINST MAJESTUALIDAQ CUBA :72:PHONBEN -} {5:{MAC:12345678}{CHK:123456789ABC}} | F36: Kiểm tra thông tin HTTP Status trả về : 200 OK "transactionType": "transactionType", "result": "KNOCKED-OUT", "score": score, "groupMessageId": "groupMessageId", "requestId": "requestId", "processDate": "processDate", "channel": "channel", "errorCode": "00", "errorDetail": "No error", "alertId": "alertId", "transactionId": "transactionId", "branchCd": "branchCd" | G36: SIT | H36: High | I36: Manual | J36: Untested | K36: Pass
A37: AML_API_MT_04 | B37: MT – body điện sai format (không phải SWIFT MT) | C37: Auth hợp lệ | D37: 1. Gửi POST với transactionType=MT 2. Body KHÔNG phải SWIFT MT (plain text) 3. Kiểm tra errorCode=03 | E37: Headers: Authorization: Basic a3ljYWRtbjphYmMxMjM= (Username and password to login) Content-Type: application/json transactionId: TF_MT_004 requestId: REQ_TF_MT_004 transactionType: MT branchCd: HN channel: T24 isCallBack: N Body: INVALID_MT_BODY_NOT_SWIFT | F37: "result": null, "score": null, "groupMessageId": null, "requestId": "requestId", "processDate": null, "channel": "T24", "errorCode": "03", "errorDetail": "Invalid message format", "alertId": null, "transactionId": "transactionId" | G37: SIT | H37: High | I37: Manual | J37: Untested | K37: Pass
A38: AML_API_MT_05 | B38: MT – body rỗng | C38: Auth hợp lệ | D38: 1. Gửi POST với transactionType=MT 2. Body = empty string 3. Kiểm tra errorCode | E38: Headers: Authorization: Basic a3ljYWRtbjphYmMxMjM= (Username and password to login) Content-Type: application/json transactionId: TF_MT_005 requestId: REQ_TF_MT_005 transactionType: MT branchCd: HN channel: T24 isCallBack: N Body: | F38: Kiểm tra thông tin HTTP Status trả về : 400 { "timestamp": "timestamp UTC", "status": 400, "error": "Bad Request", "path": "/transaction-screening/v1/transaction-screening" } | G38: SIT | H38: High | I38: Manual | J38: Untested | K38: Pass
A39: AML_API_MT_06 | B39: MT – transactionId trùng lặp (duplicate) | C39: Auth hợp lệ; Đã tồn tại giao dịch với transactionId=TF_MT_DUP_001 | D39: 1. Gửi POST lần 1 với transactionId=TF_MT_DUP_001 → ghi nhận kết quả 2. Gửi POST lần 2 với cùng transactionId=TF_MT_DUP_001 3. So sánh kết quả 2 lần | E39: Headers: Authorization: Basic a3ljYWRtbjphYmMxMjM= (Username and password to login) Content-Type: application/json transactionId: TF_MT_DUP_001 requestId: REQ_TF_MT_DUP_001 transactionType: MT branchCd: HN channel: T24 isCallBack: N Body: {1:F01SIIBSYDAXXXX0000000000} {2:I202ESSESESSXXXXN} {4: :20:MT202 :21:SENDEREFERENC001 :32A:170623CNY5000 :58D:/B/BENEFICIARYINST MAJESTUALIDAQ CUBA :72:PHONBEN -} {5:{MAC:12345678}{CHK:123456789ABC}} | F39: Hệ thống không ghi nhận lỗi. Trả kết quả phù hợp cho mỗi lần chạy | G39: SIT | H39: Medium | I39: Manual | J39: Untested | K39: Pass
A40: AML_API_MT_07 | B40: MT – isCallBack=Y, verify callback sau khi Alert hoàn thành | C40: Auth hợp lệ; Body MT có HIT; Hệ thống có endpoint nhận callback | D40: 1. Gửi POST MT với isCallBack=Y 2. Nhận response HTTP 200 (result=HIT) 3. Chờ Alert được xử lý hoàn thành 4. Kiểm tra AML đã gọi callback về hệ thống | E40: Headers: Authorization: Basic a3ljYWRtbjphYmMxMjM= (Username and password to login) Content-Type: application/json transactionId: TF_MT_007 requestId: REQ_TF_MT_007 transactionType: MT branchCd: HN channel: T24 isCallBack: Y Body: {1:F01SIIBSYDAXXXX0000000000} {2:I202ESSESESSXXXXN} {4: :20:MT202 :21:SENDEREFERENC001 :32A:170623CNY5000 :58D:/B/BENEFICIARYINST MAJESTUALIDAQ CUBA :72:PHONBEN -} {5:{MAC:12345678}{CHK:123456789ABC}} | F40: Kiểm tra thông tin HTTP Status trả về : 200 OK result: HIT errorCode: 00 Verify callback: - Hệ thống nguồn nhận callback từ AML - Callback chứa alertId và kết quả xử lý Alert | G40: SIT | H40: High | I40: Manual | J40: Untested | K40: Pending | L40: Hiện tại trên UAT chưa có đầu kênh để check call back
A41: V. Sàng lọc điện MX Standard (ISO 20022)
...

Sheet API Search
A1: Functions | B1: =[1]Cover!E11 -> DỰ ÁN TRIỂN KHAI BẢN QUYỀN PHẦN MỀM HỆ THỐNG AML MỚI
A2: Build Version | B2: v1.0
A3: ROUND 1
B4: High | C4: Medium | D4: Low | E4: Total
B5: =SUM(B6:B10) -> 24 | C5: =SUM(C6:C10) -> 0 | D5: =SUM(D6:D10) -> 0 | E5: =SUM(B5:D5) -> 24
A6: Passed | B6: =COUNTIFS($J:$J, $A$6,$H:$H,B$4) -> 0 | C6: =COUNTIFS($J:$J, $A$6,$H:$H,C$4) -> 0 | D6: =COUNTIFS($J:$J, $A$6,$H:$H,D$4) -> 0 | E6: =SUM(B6:D6) -> 0
A7: Failed | B7: =COUNTIFS($J:$J, $A$7,$H:$H,B$4) -> 0 | C7: =COUNTIFS($J:$J, $A$7,$H:$H,C$4) -> 0 | D7: =COUNTIFS($J:$J, $A$7,$H:$H,D$4) -> 0 | E7: =SUM(B7:D7) -> 0
A8: Untested | B8: =COUNTIFS($J:$J, $A$8,$H:$H,B$4) -> 24 | C8: =COUNTIFS($J:$J, $A$8,$H:$H,C$4) -> 0 | D8: =COUNTIFS($J:$J, $A$8,$H:$H,D$4) -> 0 | E8: =SUM(B8:D8) -> 24
A9: Accepted | B9: =COUNTIFS($J:$J, $A$9,$H:$H,B$4) -> 0 | C9: =COUNTIFS($J:$J, $A$9,$H:$H,C$4) -> 0 | D9: =COUNTIFS($J:$J, $A$9,$H:$H,D$4) -> 0 | E9: =SUM(B9:D9) -> 0
A10: N/A | B10: =COUNTIFS($J:$J, $A$10,H:H,B$4) -> 0 | C10: =COUNTIFS($J:$J, $A$10,I:I,C$4) -> 0 | D10: =COUNTIFS($J:$J, $A$10,J:J,D$4) -> 0 | E10: =SUM(B10:D10) -> 0
A11: ROUND 2
B12: High | C12: Medium | D12: Low | E12: Total
B13: =SUM(B14:B18) -> 24 | C13: =SUM(C14:C18) -> 0 | D13: =SUM(D14:D18) -> 0 | E13: =SUM(B13:D13) -> 24
A14: Passed | B14: =COUNTIFS($K:$K,$A$14,$H:$H,B12) -> 23 | C14: =COUNTIFS($K:$K,$A$14,$H:$H,C12) -> 0 | D14: =COUNTIFS($K:$K,$A$14,$H:$H,D12) -> 0 | E14: =SUM(B14:D14) -> 23
A15: Failed | B15: =COUNTIFS($K:$K,$A$15,$H:$H,B12) -> 0 | C15: =COUNTIFS($K:$K,$A$15,$H:$H,C12) -> 0 | D15: =COUNTIFS($K:$K,$A$15,$H:$H,D12) -> 0 | E15: =SUM(B15:D15) -> 0
A16: Untested | B16: =COUNTIFS($K:$K,$A$16,$H:$H,B12) -> 1 | C16: =COUNTIFS($K:$K,$A$16,$H:$H,C12) -> 0 | D16: =COUNTIFS($K:$K,$A$16,$H:$H,D12) -> 0 | E16: =SUM(B16:D16) -> 1 | F16: fai off server
A17: Accepted | B17: =COUNTIFS($K:$K,$A$17,$H:$H,B12) -> 0 | C17: =COUNTIFS($K:$K,$A$17,$H:$H,C12) -> 0 | D17: =COUNTIFS($K:$K,$A$17,$H:$H,D12) -> 0 | E17: =SUM(B17:D17) -> 0
A20: Test case Id | B20: Test case Title | C20: Pre-conditions | D20: Test Steps | E20: Test Datas | F20: Expected result | G20: Test Environment | H20: Priority | I20: Automation Status | J20: 1st Test Results | K20: 2nd Test Results | L20: BugID | M20: Notes
A21: API_SEARCH.01 | B21: API truy vấn kết quả sàng lọc/đánh giá sự vụ từ AML
A22: API_SEARCH.01.01 | B22: Send API truyền thông tin requestId để truy vấn kết quả sàng lọc sự vụ từ AML và thông tin giao dịch có kết quả NO HIT | C22: - Giao dịch có kết quả sàng lọc NO HIT | D22: 1. Đẩy API truyền thông tin Số tham chiếu giao dịch để nhận kết quả từ AML URL:http://ip:port/TabletoJSONService/TableToJson/createtabletojson path:/TabletoJSONService/TableToJson/createtabletojson Method: POST Request Header: Authorization: Basic a3ljYWRtbjphYmMxMjM= (Username and password to login) Truyền Param: mappingId = SEARCH_TF requestId= 'n_grp_msg_id' 2. Kiểm tra Response trả về | E22: {1:F01MCOBVNVXAXXX.SN...ISN.}{2:I195SCBLUS33XXXXN}{3:{108:262315GRVX61483}{121:f6706b2b-rrrr-444f-9ee8-0304037814c2}}{4: :20:NZ126032502700 :21:S1626084GHMFKKHF :75:ATTN PAYMENTS INVESTIGATIONS :77A:PLEASE BE ADVISED THAT WE ARE UNABLE TO EFFECT SUBJECT PAYMENT DUE TO INSUFFICIENT FUNDS IN YOUR ACCOUNT 270959NZD00001. PAYMENT HELD PENDING ACCOUNT BEING FULLY FUNDED. IF WE DO NOT HEAR FROM YOU WITHIN THE NEXT THREE WORKING DAYS, WE MAY CANCEL THE PAYMENT. THANKS ANZ MARKET TEAM :11R:103 260325 :20:S1626084GHMFKKHF -}{5:{MAC: :00000000}{CHK:D2826EE1B645}}{S:{SAC:}{COP:S}} | F22: 2. Kết quả response trả về kết quả theo đúng yêu cầu { "transactionId": "transactionId", "branchCd": "branchCd", "channel": "channel", "finalResult": "PASS", "alertStatus": null, "processDate": "processDate", "transactionType": "transactionType", "score": 0, "requestId": "requestId" } | G22: SIT | H22: High | J22: Untested | K22: Passed | N22: curl --location --request POST 'https://10.0.137.75:7001/TabletoJSONService/TableToJson/createtabletojson?mappingId=SEARCH_TF&requestId=50053' \ --header 'Cookie: JSESSIONID=zRkyggx9Ymx2EOmicEST30_kAPdkCWdFBnn7mKb5fxZA9GZ03tP6!663991662'
A23: API_SEARCH.01.02 | B23: Send API truyền thông tin requestId để truy vấn kết quả sàng lọc/đánh giá sự vụ từ AML và thông tin giao dịch có kết quả HIT và chưa hoàn thành đánh giá sự vụ | C23: - Giao dịch có kết quả sàng lọc HIT và chưa hoàn thành đánh giá sự vụ | D23: 1. Đẩy API truyền thông tin Số tham chiếu giao dịch để nhận kết quả từ AML URL:http://ip:port/TabletoJSONService/TableToJson/createtabletojson path:/TabletoJSONService/TableToJson/createtabletojson Method: POST Request Header: Authorization: Basic a3ljYWRtbjphYmMxMjM= (Username and password to login) Truyền Param: mappingId = SEARCH_TF requestId= 'n_grp_msg_id' 2. Kiểm tra Response trả về | E23: {1:F01MSBLVNVXAXXX0000000000} {2:I710DBSSSGSGXXXXN} {3:{108:MT710HIT0001}} {4: :27:1/1 :40B:IRREVOCABLE WITHOUT :20:ADV2608180001 :21:LC2608180001 :31C:260818 :40E:UCP LATEST VERSION :31D:270131SINGAPORE :50B:270131SINGAPORE :50:VIETNAM IMPORT EXPORT JSC 15 NGUYEN HUE BOULEVARD HO CHI MINH CITY VIETNAM :59:SUNRISE IMPORT EXPORT PTE LTD 18 MARINA BOULEVARD SINGAPORE :32B:USD500000,00 :41A:DBSSSGSGXXX BY PAYMENT :45A:SUMMIT EMBER :49:WITHOUT -}{5:{MAC:00000000}{CHK:1A2B3C4D5E6F}} | F23: 2. Kết quả response trả về kết quả theo đúng yêu cầu { "groupMessageId": "groupMessageId", "alertId": "alertId", "transactionId": "transactionId", "branchCd": "branchCd", "channel": "channel", "finalResult": "N/A", "alertStatus": "alertStatus", "processDate": "processDate", "transactionType": "transactionType", "score": score, "requestId": "requestId" } | G23: SIT | H23: High | J23: Untested | K23: Passed
A24: API_SEARCH.01.03 | B24: Send API truyền thông tin requestId để truy vấn kết quả sàng lọc/đánh giá sự vụ từ AML và thông tin giao dịch có kết quả Knock-Out | C24: - Giao dịch có kết quả sàng lọc là Knock-Out | D24: 1. Đẩy API truyền thông tin Số tham chiếu giao dịch để nhận kết quả từ AML URL:http://ip:port/TabletoJSONService/TableToJson/createtabletojson path:/TabletoJSONService/TableToJson/createtabletojson Method: POST Request Header: Authorization: Basic a3ljYWRtbjphYmMxMjM= (Username and password to login) Truyền Param: mappingId = SEARCH_TF requestId= 'n_grp_msg_id' 2. Kiểm tra Response trả về | E24: {1:F01BIDVTWVXAXXX0000000000} {2:I700BFICCUHHXXXXN} {3:{108:TFRISK2025TW01}} {4: :27:1/1 :40A:IRREVOCABLE :20:TESTVVVV1 :31C:260101 :40E:UCP LATEST VERSION :31D:261231SINGAPORE :50:MEKONG TRADING CO LTD 12 NGUYEN HUE HO CHI MINH VN :59:SUNRISE PTE LTD 18 MARINA BLVD SINGAPORE SG :32B:EUR200000, :41D:SCBLSGSG BY PAYMENT :42D:MAMAK PTY LTD ASSOCIATION :49:WITHOUT :57A:DEUTUSFFABC -} {5:{MAC:00000000}{CHK:123456789ABC}} | F24: 2. Kết quả response trả về kết quả theo đúng yêu cầu { "groupMessageId": "groupMessageId", "alertId": "alertId", "transactionId": "transactionId", "branchCd": "branchCd", "channel": "channel", "finalResult": "FAIL", "alertStatus": "Knock Out", "processDate": "processDate", "transactionType": "transactionType", "score": score, "requestId": "requestId" } | G24: SIT | H24: High | J24: Untested | K24: Passed
A25: API_SEARCH.01.04 | B25: Send API truyền thông tin requestId để truy vấn kết quả sàng lọc/đánh giá sự vụ từ AML và thông tin giao dịch có kết quả HIT và đã hoàn thành đánh giá sự vụ là Maker Close Accept | C25: Giao dịch có kết quả sàng lọc HIT và đã hoàn thành đánh giá sự vụ là Maker Close Accept | D25: 1. Đẩy API truyền thông tin Số tham chiếu giao dịch để nhận kết quả từ AML URL:http://ip:port/TabletoJSONService/TableToJson/createtabletojson path:/TabletoJSONService/TableToJson/createtabletojson Method: POST Request Header: Authorization: Basic a3ljYWRtbjphYmMxMjM= (Username and password to login) Truyền Param: mappingId = SEARCH_TF requestId= 'n_grp_msg_id' 2. Kiểm tra Response trả về | E25: {1:F01MCOBVNVXAXXX0000000000} {2:O7201200260101BFICCUHHAXXX00000000002601011200N} {3:{108:MT720TEST0002}} {4: :27:1/1 :40B:IRREVOCABLE ADDING OUR CONFIRMATION :20:720case2 :21:DCN000000001 :31C:260101 :40E:UCP LATEST VERSION :31D:261231SINGAPORE :50:SUMMIT EMBER 12 NGUYEN HUE HO CHI MINH VN :59:SUNRISE PTE LTD 18 MARINA BLVD SINGAPORE SG :32B:USD100000, :41A:SCBLSGSG BY PAYMENT :49:WITHOUT -} {5:{MAC:00000000}{CHK:123456789ABC}} | F25: 2. Kết quả response trả về kết quả theo đúng yêu cầu { "groupMessageId": "groupMessageId", "alertId": "alertId", "transactionId": "transactionId", "branchCd": "branchCd", "channel": "channel", "finalResult": "PASS", "alertStatus": "Maker Close Accept", "processDate": "processDate", "transactionType": "transactionType", "score": score, "requestId": "requestId" } | G25: SIT | H25: High | J25: Untested | K25: Passed
A26: API_SEARCH.01.05 | B26: Send API truyền thông tin requestId để truy vấn kết quả sàng lọc/đánh giá sự vụ từ AML và thông tin giao dịch có kết quả HIT và đã hoàn thành đánh giá sự vụ là Checker Close Accept | C26: Giao dịch có kết quả sàng lọc HIT và đã hoàn thành đánh giá sự vụ là Checker Close Accept | D26: 1. Đẩy API truyền thông tin Số tham chiếu giao dịch để nhận kết quả từ AML URL:http://ip:port/TabletoJSONService/TableToJson/createtabletojson path:/TabletoJSONService/TableToJson/createtabletojson Method: POST Request Header: Authorization: Basic a3ljYWRtbjphYmMxMjM= (Username and password to login) Truyền Param: mappingId = SEARCH_TF requestId= 'n_grp_msg_id' 2. Kiểm tra Response trả về | E26: {1:F01MCOBVNVXAXXX0000000000} {2:O7201200260101BFICCUHHAXXX00000000002601011200N} {3:{108:MT720TEST0002}} {4: :27:1/1 :40B:IRREVOCABLE ADDING OUR CONFIRMATION :20:REF000000001 :21:DCN000000001 :31C:260101 :40E:UCP LATEST VERSION :31D:261231SINGAPORE :50:SUMMIT EMBER 12 NGUYEN HUE HO CHI MINH VN :59:SUNRISE PTE LTD 18 MARINA BLVD SINGAPORE SG :32B:USD100000, :41A:SCBLSGSG BY PAYMENT :49:WITHOUT -} {5:{MAC:00000000}{CHK:123456789ABC}} | F26: 2. Kết quả response trả về kết quả theo đúng yêu cầu { "groupMessageId": "groupMessageId", "alertId": "alertId", "transactionId": "transactionId", "branchCd": "branchCd", "channel": "channel", "finalResult": "PASS", "alertStatus": "Checker Close Accept", "processDate": "processDate", "transactionType": "transactionType", "score": score, "requestId": "requestId" } | G26: SIT | H26: High | J26: Untested | K26: Passed
A27: API_SEARCH.01.06 | B27: Send API truyền thông tin requestId để truy vấn kết quả sàng lọc/đánh giá sự vụ từ AML và thông tin giao dịch có kết quả HIT và đã hoàn thành đánh giá sự vụ là AML Close Accept | C27: Giao dịch có kết quả sàng lọc HIT và đã hoàn thành đánh giá sự vụ là AML Close Accept | D27: 1. Đẩy API truyền thông tin Số tham chiếu giao dịch để nhận kết quả từ AML URL:http://ip:port/TabletoJSONService/TableToJson/createtabletojson path:/TabletoJSONService/TableToJson/createtabletojson Method: POST Request Header: Authorization: Basic a3ljYWRtbjphYmMxMjM= (Username and password to login) Truyền Param: mappingId = SEARCH_TF requestId= 'n_grp_msg_id' 2. Kiểm tra Response trả về | F27: 2. Kết quả response trả về kết quả theo đúng yêu cầu { "groupMessageId": "groupMessageId", "alertId": "alertId", "transactionId": "transactionId", "branchCd": "branchCd", "channel": "channel", "finalResult": "PASS", "alertStatus": "AML Close Accept", "processDate": "processDate", "transactionType": "transactionType", "score": score, "requestId": "requestId" } | G27: SIT | H27: High | J27: Untested | K27: Passed
A28: API_SEARCH.01.07 | B28: Send API truyền thông tin requestId để truy vấn kết quả sàng lọc/đánh giá sự vụ từ AML và thông tin giao dịch có kết quả HIT và đã hoàn thành đánh giá sự vụ là Maker Close Deny | C28: Giao dịch có kết quả sàng lọc HIT và đã hoàn thành đánh giá sự vụ là Maker Close Deny | D28: 1. Đẩy API truyền thông tin Số tham chiếu giao dịch để nhận kết quả từ AML URL:http://ip:port/TabletoJSONService/TableToJson/createtabletojson path:/TabletoJSONService/TableToJson/createtabletojson Method: POST Request Header: Authorization: Basic a3ljYWRtbjphYmMxMjM= (Username and password to login) Truyền Param: mappingId = SEARCH_TF requestId= 'n_grp_msg_id' 2. Kiểm tra Response trả về | F28: 2. Kết quả response trả về kết quả theo đúng yêu cầu { "groupMessageId": "groupMessageId", "alertId": "alertId", "transactionId": "transactionId", "branchCd": "branchCd", "channel": "channel", "finalResult": "FAIL", "alertStatus": "Maker Close Deny", "processDate": "processDate", "transactionType": "transactionType", "score": score, "requestId": "requestId" } | G28: SIT | H28: High | J28: Untested | K28: Passed
A29: API_SEARCH.01.08 | B29: Send API truyền thông tin requestId để truy vấn kết quả sàng lọc/đánh giá sự vụ từ AML và thông tin giao dịch có kết quả HIT và đã hoàn thành đánh giá sự vụ là Checker Close Deny | C29: Giao dịch có kết quả sàng lọc HIT và đã hoàn thành đánh giá sự vụ là Checker Close Deny | D29: 1. Đẩy API truyền thông tin Số tham chiếu giao dịch để nhận kết quả từ AML URL:http://ip:port/TabletoJSONService/TableToJson/createtabletojson path:/TabletoJSONService/TableToJson/createtabletojson Method: POST Request Header: Authorization: Basic a3ljYWRtbjphYmMxMjM= (Username and password to login) Truyền Param: mappingId = SEARCH_TF requestId= 'n_grp_msg_id' 2. Kiểm tra Response trả về | F29: 2. Kết quả response trả về kết quả theo đúng yêu cầu { "groupMessageId": "groupMessageId", "alertId": "alertId", "transactionId": "transactionId", "branchCd": "branchCd", "channel": "channel", "finalResult": "FAIL", "alertStatus": "Checker Close Deny", "processDate": "processDate", "transactionType": "transactionType", "score": score, "requestId": "requestId" } | G29: SIT | H29: High | J29: Untested | K29: Passed
A30: API_SEARCH.01.09 | B30: Send API truyền thông tin requestId để truy vấn kết quả sàng lọc/đánh giá sự vụ từ AML và thông tin giao dịch có kết quả HIT và đã hoàn thành đánh giá sự vụ là AML Close Deny | C30: Giao dịch có kết quả sàng lọc HIT và đã hoàn thành đánh giá sự vụ là AML Close Deny | D30: 1. Đẩy API truyền thông tin Số tham chiếu giao dịch để nhận kết quả từ AML URL:http://ip:port/TabletoJSONService/TableToJson/createtabletojson path:/TabletoJSONService/TableToJson/createtabletojson Method: POST Request Header: Authorization: Basic a3ljYWRtbjphYmMxMjM= (Username and password to login) Truyền Param: mappingId = SEARCH_TF requestId= 'n_grp_msg_id' 2. Kiểm tra Response trả về | F30: 2. Kết quả response trả về kết quả theo đúng yêu cầu { "groupMessageId": "groupMessageId", "alertId": "alertId", "transactionId": "transactionId", "branchCd": "branchCd", "channel": "channel", "finalResult": "FAIL", "alertStatus": "AML Close Deny", "processDate": "processDate", "transactionType": "transactionType", "score": score, "requestId": "requestId" } | G30: SIT | H30: High | J30: Untested | K30: Passed
A31: API_SEARCH.01.10 | B31: Send API truyền thông tin alertId để truy vấn kết quả sàng lọc/đánh giá sự vụ từ AML và thông tin giao dịch có kết quả HIT và chưa hoàn thành đánh giá sự vụ | C31: - Giao dịch có kết quả sàng lọc HIT và chưa hoàn thành đánh giá sự vụ | D31: 1. Đẩy API truyền thông tin Số tham chiếu giao dịch để nhận kết quả từ AML URL:http://ip:port/TabletoJSONService/TableToJson/createtabletojson path:/TabletoJSONService/TableToJson/createtabletojson Method: POST Request Header: Authorization: Basic a3ljYWRtbjphYmMxMjM= (Username and password to login) Truyền Param: mappingId = SEARCH_TF alertId = 'alertId' 2. Kiểm tra Response trả về | F31: 2. Kết quả response trả về kết quả theo đúng yêu cầu { "groupMessageId": "groupMessageId", "alertId": "alertId", "transactionId": "transactionId", "branchCd": "branchCd", "channel": "channel", "finalResult": "N/A", "alertStatus": "alertStatus", "processDate": "processDate", "transactionType": "transactionType", "score": score, "requestId": "requestId" } | G31: SIT | H31: High | J31: Untested | K31: Passed
A32: API_SEARCH.01.11 | B32: Send API truyền thông tin alertId để truy vấn kết quả sàng lọc/đánh giá sự vụ từ AML và thông tin giao dịch có kết quả Knock-Out | C32: - Giao dịch có kết quả sàng lọc là Knock-Out | D32: 1. Đẩy API truyền thông tin Số tham chiếu giao dịch để nhận kết quả từ AML URL:http://ip:port/TabletoJSONService/TableToJson/createtabletojson path:/TabletoJSONService/TableToJson/createtabletojson Method: POST Request Header: Authorization: Basic a3ljYWRtbjphYmMxMjM= (Username and password to login) Truyền Param: mappingId = SEARCH_TF alertId = 'alertId' 2. Kiểm tra Response trả về | E32: {1:F01MCOBVNVXAXXX0000000000} {2:O2951201260724BFICCUHHAXXX00010000012607241201N} {3:{108:MT295TESTTTTTT}} {4: :20:QRY26072400031 :21:NONREF :75:PLEASE CONFIRM STATUSS TRANSACTION -}{5:{MAC:00000000}{CHK:1A2B3C4D5E6F}} | F32: 2. Kết quả response trả về kết quả theo đúng yêu cầu { "groupMessageId": "groupMessageId", "alertId": "alertId", "transactionId": "transactionId", "branchCd": "branchCd", "channel": "channel", "finalResult": "FAIL", "alertStatus": "Knock-Out", "processDate": "processDate", "transactionType": "transactionType", "score": score, "requestId": "requestId" } | G32: SIT | H32: High | J32: Untested | K32: Passed
A33: API_SEARCH.01.12 | B33: Send API truyền thông tin alertId để truy vấn kết quả sàng lọc/đánh giá sự vụ từ AML và thông tin giao dịch có kết quả HIT và đã hoàn thành đánh giá sự vụ là Maker Close Accept | C33: Giao dịch có kết quả sàng lọc HIT và đã hoàn thành đánh giá sự vụ là Maker Close Accept | D33: 1. Đẩy API truyền thông tin Số tham chiếu giao dịch để nhận kết quả từ AML URL:http://ip:port/TabletoJSONService/TableToJson/createtabletojson path:/TabletoJSONService/TableToJson/createtabletojson Method: POST Request Header: Authorization: Basic a3ljYWRtbjphYmMxMjM= (Username and password to login) Truyền Param: mappingId = SEARCH_TF alertId = 'alertId' 2. Kiểm tra Response trả về | F33: 2. Kết quả response trả về kết quả theo đúng yêu cầu { "groupMessageId": "groupMessageId", "alertId": "alertId", "transactionId": "transactionId", "branchCd": "branchCd", "channel": "channel", "finalResult": "PASS", "alertStatus": "Maker Close Accept", "processDate": "processDate", "transactionType": "transactionType", "score": score, "requestId": "requestId" } | G33: SIT | H33: High | J33: Untested | K33: Passed
A34: API_SEARCH.01.13 | B34: Send API truyền thông tin alertId để truy vấn kết quả sàng lọc/đánh giá sự vụ từ AML và thông tin giao dịch có kết quả HIT và đã hoàn thành đánh giá sự vụ là Checker Close Accept | C34: Giao dịch có kết quả sàng lọc HIT và đã hoàn thành đánh giá sự vụ là Checker Close Accept | D34: 1. Đẩy API truyền thông tin Số tham chiếu giao dịch để nhận kết quả từ AML URL:http://ip:port/TabletoJSONService/TableToJson/createtabletojson path:/TabletoJSONService/TableToJson/createtabletojson Method: POST Request Header: Authorization: Basic a3ljYWRtbjphYmMxMjM= (Username and password to login) Truyền Param: mappingId = SEARCH_TF alertId = 'alertId' 2. Kiểm tra Response trả về | F34: 2. Kết quả response trả về kết quả theo đúng yêu cầu { "groupMessageId": "groupMessageId", "alertId": "alertId", "transactionId": "transactionId", "branchCd": "branchCd", "channel": "channel", "finalResult": "PASS", "alertStatus": "Checker Close Accept", "processDate": "processDate", "transactionType": "transactionType", "score": score, "requestId": "requestId" } | G34: SIT | H34: High | J34: Untested | K34: Passed
A35: API_SEARCH.01.14 | B35: Send API truyền thông tin alertId để truy vấn kết quả sàng lọc/đánh giá sự vụ từ AML và thông tin giao dịch có kết quả HIT và đã hoàn thành đánh giá sự vụ là AML Close Accept | C35: Giao dịch có kết quả sàng lọc HIT và đã hoàn thành đánh giá sự vụ là AML Close Accept | D35: 1. Đẩy API truyền thông tin Số tham chiếu giao dịch để nhận kết quả từ AML URL:http://ip:port/TabletoJSONService/TableToJson/createtabletojson path:/TabletoJSONService/TableToJson/createtabletojson Method: POST Request Header: Authorization: Basic a3ljYWRtbjphYmMxMjM= (Username and password to login) Truyền Param: mappingId = SEARCH_TF alertId = 'alertId' 2. Kiểm tra Response trả về | F35: 2. Kết quả response trả về kết quả theo đúng yêu cầu { "groupMessageId": "groupMessageId", "alertId": "alertId", "transactionId": "transactionId", "branchCd": "branchCd", "channel": "channel", "finalResult": "PASS", "alertStatus": "AML Close Accept", "processDate": "processDate", "transactionType": "transactionType", "score": score, "requestId": "requestId" } | G35: SIT | H35: High | J35: Untested | K35: Passed
A36: API_SEARCH.01.15 | B36: Send API truyền thông tin alertId để truy vấn kết quả sàng lọc/đánh giá sự vụ từ AML và thông tin giao dịch có kết quả HIT và đã hoàn thành đánh giá sự vụ là Maker Close Deny | C36: Giao dịch có kết quả sàng lọc HIT và đã hoàn thành đánh giá sự vụ là Maker Close Deny | D36: 1. Đẩy API truyền thông tin Số tham chiếu giao dịch để nhận kết quả từ AML URL:http://ip:port/TabletoJSONService/TableToJson/createtabletojson path:/TabletoJSONService/TableToJson/createtabletojson Method: POST Request Header: Authorization: Basic a3ljYWRtbjphYmMxMjM= (Username and password to login) Truyền Param: mappingId = SEARCH_TF alertId = 'alertId' 2. Kiểm tra Response trả về | F36: 2. Kết quả response trả về kết quả theo đúng yêu cầu { "groupMessageId": "groupMessageId", "alertId": "alertId", "transactionId": "transactionId", "branchCd": "branchCd", "channel": "channel", "finalResult": "FAIL", "alertStatus": "Maker Close Deny", "processDate": "processDate", "transactionType": "transactionType", "score": score, "requestId": "requestId" } | G36: SIT | H36: High | J36: Untested | K36: Passed
A37: API_SEARCH.01.16 | B37: Send API truyền thông tin alertId để truy vấn kết quả sàng lọc/đánh giá sự vụ từ AML và thông tin giao dịch có kết quả HIT và đã hoàn thành đánh giá sự vụ là Checker Close Deny | C37: Giao dịch có kết quả sàng lọc HIT và đã hoàn thành đánh giá sự vụ là Checker Close Deny | D37: 1. Đẩy API truyền thông tin Số tham chiếu giao dịch để nhận kết quả từ AML URL:http://ip:port/TabletoJSONService/TableToJson/createtabletojson path:/TabletoJSONService/TableToJson/createtabletojson Method: POST Request Header: Authorization: Basic a3ljYWRtbjphYmMxMjM= (Username and password to login) Truyền Param: mappingId = SEARCH_TF alertId = 'alertId' 2. Kiểm tra Response trả về | F37: 2. Kết quả response trả về kết quả theo đúng yêu cầu { "groupMessageId": "groupMessageId", "alertId": "alertId", "transactionId": "transactionId", "branchCd": "branchCd", "channel": "channel", "finalResult": "FAIL", "alertStatus": "Checker Close Deny", "processDate": "processDate", "transactionType": "transactionType", "score": score, "requestId": "requestId" } | G37: SIT | H37: High | J37: Untested | K37: Passed
A38: API_SEARCH.01.17 | B38: Send API truyền thông tin alertId để truy vấn kết quả sàng lọc/đánh giá sự vụ từ AML và thông tin giao dịch có kết quả HIT và đã hoàn thành đánh giá sự vụ là AML Close Deny | C38: Giao dịch có kết quả sàng lọc HIT và đã hoàn thành đánh giá sự vụ là AML Close Deny | D38: 1. Đẩy API truyền thông tin Số tham chiếu giao dịch để nhận kết quả từ AML URL:http://ip:port/TabletoJSONService/TableToJson/createtabletojson path:/TabletoJSONService/TableToJson/createtabletojson Method: POST Request Header: Authorization: Basic a3ljYWRtbjphYmMxMjM= (Username and password to login) Truyền Param: mappingId = SEARCH_TF alertId = 'alertId' 2. Kiểm tra Response trả về | F38: 2. Kết quả response trả về kết quả theo đúng yêu cầu { "groupMessageId": "groupMessageId", "alertId": "alertId", "transactionId": "transactionId", "branchCd": "branchCd", "channel": "channel", "finalResult": "FAIL", "alertStatus": "AML Close Deny", "processDate": "processDate", "transactionType": "transactionType", "score": score, "requestId": "requestId" } | G38: SIT | H38: High | J38: Untested | K38: Passed
A39: API_SEARCH.01.18 | B39: Send API để truy vấn kết quả sàng lọc/đánh giá sự vụ từ AML - trường hợp requestId không có dữ liệu trên OFSAA | D39: 1. Đẩy API truyền thông tin Số tham chiếu giao dịch để nhận kết quả từ AML URL:http://ip:port/TabletoJSONService/TableToJson/createtabletojson path:/TabletoJSONService/TableToJson/createtabletojson Method: POST Request Header: Authorization: Basic a3ljYWRtbjphYmMxMjM= (Username and password to login) Truyền Param: mappingId = SEARCH_TF requestId= 'n_grp_msg_id' 2. Kiểm tra Response trả về | F39: 2. Kết quả response trả về {} | G39: SIT | H39: High | J39: Untested | K39: Passed
A40: API_SEARCH.01.19 | B40: Send API để truy vấn kết quả sàng lọc/đánh giá sự vụ từ AML - trường hợp alertId không có dữ liệu trên OFSAA | D40: 1. Đẩy API truyền thông tin Số tham chiếu giao dịch để nhận kết quả từ AML URL:http://ip:port/TabletoJSONService/TableToJson/createtabletojson path:/TabletoJSONService/TableToJson/createtabletojson Method: POST Request Header: Authorization: Basic a3ljYWRtbjphYmMxMjM= (Username and password to login) Truyền Param: mappingId = SEARCH_TF alertId = 'alertId' 2. Kiểm tra Response trả về | F40: 2. Kết quả response trả về {} | G40: SIT | H40: High | J40: Untested | K40: Passed
A41: API_SEARCH.01.20 | B41: Send API để truy vấn kết quả sàng lọc/đánh giá sự vụ từ AML - trường hợp truyền thiếu hoặc sai thông tin mappingId | D41: 1. Đẩy API truyền thông tin Số tham chiếu giao dịch để nhận kết quả từ AML URL:http://ip:port/TabletoJSONService/TableToJson/createtabletojson path:/TabletoJSONService/TableToJson/createtabletojson Method: POST Request Header: Authorization: Basic a3ljYWRtbjphYmMxMjM= (Username and password to login) Truyền Param: mappingId = alertId = 'alertId' requestId= 'n_grp_msg_id' 2. Kiểm tra Response trả về | F41: 2. Kết quả response trả về {} | G41: SIT | H41: High | J41: Untested | K41: Passed
A42: API_SEARCH.01.21 | B42: Kiểm tra trường hợp lỗi 404 | C42: Truyền sai URL | D42: 1. Đẩy API truyền thông tin Số tham chiếu giao dịch để nhận kết quả từ AML URL:http://ip:port/TabletoJSONService/TableToJson/createt path:/TabletoJSONService/TableToJson/createtabletojson Method: POST Request Header: Authorization: Basic a3ljYWRtbjphYmMxMjM= (Username and password to login) Truyền Param: mappingId = alertId = 'alertId' requestId= 'n_grp_msg_id' 2. Kiểm tra Response trả về | F42: 2. Hệ thống trả lỗi 404 Not Found | G42: SIT | H42: High | J42: Untested | K42: Passed
...

Sheet API Callback
A1: Functions | B1: =[1]Cover!E11 -> DỰ ÁN TRIỂN KHAI BẢN QUYỀN PHẦN MỀM HỆ THỐNG AML MỚI
A2: Build Version | B2: v1.0
B4: High | C4: Medium | D4: Low | E4: Total
B5: =SUM(B6:B10) -> 18 | C5: =SUM(C6:C10) -> 0 | D5: =SUM(D6:D10) -> 0 | E5: =SUM(B5:D5) -> 18
A6: Pass | B6: =COUNTIFS($J:$J, $A$6,$H:$H,B$4) -> 18 | C6: =COUNTIFS($J:$J, $A$6,$H:$H,C$4) -> 0 | D6: =COUNTIFS($J:$J, $A$6,$H:$H,D$4) -> 0 | E6: =SUM(B6:D6) -> 18
A7: Fail | B7: =COUNTIFS($J:$J, $A$7,$H:$H,B$4) -> 0 | C7: =COUNTIFS($J:$J, $A$7,$H:$H,C$4) -> 0 | D7: =COUNTIFS($J:$J, $A$7,$H:$H,D$4) -> 0 | E7: =SUM(B7:D7) -> 0
A8: Untested | B8: =COUNTIFS($J:$J, $A$8,$H:$H,B$4) -> 0 | C8: =COUNTIFS($J:$J, $A$8,$H:$H,C$4) -> 0 | D8: =COUNTIFS($J:$J, $A$8,$H:$H,D$4) -> 0 | E8: =SUM(B8:D8) -> 0
A9: Accepted | B9: =COUNTIFS($J:$J, $A$9,$H:$H,B$4) -> 0 | C9: =COUNTIFS($J:$J, $A$9,$H:$H,C$4) -> 0 | D9: =COUNTIFS($J:$J, $A$9,$H:$H,D$4) -> 0 | E9: =SUM(B9:D9) -> 0
A10: N/A | B10: =COUNTIFS($J:$J, $A$10,H:H,B$4) -> 0 | C10: =COUNTIFS($J:$J, $A$10,I:I,C$4) -> 0 | D10: =COUNTIFS($J:$J, $A$10,J:J,D$4) -> 0 | E10: =SUM(B10:D10) -> 0
A12: Test case Id | B12: Test case Title | C12: Pre-conditions | D12: Test Steps | E12: Test Datas | F12: Expected result | G12: Test Environment | H12: Priority | I12: Automation Status | J12: 1st Test Results | K12: 2nd Test Results | L12: BugID | M12: Notes
A13: TF_API_CALLBACK_01 | B13: Kiểm tra API trả kết quả cuối cùng sau khi hoàn thành đánh giá sự vụ phát sinh trên OFSAA
A14: TF_API_CALLBACK_01_01 | B14: Kiểm tra API trả thành công kết quả cuối cùng theo các trạng thái case
A15: TF_API_CALLBACK.01.01 | B15: Kiểm tra body request API Callback | C15: 1. Hoàn thành đánh giá Alert trên hệ thống OFSAA 2.API truyền vào có giá trị IsCallBack = Y 3. User có quyền xem/chỉnh sửa PMF | D15: 1. Truy cập vào OFSAA AML theo đường dẫn:Financial Services Analytical Applications Transactions Filtering/Common Tasks/ Processing Modelling Framework/Process Monitor 2. Chọn Process: có Alert ID tương ứng với Alert ID trả ra ở response 3. Kiểm tra response trên màn hình | F15: API callback cần có đủ các thông tin sau: $.groupMessageId $.alertId $.transactionId $.branchCd $.channel $.finalResult $.alertStatus $.processDate $.transactionType $.score $.requestId | G15: SIT | H15: High | J15: Pass | K15: Untested
A16: TF_API_CALLBACK.01.02 | B16: Kiểm tra kết quả về hệ thống nguồn khi sự vụ đóng ở trạng thái Maker Close Accept | C16: 1. Hoàn thành đánh giá Alert trên hệ thống OFSAA 2.API truyền vào có giá trị IsCallBack = Y 3. User có quyền xem/chỉnh sửa PMF | D16: 1. Truy cập vào OFSAA AML theo đường dẫn:Financial Services Analytical Applications Transactions Filtering/Common Tasks/ Processing Modelling Framework/Process Monitor 2. Chọn Process: có Alert ID tương ứng với Alert ID trả ra ở response 3. Kiểm tra response trên màn hình so với thông tin request truyền vào và kết quả xử lý case | E16: {1:F01SCBLSGSGAXXX0000000000} {2:I299MCOBVNVXXXXXN} {3:{108:MT299TEST0002}} {4: :20:FRF2607240002 :21:NONREF :79:0099887766 -}{5:{MAC:00000000}{CHK:1A2B3C4D5E6F}} | F16: 3. Kết quả response trả về kết quả theo đúng yêu cầu { "groupMessageId": "groupMessageId", "alertId": "alertId", "transactionId": "transactionId", "branchCd": "branchCd", "channel": "channel", "finalResult": "PASS", "alertStatus": "Maker Close Accept", "processDate": "processDate", "transactionType": "transactionType", "score": "score", "requestId": "requestId" } | G16: SIT | H16: High | J16: Pass | K16: Untested
A17: TF_API_CALLBACK.01.03 | B17: Kiểm tra kết quả về hệ thống nguồn khi sự vụ đóng ở trạng thái Checker Close Accept | C17: 1. Hoàn thành đánh giá Alert trên hệ thống OFSAA 2.API truyền vào có giá trị IsCallBack = Y 3. User có quyền xem/chỉnh sửa PMF | D17: 1. Truy cập vào OFSAA AML theo đường dẫn:Financial Services Analytical Applications Transactions Filtering/Common Tasks/ Processing Modelling Framework/Process Monitor 2. Chọn Process: có Alert ID tương ứng với Alert ID trả ra ở response 3. Kiểm tra response trên màn hình so với thông tin request truyền vào và kết quả xử lý case | E17: {1:F01SCBLSGSGAXXX0000000000} {2:I499MCOBVNVXXXXXN} {3:{108:MT499TEST0002}} {4: :20:FRF2607240002 :21:NONREF :79:0099887766 -}{5:{MAC:00000000}{CHK:1A2B3C4D5E6F}} | F17: 3. Kết quả response trả về kết quả theo đúng yêu cầu { "groupMessageId": "groupMessageId", "alertId": "alertId", "transactionId": "transactionId", "branchCd": "branchCd", "channel": "channel", "finalResult": "PASS", "alertStatus": "Checker Close Accept", "processDate": "processDate", "transactionType": "transactionType", "score": "score", "requestId": "requestId" } | G17: SIT | H17: High | J17: Pass | K17: Untested
A18: TF_API_CALLBACK.01.04 | B18: Kiểm tra kết quả về hệ thống nguồn khi sự vụ đóng ở trạng thái AML Close Accept | C18: 1. Hoàn thành đánh giá Alert trên hệ thống OFSAA 2.API truyền vào có giá trị IsCallBack = Y 3. User có quyền xem/chỉnh sửa PMF | D18: 1. Truy cập vào OFSAA AML theo đường dẫn:Financial Services Analytical Applications Transactions Filtering/Common Tasks/ Processing Modelling Framework/Process Monitor 2. Chọn Process: có Alert ID tương ứng với Alert ID trả ra ở response 3. Kiểm tra response trên màn hình so với thông tin request truyền vào và kết quả xử lý case | E18: <?xml version="1.0" encoding="UTF-8"?> <Document xmlns="urn:iso:std:iso:20022:tech:xsd:pacs.008.001.08"> <FIToFICstmrCdtTrf> <GrpHdr> <MsgId>PP1_PTP1</MsgId> <CreDtTm>2026-07-28T13:31:41</CreDtTm> <NbOfTxs>1</NbOfTxs> <CtrlSum>15000.00</CtrlSum> <SttlmInf> <SttlmMtd>CLRG</SttlmMtd> </SttlmInf> </GrpHdr> <CdtTrfTxInf> <PmtId> <InstrId>SEPAINSTR0000001</InstrId> <EndToEndId>SEPAE2E0000001</EndToEndId> </PmtId> <IntrBkSttlmAmt Ccy="EUR">15000.00</IntrBkSttlmAmt> <ChrgBr>SLEV</ChrgBr> <Dbtr> <Nm>SUMMIT EMBER</Nm> </Dbtr> <DbtrAgt> <FinInstnId> <BICFI>BKBPVNTH</BICFI> </FinInstnId> </DbtrAgt> <CdtrAgt> <FinInstnId> <BICFI>BKBPVNTH</BICFI> </FinInstnId> </CdtrAgt> <Cdtr> <Nm>ABCD1234 BENEFICIARY</Nm> </Cdtr> <RmtInf> <Ustrd>0216155930</Ustrd> </RmtInf> </CdtTrfTxInf> </FIToFICstmrCdtTrf> </Document> | F18: 3. Kết quả response trả về kết quả theo đúng yêu cầu { "groupMessageId": "groupMessageId", "alertId": "alertId", "transactionId": "transactionId", "branchCd": "branchCd", "channel": "channel", "finalResult": "PASS", "alertStatus": "AML Close Accept", "processDate": "processDate", "transactionType": "transactionType", "score": "score", "requestId": "requestId" } | G18: SIT | H18: High | J18: Pass | K18: Untested
A19: TF_API_CALLBACK.01.05 | B19: Kiểm tra kết quả về hệ thống nguồn khi sự vụ đóng ở trạng thái Maker Close Deny | C19: 1. Hoàn thành đánh giá Alert trên hệ thống OFSAA 2.API truyền vào có giá trị IsCallBack = Y 3. User có quyền xem/chỉnh sửa PMF | D19: 1. Truy cập vào OFSAA AML theo đường dẫn:Financial Services Analytical Applications Transactions Filtering/Common Tasks/ Processing Modelling Framework/Process Monitor 2. Chọn Process: có Alert ID tương ứng với Alert ID trả ra ở response 3. Kiểm tra response trên màn hình so với thông tin request truyền vào và kết quả xử lý case | E19: {1:F01SCBLSGSGAXXX0000000000} {2:I199MCOBVNVXXXXXN} {3:{108:MT199TEST0002}} {4: :20:FRF2607240002 :79:0099887766 -}{5:{MAC:00000000}{CHK:1A2B3C4D5E6F}} | F19: 3. Kết quả response trả về kết quả theo đúng yêu cầu { "groupMessageId": "groupMessageId", "alertId": "alertId", "transactionId": "transactionId", "branchCd": "branchCd", "channel": "channel", "finalResult": "Fail", "alertStatus": "Maker Close Deny", "processDate": "processDate", "transactionType": "transactionType", "score": "score", "requestId": "requestId" } | G19: SIT | H19: High | J19: Pass | K19: Untested
