Workbook

Sheet Cover
E8: Test Report
C11: Project Name: | E11: DỰ ÁN TRIỂN KHAI BẢN QUYỀN PHẦN MỀM HỆ THỐNG AML MỚI | G11: Reviewer:
C12: Document Code: | G12: Position:
C13: Originator: | G13: Reviewed Date:
C14: Position: | G14: Approver:
C15: Created Date: | E15: 2026-10-06 | G15: Position:
C16: Version: | E16: 1.1 | G16: Approved Date:

Sheet Records
A1: TABLE OF CONTENT
A3: 1 | B3: Cover | C3: Cover
A4: 2 | B4: Records | C4: Record of changes
A5: 3 | B5: Test Report | C5: Tổng hợp kết quả kiểm thử
A6: 4 | B6: ETL | C6: Testcase ETL dữ liệu nguồn → staging TM
A7: 5 | B7: Legend | C7: Chú giải Test Level/Priority/Automation Status/Status
A9: RECORD OF CHANGES
A10: Effective Date | B10: A, M, D | C10: Change Description | D10: New Version | E10: Author
A11: 2026-10-06 | B11: M | C11: Chuẩn hoá cấu trúc cột theo mẫu MSB_AML_TM_UI_v1.0 (Test case Id → Notes, bỏ cột STT). Bỏ: cột Function, Group Tests (chuyển thành dòng nhóm), Risk Level, Regression, Automation Test Results, Actual result; sheet Tong hop. Thêm cột P TC ID gốc (54 mã khớp MSB v1.0) | D11: 1.1

Sheet Test Report
B2: SYSTEM TEST REPORT
A5: Project | B5: DỰ ÁN TRIỂN KHAI BẢN QUYỀN PHẦN MỀM HỆ THỐNG AML MỚI | D5: Project manager
A6: Application | B6: Module Transaction Monitoring (TM) - ETL | D6: Approved Date
A7: Consolidated By | D7: Reviewed By
A8: Build Versions | D8: Reviewed date
A9: Test Environment | B9: SIT
A10: Last Updated Date | B10: 2026-10-06
A11: Test Execution Summary
A12: Reported by
A13: Date
A14: Test Results (Round1) | B14: Passed | C14: Failed | D14: Untested | E14: Accepted | F14: Pending | G14: Cancel | H14: Total
B15: =B16 | C15: =C16 | D15: =D16 | E15: =E16 | F15: =F16 | G15: =G16 | H15: =SUM(B15:F15)
A16: Test cases | B16: ='ETL'!E6 | C16: ='ETL'!E7 | D16: ='ETL'!E8 | E16: ='ETL'!E9 | F16: ='ETL'!E10 | G16: ='ETL'!E11
A18: Test Results (Round2) | B18: =B19 | C18: =C19 | D18: =D19 | E18: =E19 | F18: =F19 | G18: =G19 | H18: =SUM(B18:F18)
A19: Test cases | B19: ='ETL'!E15 | C19: ='ETL'!E16 | D19: ='ETL'!E17 | E19: ='ETL'!E18 | F19: ='ETL'!E19 | G19: ='ETL'!E20
A20: Test coverage
A21: Test coverage
A22: Test successful coverage
A23: Issues
A24: 1. Block testing issue
A25: 2. Critical defects

Sheet ETL
A1: Functions | B1: Testcase ETL dữ liệu nguồn → staging TM
A2: Build Version | B2: v1.1
A3: ROUND 1
B4: High | C4: Medium | D4: Low | E4: Total
B5: =SUM(B6:B10) | C5: =SUM(C6:C10) | D5: =SUM(D6:D10) | E5: =SUM(B5:D5)
A6: Passed | B6: =COUNTIFS($J:$J, $A6,$H:$H,B$4) | C6: =COUNTIFS($J:$J, $A6,$H:$H,C$4) | D6: =COUNTIFS($J:$J, $A6,$H:$H,D$4) | E6: =SUM(B6:D6)
A7: Failed | B7: =COUNTIFS($J:$J, $A7,$H:$H,B$4) | C7: =COUNTIFS($J:$J, $A7,$H:$H,C$4) | D7: =COUNTIFS($J:$J, $A7,$H:$H,D$4) | E7: =SUM(B7:D7)
A8: Untested | B8: =COUNTIFS($J:$J, $A8,$H:$H,B$4) | C8: =COUNTIFS($J:$J, $A8,$H:$H,C$4) | D8: =COUNTIFS($J:$J, $A8,$H:$H,D$4) | E8: =SUM(B8:D8)
A9: Accepted | B9: =COUNTIFS($J:$J, $A9,$H:$H,B$4) | C9: =COUNTIFS($J:$J, $A9,$H:$H,C$4) | D9: =COUNTIFS($J:$J, $A9,$H:$H,D$4) | E9: =SUM(B9:D9)
A10: Pending | B10: =COUNTIFS($J:$J, $A10,$H:$H,B$4) | C10: =COUNTIFS($J:$J, $A10,$H:$H,C$4) | D10: =COUNTIFS($J:$J, $A10,$H:$H,D$4) | E10: =SUM(B10:D10)
A11: Cancel | B11: =COUNTIFS($J:$J, $A11,$H:$H,B$4) | C11: =COUNTIFS($J:$J, $A11,$H:$H,C$4) | D11: =COUNTIFS($J:$J, $A11,$H:$H,D$4) | E11: =SUM(B11:D11)
A12: ROUND2
B13: High | C13: Medium | D13: Low | E13: Total
B14: =SUM(B15:B19) | C14: =SUM(C15:C19) | D14: =SUM(D15:D19) | E14: =SUM(B14:D14)
A15: Passed | B15: =COUNTIFS($K:$K, $A15,$H:$H,B$4) | C15: =COUNTIFS($K:$K, $A15,$H:$H,C$4) | D15: =COUNTIFS($K:$K, $A15,$H:$H,D$4) | E15: =SUM(B15:D15)
A16: Failed | B16: =COUNTIFS($K:$K, $A16,$H:$H,B$4) | C16: =COUNTIFS($K:$K, $A16,$H:$H,C$4) | D16: =COUNTIFS($K:$K, $A16,$H:$H,D$4) | E16: =SUM(B16:D16)
A17: Untested | B17: =COUNTIFS($K:$K, $A17,$H:$H,B$4) | C17: =COUNTIFS($K:$K, $A17,$H:$H,C$4) | D17: =COUNTIFS($K:$K, $A17,$H:$H,D$4) | E17: =SUM(B17:D17)
A18: Accepted | B18: =COUNTIFS($K:$K, $A18,$H:$H,B$4) | C18: =COUNTIFS($K:$K, $A18,$H:$H,C$4) | D18: =COUNTIFS($K:$K, $A18,$H:$H,D$4) | E18: =SUM(B18:D18)
A19: Pending | B19: =COUNTIFS($K:$K, $A19,$H:$H,B$4) | C19: =COUNTIFS($K:$K, $A19,$H:$H,C$4) | D19: =COUNTIFS($K:$K, $A19,$H:$H,D$4) | E19: =SUM(B19:D19)
A20: Cancel | B20: =COUNTIFS($K:$K, $A20,$H:$H,B$4) | C20: =COUNTIFS($K:$K, $A20,$H:$H,C$4) | D20: =COUNTIFS($K:$K, $A20,$H:$H,D$4) | E20: =SUM(B20:D20)
A21: Test case Id | B21: Test case Title | C21: Pre-conditions | D21: Test Steps | E21: Test Datas | F21: Expected result | G21: Test Environment | H21: Priority | I21: Automation Status | J21: 1st Test Results | K21: 2nd Test Results | L21: 3rd Test Results | M21: BugID | N21: Notes | O21: TC ID gốc
B22: NHÓM FUNCTION - Bảng: STG_PARTY_MASTER
A23: TM_ETL_CU_CUS_001 | B23: Kiểm tra đối chiếu thành công số lượng bản ghi nạp vào bảng STG_PARTY_MASTER với bảng nguồn theo ngày dữ liệu | C23: - User/Quyền: Tài khoản DB có quyền SELECT trên schema staging OFSAA và trên schema hệ thống nguồn MSB - Dữ liệu có sẵn: Batch/job ETL nạp bảng STG_PARTY_MASTER đã chạy xong cho ngày dữ liệu FIC_MIS_DATE = &TEST_DATE; đã xác định được bảng nguồn tương ứng theo mapping v1.0 | D23: 1. Thực thi câu lệnh SQL kiểm tra tại cột Test Data trên schema staging. 2. Đối chiếu số dòng và giá trị trả về với kỳ vọng. | E23: - DB: Schema staging OFSAA - bảng STG_PARTY_MASTER - Tham số: &TEST_DATE = ngày dữ liệu kiểm thử (business date của batch) - SQL: SELECT (SELECT COUNT(*) FROM <bảng nguồn> WHERE <trường ngày dữ liệu nguồn> = DATE '&TEST_DATE') AS SL_NGUON, (SELECT COUNT(*) FROM STG_PARTY_MASTER WHERE FIC_MIS_DATE = DATE '&TEST_DATE') AS SL_DICH FROM DUAL; | F23: 2. Số bản ghi của bảng nguồn = số bản ghi của bảng đích STG_PARTY_MASTER đã lọc theo FIC_MIS_DATE = &TEST_DATE - SL_NGUON = SL_DICH - Không có bản ghi nào của ngày dữ liệu bị thiếu ở bảng đích | G23: SIT | H23: High | I23: Y | N23: TD: TD_D1_CU_CUS_01 | Chế độ: rà soát. [ASSUMPTION: bảng/trường nguồn chưa được MSB điền trong mapping v1.0 (AT-02) - câu SQL phía nguồn để placeholder <bảng nguồn>/<trường nguồn>, cập nhật khi có mapping] | O23: TM_ETL_CU_CUS_001
A24: TM_ETL_CU_CUS_003 | B24: Kiểm tra đối chiếu thành công giá trị toàn bộ 35 trường của bảng STG_PARTY_MASTER với bảng nguồn theo logic mapping | C24: - User/Quyền: Tài khoản DB có quyền SELECT trên schema staging OFSAA và trên schema hệ thống nguồn MSB - Dữ liệu có sẵn: Batch/job ETL nạp bảng STG_PARTY_MASTER đã chạy xong cho ngày dữ liệu FIC_MIS_DATE = &TEST_DATE; logic transform của cả 35 cột đích đã được xác nhận theo mapping v1.0 | D24: 1. Thực thi câu lệnh SQL kiểm tra tại cột Test Data trên schema staging. 2. Đối chiếu số dòng và giá trị trả về với kỳ vọng. | E24: - DB: Schema staging OFSAA - bảng STG_PARTY_MASTER - Tham số: &TEST_DATE = ngày dữ liệu kiểm thử (business date của batch) - SQL: SELECT FIC_MIS_DATE, V_DATA_JURISDICTION, V_BUSINESS_DOMAIN, V_PARTY_ID, V_PARTY_NAME, V_DISPLAY_NM, V_PARTY_TYPE, D_DATE_OF_BIRTH, V_GENDER, V_NATIONALITY_COUNTRY, V_DOMICILE_COUNTRY, V_PROFESSION, V_ORG_CONSTITUENT_TYPE, V_INDUSTRY_CODE, D_INCORPORATION_DATE, V_PARTY_TAX_ID, V_BUSS_SEGMENT, N_KYC_RISK, D_START_DATE, V_DATA_ORIGIN, V_INCORPORATION_COUNTRY_CD, V_CITIZENSHIP_TYPE, V_BENEFICIAL_OWNER_CATEGORY, V_EMP_COMPANY, V_OCCUPATION_STATUS, V_EDUCATION, V_RESIDENCY_STATUS_INDICATOR, V_ADDRESS_OFF_FAX_NO, V_WEBSITE, V_BRANCH_CODE, V_JOB_TITLE, V_PARTY_FULL_NAME, V_PARTY_ALIAS, V_SECONDARY_CITIZENSHIP, F_SAR_STR_FLAG FROM STG_PARTY_MASTER WHERE FIC_MIS_DATE = DATE '&TEST_DATE' MINUS SELECT <danh sách trường nguồn tương ứng theo logic mapping> FROM <bảng nguồn> WHERE <trường ngày dữ liệu nguồn> = DATE '&TEST_DATE'; | F24: 2. Câu lệnh MINUS trả về 0 dòng - giá trị của cả 35 cột đích trùng khớp với nguồn theo logic mapping - Các cột cần đối chiếu (35): FIC_MIS_DATE, V_DATA_JURISDICTION, V_BUSINESS_DOMAIN, V_PARTY_ID, V_PARTY_NAME, V_DISPLAY_NM, V_PARTY_TYPE, D_DATE_OF_BIRTH, V_GENDER, V_NATIONALITY_COUNTRY, V_DOMICILE_COUNTRY, V_PROFESSION, V_ORG_CONSTITUENT_TYPE, V_INDUSTRY_CODE, D_INCORPORATION_DATE, V_PARTY_TAX_ID, V_BUSS_SEGMENT, N_KYC_RISK, D_START_DATE, V_DATA_ORIGIN, V_INCORPORATION_COUNTRY_CD, V_CITIZENSHIP_TYPE, V_BENEFICIAL_OWNER_CATEGORY, V_EMP_COMPANY, V_OCCUPATION_STATUS, V_EDUCATION, V_RESIDENCY_STATUS_INDICATOR, V_ADDRESS_OFF_FAX_NO, V_WEBSITE, V_BRANCH_CODE, V_JOB_TITLE, V_PARTY_FULL_NAME, V_PARTY_ALIAS, V_SECONDARY_CITIZENSHIP, F_SAR_STR_FLAG - Chạy MINUS đảo chiều (nguồn MINUS đích) cũng trả về 0 dòng | G24: SIT | H24: High | I24: Y | N24: TD: TD_D2_CU_CUS_01 | Chế độ: rà soát. [ASSUMPTION: bảng/trường nguồn chưa được MSB điền trong mapping v1.0 (AT-02) - câu SQL phía nguồn để placeholder <bảng nguồn>/<trường nguồn>, cập nhật khi có mapping] | O24: TM_ETL_CU_CUS_003
A25: TM_ETL_CU_CUS_004 | B25: Kiểm tra không mất bản ghi âm thầm khi nạp bảng STG_PARTY_MASTER với đối chiếu tổng nguồn bằng đích cộng bản ghi bị loại | C25: - User/Quyền: Tài khoản DB có quyền SELECT trên schema staging OFSAA và trên schema hệ thống nguồn MSB - Dữ liệu có sẵn: Batch/job ETL nạp bảng STG_PARTY_MASTER đã chạy xong cho ngày dữ liệu FIC_MIS_DATE = &TEST_DATE; bảng log lỗi/reject của ETL đã được cấu hình và có ghi nhận bản ghi bị loại trong lần chạy | D25: 1. Thực thi câu lệnh SQL kiểm tra tại cột Test Data trên schema staging. 2. Đối chiếu số dòng và giá trị trả về với kỳ vọng. | E25: - DB: Schema staging OFSAA - bảng STG_PARTY_MASTER - Tham số: &TEST_DATE = ngày dữ liệu kiểm thử (business date của batch) - SQL: SELECT (SELECT COUNT(*) FROM <bảng nguồn> WHERE <trường ngày dữ liệu nguồn> = DATE '&TEST_DATE') AS SL_NGUON, (SELECT COUNT(*) FROM STG_PARTY_MASTER WHERE FIC_MIS_DATE = DATE '&TEST_DATE') AS SL_DICH, (SELECT COUNT(*) FROM <bảng log lỗi ETL> WHERE TARGET_TABLE = 'STG_PARTY_MASTER' AND BATCH_DATE = DATE '&TEST_DATE') AS SL_LOAI FROM DUAL; | F25: 2. SL_NGUON = SL_DICH + SL_LOAI - Mọi bản ghi nguồn không nạp được đều có 1 dòng tương ứng trong bảng log lỗi kèm lý do loại - Không tồn tại bản ghi nguồn nào vừa không có ở bảng đích vừa không có trong bảng log lỗi | G25: SIT | H25: High | I25: Y | N25: TD: TD_D1_CU_CUS_02 | Chế độ: rà soát. [TC MOI THEM] Bộ TC v1.0 không có TC nào phát hiện bản ghi bị bỏ âm thầm. [ASSUMPTION: tên bảng log lỗi/reject của ETL chưa được FIS cung cấp - dùng placeholder <bảng log lỗi ETL>]
A26: TM_ETL_CU_CUS_005 | B26: Kiểm tra batch ETL bảng STG_PARTY_MASTER hoàn thành thành công với nguồn không có bản ghi nào trong ngày dữ liệu | C26: - User/Quyền: Tài khoản DB có quyền SELECT trên schema staging OFSAA, quyền tạo dữ liệu thử trên hệ thống nguồn SIT và quyền chạy batch/job ETL - Dữ liệu có sẵn: Chọn 1 ngày dữ liệu &TEST_DATE_EMPTY mà hệ thống nguồn không phát sinh bản ghi nào cho bảng này (ví dụ ngày lễ/Tết không phát sinh giao dịch) | D26: 1. Tạo bản ghi nguồn theo mô tả tại cột Test Data trên hệ thống nguồn SIT. 2. Chạy batch/job ETL nạp bảng STG_PARTY_MASTER cho ngày dữ liệu FIC_MIS_DATE = &TEST_DATE. 3. Thực thi câu lệnh SQL kiểm tra tại cột Test Data trên schema staging. 4. Đối chiếu kết quả trả về và bản ghi trong bảng log lỗi ETL với kỳ vọng. | E26: - DB: Schema staging OFSAA - bảng STG_PARTY_MASTER - Tham số phụ: &TEST_DATE_EMPTY = ngày dữ liệu nguồn không phát sinh bản ghi - Tham số: &TEST_DATE = ngày dữ liệu kiểm thử (business date của batch) - SQL: SELECT COUNT(*) AS SL_DICH FROM STG_PARTY_MASTER WHERE FIC_MIS_DATE = DATE '&TEST_DATE_EMPTY'; -- Trạng thái job của lần chạy đó SELECT <cột trạng thái> FROM <bảng log job ETL> WHERE TARGET_TABLE = 'STG_PARTY_MASTER' AND BATCH_DATE = DATE '&TEST_DATE_EMPTY'; | F26: 4. Job ETL kết thúc ở trạng thái hoàn thành thành công, KHÔNG báo lỗi và KHÔNG treo - SL_DICH = 0 - bảng đích không có bản ghi nào cho ngày dữ liệu đó - Không có bản ghi rác và không có bản ghi của ngày khác bị nạp thay thế | G26: SIT | H26: Low | I26: Y | N26: TD: TD_D6_CU_CUS_01 | Chế độ: tiêm. [TC MOI THEM] [ASSUMPTION: tên bảng log lỗi/reject của ETL chưa được FIS cung cấp - dùng placeholder <bảng log lỗi ETL>]
A27: TM_ETL_CU_CUS_006 | B27: Kiểm tra chạy lại batch ETL bảng STG_PARTY_MASTER lần thứ hai với cùng ngày dữ liệu không làm nhân đôi bản ghi | C27: - User/Quyền: Tài khoản DB có quyền SELECT trên schema staging OFSAA, quyền tạo dữ liệu thử trên hệ thống nguồn SIT và quyền chạy batch/job ETL - Dữ liệu có sẵn: Batch ETL nạp bảng STG_PARTY_MASTER đã chạy thành công lần 1 cho FIC_MIS_DATE = &TEST_DATE; đã ghi lại số bản ghi sau lần 1 để so sánh | D27: 1. Ghi lại số bản ghi của bảng STG_PARTY_MASTER sau lần chạy thứ nhất. 2. Chạy lại batch/job ETL nạp bảng STG_PARTY_MASTER lần thứ hai cho cùng FIC_MIS_DATE = &TEST_DATE. 3. Thực thi câu lệnh SQL kiểm tra tại cột Test Data trên schema staging. 4. Đối chiếu kết quả sau lần chạy thứ hai với số liệu đã ghi ở bước 1. | E27: - DB: Schema staging OFSAA - bảng STG_PARTY_MASTER - Tham số: &TEST_DATE = ngày dữ liệu kiểm thử (business date của batch) - SQL: SELECT COUNT(*) AS SL, COUNT(DISTINCT V_PARTY_ID || '|' || FIC_MIS_DATE) AS SL_KEY_DISTINCT FROM STG_PARTY_MASTER WHERE FIC_MIS_DATE = DATE '&TEST_DATE'; -- Trùng khoá sau lần chạy thứ hai SELECT V_PARTY_ID, FIC_MIS_DATE, COUNT(*) AS SL FROM STG_PARTY_MASTER WHERE FIC_MIS_DATE = DATE '&TEST_DATE' GROUP BY V_PARTY_ID, FIC_MIS_DATE HAVING COUNT(*) > 1; | F27: 4. Số bản ghi sau lần chạy thứ hai bằng đúng số bản ghi sau lần chạy thứ nhất - SL = SL_KEY_DISTINCT - không có bản ghi nào bị nhân đôi - Câu SQL kiểm trùng khoá (V_PARTY_ID, FIC_MIS_DATE) trả về 0 dòng | G27: SIT | H27: High | I27: Y | N27: TD: TD_D6_CU_CUS_02 | Chế độ: tiêm. [TC MOI THEM] Sheet "1. Cơ chế Load" gán N_LOAD_RUN_ID = 1 cố định nên chạy lại phải ghi đè, không tạo lần chạy mới.
A28: TM_ETL_CU_CUS_007 | B28: Kiểm tra bảng STG_PARTY_MASTER chỉ chứa dữ liệu đúng ngày dữ liệu đang nạp với điều kiện lọc FIC_MIS_DATE | C28: - User/Quyền: Tài khoản DB có quyền SELECT trên schema staging OFSAA và trên schema hệ thống nguồn MSB - Dữ liệu có sẵn: Batch/job ETL nạp bảng STG_PARTY_MASTER đã chạy xong cho ngày dữ liệu FIC_MIS_DATE = &TEST_DATE; đã nạp thành công tối thiểu 2 ngày dữ liệu liên tiếp &TEST_DATE và &TEST_DATE - 1 | D28: 1. Thực thi câu lệnh SQL kiểm tra tại cột Test Data trên schema staging. 2. Đối chiếu số dòng và giá trị trả về với kỳ vọng. | E28: - DB: Schema staging OFSAA - bảng STG_PARTY_MASTER - Tham số: &TEST_DATE = ngày dữ liệu kiểm thử (business date của batch) - SQL: -- Dữ liệu 2 ngày không lẫn vào nhau SELECT FIC_MIS_DATE, COUNT(*) AS SL FROM STG_PARTY_MASTER WHERE FIC_MIS_DATE BETWEEN DATE '&TEST_DATE' - 1 AND DATE '&TEST_DATE' GROUP BY FIC_MIS_DATE ORDER BY FIC_MIS_DATE; -- FIC_MIS_DATE không NULL và không phải ngày tương lai SELECT COUNT(*) AS SL_SAI FROM STG_PARTY_MASTER WHERE FIC_MIS_DATE IS NULL OR FIC_MIS_DATE > DATE '&TEST_DATE'; | F28: 2. Mỗi ngày dữ liệu có đúng 1 nhóm FIC_MIS_DATE riêng biệt, bản ghi ngày &TEST_DATE không lẫn vào ngày &TEST_DATE - 1 - SL_SAI = 0 - không có bản ghi nào có FIC_MIS_DATE NULL hoặc lớn hơn ngày dữ liệu đang nạp - Lần chạy ngày &TEST_DATE không làm thay đổi số bản ghi của ngày &TEST_DATE - 1 | G28: SIT | H28: Medium | I28: Y | N28: TD: TD_D6_CU_CUS_03 | Chế độ: rà soát. [TC MOI THEM] FIC_MIS_DATE là thành phần PK của mọi bảng và là khoá join KDD_PRCSNG_BATCH_CONTROL.DATA_DUMP_DT.
A29: TM_ETL_CU_CUS_008 | B29: Kiểm tra nạp Daily delta bảng STG_PARTY_MASTER thành công với cả bản ghi mới và bản ghi được cập nhật trong ngày | C29: - User/Quyền: Tài khoản DB có quyền SELECT trên schema staging OFSAA, quyền tạo dữ liệu thử trên hệ thống nguồn SIT và quyền chạy batch/job ETL - Dữ liệu có sẵn: Chuẩn bị trên hệ thống nguồn SIT 1 bản ghi MỚI phát sinh trong ngày &TEST_DATE và 1 bản ghi ĐÃ TỒN TẠI được cập nhật giá trị trong ngày &TEST_DATE; đã ghi lại giá trị trước khi cập nhật | D29: 1. Tạo bản ghi nguồn theo mô tả tại cột Test Data trên hệ thống nguồn SIT. 2. Chạy batch/job ETL nạp bảng STG_PARTY_MASTER cho ngày dữ liệu FIC_MIS_DATE = &TEST_DATE. 3. Thực thi câu lệnh SQL kiểm tra tại cột Test Data trên schema staging. 4. Đối chiếu kết quả trả về và bản ghi trong bảng log lỗi ETL với kỳ vọng. | E29: - DB: Schema staging OFSAA - bảng STG_PARTY_MASTER - Tham số: &TEST_DATE = ngày dữ liệu kiểm thử (business date của batch) - SQL: -- Bản ghi mới phải xuất hiện ở ngày dữ liệu mới SELECT V_PARTY_ID, FIC_MIS_DATE FROM STG_PARTY_MASTER WHERE FIC_MIS_DATE = DATE '&TEST_DATE' AND V_PARTY_ID = '<khoá bản ghi mới>'; -- Bản ghi cập nhật phải mang giá trị MỚI SELECT V_DATA_JURISDICTION, V_BUSINESS_DOMAIN, V_PARTY_NAME, V_DISPLAY_NM, V_PARTY_TYPE FROM STG_PARTY_MASTER WHERE FIC_MIS_DATE = DATE '&TEST_DATE' AND V_PARTY_ID = '<khoá bản ghi được cập nhật>'; | F29: 4. Bản ghi MỚI được nạp vào bảng đích với FIC_MIS_DATE = &TEST_DATE - Bản ghi ĐƯỢC CẬP NHẬT mang giá trị MỚI sau cập nhật, không giữ giá trị cũ - Bản ghi không thay đổi trong ngày không bị nạp lặp gây sai lệch số lượng | G29: SIT | H29: High | I29: Y | N29: TD: TD_D6_CU_CUS_04 | Chế độ: tiêm. [TC MOI THEM] Sheet "1. Cơ chế Load": Daily nạp DELTA gồm bản ghi mới và bản ghi cập nhật. [ASSUMPTION: dấu hiệu nhận biết bản ghi MỚI vs CẬP NHẬT chưa được MSB cung cấp - AT-02 ưu tiên Cao, còn Mở]
B30: NHÓM FUNCTION - Bảng: STG_ADDRESS_MASTER
A31: TM_ETL_CU_ADR_001 | B31: Kiểm tra đối chiếu thành công số lượng bản ghi nạp vào bảng STG_ADDRESS_MASTER với bảng nguồn theo ngày dữ liệu | C31: - User/Quyền: Tài khoản DB có quyền SELECT trên schema staging OFSAA và trên schema hệ thống nguồn MSB - Dữ liệu có sẵn: Batch/job ETL nạp bảng STG_ADDRESS_MASTER đã chạy xong cho ngày dữ liệu FIC_MIS_DATE = &TEST_DATE; đã xác định được bảng nguồn tương ứng theo mapping v1.0 | D31: 1. Thực thi câu lệnh SQL kiểm tra tại cột Test Data trên schema staging. 2. Đối chiếu số dòng và giá trị trả về với kỳ vọng. | E31: - DB: Schema staging OFSAA - bảng STG_ADDRESS_MASTER - Tham số: &TEST_DATE = ngày dữ liệu kiểm thử (business date của batch) - SQL: SELECT (SELECT COUNT(*) FROM <bảng nguồn> WHERE <trường ngày dữ liệu nguồn> = DATE '&TEST_DATE') AS SL_NGUON, (SELECT COUNT(*) FROM STG_ADDRESS_MASTER WHERE FIC_MIS_DATE = DATE '&TEST_DATE') AS SL_DICH FROM DUAL; | F31: 2. Số bản ghi của bảng nguồn = số bản ghi của bảng đích STG_ADDRESS_MASTER đã lọc theo FIC_MIS_DATE = &TEST_DATE - SL_NGUON = SL_DICH - Không có bản ghi nào của ngày dữ liệu bị thiếu ở bảng đích | G31: SIT | H31: High | I31: Y | N31: TD: TD_D1_CU_ADR_01 | Chế độ: rà soát. [ASSUMPTION: bảng/trường nguồn chưa được MSB điền trong mapping v1.0 (AT-02) - câu SQL phía nguồn để placeholder <bảng nguồn>/<trường nguồn>, cập nhật khi có mapping] | O31: TM_ETL_CU_ADR_001
A32: TM_ETL_CU_ADR_003 | B32: Kiểm tra đối chiếu thành công giá trị toàn bộ 7 trường của bảng STG_ADDRESS_MASTER với bảng nguồn theo logic mapping | C32: - User/Quyền: Tài khoản DB có quyền SELECT trên schema staging OFSAA và trên schema hệ thống nguồn MSB - Dữ liệu có sẵn: Batch/job ETL nạp bảng STG_ADDRESS_MASTER đã chạy xong cho ngày dữ liệu FIC_MIS_DATE = &TEST_DATE; logic transform của cả 7 cột đích đã được xác nhận theo mapping v1.0 | D32: 1. Thực thi câu lệnh SQL kiểm tra tại cột Test Data trên schema staging. 2. Đối chiếu số dòng và giá trị trả về với kỳ vọng. | E32: - DB: Schema staging OFSAA - bảng STG_ADDRESS_MASTER - Tham số: &TEST_DATE = ngày dữ liệu kiểm thử (business date của batch) - SQL: SELECT FIC_MIS_DATE, V_ADDRESS_ID, V_ADDRESS_LINE1, V_ADDRESS_LINE2, V_CITY, V_COUNTRY_CODE, V_DATA_ORIGIN FROM STG_ADDRESS_MASTER WHERE FIC_MIS_DATE = DATE '&TEST_DATE' MINUS SELECT <danh sách trường nguồn tương ứng theo logic mapping> FROM <bảng nguồn> WHERE <trường ngày dữ liệu nguồn> = DATE '&TEST_DATE'; | F32: 2. Câu lệnh MINUS trả về 0 dòng - giá trị của cả 7 cột đích trùng khớp với nguồn theo logic mapping - Các cột cần đối chiếu (7): FIC_MIS_DATE, V_ADDRESS_ID, V_ADDRESS_LINE1, V_ADDRESS_LINE2, V_CITY, V_COUNTRY_CODE, V_DATA_ORIGIN - Chạy MINUS đảo chiều (nguồn MINUS đích) cũng trả về 0 dòng | G32: SIT | H32: High | I32: Y | N32: TD: TD_D2_CU_ADR_01 | Chế độ: rà soát. [ASSUMPTION: bảng/trường nguồn chưa được MSB điền trong mapping v1.0 (AT-02) - câu SQL phía nguồn để placeholder <bảng nguồn>/<trường nguồn>, cập nhật khi có mapping] | O32: TM_ETL_CU_ADR_003
A33: TM_ETL_CU_ADR_004 | B33: Kiểm tra không mất bản ghi âm thầm khi nạp bảng STG_ADDRESS_MASTER với đối chiếu tổng nguồn bằng đích cộng bản ghi bị loại | C33: - User/Quyền: Tài khoản DB có quyền SELECT trên schema staging OFSAA và trên schema hệ thống nguồn MSB - Dữ liệu có sẵn: Batch/job ETL nạp bảng STG_ADDRESS_MASTER đã chạy xong cho ngày dữ liệu FIC_MIS_DATE = &TEST_DATE; bảng log lỗi/reject của ETL đã được cấu hình và có ghi nhận bản ghi bị loại trong lần chạy | D33: 1. Thực thi câu lệnh SQL kiểm tra tại cột Test Data trên schema staging. 2. Đối chiếu số dòng và giá trị trả về với kỳ vọng. | E33: - DB: Schema staging OFSAA - bảng STG_ADDRESS_MASTER - Tham số: &TEST_DATE = ngày dữ liệu kiểm thử (business date của batch) - SQL: SELECT (SELECT COUNT(*) FROM <bảng nguồn> WHERE <trường ngày dữ liệu nguồn> = DATE '&TEST_DATE') AS SL_NGUON, (SELECT COUNT(*) FROM STG_ADDRESS_MASTER WHERE FIC_MIS_DATE = DATE '&TEST_DATE') AS SL_DICH, (SELECT COUNT(*) FROM <bảng log lỗi ETL> WHERE TARGET_TABLE = 'STG_ADDRESS_MASTER' AND BATCH_DATE = DATE '&TEST_DATE') AS SL_LOAI FROM DUAL; | F33: 2. SL_NGUON = SL_DICH + SL_LOAI - Mọi bản ghi nguồn không nạp được đều có 1 dòng tương ứng trong bảng log lỗi kèm lý do loại - Không tồn tại bản ghi nguồn nào vừa không có ở bảng đích vừa không có trong bảng log lỗi | G33: SIT | H33: High | I33: Y | N33: TD: TD_D1_CU_ADR_02 | Chế độ: rà soát. [TC MOI THEM] Bộ TC v1.0 không có TC nào phát hiện bản ghi bị bỏ âm thầm. [ASSUMPTION: tên bảng log lỗi/reject của ETL chưa được FIS cung cấp - dùng placeholder <bảng log lỗi ETL>]
A34: TM_ETL_CU_ADR_005 | B34: Kiểm tra batch ETL bảng STG_ADDRESS_MASTER hoàn thành thành công với nguồn không có bản ghi nào trong ngày dữ liệu | C34: - User/Quyền: Tài khoản DB có quyền SELECT trên schema staging OFSAA, quyền tạo dữ liệu thử trên hệ thống nguồn SIT và quyền chạy batch/job ETL - Dữ liệu có sẵn: Chọn 1 ngày dữ liệu &TEST_DATE_EMPTY mà hệ thống nguồn không phát sinh bản ghi nào cho bảng này (ví dụ ngày lễ/Tết không phát sinh giao dịch) | D34: 1. Tạo bản ghi nguồn theo mô tả tại cột Test Data trên hệ thống nguồn SIT. 2. Chạy batch/job ETL nạp bảng STG_ADDRESS_MASTER cho ngày dữ liệu FIC_MIS_DATE = &TEST_DATE. 3. Thực thi câu lệnh SQL kiểm tra tại cột Test Data trên schema staging. 4. Đối chiếu kết quả trả về và bản ghi trong bảng log lỗi ETL với kỳ vọng. | E34: - DB: Schema staging OFSAA - bảng STG_ADDRESS_MASTER - Tham số phụ: &TEST_DATE_EMPTY = ngày dữ liệu nguồn không phát sinh bản ghi - Tham số: &TEST_DATE = ngày dữ liệu kiểm thử (business date của batch) - SQL: SELECT COUNT(*) AS SL_DICH FROM STG_ADDRESS_MASTER WHERE FIC_MIS_DATE = DATE '&TEST_DATE_EMPTY'; -- Trạng thái job của lần chạy đó SELECT <cột trạng thái> FROM <bảng log job ETL> WHERE TARGET_TABLE = 'STG_ADDRESS_MASTER' AND BATCH_DATE = DATE '&TEST_DATE_EMPTY'; | F34: 4. Job ETL kết thúc ở trạng thái hoàn thành thành công, KHÔNG báo lỗi và KHÔNG treo - SL_DICH = 0 - bảng đích không có bản ghi nào cho ngày dữ liệu đó - Không có bản ghi rác và không có bản ghi của ngày khác bị nạp thay thế | G34: SIT | H34: Low | I34: Y | N34: TD: TD_D6_CU_ADR_01 | Chế độ: tiêm. [TC MOI THEM] [ASSUMPTION: tên bảng log lỗi/reject của ETL chưa được FIS cung cấp - dùng placeholder <bảng log lỗi ETL>]
A35: TM_ETL_CU_ADR_006 | B35: Kiểm tra chạy lại batch ETL bảng STG_ADDRESS_MASTER lần thứ hai với cùng ngày dữ liệu không làm nhân đôi bản ghi | C35: - User/Quyền: Tài khoản DB có quyền SELECT trên schema staging OFSAA, quyền tạo dữ liệu thử trên hệ thống nguồn SIT và quyền chạy batch/job ETL - Dữ liệu có sẵn: Batch ETL nạp bảng STG_ADDRESS_MASTER đã chạy thành công lần 1 cho FIC_MIS_DATE = &TEST_DATE; đã ghi lại số bản ghi sau lần 1 để so sánh | D35: 1. Ghi lại số bản ghi của bảng STG_ADDRESS_MASTER sau lần chạy thứ nhất. 2. Chạy lại batch/job ETL nạp bảng STG_ADDRESS_MASTER lần thứ hai cho cùng FIC_MIS_DATE = &TEST_DATE. 3. Thực thi câu lệnh SQL kiểm tra tại cột Test Data trên schema staging. 4. Đối chiếu kết quả sau lần chạy thứ hai với số liệu đã ghi ở bước 1. | E35: - DB: Schema staging OFSAA - bảng STG_ADDRESS_MASTER - Tham số: &TEST_DATE = ngày dữ liệu kiểm thử (business date của batch) - SQL: SELECT COUNT(*) AS SL, COUNT(DISTINCT FIC_MIS_DATE || '|' || V_ADDRESS_ID) AS SL_KEY_DISTINCT FROM STG_ADDRESS_MASTER WHERE FIC_MIS_DATE = DATE '&TEST_DATE'; -- Trùng khoá sau lần chạy thứ hai SELECT FIC_MIS_DATE, V_ADDRESS_ID, COUNT(*) AS SL FROM STG_ADDRESS_MASTER WHERE FIC_MIS_DATE = DATE '&TEST_DATE' GROUP BY FIC_MIS_DATE, V_ADDRESS_ID HAVING COUNT(*) > 1; | F35: 4. Số bản ghi sau lần chạy thứ hai bằng đúng số bản ghi sau lần chạy thứ nhất - SL = SL_KEY_DISTINCT - không có bản ghi nào bị nhân đôi - Câu SQL kiểm trùng khoá (FIC_MIS_DATE, V_ADDRESS_ID) trả về 0 dòng | G35: SIT | H35: High | I35: Y | N35: TD: TD_D6_CU_ADR_02 | Chế độ: tiêm. [TC MOI THEM] Sheet "1. Cơ chế Load" gán N_LOAD_RUN_ID = 1 cố định nên chạy lại phải ghi đè, không tạo lần chạy mới.
A36: TM_ETL_CU_ADR_007 | B36: Kiểm tra bảng STG_ADDRESS_MASTER chỉ chứa dữ liệu đúng ngày dữ liệu đang nạp với điều kiện lọc FIC_MIS_DATE | C36: - User/Quyền: Tài khoản DB có quyền SELECT trên schema staging OFSAA và trên schema hệ thống nguồn MSB - Dữ liệu có sẵn: Batch/job ETL nạp bảng STG_ADDRESS_MASTER đã chạy xong cho ngày dữ liệu FIC_MIS_DATE = &TEST_DATE; đã nạp thành công tối thiểu 2 ngày dữ liệu liên tiếp &TEST_DATE và &TEST_DATE - 1 | D36: 1. Thực thi câu lệnh SQL kiểm tra tại cột Test Data trên schema staging. 2. Đối chiếu số dòng và giá trị trả về với kỳ vọng. | E36: - DB: Schema staging OFSAA - bảng STG_ADDRESS_MASTER - Tham số: &TEST_DATE = ngày dữ liệu kiểm thử (business date của batch) - SQL: -- Dữ liệu 2 ngày không lẫn vào nhau SELECT FIC_MIS_DATE, COUNT(*) AS SL FROM STG_ADDRESS_MASTER WHERE FIC_MIS_DATE BETWEEN DATE '&TEST_DATE' - 1 AND DATE '&TEST_DATE' GROUP BY FIC_MIS_DATE ORDER BY FIC_MIS_DATE; -- FIC_MIS_DATE không NULL và không phải ngày tương lai SELECT COUNT(*) AS SL_SAI FROM STG_ADDRESS_MASTER WHERE FIC_MIS_DATE IS NULL OR FIC_MIS_DATE > DATE '&TEST_DATE'; | F36: 2. Mỗi ngày dữ liệu có đúng 1 nhóm FIC_MIS_DATE riêng biệt, bản ghi ngày &TEST_DATE không lẫn vào ngày &TEST_DATE - 1 - SL_SAI = 0 - không có bản ghi nào có FIC_MIS_DATE NULL hoặc lớn hơn ngày dữ liệu đang nạp - Lần chạy ngày &TEST_DATE không làm thay đổi số bản ghi của ngày &TEST_DATE - 1 | G36: SIT | H36: Medium | I36: Y | N36: TD: TD_D6_CU_ADR_03 | Chế độ: rà soát. [TC MOI THEM] FIC_MIS_DATE là thành phần PK của mọi bảng và là khoá join KDD_PRCSNG_BATCH_CONTROL.DATA_DUMP_DT.
A37: TM_ETL_CU_ADR_008 | B37: Kiểm tra nạp Daily delta bảng STG_ADDRESS_MASTER thành công với cả bản ghi mới và bản ghi được cập nhật trong ngày | C37: - User/Quyền: Tài khoản DB có quyền SELECT trên schema staging OFSAA, quyền tạo dữ liệu thử trên hệ thống nguồn SIT và quyền chạy batch/job ETL - Dữ liệu có sẵn: Chuẩn bị trên hệ thống nguồn SIT 1 bản ghi MỚI phát sinh trong ngày &TEST_DATE và 1 bản ghi ĐÃ TỒN TẠI được cập nhật giá trị trong ngày &TEST_DATE; đã ghi lại giá trị trước khi cập nhật | D37: 1. Tạo bản ghi nguồn theo mô tả tại cột Test Data trên hệ thống nguồn SIT. 2. Chạy batch/job ETL nạp bảng STG_ADDRESS_MASTER cho ngày dữ liệu FIC_MIS_DATE = &TEST_DATE. 3. Thực thi câu lệnh SQL kiểm tra tại cột Test Data trên schema staging. 4. Đối chiếu kết quả trả về và bản ghi trong bảng log lỗi ETL với kỳ vọng. | E37: - DB: Schema staging OFSAA - bảng STG_ADDRESS_MASTER - Tham số: &TEST_DATE = ngày dữ liệu kiểm thử (business date của batch) - SQL: -- Bản ghi mới phải xuất hiện ở ngày dữ liệu mới SELECT FIC_MIS_DATE, V_ADDRESS_ID FROM STG_ADDRESS_MASTER WHERE FIC_MIS_DATE = DATE '&TEST_DATE' AND V_ADDRESS_ID = '<khoá bản ghi mới>'; -- Bản ghi cập nhật phải mang giá trị MỚI SELECT V_ADDRESS_LINE1, V_ADDRESS_LINE2, V_CITY, V_COUNTRY_CODE, V_DATA_ORIGIN FROM STG_ADDRESS_MASTER WHERE FIC_MIS_DATE = DATE '&TEST_DATE' AND V_ADDRESS_ID = '<khoá bản ghi được cập nhật>'; | F37: 4. Bản ghi MỚI được nạp vào bảng đích với FIC_MIS_DATE = &TEST_DATE - Bản ghi ĐƯỢC CẬP NHẬT mang giá trị MỚI sau cập nhật, không giữ giá trị cũ - Bản ghi không thay đổi trong ngày không bị nạp lặp gây sai lệch số lượng | G37: SIT | H37: High | I37: Y | N37: TD: TD_D6_CU_ADR_04 | Chế độ: tiêm. [TC MOI THEM] Sheet "1. Cơ chế Load": Daily nạp DELTA gồm bản ghi mới và bản ghi cập nhật. [ASSUMPTION: dấu hiệu nhận biết bản ghi MỚI vs CẬP NHẬT chưa được MSB cung cấp - AT-02 ưu tiên Cao, còn Mở]
B38: NHÓM FUNCTION - Bảng: STG_PARTY_ADDRESS_MAP
A39: TM_ETL_CU_PAD_001 | B39: Kiểm tra đối chiếu thành công số lượng bản ghi nạp vào bảng STG_PARTY_ADDRESS_MAP với bảng nguồn theo ngày dữ liệu | C39: - User/Quyền: Tài khoản DB có quyền SELECT trên schema staging OFSAA và trên schema hệ thống nguồn MSB - Dữ liệu có sẵn: Batch/job ETL nạp bảng STG_PARTY_ADDRESS_MAP đã chạy xong cho ngày dữ liệu FIC_MIS_DATE = &TEST_DATE; đã xác định được bảng nguồn tương ứng theo mapping v1.0 | D39: 1. Thực thi câu lệnh SQL kiểm tra tại cột Test Data trên schema staging. 2. Đối chiếu số dòng và giá trị trả về với kỳ vọng. | E39: - DB: Schema staging OFSAA - bảng STG_PARTY_ADDRESS_MAP - Tham số: &TEST_DATE = ngày dữ liệu kiểm thử (business date của batch) - SQL: SELECT (SELECT COUNT(*) FROM <bảng nguồn> WHERE <trường ngày dữ liệu nguồn> = DATE '&TEST_DATE') AS SL_NGUON, (SELECT COUNT(*) FROM STG_PARTY_ADDRESS_MAP WHERE FIC_MIS_DATE = DATE '&TEST_DATE') AS SL_DICH FROM DUAL; | F39: 2. Số bản ghi của bảng nguồn = số bản ghi của bảng đích STG_PARTY_ADDRESS_MAP đã lọc theo FIC_MIS_DATE = &TEST_DATE - SL_NGUON = SL_DICH - Không có bản ghi nào của ngày dữ liệu bị thiếu ở bảng đích | G39: SIT | H39: High | I39: Y | N39: TD: TD_D1_CU_PAD_01 | Chế độ: rà soát. [ASSUMPTION: bảng/trường nguồn chưa được MSB điền trong mapping v1.0 (AT-02) - câu SQL phía nguồn để placeholder <bảng nguồn>/<trường nguồn>, cập nhật khi có mapping] | O39: TM_ETL_CU_PAD_001
A40: TM_ETL_CU_PAD_003 | B40: Kiểm tra đối chiếu thành công giá trị toàn bộ 5 trường của bảng STG_PARTY_ADDRESS_MAP với bảng nguồn theo logic mapping | C40: - User/Quyền: Tài khoản DB có quyền SELECT trên schema staging OFSAA và trên schema hệ thống nguồn MSB - Dữ liệu có sẵn: Batch/job ETL nạp bảng STG_PARTY_ADDRESS_MAP đã chạy xong cho ngày dữ liệu FIC_MIS_DATE = &TEST_DATE; logic transform của cả 5 cột đích đã được xác nhận theo mapping v1.0 | D40: 1. Thực thi câu lệnh SQL kiểm tra tại cột Test Data trên schema staging. 2. Đối chiếu số dòng và giá trị trả về với kỳ vọng. | E40: - DB: Schema staging OFSAA - bảng STG_PARTY_ADDRESS_MAP - Tham số: &TEST_DATE = ngày dữ liệu kiểm thử (business date của batch) - SQL: SELECT FIC_MIS_DATE, V_ADDRESS_ID, V_ADDRESS_PURPOSE_TYPE_CD, V_PARTY_ID, N_SEQUENCE_NUMBER FROM STG_PARTY_ADDRESS_MAP WHERE FIC_MIS_DATE = DATE '&TEST_DATE' MINUS SELECT <danh sách trường nguồn tương ứng theo logic mapping> FROM <bảng nguồn> WHERE <trường ngày dữ liệu nguồn> = DATE '&TEST_DATE'; | F40: 2. Câu lệnh MINUS trả về 0 dòng - giá trị của cả 5 cột đích trùng khớp với nguồn theo logic mapping - Các cột cần đối chiếu (5): FIC_MIS_DATE, V_ADDRESS_ID, V_ADDRESS_PURPOSE_TYPE_CD, V_PARTY_ID, N_SEQUENCE_NUMBER - Chạy MINUS đảo chiều (nguồn MINUS đích) cũng trả về 0 dòng | G40: SIT | H40: High | I40: Y | N40: TD: TD_D2_CU_PAD_01 | Chế độ: rà soát. [ASSUMPTION: bảng/trường nguồn chưa được MSB điền trong mapping v1.0 (AT-02) - câu SQL phía nguồn để placeholder <bảng nguồn>/<trường nguồn>, cập nhật khi có mapping] | O40: TM_ETL_CU_PAD_003
...

Sheet Legend
A1: Giai đoạn kiểm thử
A2: Test Level
A3: Giá trị | B3: Giải thích
A4: Value | B4: Description
A5: UT | B5: Kiểm thử kỹ thuật (Unit Test) (IT thực hiện)
A6: SIT | B6: Kiểm thử tích hợp hệ thống (System Integration Test) (IT thực hiện)
A7: OAT | B7: Kiểm thử vận hành (Operation Acceptance Test) (IT thực hiện)
A8: ST | B8: Kiểm thử an ninh thông tin (Security Test) (IT thực hiện)
A9: UAT | B9: Kiểm thử người dùng cuối (User Acceptance Test) (ĐVNV thực hiện)
A12: Độ ưu tiên
A13: Priority
A14: Giá trị | B14: Giải thích
A15: Value | B15: Description
A16: High | B16: Ưu tiên cao
A17: Medium | B17: Ưu tiên trung bình
A18: Low | B18: Ưu tiên thấp/không ưu tiên
A20: Cách thực hiện test | F20: Passed
A21: Automation Status | F21: Failed
A22: Giá trị | B22: Giải thích | F22: Untested
A23: Value | B23: Description | F23: Accepted
A24: Y | B24: Thực hiện Auto test | F24: Pending
A25: N | B25: Thực hiện Manual test | F25: Cancel
A27: Trạng thái
A28: Status
A29: Giá trị | B29: Giải thích
A30: Value | B30: Description
A31: Untested | B31: Chưa thực hiện
A32: Passed | B32: Đạt yêu cầu
A33: Failed | B33: Không đạt yêu cầu
A34: Pending | B34: Pending
B35: Một testcase tạm dừng thực hiện do ảnh hưởng bởi testcase khác fail hoặc cần xác nhận từ các bên liên quan.
A36: Cancel | B36: Không thực hiện
A37: Total | B37: Total = 'Untested' + 'Passed' + 'Failed' + 'Pending' + 'Cancel
A38: % Executed | B38: % Executed = ('Total' - 'Todo' - 'Un-executed')/'Total'
A39: % Pass | B39: % Pass = 'Pass'/'Total'
