Workbook

Sheet Cover
E8: Test Report
C11: Project Name: | E11: DỰ ÁN TRIỂN KHAI BẢN QUYỀN PHẦN MỀM HỆ THỐNG AML MỚI | G11: Reviewer:
C12: Document Code: | G12: Position:
C13: Originator: | G13: Reviewed Date:
C14: Position: | G14: Approver:
C15: Created Date: | E15: 2026-10-06 | G15: Position:
C16: Version: | E16: 1.0 | G16: Approved Date:

Sheet Records
A1: TABLE OF CONTENT
A3: 1 | B3: Cover | C3: Cover
A4: 2 | B4: Records | C4: Record of changes
A5: 3 | B5: Test Report | C5: Tổng hợp kết quả kiểm thử
A6: 4 | B6: Phan Quyen | C6: Testcase phân quyền module TM
A7: 5 | B7: Legend | C7: Chú giải Test Level/Priority/Automation Status/Status
A9: RECORD OF CHANGES
A10: Effective Date | B10: A, M, D | C10: Change Description | D10: New Version | E10: Author
A11: 2026-10-06 | B11: M | C11: Chuẩn hoá cấu trúc cột theo mẫu MSB_AML_TM_UI_v1.0 (Test case Id → Notes, bỏ cột STT). Bỏ: cột Module, Risk Level; Priority Critical quy về High | D11: 1.0

Sheet Test Report
B2: SYSTEM TEST REPORT
A5: Project | B5: DỰ ÁN TRIỂN KHAI BẢN QUYỀN PHẦN MỀM HỆ THỐNG AML MỚI | D5: Project manager
A6: Application | B6: Module Transaction Monitoring (TM) - Phân quyền | D6: Approved Date
A7: Consolidated By | D7: Reviewed By
A8: Build Versions | D8: Reviewed date
A9: Test Environment | B9: SIT
A10: Last Updated Date | B10: 2026-10-06
A11: Test Execution Summary
A12: Reported by
A13: Date
A14: Test Results (Round1) | B14: Passed | C14: Failed | D14: Untested | E14: Accepted | F14: Pending | G14: Cancel | H14: Total
B15: =B16 | C15: =C16 | D15: =D16 | E15: =E16 | F15: =F16 | G15: =G16 | H15: =SUM(B15:F15)
A16: Test cases | B16: ='Phan Quyen'!E6 | C16: ='Phan Quyen'!E7 | D16: ='Phan Quyen'!E8 | E16: ='Phan Quyen'!E9 | F16: ='Phan Quyen'!E10 | G16: ='Phan Quyen'!E11
A18: Test Results (Round2) | B18: =B19 | C18: =C19 | D18: =D19 | E18: =E19 | F18: =F19 | G18: =G19 | H18: =SUM(B18:F18)
A19: Test cases | B19: ='Phan Quyen'!E15 | C19: ='Phan Quyen'!E16 | D19: ='Phan Quyen'!E17 | E19: ='Phan Quyen'!E18 | F19: ='Phan Quyen'!E19 | G19: ='Phan Quyen'!E20
A20: Test coverage
A21: Test coverage
A22: Test successful coverage
A23: Issues
A24: 1. Block testing issue
A25: 2. Critical defects

Sheet Phan Quyen
A1: Functions | B1: Testcase phân quyền module TM
A2: Build Version | B2: v1.0
A3: ROUND 1
B4: High | C4: Medium | D4: Low | E4: Total
B5: =SUM(B6:B10) | C5: =SUM(C6:C10) | D5: =SUM(D6:D10) | E5: =SUM(B5:D5)
A6: Passed | B6: =COUNTIFS($J:$J, $A6,$H:$H,B$4) | C6: =COUNTIFS($J:$J, $A6,$H:$H,C$4) | D6: =COUNTIFS($J:$J, $A6,$H:$H,D$4) | E6: =SUM(B6:D6)
A7: Failed | B7: =COUNTIFS($J:$J, $A7,$H:$H,B$4) | C7: =COUNTIFS($J:$J, $A7,$H:$H,C$4) | D7: =COUNTIFS($J:$J, $A7,$H:$H,D$4) | E7: =SUM(B7:D7)
A8: Untested | B8: =COUNTIFS($J:$J, $A8,$H:$H,B$4) | C8: =COUNTIFS($J:$J, $A8,$H:$H,C$4) | D8: =COUNTIFS($J:$J, $A8,$H:$H,D$4) | E8: =SUM(B8:D8)
A9: Accepted | B9: =COUNTIFS($J:$J, $A9,$H:$H,B$4) | C9: =COUNTIFS($J:$J, $A9,$H:$H,C$4) | D9: =COUNTIFS($J:$J, $A9,$H:$H,D$4) | E9: =SUM(B9:D9)
A10: Pending | B10: =COUNTIFS($J:$J, $A10,$H:$H,B$4) | C10: =COUNTIFS($J:$J, $A10,$H:$H,C$4) | D10: =COUNTIFS($J:$J, $A10,$H:$H,D$4) | E10: =SUM(B10:D10)
A11: Cancel | B11: =COUNTIFS($J:$J, $A11,$H:$H,B$4) | C11: =COUNTIFS($J:$J, $A11,$H:$H,C$4) | D11: =COUNTIFS($J:$J, $A11,$H:$H,D$4) | E11: =SUM(B11:D11)
A12: ROUND2
B13: High | C13: Medium | D13: Low | E13: Total
B14: =SUM(B15:B19) | C14: =SUM(C15:C19) | D14: =SUM(D15:D19) | E14: =SUM(B14:D14)
A15: Passed | B15: =COUNTIFS($K:$K, $A15,$H:$H,B$4) | C15: =COUNTIFS($K:$K, $A15,$H:$H,C$4) | D15: =COUNTIFS($K:$K, $A15,$H:$H,D$4) | E15: =SUM(B15:D15)
A16: Failed | B16: =COUNTIFS($K:$K, $A16,$H:$H,B$4) | C16: =COUNTIFS($K:$K, $A16,$H:$H,C$4) | D16: =COUNTIFS($K:$K, $A16,$H:$H,D$4) | E16: =SUM(B16:D16)
A17: Untested | B17: =COUNTIFS($K:$K, $A17,$H:$H,B$4) | C17: =COUNTIFS($K:$K, $A17,$H:$H,C$4) | D17: =COUNTIFS($K:$K, $A17,$H:$H,D$4) | E17: =SUM(B17:D17)
A18: Accepted | B18: =COUNTIFS($K:$K, $A18,$H:$H,B$4) | C18: =COUNTIFS($K:$K, $A18,$H:$H,C$4) | D18: =COUNTIFS($K:$K, $A18,$H:$H,D$4) | E18: =SUM(B18:D18)
A19: Pending | B19: =COUNTIFS($K:$K, $A19,$H:$H,B$4) | C19: =COUNTIFS($K:$K, $A19,$H:$H,C$4) | D19: =COUNTIFS($K:$K, $A19,$H:$H,D$4) | E19: =SUM(B19:D19)
A20: Cancel | B20: =COUNTIFS($K:$K, $A20,$H:$H,B$4) | C20: =COUNTIFS($K:$K, $A20,$H:$H,C$4) | D20: =COUNTIFS($K:$K, $A20,$H:$H,D$4) | E20: =SUM(B20:D20)
A21: Test case Id | B21: Test case Title | C21: Pre-conditions | D21: Test Steps | E21: Test Datas | F21: Expected result | G21: Test Environment | H21: Priority | I21: Automation Status | J21: 1st Test Results | K21: 2nd Test Results | L21: 3rd Test Results | M21: BugID | N21: Notes
B22: NHÓM PHÂN QUYỀN (M1 CASE-ACTION)
B23: — REQ-01: Đề xuất xử lý cảnh báo
A24: MSB_TM-PQ_TC_001 | B24: Kiểm tra DVKH Maker CÓ QUYỀN đề xuất xử lý cảnh báo Đáng ngờ/Không đáng ngờ/Cần giám sát thêm với case hệ thống trạng thái New | C24: - User: Đăng nhập tm_dvkh_maker_hn (DVKH Maker – CN Hà Nội) - Màn hình: OFSAA ECM > Case Management > Case List (màn hình mặc định sau đăng nhập) - Dữ liệu: đã tồn tại sẵn case PQ-HN-01 – trạng thái New, case sinh tự động từ kịch bản AML-01, Jurisdiction = CN Hà Nội (VN0010001) - Dữ liệu: EDD của case đã được DVKH Maker lưu | D24: 1. Kiểm tra thông tin quyền "Đề xuất xử lý cảnh báo Đáng ngờ/Không đáng ngờ/Cần giám sát thêm" tại màn hình chi tiết case PQ-HN-01 (Status = New) bằng user tm_dvkh_maker_hn | E24: - User: tm_dvkh_maker_hn - Case: PQ-HN-01 (Status = New) | F24: 1. User tm_dvkh_maker_hn có quyền thao tác với quyền "Đề xuất xử lý cảnh báo Đáng ngờ/Không đáng ngờ/Cần giám sát thêm" và sử dụng thông tin case PQ-HN-01 (Status = New) | H24: High | I24: N
A25: MSB_TM-PQ_TC_002 | B25: Kiểm tra DVKH Maker CÓ QUYỀN đề xuất xử lý cảnh báo Đáng ngờ/Không đáng ngờ/Cần giám sát thêm với case hệ thống trạng thái Pending Maker | C25: - User: Đăng nhập tm_dvkh_maker_hn (DVKH Maker – CN Hà Nội) - Màn hình: OFSAA ECM > Case Management > Case List (màn hình mặc định sau đăng nhập) - Dữ liệu: đã tồn tại sẵn case PQ-HN-02 – trạng thái Pending Maker, case sinh tự động từ kịch bản AML-01, Jurisdiction = CN Hà Nội, vừa được DVKH Checker mở lại từ trạng thái Closed - No Further Action - Dữ liệu: EDD của case đã được DVKH Maker lưu lại | D25: 1. Kiểm tra thông tin quyền "Đề xuất xử lý cảnh báo Đáng ngờ/Không đáng ngờ/Cần giám sát thêm" tại màn hình chi tiết case PQ-HN-02 (Status = Pending Maker) bằng user tm_dvkh_maker_hn | E25: - User: tm_dvkh_maker_hn - Case: PQ-HN-02 (Status = Pending Maker) | F25: 1. User tm_dvkh_maker_hn có quyền thao tác với quyền "Đề xuất xử lý cảnh báo Đáng ngờ/Không đáng ngờ/Cần giám sát thêm" và sử dụng thông tin case PQ-HN-02 (Status = Pending Maker) | H25: High | I25: N
A26: MSB_TM-PQ_TC_003 | B26: Kiểm tra DVKH Checker KHÔNG CÓ QUYỀN đề xuất xử lý cảnh báo Đáng ngờ/Không đáng ngờ/Cần giám sát thêm với case hệ thống trạng thái New | C26: - User: Đăng nhập tm_dvkh_checker_hn (DVKH Checker – CN Hà Nội) - Màn hình: OFSAA ECM > Case Management > Case List (màn hình mặc định sau đăng nhập) - Dữ liệu: đã tồn tại sẵn case PQ-HN-01 – trạng thái New, case sinh tự động từ kịch bản AML-01, Jurisdiction = CN Hà Nội (VN0010001) - Dữ liệu: EDD của case đã được DVKH Maker lưu | D26: 1. Kiểm tra thông tin quyền "Đề xuất xử lý cảnh báo Đáng ngờ/Không đáng ngờ/Cần giám sát thêm" tại màn hình chi tiết case PQ-HN-01 (Status = New) bằng user tm_dvkh_checker_hn | E26: - User: tm_dvkh_checker_hn - Case: PQ-HN-01 (Status = New) | F26: 1. User tm_dvkh_checker_hn không có quyền thao tác với quyền "Đề xuất xử lý cảnh báo Đáng ngờ/Không đáng ngờ/Cần giám sát thêm" đối với case PQ-HN-01 (Status = New) | H26: High | I26: N
A27: MSB_TM-PQ_TC_004 | B27: Kiểm tra Checker N+1 KHÔNG CÓ QUYỀN đề xuất xử lý cảnh báo Đáng ngờ/Không đáng ngờ/Cần giám sát thêm với case hệ thống trạng thái New | C27: - User: Đăng nhập tm_checker_n1_hn (Checker N+1 – CN Hà Nội) - Màn hình: OFSAA ECM > Case Management > Case List (màn hình mặc định sau đăng nhập) - Dữ liệu: đã tồn tại sẵn case PQ-HN-01 – trạng thái New, case sinh tự động từ kịch bản AML-01, Jurisdiction = CN Hà Nội (VN0010001) - Dữ liệu: EDD của case đã được DVKH Maker lưu | D27: 1. Kiểm tra thông tin quyền "Đề xuất xử lý cảnh báo Đáng ngờ/Không đáng ngờ/Cần giám sát thêm" tại màn hình chi tiết case PQ-HN-01 (Status = New) bằng user tm_checker_n1_hn | E27: - User: tm_checker_n1_hn - Case: PQ-HN-01 (Status = New) | F27: 1. User tm_checker_n1_hn không có quyền thao tác với quyền "Đề xuất xử lý cảnh báo Đáng ngờ/Không đáng ngờ/Cần giám sát thêm" đối với case PQ-HN-01 (Status = New) | H27: High | I27: N
A28: MSB_TM-PQ_TC_005 | B28: Kiểm tra AML Maker KHÔNG CÓ QUYỀN đề xuất xử lý cảnh báo Đáng ngờ/Không đáng ngờ/Cần giám sát thêm với case hệ thống trạng thái New | C28: - User: Đăng nhập tm_aml_maker (AML Maker – HO) - Màn hình: OFSAA ECM > Case Management > Case List (màn hình mặc định sau đăng nhập) - Dữ liệu: đã tồn tại sẵn case PQ-HN-01 – trạng thái New, case sinh tự động từ kịch bản AML-01, Jurisdiction = CN Hà Nội (VN0010001) - Dữ liệu: EDD của case đã được DVKH Maker lưu | D28: 1. Kiểm tra thông tin quyền "Đề xuất xử lý cảnh báo Đáng ngờ/Không đáng ngờ/Cần giám sát thêm" tại màn hình chi tiết case PQ-HN-01 (Status = New) bằng user tm_aml_maker | E28: - User: tm_aml_maker - Case: PQ-HN-01 (Status = New) | F28: 1. User tm_aml_maker không có quyền thao tác với quyền "Đề xuất xử lý cảnh báo Đáng ngờ/Không đáng ngờ/Cần giám sát thêm" đối với case PQ-HN-01 (Status = New) | H28: High | I28: N
A29: MSB_TM-PQ_TC_006 | B29: Kiểm tra AML Checker KHÔNG CÓ QUYỀN đề xuất xử lý cảnh báo Đáng ngờ/Không đáng ngờ/Cần giám sát thêm với case hệ thống trạng thái New | C29: - User: Đăng nhập tm_aml_checker (AML Checker – HO) - Màn hình: OFSAA ECM > Case Management > Case List (màn hình mặc định sau đăng nhập) - Dữ liệu: đã tồn tại sẵn case PQ-HN-01 – trạng thái New, case sinh tự động từ kịch bản AML-01, Jurisdiction = CN Hà Nội (VN0010001) - Dữ liệu: EDD của case đã được DVKH Maker lưu | D29: 1. Kiểm tra thông tin quyền "Đề xuất xử lý cảnh báo Đáng ngờ/Không đáng ngờ/Cần giám sát thêm" tại màn hình chi tiết case PQ-HN-01 (Status = New) bằng user tm_aml_checker | E29: - User: tm_aml_checker - Case: PQ-HN-01 (Status = New) | F29: 1. User tm_aml_checker không có quyền thao tác với quyền "Đề xuất xử lý cảnh báo Đáng ngờ/Không đáng ngờ/Cần giám sát thêm" đối với case PQ-HN-01 (Status = New) | H29: High | I29: N
A30: MSB_TM-PQ_TC_007 | B30: Kiểm tra Admin/IT KHÔNG CÓ QUYỀN đề xuất xử lý cảnh báo Đáng ngờ/Không đáng ngờ/Cần giám sát thêm với case hệ thống trạng thái New | C30: - User: Đăng nhập tm_admin_it (Admin/IT – HO) - Màn hình: OFSAA ECM > Case Management > Case List (màn hình mặc định sau đăng nhập) - Dữ liệu: đã tồn tại sẵn case PQ-HN-01 – trạng thái New, case sinh tự động từ kịch bản AML-01, Jurisdiction = CN Hà Nội (VN0010001) - Dữ liệu: EDD của case đã được DVKH Maker lưu | D30: 1. Kiểm tra thông tin quyền "Đề xuất xử lý cảnh báo Đáng ngờ/Không đáng ngờ/Cần giám sát thêm" tại màn hình chi tiết case PQ-HN-01 (Status = New) bằng user tm_admin_it | E30: - User: tm_admin_it - Case: PQ-HN-01 (Status = New) | F30: 1. User tm_admin_it không có quyền thao tác với quyền "Đề xuất xử lý cảnh báo Đáng ngờ/Không đáng ngờ/Cần giám sát thêm" đối với case PQ-HN-01 (Status = New) | H30: High | I30: N
B31: — REQ-02: Bổ sung thông tin
A32: MSB_TM-PQ_TC_008 | B32: Kiểm tra DVKH Maker CÓ QUYỀN bổ sung thông tin với case hệ thống trạng thái Pending Maker | C32: - User: Đăng nhập tm_dvkh_maker_hn (DVKH Maker – CN Hà Nội) - Màn hình: OFSAA ECM > Case Management > Case List (màn hình mặc định sau đăng nhập) - Dữ liệu: đã tồn tại sẵn case PQ-HN-03 – trạng thái Pending Maker, case sinh tự động từ kịch bản AML-01, Jurisdiction = CN Hà Nội, bị DVKH Checker yêu cầu bổ sung thông tin tại bước rà soát cảnh báo | D32: 1. Kiểm tra thông tin quyền "Bổ sung thông tin" tại màn hình chi tiết case PQ-HN-03 (Status = Pending Maker) bằng user tm_dvkh_maker_hn | E32: - User: tm_dvkh_maker_hn - Case: PQ-HN-03 (Status = Pending Maker) | F32: 1. User tm_dvkh_maker_hn có quyền thao tác với quyền "Bổ sung thông tin" và sử dụng thông tin case PQ-HN-03 (Status = Pending Maker) | H32: High | I32: N
A33: MSB_TM-PQ_TC_009 | B33: Kiểm tra AML Maker CÓ QUYỀN bổ sung thông tin với case do AML tạo trạng thái Pending AML Maker | C33: - User: Đăng nhập tm_aml_maker (AML Maker – HO) - Màn hình: OFSAA ECM > Case Management > Case List (màn hình mặc định sau đăng nhập) - Dữ liệu: đã tồn tại sẵn case PQ-AML-01 – trạng thái Pending AML Maker, case thủ công do AML Maker (tm_aml_maker) tạo, Type = AML_MN, Jurisdiction = CN Hà Nội, bị AML Checker yêu cầu bổ sung thông tin tại bước rà soát STR - Dữ liệu: STR của case đã được AML Maker lưu lại | D33: 1. Kiểm tra thông tin quyền "Bổ sung thông tin" tại màn hình chi tiết case PQ-AML-01 (Status = Pending AML Maker) bằng user tm_aml_maker | E33: - User: tm_aml_maker - Case: PQ-AML-01 (Status = Pending AML Maker) | F33: 1. User tm_aml_maker có quyền thao tác với quyền "Bổ sung thông tin" và sử dụng thông tin case PQ-AML-01 (Status = Pending AML Maker) - [ASSUMPTION: trạng thái kế tiếp theo BRD dòng 501-503 (bước 1b), Q3] | H33: High | I33: N
A34: MSB_TM-PQ_TC_010 | B34: Kiểm tra DVKH Checker KHÔNG CÓ QUYỀN bổ sung thông tin với case hệ thống trạng thái Pending Maker | C34: - User: Đăng nhập tm_dvkh_checker_hn (DVKH Checker – CN Hà Nội) - Màn hình: OFSAA ECM > Case Management > Case List (màn hình mặc định sau đăng nhập) - Dữ liệu: đã tồn tại sẵn case PQ-HN-03 – trạng thái Pending Maker, case sinh tự động từ kịch bản AML-01, Jurisdiction = CN Hà Nội, bị DVKH Checker yêu cầu bổ sung thông tin tại bước rà soát cảnh báo | D34: 1. Kiểm tra thông tin quyền "Bổ sung thông tin" tại màn hình chi tiết case PQ-HN-03 (Status = Pending Maker) bằng user tm_dvkh_checker_hn | E34: - User: tm_dvkh_checker_hn - Case: PQ-HN-03 (Status = Pending Maker) | F34: 1. User tm_dvkh_checker_hn không có quyền thao tác với quyền "Bổ sung thông tin" đối với case PQ-HN-03 (Status = Pending Maker) | H34: High | I34: N
A35: MSB_TM-PQ_TC_011 | B35: Kiểm tra Checker N+1 KHÔNG CÓ QUYỀN bổ sung thông tin với case hệ thống trạng thái Pending Maker | C35: - User: Đăng nhập tm_checker_n1_hn (Checker N+1 – CN Hà Nội) - Màn hình: OFSAA ECM > Case Management > Case List (màn hình mặc định sau đăng nhập) - Dữ liệu: đã tồn tại sẵn case PQ-HN-03 – trạng thái Pending Maker, case sinh tự động từ kịch bản AML-01, Jurisdiction = CN Hà Nội, bị DVKH Checker yêu cầu bổ sung thông tin tại bước rà soát cảnh báo | D35: 1. Kiểm tra thông tin quyền "Bổ sung thông tin" tại màn hình chi tiết case PQ-HN-03 (Status = Pending Maker) bằng user tm_checker_n1_hn | E35: - User: tm_checker_n1_hn - Case: PQ-HN-03 (Status = Pending Maker) | F35: 1. User tm_checker_n1_hn không có quyền thao tác với quyền "Bổ sung thông tin" đối với case PQ-HN-03 (Status = Pending Maker) | H35: High | I35: N
A36: MSB_TM-PQ_TC_012 | B36: Kiểm tra AML Maker KHÔNG CÓ QUYỀN bổ sung thông tin với case hệ thống trạng thái Pending Maker | C36: - User: Đăng nhập tm_aml_maker (AML Maker – HO) - Màn hình: OFSAA ECM > Case Management > Case List (màn hình mặc định sau đăng nhập) - Dữ liệu: đã tồn tại sẵn case PQ-HN-03 – trạng thái Pending Maker, case sinh tự động từ kịch bản AML-01, Jurisdiction = CN Hà Nội, bị DVKH Checker yêu cầu bổ sung thông tin tại bước rà soát cảnh báo | D36: 1. Kiểm tra thông tin quyền "Bổ sung thông tin" tại màn hình chi tiết case PQ-HN-03 (Status = Pending Maker) bằng user tm_aml_maker | E36: - User: tm_aml_maker - Case: PQ-HN-03 (Status = Pending Maker) | F36: 1. User tm_aml_maker không có quyền thao tác với quyền "Bổ sung thông tin" đối với case PQ-HN-03 (Status = Pending Maker) | H36: High | I36: N
A37: MSB_TM-PQ_TC_013 | B37: Kiểm tra AML Checker KHÔNG CÓ QUYỀN bổ sung thông tin với case hệ thống trạng thái Pending Maker | C37: - User: Đăng nhập tm_aml_checker (AML Checker – HO) - Màn hình: OFSAA ECM > Case Management > Case List (màn hình mặc định sau đăng nhập) - Dữ liệu: đã tồn tại sẵn case PQ-HN-03 – trạng thái Pending Maker, case sinh tự động từ kịch bản AML-01, Jurisdiction = CN Hà Nội, bị DVKH Checker yêu cầu bổ sung thông tin tại bước rà soát cảnh báo | D37: 1. Kiểm tra thông tin quyền "Bổ sung thông tin" tại màn hình chi tiết case PQ-HN-03 (Status = Pending Maker) bằng user tm_aml_checker | E37: - User: tm_aml_checker - Case: PQ-HN-03 (Status = Pending Maker) | F37: 1. User tm_aml_checker không có quyền thao tác với quyền "Bổ sung thông tin" đối với case PQ-HN-03 (Status = Pending Maker) | H37: High | I37: N
A38: MSB_TM-PQ_TC_014 | B38: Kiểm tra Admin/IT KHÔNG CÓ QUYỀN bổ sung thông tin với case hệ thống trạng thái Pending Maker | C38: - User: Đăng nhập tm_admin_it (Admin/IT – HO) - Màn hình: OFSAA ECM > Case Management > Case List (màn hình mặc định sau đăng nhập) - Dữ liệu: đã tồn tại sẵn case PQ-HN-03 – trạng thái Pending Maker, case sinh tự động từ kịch bản AML-01, Jurisdiction = CN Hà Nội, bị DVKH Checker yêu cầu bổ sung thông tin tại bước rà soát cảnh báo | D38: 1. Kiểm tra thông tin quyền "Bổ sung thông tin" tại màn hình chi tiết case PQ-HN-03 (Status = Pending Maker) bằng user tm_admin_it | E38: - User: tm_admin_it - Case: PQ-HN-03 (Status = Pending Maker) | F38: 1. User tm_admin_it không có quyền thao tác với quyền "Bổ sung thông tin" đối với case PQ-HN-03 (Status = Pending Maker) | H38: High | I38: N
B39: — REQ-03: Phê duyệt kết quả xử lý cảnh báo
A40: MSB_TM-PQ_TC_015 | B40: Kiểm tra DVKH Checker CÓ QUYỀN phê duyệt kết quả xử lý cảnh báo Không đáng ngờ/Đáng ngờ/Cần giám sát thêm với case hệ thống trạng thái Pending Checker Review | C40: - User: Đăng nhập tm_dvkh_checker_hn (DVKH Checker – CN Hà Nội) - Màn hình: OFSAA ECM > Case Management > Case List (màn hình mặc định sau đăng nhập) - Dữ liệu: đã tồn tại sẵn case PQ-HN-04 – trạng thái Pending Checker Review, case sinh tự động từ kịch bản AML-01, Jurisdiction = CN Hà Nội, DVKH Maker đã đề xuất Đáng ngờ | D40: 1. Kiểm tra thông tin quyền "Phê duyệt kết quả xử lý cảnh báo Không đáng ngờ/Đáng ngờ/Cần giám sát thêm" tại màn hình chi tiết case PQ-HN-04 (Status = Pending Checker Review) bằng user tm_dvkh_checker_hn | E40: - User: tm_dvkh_checker_hn - Case: PQ-HN-04 (Status = Pending Checker Review) | F40: 1. User tm_dvkh_checker_hn có quyền thao tác với quyền "Phê duyệt kết quả xử lý cảnh báo Không đáng ngờ/Đáng ngờ/Cần giám sát thêm" và sử dụng thông tin case PQ-HN-04 (Status = Pending Checker Review) | H40: High | I40: N
...

Sheet Legend
A1: Giai đoạn kiểm thử
A2: Test Level
A3: Giá trị | B3: Giải thích
A4: Value | B4: Description
A5: UT | B5: Kiểm thử kỹ thuật (Unit Test) (IT thực hiện)
A6: SIT | B6: Kiểm thử tích hợp hệ thống (System Integration Test) (IT thực hiện)
A7: OAT | B7: Kiểm thử vận hành (Operation Acceptance Test) (IT thực hiện)
A8: ST | B8: Kiểm thử an ninh thông tin (Security Test) (IT thực hiện)
A9: UAT | B9: Kiểm thử người dùng cuối (User Acceptance Test) (ĐVNV thực hiện)
A12: Độ ưu tiên
A13: Priority
A14: Giá trị | B14: Giải thích
A15: Value | B15: Description
A16: High | B16: Ưu tiên cao
A17: Medium | B17: Ưu tiên trung bình
A18: Low | B18: Ưu tiên thấp/không ưu tiên
A20: Cách thực hiện test | F20: Passed
A21: Automation Status | F21: Failed
A22: Giá trị | B22: Giải thích | F22: Untested
A23: Value | B23: Description | F23: Accepted
A24: Y | B24: Thực hiện Auto test | F24: Pending
A25: N | B25: Thực hiện Manual test | F25: Cancel
A27: Trạng thái
A28: Status
A29: Giá trị | B29: Giải thích
A30: Value | B30: Description
A31: Untested | B31: Chưa thực hiện
A32: Passed | B32: Đạt yêu cầu
A33: Failed | B33: Không đạt yêu cầu
A34: Pending | B34: Pending
B35: Một testcase tạm dừng thực hiện do ảnh hưởng bởi testcase khác fail hoặc cần xác nhận từ các bên liên quan.
A36: Cancel | B36: Không thực hiện
A37: Total | B37: Total = 'Untested' + 'Passed' + 'Failed' + 'Pending' + 'Cancel
A38: % Executed | B38: % Executed = ('Total' - 'Todo' - 'Un-executed')/'Total'
A39: % Pass | B39: % Pass = 'Pass'/'Total'
