Workbook

Sheet Cover
E8: Test Report
C11: Project Name: | E11: DỰ ÁN TRIỂN KHAI BẢN QUYỀN PHẦN MỀM HỆ THỐNG AML MỚI | G11: Reviewer:
C12: Document Code: | E12: MSB_AML_Testcase_TF_Push_Data | G12: Position:
C13: Originator: | G13: Reviewed Date:
C14: Position: | G14: Approver:
C15: Created Date: | E15: 46153 | G15: Position:
C16: Version: | E16: 1.0 | G16: Approved Date:

Sheet Records
A1: TABLE OF CONTENT
A3: No | B3: Items | C3: Content
A4: 1 | B4: Cover | C4: Cover
A5: 2 | B5: Records | C5: Record of changes
A6: 3 | B6: Function | C6: List out all test cases of the application
A7: 4 | B7: Screen Element | C7: Screen Element test cases, which are based on the application's SRS
A9: Effective Date | B9: A, M, D | C9: Change Description | F9: New Version | G9: Author
A10: 46153 | B10: A | C10: Create new TC | F10: 1

Sheet Test Report
B2: SYSTEM TEST REPORT
A5: Project | B5: =#NAME? -> #NAME? | D5: Project manager
A6: Application | D6: Approved Date
A7: Consolidated By | D7: Reviewed By
A8: Build Versions | D8: Reviewed date
A9: Test Environment | B9: SIT
A10: Last Updated Date
A11: Test Execution Summary
A12: Reported by
A13: Date
A14: Test Results | B14: Passed | C14: Failed | D14: Accepted | E14: Pending | F14: Untested | G14: Total
A15: Total | B15: =SUM(B16:B16) -> 6 | C15: =SUM(C16:C16) -> 19 | D15: =SUM(D16:D16) -> 0 | E15: =SUM(E16:E16) -> 0 | F15: =SUM(F16:F16) -> 22 | G15: =SUM(B15:F15) -> 47
A16: Test case | B16: =Testcase!E6 -> 6 | C16: =Testcase!E7 -> 19 | D16: =Testcase!E9 -> 0 | E16: =Testcase!E10 -> 0 | F16: =Testcase!E8 -> 22 | G16: =SUM(B16:F16) -> 47
A17: Test coverage
A18: Test coverage | G18: =IFERROR(SUM(B15,C15,E15)/G15, 0) -> 0.53191489
A19: Test successful coverage | G19: =IFERROR(SUM(B15,E15)/G15, 0) -> 0.12765957
A20: Issues
A21: 1. Block testing issue
A22: 2. Critical defects | S22: b

Sheet Testcase
A1: Functions | B1: AML Screening - Push Data theo mọi danh sách (WC/AML/BCA/Knock-out) với các Webservice
A2: Build Version | B2: v1.0
B4: High | C4: Medium | D4: Low | E4: Total
B5: =SUM(B6:B10) -> 47 | C5: =SUM(C6:C10) -> 0 | D5: =SUM(D6:D10) -> 0 | E5: =SUM(B5:D5) -> 47
A6: Passed | B6: =COUNTIFS($J:$J, $A$6,$H:$H,B$4) -> 6 | C6: =COUNTIFS($J:$J, $A$6,$H:$H,C$4) -> 0 | D6: =COUNTIFS($J:$J, $A$6,$H:$H,D$4) -> 0 | E6: =SUM(B6:D6) -> 6
A7: Failed | B7: =COUNTIFS($J:$J, $A$7,$H:$H,B$4) -> 19 | C7: =COUNTIFS($J:$J, $A$7,$H:$H,C$4) -> 0 | D7: =COUNTIFS($J:$J, $A$7,$H:$H,D$4) -> 0 | E7: =SUM(B7:D7) -> 19
A8: Untested | B8: =COUNTIFS($J:$J, $A$8,$H:$H,B$4) -> 22 | C8: =COUNTIFS($J:$J, $A$8,$H:$H,C$4) -> 0 | D8: =COUNTIFS($J:$J, $A$8,$H:$H,D$4) -> 0 | E8: =SUM(B8:D8) -> 22
A9: Accepted | B9: =COUNTIFS($J:$J, $A$9,$H:$H,B$4) -> 0 | C9: =COUNTIFS($J:$J, $A$9,$H:$H,C$4) -> 0 | D9: =COUNTIFS($J:$J, $A$9,$H:$H,D$4) -> 0 | E9: =SUM(B9:D9) -> 0
A10: Pending | B10: =COUNTIFS($J:$J, $A$10,H:H,B$4) -> 0 | C10: =COUNTIFS($J:$J, $A$10,I:I,C$4) -> 0 | D10: =COUNTIFS($J:$J, $A$10,J:J,D$4) -> 0 | E10: =SUM(B10:D10) -> 0
A12: Test case Id | B12: Test case Title | C12: Pre-conditions | D12: Test Step | E12: Test Datas | F12: Expected result | G12: Test Environment | H12: Priority | I12: Automation Status | J12: 1st Test Results | K12: 2nd Test Results | L12: BugID | M12: Notes
B13: Kiểm tra giá trị từng trường trong danh sách theo dõi quét với Webservice tương ứng
B14: Webservice Name And Address
A15: NAD.01 | B15: Sàng lọc điện trường hợp Xpath /Document/FIToFICstmrCdtTrf/CdtTrfTxInf/Cdtr/Nm điện pacs.008.001.08 trùng với giá trị trường 'FIRST NAME + LAST NAME' trong danh sách WC | C15: 1. Điện được đẩy đúng format | D15: 1. Đẩy giao dịch vào API Post Message với Xpath điện pacs.008.001.08 2. Kiểm tra thông tin Event của giao dịch theo đường dẫn Financial Services Analytical Applications Transactions Filtering > Financial services Sanctions Pack > Transaction Filtering Alert List Chọn Filter, nhập thông tin tìm kiếm theo AlertID, nhấn <Search> Click mã AlertID và kiểm tra các thông tin Hoặc kiểm tra các thông tin trong file kết quả truy vấn Database | E15: <?xml version='1.0' encoding='UTF-8'?> <Document xmlns="urn:iso:std:iso:20022:tech:xsd:pacs.008.001.08"> <FIToFICstmrCdtTrf> <GrpHdr> <MsgId>SUMMITEMBER-MSG-AGT</MsgId> <CreDtTm>2026-07-28T13:31:41</CreDtTm> <NbOfTxs>1</NbOfTxs> <SttlmInf> <SttlmMtd>INDA</SttlmMtd> </SttlmInf> </GrpHdr> <CdtTrfTxInf> <PmtId> <EndToEndId>SE-E2E-AGT</EndToEndId> </PmtId> <IntrBkSttlmAmt Ccy="USD">1000.00</IntrBkSttlmAmt> <ChrgBr>SHAR</ChrgBr> <Dbtr> <Nm>SUMMIT EMBER</Nm> </Dbtr> <DbtrAgt> <FinInstnId> <Nm>SUMMIT EMBER</Nm> </FinInstnId> </DbtrAgt> <CdtrAgt> <FinInstnId> <Nm>SUMMIT EMBER</Nm> </FinInstnId> </CdtrAgt> <Cdtr> <Nm>SUMMIT EMBER</Nm> </Cdtr> </CdtTrfTxInf> </FIToFICstmrCdtTrf> </Document> | F15: 2. Hệ thống sinh HIT tại xpath /Document/FIToFICstmrCdtTrf/CdtTrfTxInf/Cdtr/Nm qua webservice NAME AND ADDRESS, khớp với danh sách WC. SELECT CASE WHEN COUNT(1) >= 1 THEN 'Pass' ELSE 'Fail' END sql_check FROM fsi_rt_xml_wls_response t WHERE n_grp_msg_id = :n_grp_msg_id AND V_MATCHED_LIST_REC_ID = 'nhập lại' AND n_webservice_id = 1 AND V_MATCHED_LIST_NAME = 'WC' AND regexp_replace(to_char(t.x_path), '\[\d+\]', '') LIKE '%' || regexp_replace('Document/FIToFICstmrCdtTrf/CdtTrfTxInf/Cdtr/Nm', '\[\d+\]', '') || '%'; | H15: High | I15: Manual | J15: Passed | K15: Passed
A16: NAD.05 | B16: Sàng lọc điện trường hợp Xpath /Document/FIToFICstmrCdtTrf/CdtTrfTxInf/Cdtr/Nm điện pacs.008.001.08 trùng với giá trị trường 'LAST NAME' trong danh sách WC | C16: 1. Điện được đẩy đúng format | D16: 1. Đẩy giao dịch vào API Post Message với Xpath điện pacs.008.001.08 2. Kiểm tra thông tin Event của giao dịch theo đường dẫn Financial Services Analytical Applications Transactions Filtering > Financial services Sanctions Pack > Transaction Filtering Alert List Chọn Filter, nhập thông tin tìm kiếm theo AlertID, nhấn <Search> Click mã AlertID và kiểm tra các thông tin Hoặc kiểm tra các thông tin trong file kết quả truy vấn Database | E16: <?xml version='1.0' encoding='UTF-8'?> <Document xmlns="urn:iso:std:iso:20022:tech:xsd:pacs.008.001.08"> <FIToFICstmrCdtTrf> <GrpHdr> <MsgId>SUMMITEMBER-MSG-AGT</MsgId> <CreDtTm>2026-07-28T13:31:41</CreDtTm> <NbOfTxs>1</NbOfTxs> <SttlmInf> <SttlmMtd>INDA</SttlmMtd> </SttlmInf> </GrpHdr> <CdtTrfTxInf> <PmtId> <EndToEndId>SE-E2E-AGT</EndToEndId> </PmtId> <IntrBkSttlmAmt Ccy="USD">1000.00</IntrBkSttlmAmt> <ChrgBr>SHAR</ChrgBr> <Dbtr> <Nm>SUMMIT EMBER</Nm> </Dbtr> <DbtrAgt> <FinInstnId> <Nm>SUMMIT EMBER</Nm> </FinInstnId> </DbtrAgt> <CdtrAgt> <FinInstnId> <Nm>SUMMIT EMBER</Nm> </FinInstnId> </CdtrAgt> <Cdtr> <Nm>SUMMIT EMBER</Nm> </Cdtr> </CdtTrfTxInf> </FIToFICstmrCdtTrf> </Document> | F16: 2. Hệ thống sinh HIT tại xpath /Document/FIToFICstmrCdtTrf/CdtTrfTxInf/Cdtr/Nm qua webservice NAME AND ADDRESS, khớp với danh sách WC. SELECT CASE WHEN COUNT(1) >= 1 THEN 'Pass' ELSE 'Fail' END sql_check FROM fsi_rt_xml_wls_response t WHERE n_grp_msg_id = :n_grp_msg_id AND V_MATCHED_LIST_REC_ID = 'nhập lại' AND n_webservice_id = 1 AND V_MATCHED_LIST_NAME = 'WC' AND regexp_replace(to_char(t.x_path), '\[\d+\]', '') LIKE '%' || regexp_replace('Document/FIToFICstmrCdtTrf/CdtTrfTxInf/Cdtr/Nm', '\[\d+\]', '') || '%'; | H16: High | I16: Manual | J16: Failed | K16: Passed
A17: NAD.06 | B17: Sàng lọc điện trường hợp Xpath /Document/FIToFICstmrCdtTrf/CdtTrfTxInf/UltmtCdtr/CtctDtls/Nm điện pacs.008.001.08 trùng với giá trị trường 'ALIASES' trong danh sách WC | C17: 1. Điện được đẩy đúng format | D17: 1. Đẩy giao dịch vào API Post Message với Xpath điện pacs.008.001.08 2. Kiểm tra thông tin Event của giao dịch theo đường dẫn Financial Services Analytical Applications Transactions Filtering > Financial services Sanctions Pack > Transaction Filtering Alert List Chọn Filter, nhập thông tin tìm kiếm theo AlertID, nhấn <Search> Click mã AlertID và kiểm tra các thông tin Hoặc kiểm tra các thông tin trong file kết quả truy vấn Database | E17: <?xml version='1.0' encoding='UTF-8'?> <Document xmlns="urn:iso:std:iso:20022:tech:xsd:pacs.008.001.08"> <FIToFICstmrCdtTrf> <GrpHdr> <MsgId>DRIFTWOODHORIZON-MSG-008</MsgId> <CreDtTm>2026-07-28T13:31:41</CreDtTm> <NbOfTxs>1</NbOfTxs> <SttlmInf> <SttlmMtd>INDA</SttlmMtd> </SttlmInf> </GrpHdr> <CdtTrfTxInf> <PmtId> <EndToEndId>DH-E2E-008</EndToEndId> </PmtId> <IntrBkSttlmAmt Ccy="USD">1000.00</IntrBkSttlmAmt> <ChrgBr>SHAR</ChrgBr> <Dbtr> <Nm>DRIFTWOOD HORIZON</Nm> </Dbtr> <DbtrAgt> <FinInstnId> <Nm>DRIFTWOOD HORIZON</Nm> </FinInstnId> </DbtrAgt> <CdtrAgt> <FinInstnId> <Nm>DRIFTWOOD HORIZON</Nm> </FinInstnId> </CdtrAgt> <Cdtr> <Nm>DRIFTWOOD HORIZON</Nm> </Cdtr> <UltmtCdtr> <CtctDtls> <Nm>DRIFTWOOD HORIZON</Nm> </CtctDtls> </UltmtCdtr> </CdtTrfTxInf> </FIToFICstmrCdtTrf> </Document> | F17: 2. Hệ thống sinh HIT tại xpath /Document/FIToFICstmrCdtTrf/CdtTrfTxInf/UltmtCdtr/CtctDtls/Nm qua webservice NAME AND ADDRESS, khớp với danh sách WC. SELECT CASE WHEN COUNT(1) >= 1 THEN 'Pass' ELSE 'Fail' END sql_check FROM fsi_rt_xml_wls_response t WHERE n_grp_msg_id = :n_grp_msg_id AND V_MATCHED_LIST_REC_ID = 'nhập lại' AND n_webservice_id = 1 AND V_MATCHED_LIST_NAME = 'WC' AND regexp_replace(to_char(t.x_path), '\[\d+\]', '') LIKE '%' || regexp_replace('Document/FIToFICstmrCdtTrf/CdtTrfTxInf/UltmtCdtr/CtctDtls/Nm', '\[\d+\]', '') || '%'; | H17: High | I17: Manual | J17: Failed | K17: Passed
A18: NAD.07 | B18: Sàng lọc điện trường hợp Xpath /Document/FIToFICstmrCdtTrf/CdtTrfTxInf/UltmtDbtr/Nm điện pacs.008.001.08 trùng với giá trị trường 'LOW QUALITY ALIASES' trong danh sách WC | C18: 1. Điện được đẩy đúng format | D18: 1. Đẩy giao dịch vào API Post Message với Xpath điện pacs.008.001.08 2. Kiểm tra thông tin Event của giao dịch theo đường dẫn Financial Services Analytical Applications Transactions Filtering > Financial services Sanctions Pack > Transaction Filtering Alert List Chọn Filter, nhập thông tin tìm kiếm theo AlertID, nhấn <Search> Click mã AlertID và kiểm tra các thông tin Hoặc kiểm tra các thông tin trong file kết quả truy vấn Database | E18: <?xml version='1.0' encoding='UTF-8'?> <Document xmlns="urn:iso:std:iso:20022:tech:xsd:pacs.008.001.08"> <FIToFICstmrCdtTrf> <GrpHdr> <MsgId>IRONPINE-MSG-008</MsgId> <CreDtTm>2026-07-28T13:31:41</CreDtTm> <NbOfTxs>1</NbOfTxs> <SttlmInf> <SttlmMtd>INDA</SttlmMtd> </SttlmInf> </GrpHdr> <CdtTrfTxInf> <PmtId> <EndToEndId>IP-E2E-008</EndToEndId> </PmtId> <IntrBkSttlmAmt Ccy="USD">1000.00</IntrBkSttlmAmt> <ChrgBr>SHAR</ChrgBr> <UltmtDbtr> <Nm>IRON PINE</Nm> </UltmtDbtr> <Dbtr> <Nm>IRON PINE</Nm> </Dbtr> <DbtrAgt> <FinInstnId> <Nm>IRON PINE</Nm> </FinInstnId> </DbtrAgt> <CdtrAgt> <FinInstnId> <Nm>IRON PINE</Nm> </FinInstnId> </CdtrAgt> <Cdtr> <Nm>IRON PINE</Nm> </Cdtr> </CdtTrfTxInf> </FIToFICstmrCdtTrf> </Document> | F18: 2. Hệ thống sinh HIT tại xpath /Document/FIToFICstmrCdtTrf/CdtTrfTxInf/UltmtDbtr/Nm qua webservice NAME AND ADDRESS, khớp với danh sách WC. SELECT CASE WHEN COUNT(1) >= 1 THEN 'Pass' ELSE 'Fail' END sql_check FROM fsi_rt_xml_wls_response t WHERE n_grp_msg_id = :n_grp_msg_id AND V_MATCHED_LIST_REC_ID = 'nhập lại' AND n_webservice_id = 1 AND V_MATCHED_LIST_NAME = 'WC' AND regexp_replace(to_char(t.x_path), '\[\d+\]', '') LIKE '%' || regexp_replace('Document/FIToFICstmrCdtTrf/CdtTrfTxInf/UltmtDbtr/Nm', '\[\d+\]', '') || '%'; | H18: High | I18: Manual | J18: Failed | K18: Passed
A19: NAD.08 | B19: Sàng lọc điện trường hợp Xpath /Document/FIToFICstmrCdtTrf/GrpHdr/InstgAgt/BrnchId/Nm điện pacs.008.001.08 trùng với giá trị trường 'ALTERNATIVE SPELLING' trong danh sách WC | C19: 1. Điện được đẩy đúng format | D19: 1. Đẩy giao dịch vào API Post Message với Xpath điện pacs.008.001.08 2. Kiểm tra thông tin Event của giao dịch theo đường dẫn Financial Services Analytical Applications Transactions Filtering > Financial services Sanctions Pack > Transaction Filtering Alert List Chọn Filter, nhập thông tin tìm kiếm theo AlertID, nhấn <Search> Click mã AlertID và kiểm tra các thông tin Hoặc kiểm tra các thông tin trong file kết quả truy vấn Database | E19: <?xml version='1.0' encoding='UTF-8'?> <Document xmlns="urn:iso:std:iso:20022:tech:xsd:pacs.008.001.08"> <FIToFICstmrCdtTrf> <GrpHdr> <MsgId>GREENRIPPLE-MSG-008</MsgId> <CreDtTm>2026-07-28T13:31:41</CreDtTm> <NbOfTxs>1</NbOfTxs> <SttlmInf> <SttlmMtd>INDA</SttlmMtd> </SttlmInf> <InstgAgt> <FinInstnId> <BICFI>MSCBVNVX</BICFI> </FinInstnId> <BrnchId> <Nm>GREEN RIPPLE</Nm> </BrnchId> </InstgAgt> </GrpHdr> <CdtTrfTxInf> <PmtId> <EndToEndId>GR-E2E-008</EndToEndId> </PmtId> <IntrBkSttlmAmt Ccy="USD">1000.00</IntrBkSttlmAmt> <IntrBkSttlmDt>2026-07-28</IntrBkSttlmDt> <ChrgBr>SHAR</ChrgBr> <Dbtr> <Nm>VIET THANH IMPORT EXPORT JSC</Nm> </Dbtr> <DbtrAgt> <FinInstnId> <BICFI>MSCBVNVX</BICFI> </FinInstnId> </DbtrAgt> <CdtrAgt> <FinInstnId> <BICFI>SCBLSGSG</BICFI> </FinInstnId> </CdtrAgt> <Cdtr> <Nm>ORIENT PACIFIC TRADING PTE LTD</Nm> </Cdtr> </CdtTrfTxInf> </FIToFICstmrCdtTrf> </Document> | F19: 2. Hệ thống sinh HIT tại xpath /Document/FIToFICstmrCdtTrf/GrpHdr/InstgAgt/BrnchId/Nm qua webservice NAME AND ADDRESS, khớp với danh sách WC. SELECT CASE WHEN COUNT(1) >= 1 THEN 'Pass' ELSE 'Fail' END sql_check FROM fsi_rt_xml_wls_response t WHERE n_grp_msg_id = :n_grp_msg_id AND V_MATCHED_LIST_REC_ID = 'nhập lại' AND n_webservice_id = 1 AND V_MATCHED_LIST_NAME = 'WC' AND regexp_replace(to_char(t.x_path), '\[\d+\]', '') LIKE '%' || regexp_replace( 'Document/FIToFICstmrCdtTrf/GrpHdr/InstgAgt/BrnchId/Nm', '\[\d+\]', '' ) || '%'; | H19: High | I19: Manual | J19: Failed | K19: Passed
A20: NAD.17 | B20: Sàng lọc điện trường hợp Xpath /Document/FIToFICstmrCdtTrf/CdtTrfTxInf/UltmtDbtr/CtctDtls/Nm điện pacs.008.001.08 trùng với giá trị trường 'Họ và tên/Tên KHTC' trong danh sách AML | C20: 1. Điện được đẩy đúng format | D20: 1. Đẩy giao dịch vào API Post Message với Xpath điện pacs.008.001.08 2. Kiểm tra thông tin Event của giao dịch theo đường dẫn Financial Services Analytical Applications Transactions Filtering > Financial services Sanctions Pack > Transaction Filtering Alert List Chọn Filter, nhập thông tin tìm kiếm theo AlertID, nhấn <Search> Click mã AlertID và kiểm tra các thông tin Hoặc kiểm tra các thông tin trong file kết quả truy vấn Database | E20: <?xml version='1.0' encoding='UTF-8'?> <Document xmlns="urn:iso:std:iso:20022:tech:xsd:pacs.008.001.08"> <FIToFICstmrCdtTrf> <GrpHdr> <MsgId>MAITHUHA-MSG-008</MsgId> <CreDtTm>2026-07-28T13:31:41</CreDtTm> <NbOfTxs>1</NbOfTxs> <SttlmInf> <SttlmMtd>INDA</SttlmMtd> </SttlmInf> </GrpHdr> <CdtTrfTxInf> <PmtId> <EndToEndId>MTH-E2E-008</EndToEndId> </PmtId> <IntrBkSttlmAmt Ccy="USD">1000.00</IntrBkSttlmAmt> <ChrgBr>SHAR</ChrgBr> <UltmtDbtr> <CtctDtls> <Nm>MAI THU HA</Nm> </CtctDtls> </UltmtDbtr> <Dbtr> <Nm>MAI THU HA</Nm> </Dbtr> <DbtrAgt> <FinInstnId> <Nm>MAI THU HA</Nm> </FinInstnId> </DbtrAgt> <CdtrAgt> <FinInstnId> <Nm>MAI THU HA</Nm> </FinInstnId> </CdtrAgt> <Cdtr> <Nm>MAI THU HA</Nm> </Cdtr> </CdtTrfTxInf> </FIToFICstmrCdtTrf> </Document> | F20: 2. Hệ thống sinh HIT tại xpath /Document/FIToFICstmrCdtTrf/CdtTrfTxInf/UltmtDbtr/CtctDtls/Nm qua webservice NAME AND ADDRESS, khớp với danh sách WC. SELECT CASE WHEN COUNT(1) >= 1 THEN 'Pass' ELSE 'Fail' END sql_check FROM fsi_rt_xml_wls_response t WHERE n_grp_msg_id = :n_grp_msg_id AND V_MATCHED_LIST_REC_ID = 'nhập lại' AND n_webservice_id = 1 AND V_MATCHED_LIST_NAME = 'PRIV' AND t.V_MATCHED_SUBLIST_NAME = 'AML' AND regexp_replace(to_char(t.x_path), '\[[0-9]+\]', '') LIKE '%' || regexp_replace( 'Document/FIToFICstmrCdtTrf/CdtTrfTxInf/UltmtDbtr/CtctDtls/Nm', '\[[0-9]+\]', '' ) || '%'; | H20: High | I20: Manual | J20: Failed | K20: Passed
A21: NAD.18 | B21: Sàng lọc điện trường hợp Xpath /Document/FIToFICstmrCdtTrf/CdtTrfTxInf/UltmtCdtr/Nm điện pacs.008.001.08 trùng với giá trị trường 'Tên bí danh/tên tiếng anh/tên viết tắt' trong danh sách AML | C21: 1. Điện được đẩy đúng format | D21: 1. Đẩy giao dịch vào API Post Message với Xpath điện pacs.008.001.08 2. Kiểm tra thông tin Event của giao dịch theo đường dẫn Financial Services Analytical Applications Transactions Filtering > Financial services Sanctions Pack > Transaction Filtering Alert List Chọn Filter, nhập thông tin tìm kiếm theo AlertID, nhấn <Search> Click mã AlertID và kiểm tra các thông tin Hoặc kiểm tra các thông tin trong file kết quả truy vấn Database | E21: <?xml version='1.0' encoding='UTF-8'?> <Document xmlns="urn:iso:std:iso:20022:tech:xsd:pacs.008.001.08"> <FIToFICstmrCdtTrf> <GrpHdr> <MsgId>NAD17</MsgId> <CreDtTm>2026-07-28T13:31:41</CreDtTm> <NbOfTxs>1</NbOfTxs> <SttlmInf> <SttlmMtd>INDA</SttlmMtd> </SttlmInf> </GrpHdr> <CdtTrfTxInf> <PmtId> <EndToEndId>BL-E2E-008</EndToEndId> </PmtId> <IntrBkSttlmAmt Ccy="USD">1000.00</IntrBkSttlmAmt> <ChrgBr>SHAR</ChrgBr> <Dbtr> <Nm>A NGUYEN</Nm> </Dbtr> <DbtrAgt> <FinInstnId> <Nm>A NGUYEN</Nm> </FinInstnId> </DbtrAgt> <CdtrAgt> <FinInstnId> <Nm>A NGUYEN</Nm> </FinInstnId> </CdtrAgt> <Cdtr> <Nm>A NGUYEN</Nm> </Cdtr> <UltmtCdtr> <Nm>A NGUYEN</Nm> </UltmtCdtr> </CdtTrfTxInf> </FIToFICstmrCdtTrf> </Document> | F21: 2. Hệ thống sinh HIT tại xpath /Document/FIToFICstmrCdtTrf/CdtTrfTxInf/UltmtCdtr/Nm qua webservice NAME AND ADDRESS, khớp với danh sách AML. SELECT CASE WHEN COUNT(1) >= 1 THEN 'Pass' ELSE 'Fail' END sql_check FROM fsi_rt_xml_wls_response t WHERE n_grp_msg_id = :n_grp_msg_id AND V_MATCHED_LIST_REC_ID = 'nhập lại' AND n_webservice_id = 1 AND V_MATCHED_LIST_NAME = 'PRIV' AND t.V_MATCHED_SUBLIST_NAME = 'AML' AND regexp_replace(to_char(t.x_path), '\[[0-9]+\]', '') LIKE '%' || regexp_replace( 'Document/FIToFICstmrCdtTrf/CdtTrfTxInf/UltmtCdtr/Nm', '\[[0-9]+\]', '' ) || '%'; | H21: High | I21: Manual | J21: Failed | K21: Passed
A22: NAD.19 | B22: Sàng lọc điện trường hợp Xpath /Document/FIToFICstmrCdtTrf/CdtTrfTxInf/Dbtr/Nm điện pacs.008.001.08 trùng với giá trị trường 'Họ và tên' trong danh sách BCA | C22: 1. Điện được đẩy đúng format | D22: 1. Đẩy giao dịch vào API Post Message với Xpath điện pacs.008.001.08 2. Kiểm tra thông tin Event của giao dịch theo đường dẫn Financial Services Analytical Applications Transactions Filtering > Financial services Sanctions Pack > Transaction Filtering Alert List Chọn Filter, nhập thông tin tìm kiếm theo AlertID, nhấn <Search> Click mã AlertID và kiểm tra các thông tin Hoặc kiểm tra các thông tin trong file kết quả truy vấn Database | E22: <?xml version='1.0' encoding='UTF-8'?> <Document xmlns="urn:iso:std:iso:20022:tech:xsd:pacs.008.001.08"> <FIToFICstmrCdtTrf> <GrpHdr> <MsgId>DANGCONGQUAN-MSG-008</MsgId> <CreDtTm>2026-07-28T13:31:41</CreDtTm> <NbOfTxs>1</NbOfTxs> <SttlmInf> <SttlmMtd>INDA</SttlmMtd> </SttlmInf> </GrpHdr> <CdtTrfTxInf> <PmtId> <EndToEndId>DCQ-E2E-008</EndToEndId> </PmtId> <IntrBkSttlmAmt Ccy="USD">1000.00</IntrBkSttlmAmt> <ChrgBr>SHAR</ChrgBr> <UltmtDbtr> <CtctDtls> <Nm>DANG CONG QUAN</Nm> </CtctDtls> </UltmtDbtr> <Dbtr> <Nm>DANG CONG QUAN</Nm> </Dbtr> <DbtrAgt> <FinInstnId> <Nm>DANG CONG QUAN</Nm> </FinInstnId> </DbtrAgt> <CdtrAgt> <FinInstnId> <Nm>DANG CONG QUAN</Nm> </FinInstnId> </CdtrAgt> <Cdtr> <Nm>DANG CONG QUAN</Nm> </Cdtr> </CdtTrfTxInf> </FIToFICstmrCdtTrf> </Document> | F22: 2. Hệ thống sinh HIT tại xpath /Document/FIToFICstmrCdtTrf/CdtTrfTxInf/Dbtr/Nm qua webservice NAME AND ADDRESS, khớp với danh sách WC. SELECT CASE WHEN COUNT(1) >= 1 THEN 'Pass' ELSE 'Fail' END sql_check FROM fsi_rt_xml_wls_response t WHERE n_grp_msg_id = :n_grp_msg_id AND V_MATCHED_LIST_REC_ID = 'nhập lại' AND n_webservice_id = 1 AND V_MATCHED_LIST_NAME = 'PRIV' AND t.V_MATCHED_SUBLIST_NAME = 'BCA' AND regexp_replace(to_char(t.x_path), '\[[0-9]+\]', '') LIKE '%' || regexp_replace( 'Document/FIToFICstmrCdtTrf/CdtTrfTxInf/Dbtr/Nm', '\[[0-9]+\]', '' ) || '%'; | H22: High | I22: Manual | J22: Failed | K22: Passed
A23: NAD.20 | B23: Sàng lọc điện trường hợp Xpath /Document/FIToFICstmrCdtTrf/CdtTrfTxInf/InitgPty/Nm điện pacs.008.001.08 trùng với giá trị trường 'Tên bí danh/tên tiếng anh/tên viết tắt' trong danh sách BCA | C23: 1. Điện được đẩy đúng format | D23: 1. Đẩy giao dịch vào API Post Message với Xpath điện pacs.008.001.08 2. Kiểm tra thông tin Event của giao dịch theo đường dẫn Financial Services Analytical Applications Transactions Filtering > Financial services Sanctions Pack > Transaction Filtering Alert List Chọn Filter, nhập thông tin tìm kiếm theo AlertID, nhấn <Search> Click mã AlertID và kiểm tra các thông tin Hoặc kiểm tra các thông tin trong file kết quả truy vấn Database | E23: <?xml version='1.0' encoding='UTF-8'?> <Document xmlns="urn:iso:std:iso:20022:tech:xsd:pacs.008.001.08"> <FIToFICstmrCdtTrf> <GrpHdr> <MsgId>DAVIDDAT-MSG-008</MsgId> <CreDtTm>2026-07-28T13:31:41</CreDtTm> <NbOfTxs>1</NbOfTxs> <SttlmInf> <SttlmMtd>INDA</SttlmMtd> </SttlmInf> </GrpHdr> <CdtTrfTxInf> <PmtId> <EndToEndId>DD-E2E-008</EndToEndId> </PmtId> <IntrBkSttlmAmt Ccy="USD">1000.00</IntrBkSttlmAmt> <ChrgBr>SHAR</ChrgBr> <InitgPty> <Nm>DAVID DAT</Nm> </InitgPty> <Dbtr> <Nm>DAVID DAT</Nm> </Dbtr> <DbtrAgt> <FinInstnId> <Nm>DAVID DAT</Nm> </FinInstnId> </DbtrAgt> <CdtrAgt> <FinInstnId> <Nm>DAVID DAT</Nm> </FinInstnId> </CdtrAgt> <Cdtr> <Nm>DAVID DAT</Nm> </Cdtr> </CdtTrfTxInf> </FIToFICstmrCdtTrf> </Document> | F23: 2. Hệ thống sinh HIT tại xpath /Document/FIToFICstmrCdtTrf/CdtTrfTxInf/InitgPty/Nm qua webservice NAME AND ADDRESS, khớp với danh sách BCA. SELECT CASE WHEN COUNT(1) >= 1 THEN 'Pass' ELSE 'Fail' END sql_check FROM fsi_rt_xml_wls_response t WHERE n_grp_msg_id = :n_grp_msg_id AND V_MATCHED_LIST_REC_ID = 'nhập lại' AND n_webservice_id = 1 AND V_MATCHED_LIST_NAME = 'PRIV' AND t.V_MATCHED_SUBLIST_NAME = 'BCA' AND regexp_replace(to_char(t.x_path), '\[[0-9]+\]', '') LIKE '%' || regexp_replace( 'Document/FIToFICstmrCdtTrf/CdtTrfTxInf/InitgPty/Nm', '\[[0-9]+\]', '' ) || '%'; | H23: High | I23: Manual | J23: Failed | K23: Passed
B24: Webservice IDENTIFIER
A25: IDEN.01 | B25: Sàng lọc điện trường hợp dữ liệu xpath '/Document/FIToFICstmrCdtTrf/CdtTrfTxInf/Cdtr/Id/PrvtId/Othr/Id' điện pacs.008.001.08 trùng với giá trị trường 'PASSPORTS' trong danh sách WC | C25: 1. Điện được đẩy đúng format | D25: 1. Đẩy giao dịch vào API Post Message với trường thông tin '/Document/FIToFICstmrCdtTrf/CdtTrfTxInf/Cdtr/Id/PrvtId/Othr/Id' điện pacs.008.001.08 có dữ liệu nằm trong các danh sách theo dõi <Link URL hệ thống AML ở môi trường SIT> Path: transaction-screening/v1/transaction-screening Method: POST Request Header: Authorization: Basic Auth (Username and password to login to application) Content-Type: text/plain Accept: */* Request Body: cột Test Datas 2. Kiểm tra thông tin Event của giao dịch theo đường dẫn Financial Services Analytical Applications Transactions Filtering > Financial services Sanctions Pack > Transaction Filtering Alert List Chọn Filter, nhập thông tin tìm kiếm theo AlertID, nhấn <Search> Click mã AlertID và kiểm tra các thông tin Hoặc kiểm tra các thông tin trong file kết quả truy vấn Database | E25: <?xml version="1.0" encoding="UTF-8"?> <Document xmlns="urn:iso:std:iso:20022:tech:xsd:pacs.008.001.08"> <FIToFICstmrCdtTrf> <GrpHdr><MsgId>thucaseIDEN01</MsgId><CreDtTm>2026-07-24T09:15:00</CreDtTm><NbOfTxs>1</NbOfTxs> <SttlmInf><SttlmMtd>INDA</SttlmMtd></SttlmInf></GrpHdr> <CdtTrfTxInf> <PmtId><InstrId>MSBIDEN01</InstrId><EndToEndId>MSBIDEN01</EndToEndId><TxId>MSBIDEN01</TxId></PmtId> <IntrBkSttlmAmt Ccy="USD">25000.00</IntrBkSttlmAmt> <IntrBkSttlmDt>2026-07-24</IntrBkSttlmDt><ChrgBr>SHAR</ChrgBr> <Dbtr><Nm>VIET THANH IMPORT EXPORT JSC</Nm><PstlAdr><TwnNm>HANOI</TwnNm><Ctry>VN</Ctry></PstlAdr></Dbtr> <DbtrAcct><Id><Othr><Id>0011000123456</Id></Othr></Id></DbtrAcct> <DbtrAgt><FinInstnId><BICFI>MSCBVNVX</BICFI></FinInstnId></DbtrAgt> <CdtrAgt><FinInstnId><BICFI>SCBLSGSG</BICFI></FinInstnId></CdtrAgt> <Cdtr><Nm>ORIENT PACIFIC TRADING PTE LTD</Nm> <PstlAdr><TwnNm>SINGAPORE</TwnNm><Ctry>SG</Ctry></PstlAdr> <Id><PrvtId><Othr><Id>MP4274241</Id><SchmeNm><Cd>CCPT</Cd></SchmeNm></Othr></PrvtId></Id></Cdtr> <CdtrAcct><Id><Othr><Id>7788990011</Id></Othr></Id></CdtrAcct> <RmtInf><Ustrd>PAYMENT FOR INVOICE INV-2026-0714</Ustrd></RmtInf> </CdtTrfTxInf> </FIToFICstmrCdtTrf> </Document> | F25: 2. Hệ thống sinh HIT tại xpath '/Document/FIToFICstmrCdtTrf/CdtTrfTxInf/Cdtr/Id/PrvtId/Othr/Id' qua webservice IDENTIFIER, khớp với danh sách WC Câu query kiểm tra kết quả (KET_QUA = Pass): SELECT CASE WHEN COUNT(1) >= 1 THEN 'Pass' ELSE 'Fail' END sql_check FROM fsi_rt_xml_wls_response t WHERE n_grp_msg_id = :n_grp_msg_id AND V_MATCHED_LIST_REC_ID = 'nhập lại' AND n_webservice_id = 2 AND V_MATCHED_LIST_NAME = 'WC' AND regexp_replace(to_char(t.x_path), '\[\d+\]', '') LIKE '%' || regexp_replace('Document/FIToFICstmrCdtTrf/CdtTrfTxInf/Cdtr/Id/PrvtId/Othr/Id', '\[\d+\]', '') || '%'; | H25: High | I25: Manual | J25: Failed | K25: Passed | M25: V_MATCHED_LIST_NAME đang bị map thành loại khách hàng
A26: IDEN.02 | B26: Sàng lọc điện trường hợp dữ liệu xpath '/Document/FIToFICstmrCdtTrf/GrpHdr/InstgAgt/FinInstnId/Othr/Id' điện pacs.008.001.08 trùng với giá trị trường 'SSN' trong danh sách WC | C26: 1. Điện được đẩy đúng format | D26: 1. Đẩy giao dịch vào API Post Message với trường thông tin '/Document/FIToFICstmrCdtTrf/CdtTrfTxInf/Cdtr/Id/PrvtId/Othr/Id' điện pacs.008.001.08 có dữ liệu nằm trong các danh sách theo dõi <Link URL hệ thống AML ở môi trường SIT> Path: transaction-screening/v1/transaction-screening Method: POST Request Header: Authorization: Basic Auth (Username and password to login to application) Content-Type: text/plain Accept: */* Request Body: cột Test Datas 2. Kiểm tra thông tin Event của giao dịch theo đường dẫn Financial Services Analytical Applications Transactions Filtering > Financial services Sanctions Pack > Transaction Filtering Alert List Chọn Filter, nhập thông tin tìm kiếm theo AlertID, nhấn <Search> Click mã AlertID và kiểm tra các thông tin Hoặc kiểm tra các thông tin trong file kết quả truy vấn Database | E26: <?xml version="1.0" encoding="UTF-8"?> <Document xmlns="urn:iso:std:iso:20022:tech:xsd:pacs.008.001.08"> <FIToFICstmrCdtTrf> <GrpHdr><MsgId>MSBIDEN02</MsgId><CreDtTm>2026-07-24T09:15:00</CreDtTm><NbOfTxs>1</NbOfTxs> <SttlmInf><SttlmMtd>INDA</SttlmMtd></SttlmInf> <InstgAgt><FinInstnId><Othr><Id>MSCBVNVX</Id></Othr></FinInstnId></InstgAgt></GrpHdr> <CdtTrfTxInf> <PmtId><InstrId>MSBIDEN02</InstrId><EndToEndId>MSBIDEN02</EndToEndId><TxId>MSBIDEN02</TxId></PmtId> <IntrBkSttlmAmt Ccy="USD">25000.00</IntrBkSttlmAmt> <IntrBkSttlmDt>2026-07-24</IntrBkSttlmDt><ChrgBr>SHAR</ChrgBr> <Dbtr><Nm>VIET THANH IMPORT EXPORT JSC</Nm><PstlAdr><TwnNm>HANOI</TwnNm><Ctry>VN</Ctry></PstlAdr></Dbtr> <DbtrAcct><Id><Othr><Id>0011000123456</Id></Othr></Id></DbtrAcct> <DbtrAgt><FinInstnId><BICFI>MSCBVNVX</BICFI></FinInstnId></DbtrAgt> <CdtrAgt><FinInstnId><BICFI>SCBLSGSG</BICFI></FinInstnId></CdtrAgt> <Cdtr><Nm>ORIENT PACIFIC TRADING PTE LTD</Nm> <PstlAdr><TwnNm>SINGAPORE</TwnNm><Ctry>SG</Ctry></PstlAdr> <Id><PrvtId><Othr><Id>123-45-6789</Id><SchmeNm><Cd>SOSE</Cd></SchmeNm></Othr></PrvtId></Id></Cdtr> <CdtrAcct><Id><Othr><Id>7788990011</Id></Othr></Id></CdtrAcct> <RmtInf><Ustrd>PAYMENT FOR INVOICE INV-2026-0714</Ustrd></RmtInf> </CdtTrfTxInf> </FIToFICstmrCdtTrf> </Document> | F26: 2. Hệ thống sinh HIT tại xpath'/Document/FIToFICstmrCdtTrf/GrpHdr/InstgAgt/FinInstnId/Othr/Id' qua webservice IDENTIFIER, khớp với danh sách WC Câu query kiểm tra kết quả (KET_QUA = Pass): SELECT CASE WHEN COUNT(1) >= 1 THEN 'Pass' ELSE 'Fail' END sql_check FROM fsi_rt_xml_wls_response t WHERE n_grp_msg_id = :n_grp_msg_id AND V_MATCHED_LIST_REC_ID = 'nhập lại' AND n_webservice_id = 2 AND V_MATCHED_LIST_NAME = 'WC' AND regexp_replace(to_char(t.x_path), '\[\d+\]', '') LIKE '%' || regexp_replace('Document/FIToFICstmrCdtTrf/GrpHdr/InstgAgt/FinInstnId/Othr/Id', '\[\d+\]', '') || '%'; | H26: High | I26: Manual | J26: Failed | K26: Passed
A27: IDEN.03 | B27: Sàng lọc điện trường hợp dữ liệu xpath '/Document/FIToFICstmrCdtTrf/GrpHdr/InstgAgt/FinInstnId/Othr/Id' điện pacs.008.001.08 trùng với giá trị trường 'IDENTIFICATION NUMBERS' trong danh sách WC | C27: 1. Điện được đẩy đúng format | D27: 1. Đẩy giao dịch vào API Post Message với trường thông tin '/Document/FIToFICstmrCdtTrf/GrpHdr/InstgAgt/FinInstnId/Othr/Id' điện pacs.008.001.08 có dữ liệu nằm trong các danh sách theo dõi <Link URL hệ thống AML ở môi trường SIT> Path: transaction-screening/v1/transaction-screening Method: POST Request Header: Authorization: Basic Auth (Username and password to login to application) Content-Type: text/plain Accept: */* Request Body: cột Test Datas 2. Kiểm tra thông tin Event của giao dịch theo đường dẫn Financial Services Analytical Applications Transactions Filtering > Financial services Sanctions Pack > Transaction Filtering Alert List Chọn Filter, nhập thông tin tìm kiếm theo AlertID, nhấn <Search> Click mã AlertID và kiểm tra các thông tin Hoặc kiểm tra các thông tin trong file kết quả truy vấn Database | E27: <?xml version="1.0" encoding="UTF-8"?> <Document xmlns="urn:iso:std:iso:20022:tech:xsd:pacs.008.001.08"> <FIToFICstmrCdtTrf> <GrpHdr><MsgId>MSBIDEN03</MsgId><CreDtTm>2026-07-24T09:15:00</CreDtTm><NbOfTxs>1</NbOfTxs> <SttlmInf><SttlmMtd>INDA</SttlmMtd></SttlmInf> <InstgAgt><FinInstnId><Othr><Id>0099887766</Id></Othr></FinInstnId></InstgAgt> </GrpHdr> <CdtTrfTxInf> <PmtId><InstrId>MSBIDEN03</InstrId><EndToEndId>MSBIDEN03</EndToEndId><TxId>MSBIDEN03</TxId></PmtId> <IntrBkSttlmAmt Ccy="USD">25000.00</IntrBkSttlmAmt> <IntrBkSttlmDt>2026-07-24</IntrBkSttlmDt><ChrgBr>SHAR</ChrgBr> <Dbtr><Nm>VIET THANH IMPORT EXPORT JSC</Nm></Dbtr> <DbtrAgt><FinInstnId/></DbtrAgt> <CdtrAgt><FinInstnId/></CdtrAgt> <Cdtr><Nm>ORIENT PACIFIC TRADING PTE LTD</Nm></Cdtr> </CdtTrfTxInf> </FIToFICstmrCdtTrf> </Document> | F27: 2. Hệ thống sinh HIT tại xpath'/Document/FIToFICstmrCdtTrf/GrpHdr/InstgAgt/FinInstnId/Othr/Id' qua webservice IDENTIFIER, khớp với danh sách WC Câu query kiểm tra kết quả (KET_QUA = Pass): SELECT CASE WHEN COUNT(1) >= 1 THEN 'Pass' ELSE 'Fail' END sql_check FROM fsi_rt_xml_wls_response t WHERE n_grp_msg_id = :n_grp_msg_id AND V_MATCHED_LIST_REC_ID = 'nhập lại' AND n_webservice_id = 2 AND V_MATCHED_LIST_NAME = 'WC' AND regexp_replace(to_char(t.x_path), '\[\d+\]', '') LIKE '%' || regexp_replace('Document/FIToFICstmrCdtTrf/GrpHdr/InstgAgt/FinInstnId/Othr/Id', '\[\d+\]', '') || '%'; | H27: High | I27: Manual | J27: Failed | K27: Passed
A28: IDEN.04 | B28: Sàng lọc điện trường hợp dữ liệu xpath '/Document/FIToFICstmrCdtTrf/CdtTrfTxInf/Cdtr/Id/PrvtId/Othr/Id' điện pacs.008.001.08 trùng với giá trị trường 'CC/Thẻ CC' trong danh sách AML | C28: 1. Điện được đẩy đúng format | D28: 1. Đẩy giao dịch vào API Post Message với trường thông tin '/Document/FIToFICstmrCdtTrf/CdtTrfTxInf/Cdtr/Id/PrvtId/Othr/Id' điện pacs.008.001.08 có dữ liệu nằm trong các danh sách theo dõi <Link URL hệ thống AML ở môi trường SIT> Path: transaction-screening/v1/transaction-screening Method: POST Request Header: Authorization: Basic Auth (Username and password to login to application) Content-Type: text/plain Accept: */* Request Body: cột Test Datas 2. Kiểm tra thông tin Event của giao dịch theo đường dẫn Financial Services Analytical Applications Transactions Filtering > Financial services Sanctions Pack > Transaction Filtering Alert List Chọn Filter, nhập thông tin tìm kiếm theo AlertID, nhấn <Search> Click mã AlertID và kiểm tra các thông tin Hoặc kiểm tra các thông tin trong file kết quả truy vấn Database | E28: <?xml version="1.0" encoding="UTF-8"?> <Document xmlns="urn:iso:std:iso:20022:tech:xsd:pacs.008.001.08"> <FIToFICstmrCdtTrf> <GrpHdr><MsgId>MSBIDEN04</MsgId><CreDtTm>2026-07-24T09:15:00</CreDtTm><NbOfTxs>1</NbOfTxs> <SttlmInf><SttlmMtd>INDA</SttlmMtd></SttlmInf></GrpHdr> <CdtTrfTxInf> <PmtId><InstrId>MSBIDEN04</InstrId><EndToEndId>MSBIDEN04</EndToEndId><TxId>MSBIDEN04</TxId></PmtId> <IntrBkSttlmAmt Ccy="USD">25000.00</IntrBkSttlmAmt> <IntrBkSttlmDt>2026-07-24</IntrBkSttlmDt><ChrgBr>SHAR</ChrgBr> <Dbtr><Nm>VIET THANH IMPORT EXPORT JSC</Nm><PstlAdr><TwnNm>HANOI</TwnNm><Ctry>VN</Ctry></PstlAdr></Dbtr> <DbtrAcct><Id><Othr><Id>079173453008</Id></Othr></Id></DbtrAcct> <DbtrAgt><FinInstnId><BICFI>MSCBVNVX</BICFI></FinInstnId></DbtrAgt> <CdtrAgt><FinInstnId><BICFI>SCBLSGSG</BICFI></FinInstnId></CdtrAgt> <Cdtr><Nm>ORIENT PACIFIC TRADING PTE LTD</Nm> <PstlAdr><TwnNm>SINGAPORE</TwnNm><Ctry>SG</Ctry></PstlAdr> <Id><PrvtId><Othr><Id>079173453008</Id><SchmeNm><Cd>NIDN</Cd></SchmeNm></Othr></PrvtId></Id></Cdtr> <CdtrAcct><Id><Othr><Id>7788990011</Id></Othr></Id></CdtrAcct> <RmtInf><Ustrd>PAYMENT FOR INVOICE INV-2026-0714</Ustrd></RmtInf> </CdtTrfTxInf> </FIToFICstmrCdtTrf> </Document> | F28: 2. Hệ thống sinh HIT tại xpath '/Document/FIToFICstmrCdtTrf/CdtTrfTxInf/Cdtr/Id/PrvtId/Othr/Id' qua webservice IDENTIFIER, khớp với danh sách "AML" Câu query kiểm tra kết quả (KET_QUA = Pass): SELECT CASE WHEN COUNT(1) >= 1 THEN 'Pass' ELSE 'Fail' END sql_check FROM fsi_rt_xml_wls_response t WHERE n_grp_msg_id = :n_grp_msg_id AND V_MATCHED_LIST_REC_ID = 'nhập lại' AND n_webservice_id = 2 AND V_MATCHED_SUBLIST_NAME = 'AML' AND regexp_replace(to_char(t.x_path), '\[\d+\]', '') LIKE '%' || regexp_replace('Document/FIToFICstmrCdtTrf/CdtTrfTxInf/Cdtr/Id/PrvtId/Othr/Id', '\[\d+\]', '') || '%'; | H28: High | I28: Manual | J28: Failed | K28: Passed
A29: IDEN.05 | B29: Sàng lọc điện trường hợp dữ liệu xpath '/Document/FIToFICstmrCdtTrf/CdtTrfTxInf/Cdtr/Id/PrvtId/Othr/Id' điện pacs.008.001.08 trùng với giá trị trường 'CMND/CMT' trong danh sách AML | C29: 1. Điện được đẩy đúng format | D29: 1. Đẩy giao dịch vào API Post Message với trường thông tin '/Document/FIToFICstmrCdtTrf/CdtTrfTxInf/Cdtr/Id/PrvtId/Othr/Id' điện pacs.008.001.08 có dữ liệu nằm trong các danh sách theo dõi <Link URL hệ thống AML ở môi trường SIT> Path: transaction-screening/v1/transaction-screening Method: POST Request Header: Authorization: Basic Auth (Username and password to login to application) Content-Type: text/plain Accept: */* Request Body: cột Test Datas 2. Kiểm tra thông tin Event của giao dịch theo đường dẫn Financial Services Analytical Applications Transactions Filtering > Financial services Sanctions Pack > Transaction Filtering Alert List Chọn Filter, nhập thông tin tìm kiếm theo AlertID, nhấn <Search> Click mã AlertID và kiểm tra các thông tin Hoặc kiểm tra các thông tin trong file kết quả truy vấn Database | E29: <?xml version="1.0" encoding="UTF-8"?> <Document xmlns="urn:iso:std:iso:20022:tech:xsd:pacs.008.001.08"> <FIToFICstmrCdtTrf> <GrpHdr><MsgId>MSBIDEN05</MsgId><CreDtTm>2026-07-24T09:15:00</CreDtTm><NbOfTxs>1</NbOfTxs> <SttlmInf><SttlmMtd>INDA</SttlmMtd></SttlmInf></GrpHdr> <CdtTrfTxInf> <PmtId><InstrId>MSBIDEN05</InstrId><EndToEndId>MSBIDEN05</EndToEndId><TxId>MSBIDEN05</TxId></PmtId> <IntrBkSttlmAmt Ccy="USD">25000.00</IntrBkSttlmAmt> <IntrBkSttlmDt>2026-07-24</IntrBkSttlmDt><ChrgBr>SHAR</ChrgBr> <Dbtr><Nm>VIET THANH IMPORT EXPORT JSC</Nm><PstlAdr><TwnNm>HANOI</TwnNm><Ctry>VN</Ctry></PstlAdr></Dbtr> <DbtrAcct><Id><Othr><Id>120029276</Id></Othr></Id></DbtrAcct> <DbtrAgt><FinInstnId><BICFI>MSCBVNVX</BICFI></FinInstnId></DbtrAgt> <CdtrAgt><FinInstnId><BICFI>SCBLSGSG</BICFI></FinInstnId></CdtrAgt> <Cdtr><Nm>ORIENT PACIFIC TRADING PTE LTD</Nm> <PstlAdr><TwnNm>SINGAPORE</TwnNm><Ctry>SG</Ctry></PstlAdr> <Id><PrvtId><Othr><Id>025004858</Id><SchmeNm><Cd>NIDN</Cd></SchmeNm></Othr></PrvtId></Id></Cdtr> <CdtrAcct><Id><Othr><Id>7788990011</Id></Othr></Id></CdtrAcct> <RmtInf><Ustrd>PAYMENT FOR INVOICE INV-2026-0714</Ustrd></RmtInf> </CdtTrfTxInf> </FIToFICstmrCdtTrf> </Document> | F29: 2. Hệ thống sinh HIT tại xpath '/Document/FIToFICstmrCdtTrf/CdtTrfTxInf/Cdtr/Id/PrvtId/Othr/Id' qua webservice IDENTIFIER, khớp với danh sách "AML" Câu query kiểm tra kết quả (KET_QUA = Pass): SELECT CASE WHEN COUNT(1) >= 1 THEN 'Pass' ELSE 'Fail' END sql_check FROM fsi_rt_xml_wls_response t WHERE n_grp_msg_id = :n_grp_msg_id AND V_MATCHED_LIST_REC_ID = 'nhập lại' AND n_webservice_id = 2 AND V_MATCHED_SUBLIST_NAME = 'AML' AND regexp_replace(to_char(t.x_path), '\[\d+\]', '') LIKE '%' || regexp_replace('Document/FIToFICstmrCdtTrf/CdtTrfTxInf/Cdtr/Id/PrvtId/Othr/Id', '\[\d+\]', '') || '%'; | H29: High | I29: Manual | J29: Failed | K29: Passed
A30: IDEN.06 | B30: Sàng lọc điện trường hợp dữ liệu xpath '/Document/FIToFICstmrCdtTrf/GrpHdr/InstgAgt/FinInstnId/Othr/Id' điện pacs.008.001.08 trùng với giá trị trường 'GPTL/MSDN/MST' trong danh sách AML | C30: 1. Điện được đẩy đúng format | D30: 1. Đẩy giao dịch vào API Post Message với trường thông tin '/Document/FIToFICstmrCdtTrf/GrpHdr/InstgAgt/FinInstnId/Othr/Id' điện pacs.008.001.08 có dữ liệu nằm trong các danh sách theo dõi <Link URL hệ thống AML ở môi trường SIT> Path: transaction-screening/v1/transaction-screening Method: POST Request Header: Authorization: Basic Auth (Username and password to login to application) Content-Type: text/plain Accept: */* Request Body: cột Test Datas 2. Kiểm tra thông tin Event của giao dịch theo đường dẫn Financial Services Analytical Applications Transactions Filtering > Financial services Sanctions Pack > Transaction Filtering Alert List Chọn Filter, nhập thông tin tìm kiếm theo AlertID, nhấn <Search> Click mã AlertID và kiểm tra các thông tin Hoặc kiểm tra các thông tin trong file kết quả truy vấn Database | E30: <?xml version="1.0" encoding="UTF-8"?> <Document xmlns="urn:iso:std:iso:20022:tech:xsd:pacs.008.001.08"> <FIToFICstmrCdtTrf> <GrpHdr><MsgId>MSBIDEN06</MsgId><CreDtTm>2026-07-24T09:15:00</CreDtTm><NbOfTxs>1</NbOfTxs> <SttlmInf><SttlmMtd>INDA</SttlmMtd></SttlmInf> <InstgAgt><FinInstnId><Othr><Id>9473331817</Id></Othr></FinInstnId></InstgAgt></GrpHdr> <CdtTrfTxInf> <PmtId><InstrId>MSBIDEN06</InstrId><EndToEndId>MSBIDEN06</EndToEndId><TxId>MSBIDEN06</TxId></PmtId> <IntrBkSttlmAmt Ccy="USD">25000.00</IntrBkSttlmAmt> <IntrBkSttlmDt>2026-07-24</IntrBkSttlmDt><ChrgBr>SHAR</ChrgBr> <Dbtr><Nm>VIET THANH IMPORT EXPORT JSC</Nm><PstlAdr><TwnNm>HANOI</TwnNm><Ctry>VN</Ctry></PstlAdr></Dbtr> <DbtrAcct><Id><Othr><Id>2003558140</Id></Othr></Id></DbtrAcct> <DbtrAgt><FinInstnId><BICFI>MSCBVNVX</BICFI></FinInstnId></DbtrAgt> <CdtrAgt><FinInstnId><BICFI>SCBLSGSG</BICFI></FinInstnId></CdtrAgt> <Cdtr><Nm>ORIENT PACIFIC TRADING PTE LTD</Nm> <PstlAdr><TwnNm>SINGAPORE</TwnNm><Ctry>SG</Ctry></PstlAdr> <Id><PrvtId><Othr><Id>025004858</Id><SchmeNm><Cd>NIDN</Cd></SchmeNm></Othr></PrvtId></Id></Cdtr> <CdtrAcct><Id><Othr><Id>9473331817</Id></Othr></Id></CdtrAcct> <RmtInf><Ustrd>PAYMENT FOR INVOICE INV-2026-0714</Ustrd></RmtInf> </CdtTrfTxInf> </FIToFICstmrCdtTrf> </Document> | F30: 2. Hệ thống sinh HIT tại xpath'/Document/FIToFICstmrCdtTrf/GrpHdr/InstgAgt/FinInstnId/Othr/Id' qua webservice IDENTIFIER, khớp với danh sách "AML" Câu query kiểm tra kết quả (KET_QUA = Pass): SELECT CASE WHEN COUNT(1) >= 1 THEN 'Pass' ELSE 'Fail' END sql_check FROM fsi_rt_xml_wls_response t WHERE n_grp_msg_id = :n_grp_msg_id AND V_MATCHED_LIST_REC_ID = 'nhập lại' AND n_webservice_id = 2 AND V_MATCHED_SUBLIST_NAME = 'AML' AND regexp_replace(to_char(t.x_path), '\[\d+\]', '') LIKE '%' || regexp_replace('Document/FIToFICstmrCdtTrf/GrpHdr/InstgAgt/FinInstnId/Othr/Id', '\[\d+\]', '') || '%'; | H30: High | I30: Manual | J30: Failed | K30: Passed
A31: IDEN.07 | B31: Sàng lọc điện trường hợp dữ liệu xpath '/Document/FIToFICstmrCdtTrf/GrpHdr/InstgAgt/FinInstnId/Othr/Id' điện pacs.008.001.08 trùng với giá trị trường 'DKKD' trong danh sách AML | C31: 1. Điện được đẩy đúng format | D31: 1. Đẩy giao dịch vào API Post Message với trường thông tin '/Document/FIToFICstmrCdtTrf/GrpHdr/InstgAgt/FinInstnId/Othr/Id' điện pacs.008.001.08 có dữ liệu nằm trong các danh sách theo dõi <Link URL hệ thống AML ở môi trường SIT> Path: transaction-screening/v1/transaction-screening Method: POST Request Header: Authorization: Basic Auth (Username and password to login to application) Content-Type: text/plain Accept: */* Request Body: cột Test Datas 2. Kiểm tra thông tin Event của giao dịch theo đường dẫn Financial Services Analytical Applications Transactions Filtering > Financial services Sanctions Pack > Transaction Filtering Alert List Chọn Filter, nhập thông tin tìm kiếm theo AlertID, nhấn <Search> Click mã AlertID và kiểm tra các thông tin Hoặc kiểm tra các thông tin trong file kết quả truy vấn Database | E31: <?xml version="1.0" encoding="UTF-8"?> <Document xmlns="urn:iso:std:iso:20022:tech:xsd:pacs.008.001.08"> <FIToFICstmrCdtTrf> <GrpHdr><MsgId>MSBIDEN07</MsgId><CreDtTm>2026-07-24T09:15:00</CreDtTm><NbOfTxs>1</NbOfTxs> <SttlmInf><SttlmMtd>INDA</SttlmMtd></SttlmInf> <InstgAgt><FinInstnId><Othr><Id>2817292918</Id></Othr></FinInstnId></InstgAgt></GrpHdr> <CdtTrfTxInf> <PmtId><InstrId>MSBIDEN07</InstrId><EndToEndId>MSBIDEN07</EndToEndId><TxId>MSBIDEN07</TxId></PmtId> <IntrBkSttlmAmt Ccy="USD">25000.00</IntrBkSttlmAmt> <IntrBkSttlmDt>2026-07-24</IntrBkSttlmDt><ChrgBr>SHAR</ChrgBr> <Dbtr><Nm>VIET THANH IMPORT EXPORT JSC</Nm><PstlAdr><TwnNm>HANOI</TwnNm><Ctry>VN</Ctry></PstlAdr></Dbtr> <DbtrAcct><Id><Othr><Id>2003558140</Id></Othr></Id></DbtrAcct> <DbtrAgt><FinInstnId><BICFI>MSCBVNVX</BICFI></FinInstnId></DbtrAgt> <CdtrAgt><FinInstnId><BICFI>SCBLSGSG</BICFI></FinInstnId></CdtrAgt> <Cdtr><Nm>ORIENT PACIFIC TRADING PTE LTD</Nm> <PstlAdr><TwnNm>SINGAPORE</TwnNm><Ctry>SG</Ctry></PstlAdr> <Id><PrvtId><Othr><Id>025004858</Id><SchmeNm><Cd>NIDN</Cd></SchmeNm></Othr></PrvtId></Id></Cdtr> <CdtrAcct><Id><Othr><Id>2817292918</Id></Othr></Id></CdtrAcct> <RmtInf><Ustrd>PAYMENT FOR INVOICE INV-2026-0714</Ustrd></RmtInf> </CdtTrfTxInf> </FIToFICstmrCdtTrf> </Document> | F31: 2. Hệ thống sinh HIT tại xpath'/Document/FIToFICstmrCdtTrf/GrpHdr/InstgAgt/FinInstnId/Othr/Id' qua webservice IDENTIFIER, khớp với danh sách "AML" Câu query kiểm tra kết quả (KET_QUA = Pass): SELECT CASE WHEN COUNT(1) >= 1 THEN 'Pass' ELSE 'Fail' END sql_check FROM fsi_rt_xml_wls_response t WHERE n_grp_msg_id = :n_grp_msg_id AND V_MATCHED_LIST_REC_ID = 'nhập lại' AND n_webservice_id = 2 AND V_MATCHED_SUBLIST_NAME = 'AML' AND regexp_replace(to_char(t.x_path), '\[\d+\]', '') LIKE '%' || regexp_replace('Document/FIToFICstmrCdtTrf/GrpHdr/InstgAgt/FinInstnId/Othr/Id', '\[\d+\]', '') || '%'; | H31: High | I31: Manual | J31: Failed | K31: Passed
A32: IDEN.08 | B32: Sàng lọc điện trường hợp dữ liệu xpath '/Document/FIToFICstmrCdtTrf/CdtTrfTxInf/Cdtr/Id/PrvtId/Othr/Id' điện pacs.008.001.08 trùng với giá trị trường 'GTTT khác 1' trong danh sách AML | C32: 1. Điện được đẩy đúng format | D32: 1. Đẩy giao dịch vào API Post Message với trường thông tin '/Document/FIToFICstmrCdtTrf/CdtTrfTxInf/Cdtr/Id/PrvtId/Othr/Id' điện pacs.008.001.08 có dữ liệu nằm trong các danh sách theo dõi <Link URL hệ thống AML ở môi trường SIT> Path: transaction-screening/v1/transaction-screening Method: POST Request Header: Authorization: Basic Auth (Username and password to login to application) Content-Type: text/plain Accept: */* Request Body: cột Test Datas 2. Kiểm tra thông tin Event của giao dịch theo đường dẫn Financial Services Analytical Applications Transactions Filtering > Financial services Sanctions Pack > Transaction Filtering Alert List Chọn Filter, nhập thông tin tìm kiếm theo AlertID, nhấn <Search> Click mã AlertID và kiểm tra các thông tin Hoặc kiểm tra các thông tin trong file kết quả truy vấn Database | E32: <?xml version="1.0" encoding="UTF-8"?> <Document xmlns="urn:iso:std:iso:20022:tech:xsd:pacs.008.001.08"> <FIToFICstmrCdtTrf> <GrpHdr><MsgId>MSBIDEN08</MsgId><CreDtTm>2026-07-24T09:15:00</CreDtTm><NbOfTxs>1</NbOfTxs> <SttlmInf><SttlmMtd>INDA</SttlmMtd></SttlmInf></GrpHdr> <CdtTrfTxInf> <PmtId><InstrId>MSBIDEN08</InstrId><EndToEndId>MSBIDEN10</EndToEndId><TxId>MSBIDEN08</TxId></PmtId> <IntrBkSttlmAmt Ccy="USD">25000.00</IntrBkSttlmAmt> <IntrBkSttlmDt>2026-07-24</IntrBkSttlmDt><ChrgBr>SHAR</ChrgBr> <Dbtr><Nm>VIET THANH IMPORT EXPORT JSC</Nm><PstlAdr><TwnNm>HANOI</TwnNm><Ctry>VN</Ctry></PstlAdr></Dbtr> <DbtrAcct><Id><Othr><Id>0011000123456</Id></Othr></Id></DbtrAcct> <DbtrAgt><FinInstnId><BICFI>MSCBVNVX</BICFI></FinInstnId></DbtrAgt> <CdtrAgt><FinInstnId><BICFI>SCBLSGSG</BICFI></FinInstnId></CdtrAgt> <Cdtr><Nm>ORIENT PACIFIC TRADING PTE LTD</Nm> <PstlAdr><TwnNm>SINGAPORE</TwnNm><Ctry>SG</Ctry></PstlAdr> <Id><PrvtId><Othr><Id>HC96865049</Id><SchmeNm><Cd>NIDN</Cd></SchmeNm></Othr></PrvtId></Id></Cdtr> <CdtrAcct><Id><Othr><Id>7788990011</Id></Othr></Id></CdtrAcct> <RmtInf><Ustrd>PAYMENT FOR INVOICE INV-2026-0714</Ustrd></RmtInf> </CdtTrfTxInf> </FIToFICstmrCdtTrf> </Document> | F32: 2. Hệ thống sinh HIT tại xpath'/Document/FIToFICstmrCdtTrf/CdtTrfTxInf/Cdtr/Id/PrvtId/Othr/Id' qua webservice IDENTIFIER, khớp với danh sách "AML" Câu query kiểm tra kết quả (KET_QUA = Pass): SELECT CASE WHEN COUNT(1) >= 1 THEN 'Pass' ELSE 'Fail' END sql_check FROM fsi_rt_xml_wls_response t WHERE n_grp_msg_id = :n_grp_msg_id AND V_MATCHED_LIST_REC_ID = 'nhập lại' AND n_webservice_id = 2 AND V_MATCHED_SUBLIST_NAME = 'AML' AND regexp_replace(to_char(t.x_path), '\[\d+\]', '') LIKE '%' || regexp_replace('Document/FIToFICstmrCdtTrf/CdtTrfTxInf/Cdtr/Id/PrvtId/Othr/Id', '\[\d+\]', '') || '%'; | H32: High | I32: Manual | J32: Failed | K32: Passed
A33: IDEN.09 | B33: Sàng lọc điện trường hợp dữ liệu xpath '/Document/FIToFICstmrCdtTrf/CdtTrfTxInf/Cdtr/Id/PrvtId/Othr/Id' điện pacs.008.001.08 trùng với giá trị trường 'GTTT khác 2' trong danh sách AML | C33: 1. Điện được đẩy đúng format | D33: 1. Đẩy giao dịch vào API Post Message với trường thông tin '/Document/FIToFICstmrCdtTrf/CdtTrfTxInf/Cdtr/Id/PrvtId/Othr/Id' điện pacs.008.001.08 có dữ liệu nằm trong các danh sách theo dõi <Link URL hệ thống AML ở môi trường SIT> Path: transaction-screening/v1/transaction-screening Method: POST Request Header: Authorization: Basic Auth (Username and password to login to application) Content-Type: text/plain Accept: */* Request Body: cột Test Datas 2. Kiểm tra thông tin Event của giao dịch theo đường dẫn Financial Services Analytical Applications Transactions Filtering > Financial services Sanctions Pack > Transaction Filtering Alert List Chọn Filter, nhập thông tin tìm kiếm theo AlertID, nhấn <Search> Click mã AlertID và kiểm tra các thông tin Hoặc kiểm tra các thông tin trong file kết quả truy vấn Database | E33: <?xml version="1.0" encoding="UTF-8"?> <Document xmlns="urn:iso:std:iso:20022:tech:xsd:pacs.008.001.08"> <FIToFICstmrCdtTrf> <GrpHdr><MsgId>MSBIDEN09</MsgId><CreDtTm>2026-07-24T09:15:00</CreDtTm><NbOfTxs>1</NbOfTxs> <SttlmInf><SttlmMtd>INDA</SttlmMtd></SttlmInf></GrpHdr> <CdtTrfTxInf> <PmtId><InstrId>MSBIDEN09</InstrId><EndToEndId>MSBIDEN09</EndToEndId><TxId>MSBIDEN09</TxId></PmtId> <IntrBkSttlmAmt Ccy="USD">25000.00</IntrBkSttlmAmt> <IntrBkSttlmDt>2026-07-24</IntrBkSttlmDt><ChrgBr>SHAR</ChrgBr> <Dbtr><Nm>VIET THANH IMPORT EXPORT JSC</Nm><PstlAdr><TwnNm>HANOI</TwnNm><Ctry>VN</Ctry></PstlAdr></Dbtr> <DbtrAcct><Id><Othr><Id>2003558140</Id></Othr></Id></DbtrAcct> <DbtrAgt><FinInstnId><BICFI>MSCBVNVX</BICFI></FinInstnId></DbtrAgt> <CdtrAgt><FinInstnId><BICFI>SCBLSGSG</BICFI></FinInstnId></CdtrAgt> <Cdtr><Nm>ORIENT PACIFIC TRADING PTE LTD</Nm> <PstlAdr><TwnNm>SINGAPORE</TwnNm><Ctry>SG</Ctry></PstlAdr> <Id><PrvtId><Othr><Id>HC62779627</Id><SchmeNm><Cd>NIDN</Cd></SchmeNm></Othr></PrvtId></Id></Cdtr> <CdtrAcct><Id><Othr><Id>7788990011</Id></Othr></Id></CdtrAcct> <RmtInf><Ustrd>PAYMENT FOR INVOICE INV-2026-0714</Ustrd></RmtInf> </CdtTrfTxInf> </FIToFICstmrCdtTrf> </Document> | F33: 2. Hệ thống sinh HIT tại xpath'/Document/FIToFICstmrCdtTrf/CdtTrfTxInf/Cdtr/Id/PrvtId/Othr/Id' qua webservice IDENTIFIER, khớp với danh sách "AML" Câu query kiểm tra kết quả (KET_QUA = Pass): SELECT CASE WHEN COUNT(1) >= 1 THEN 'Pass' ELSE 'Fail' END sql_check FROM fsi_rt_xml_wls_response t WHERE n_grp_msg_id = :n_grp_msg_id AND V_MATCHED_LIST_REC_ID = 'nhập lại' AND n_webservice_id = 2 AND V_MATCHED_SUBLIST_NAME = 'AML' AND regexp_replace(to_char(t.x_path), '\[\d+\]', '') LIKE '%' || regexp_replace('Document/FIToFICstmrCdtTrf/CdtTrfTxInf/Cdtr/Id/PrvtId/Othr/Id', '\[\d+\]', '') || '%'; | H33: High | I33: Manual | J33: Failed | K33: Passed
A34: IDEN.10 | B34: Sàng lọc điện trường hợp dữ liệu xpath '/Document/FIToFICstmrCdtTrf/CdtTrfTxInf/Cdtr/Id/PrvtId/Othr/Id' điện pacs.008.001.08 trùng với giá trị trường 'CC/Thẻ CC' trong danh sách BCA | C34: 1. Điện được đẩy đúng format | D34: 1. Đẩy giao dịch vào API Post Message với trường thông tin '/Document/FIToFICstmrCdtTrf/CdtTrfTxInf/Cdtr/Id/PrvtId/Othr/Id' điện pacs.008.001.08 có dữ liệu nằm trong các danh sách theo dõi <Link URL hệ thống AML ở môi trường SIT> Path: transaction-screening/v1/transaction-screening Method: POST Request Header: Authorization: Basic Auth (Username and password to login to application) Content-Type: text/plain Accept: */* Request Body: cột Test Datas 2. Kiểm tra thông tin Event của giao dịch theo đường dẫn Financial Services Analytical Applications Transactions Filtering > Financial services Sanctions Pack > Transaction Filtering Alert List Chọn Filter, nhập thông tin tìm kiếm theo AlertID, nhấn <Search> Click mã AlertID và kiểm tra các thông tin Hoặc kiểm tra các thông tin trong file kết quả truy vấn Database | E34: <?xml version="1.0" encoding="UTF-8"?> <Document xmlns="urn:iso:std:iso:20022:tech:xsd:pacs.008.001.08"> <FIToFICstmrCdtTrf> <GrpHdr><MsgId>MSBIDEN10</MsgId><CreDtTm>2026-07-24T09:15:00</CreDtTm><NbOfTxs>1</NbOfTxs> <SttlmInf><SttlmMtd>INDA</SttlmMtd></SttlmInf></GrpHdr> <CdtTrfTxInf> <PmtId><InstrId>MSBIDEN10</InstrId><EndToEndId>MSBIDEN10</EndToEndId><TxId>MSBIDEN10</TxId></PmtId> <IntrBkSttlmAmt Ccy="USD">25000.00</IntrBkSttlmAmt> <IntrBkSttlmDt>2026-07-24</IntrBkSttlmDt><ChrgBr>SHAR</ChrgBr> <Dbtr><Nm>VIET THANH IMPORT EXPORT JSC</Nm><PstlAdr><TwnNm>HANOI</TwnNm><Ctry>VN</Ctry></PstlAdr></Dbtr> <DbtrAcct><Id><Othr><Id>0011000123456</Id></Othr></Id></DbtrAcct> <DbtrAgt><FinInstnId><BICFI>MSCBVNVX</BICFI></FinInstnId></DbtrAgt> <CdtrAgt><FinInstnId><BICFI>SCBLSGSG</BICFI></FinInstnId></CdtrAgt> <Cdtr><Nm>ORIENT PACIFIC TRADING PTE LTD</Nm> <PstlAdr><TwnNm>SINGAPORE</TwnNm><Ctry>SG</Ctry></PstlAdr> <Id><PrvtId><Othr><Id>75073007151</Id><SchmeNm><Cd>NIDN</Cd></SchmeNm></Othr></PrvtId></Id></Cdtr> <CdtrAcct><Id><Othr><Id>7788990011</Id></Othr></Id></CdtrAcct> <RmtInf><Ustrd>PAYMENT FOR INVOICE INV-2026-0714</Ustrd></RmtInf> </CdtTrfTxInf> </FIToFICstmrCdtTrf> </Document> | F34: 2. Hệ thống sinh HIT tại xpath '/Document/FIToFICstmrCdtTrf/CdtTrfTxInf/Cdtr/Id/PrvtId/Othr/Id' qua webservice IDENTIFIER, khớp với danh sách "BCA" Câu query kiểm tra kết quả (KET_QUA = Pass): SELECT CASE WHEN COUNT(1) >= 1 THEN 'Pass' ELSE 'Fail' END sql_check FROM fsi_rt_xml_wls_response t WHERE n_grp_msg_id = :n_grp_msg_id AND V_MATCHED_LIST_REC_ID = 'nhập lại' AND n_webservice_id = 2 AND V_MATCHED_SUBLIST_NAME = 'BCA' AND regexp_replace(to_char(t.x_path), '\[\d+\]', '') LIKE '%' || regexp_replace('/Document/FIToFICstmrCdtTrf/CdtTrfTxInf/Cdtr/Id/PrvtId/Othr/Id', '\[\d+\]', '') || '%'; | H34: High | I34: Manual | J34: Failed | K34: Passed
A35: IDEN.11 | B35: Sàng lọc điện trường hợp dữ liệu xpath '/Document/FIToFICstmrCdtTrf/CdtTrfTxInf/Cdtr/Id/PrvtId/Othr/Id' điện pacs.008.001.08 trùng với giá trị trường 'CMND/CMT' trong danh sách BCA | C35: 1. Điện được đẩy đúng format | D35: 1. Đẩy giao dịch vào API Post Message với trường thông tin '/Document/FIToFICstmrCdtTrf/CdtTrfTxInf/Cdtr/Id/PrvtId/Othr/Id' điện pacs.008.001.08 có dữ liệu nằm trong các danh sách theo dõi <Link URL hệ thống AML ở môi trường SIT> Path: transaction-screening/v1/transaction-screening Method: POST Request Header: Authorization: Basic Auth (Username and password to login to application) Content-Type: text/plain Accept: */* Request Body: cột Test Datas 2. Kiểm tra thông tin Event của giao dịch theo đường dẫn Financial Services Analytical Applications Transactions Filtering > Financial services Sanctions Pack > Transaction Filtering Alert List Chọn Filter, nhập thông tin tìm kiếm theo AlertID, nhấn <Search> Click mã AlertID và kiểm tra các thông tin Hoặc kiểm tra các thông tin trong file kết quả truy vấn Database | E35: <?xml version="1.0" encoding="UTF-8"?> <Document xmlns="urn:iso:std:iso:20022:tech:xsd:pacs.008.001.08"> <FIToFICstmrCdtTrf> <GrpHdr><MsgId>MSBIDEN11</MsgId><CreDtTm>2026-07-24T09:15:00</CreDtTm><NbOfTxs>1</NbOfTxs> <SttlmInf><SttlmMtd>INDA</SttlmMtd></SttlmInf></GrpHdr> <CdtTrfTxInf> <PmtId><InstrId>MSBIDEN11</InstrId><EndToEndId>MSBIDEN11</EndToEndId><TxId>MSBIDEN11</TxId></PmtId> <IntrBkSttlmAmt Ccy="USD">25000.00</IntrBkSttlmAmt> <IntrBkSttlmDt>2026-07-24</IntrBkSttlmDt><ChrgBr>SHAR</ChrgBr> <Dbtr><Nm>VIET THANH IMPORT EXPORT JSC</Nm><PstlAdr><TwnNm>HANOI</TwnNm><Ctry>VN</Ctry></PstlAdr></Dbtr> <DbtrAcct><Id><Othr><Id>0011000123456</Id></Othr></Id></DbtrAcct> <DbtrAgt><FinInstnId><BICFI>MSCBVNVX</BICFI></FinInstnId></DbtrAgt> <CdtrAgt><FinInstnId><BICFI>SCBLSGSG</BICFI></FinInstnId></CdtrAgt> <Cdtr><Nm>ORIENT PACIFIC TRADING PTE LTD</Nm> <PstlAdr><TwnNm>SINGAPORE</TwnNm><Ctry>SG</Ctry></PstlAdr> <Id><PrvtId><Othr><Id>48054963</Id><SchmeNm><Cd>NIDN</Cd></SchmeNm></Othr></PrvtId></Id></Cdtr> <CdtrAcct><Id><Othr><Id>7788990011</Id></Othr></Id></CdtrAcct> <RmtInf><Ustrd>PAYMENT FOR INVOICE INV-2026-0714</Ustrd></RmtInf> </CdtTrfTxInf> </FIToFICstmrCdtTrf> </Document> | F35: 2. Hệ thống sinh HIT tại xpath '/Document/FIToFICstmrCdtTrf/CdtTrfTxInf/Cdtr/Id/PrvtId/Othr/Id' qua webservice IDENTIFIER, khớp với danh sách "BCA" Câu query kiểm tra kết quả (KET_QUA = Pass): SELECT CASE WHEN COUNT(1) >= 1 THEN 'Pass' ELSE 'Fail' END sql_check FROM fsi_rt_xml_wls_response t WHERE n_grp_msg_id = :n_grp_msg_id AND V_MATCHED_LIST_REC_ID = 'nhập lại' AND n_webservice_id = 2 AND V_MATCHED_SUBLIST_NAME = 'BCA' AND regexp_replace(to_char(t.x_path), '\[\d+\]', '') LIKE '%' || regexp_replace('/Document/FIToFICstmrCdtTrf/CdtTrfTxInf/Cdtr/Id/PrvtId/Othr/Id', '\[\d+\]', '') || '%'; | H35: High | I35: Manual | J35: Failed | K35: Passed
B36: Webservice Country and City
A37: COUNTRY.01 | B37: Sàng lọc điện trường hợp dữ liệu xpath '/Document/FIToFICstmrCdtTrf/GrpHdr/InstgAgt/FinInstnId/PstlAdr/Ctry' điện pacs.008.001.08 trùng với giá trị trường 'Mã quốc gia' trong danh sách Quốc gia Blacklisted Country | C37: 1. Điện được đẩy đúng format | D37: 1. Đẩy giao dịch vào API Post Message với trường thông tin '/Document/FIToFICstmrCdtTrf/GrpHdr/InstgAgt/FinInstnId/PstlAdr/Ctry' điện pacs.008.001.08 có dữ liệu nằm trong các danh sách theo dõi <Link URL hệ thống AML ở môi trường SIT> Path: transaction-screening/v1/transaction-screening Method: POST Request Header: Authorization: Basic Auth (Username and password to login to application) Content-Type: text/plain Accept: */* Request Body: cột Test Datas 2. Kiểm tra thông tin Event của giao dịch theo đường dẫn Financial Services Analytical Applications Transactions Filtering > Financial services Sanctions Pack > Transaction Filtering Alert List Chọn Filter, nhập thông tin tìm kiếm theo AlertID, nhấn <Search> Click mã AlertID và kiểm tra các thông tin Hoặc kiểm tra các thông tin trong file kết quả truy vấn Database | E37: <?xml version="1.0" encoding="UTF-8"?> <Document xmlns="urn:iso:std:iso:20022:tech:xsd:pacs.008.001.08"> <FIToFICstmrCdtTrf> <GrpHdr><MsgId>MSBCOUNTRY01</MsgId><CreDtTm>2026-07-24T09:15:00</CreDtTm><NbOfTxs>1</NbOfTxs> <SttlmInf><SttlmMtd>INDA</SttlmMtd></SttlmInf> <InstgAgt><FinInstnId><PstlAdr><Ctry>IR</Ctry></PstlAdr></FinInstnId></InstgAgt></GrpHdr> <CdtTrfTxInf> <PmtId><InstrId>MSBCOUNTRY01</InstrId><EndToEndId>MSBCOUNTRY01</EndToEndId><TxId>MSBCOUNTRY01</TxId></PmtId> <IntrBkSttlmAmt Ccy="USD">25000.00</IntrBkSttlmAmt> <IntrBkSttlmDt>2026-07-24</IntrBkSttlmDt><ChrgBr>SHAR</ChrgBr> <Dbtr><Nm>VIET THANH IMPORT EXPORT JSC</Nm><PstlAdr><TwnNm>HANOI</TwnNm><Ctry>VN</Ctry></PstlAdr></Dbtr> <DbtrAcct><Id><Othr><Id>0011000123456</Id></Othr></Id></DbtrAcct> <DbtrAgt><FinInstnId><BICFI>MSCBVNVX</BICFI></FinInstnId></DbtrAgt> <CdtrAgt><FinInstnId><BICFI>SCBLSGSG</BICFI></FinInstnId></CdtrAgt> <Cdtr><Nm>ORIENT PACIFIC TRADING PTE LTD</Nm> <PstlAdr><TwnNm>SINGAPORE</TwnNm><Ctry>SG</Ctry></PstlAdr> <Id><PrvtId><Othr><Id>48054963</Id><SchmeNm><Cd>NIDN</Cd></SchmeNm></Othr></PrvtId></Id></Cdtr> <CdtrAcct><Id><Othr><Id>7788990011</Id></Othr></Id></CdtrAcct> <RmtInf><Ustrd>PAYMENT FOR INVOICE INV-2026-0714</Ustrd></RmtInf> </CdtTrfTxInf> </FIToFICstmrCdtTrf> </Document> | F37: 2. Hệ thống sinh HIT tại tag 51A qua webservice COUNTRY AND CITY, khớp với danh sách "Knock-Out" Câu query kiểm tra kết quả (KET_QUA = Pass): SELECT CASE WHEN COUNT(1) >= 1 THEN 'Pass' ELSE 'Fail' END sql_check FROM fsi_rt_xml_wls_response t WHERE n_grp_msg_id = :n_grp_msg_id AND V_MATCHED_LIST_REC_ID = 'nhập lại' AND n_webservice_id = 3 AND V_MATCHED_LIST_NAME = 'Blacklisted Country' AND regexp_replace(to_char(t.x_path), '\[\d+\]', '') LIKE '%' || regexp_replace('/Document/FIToFICstmrCdtTrf/GrpHdr/InstgAgt/FinInstnId/PstlAdr/Ctry', '\[\d+\]', '') || '%'; | H37: High | I37: Manual | J37: Passed | K37: Passed
B38: Webservice Narrative
A39: NARRATIVE.01 | B39: Sàng lọc điện trường hợp dữ liệu tag '75' điện MT195 trùng với giá trị trường 'LAST NAME' trong danh sách WC | C39: 1. Điện được đẩy đúng format | D39: 1. Đẩy giao dịch vào API Post Message với trường thông tin '75' điện MT195 có dữ liệu nằm trong các danh sách theo dõi <Link URL hệ thống AML ở môi trường SIT> Path: transaction-screening/v1/transaction-screening Method: POST Request Header: Authorization: Basic Auth (Username and password to login to application) Content-Type: text/plain Accept: */* Request Body: cột Test Datas 2. Kiểm tra thông tin Event của giao dịch theo đường dẫn Financial Services Analytical Applications Transactions Filtering > Financial services Sanctions Pack > Transaction Filtering Alert List Chọn Filter, nhập thông tin tìm kiếm theo AlertID, nhấn <Search> Click mã AlertID và kiểm tra các thông tin Hoặc kiểm tra các thông tin trong file kết quả truy vấn Database | E39: {1:F01BFICCUHHAXXX0000000000} {2:I195BFICCUHHXXXXN} {3:{108:MT195TEST0001}} {4: :20:QRY2607240001 :21:NONREF :75:SUMMIT EMBER -}{5:{MAC:00000000}{CHK:1A2B3C4D5E6F}} | F39: 2. Hệ thống sinh HIT tại tag 75 qua webservice NARRATIVE, khớp với danh sách WC Câu query kiểm tra kết quả (KET_QUA = Pass): SELECT CASE WHEN COUNT(1) >= 1 THEN 'Pass' ELSE 'Fail' END sql_check FROM fsi_rt_al_wls_response t WHERE n_grp_msg_id = :n_grp_msg_id AND n_webservice_id = 4 AND v_tag_name = '75' AND v_matched_list_rec_id = 'nhập lại' AND V_MATCHED_LIST_NAME = 'WC'; | H39: High | I39: Manual | J39: Untested | K39: Passed
A40: NARRATIVE.01.a | B40: Sàng lọc điện trường hợp dữ liệu tag '75' điện MT195 trùng với giá trị trường 'Họ và tên' trong danh sách AML | D40: 1. Đẩy giao dịch vào API Post Message với trường thông tin '75' điện MT195 có dữ liệu nằm trong các danh sách theo dõi <Link URL hệ thống AML ở môi trường SIT> Path: transaction-screening/v1/transaction-screening Method: POST Request Header: Authorization: Basic Auth (Username and password to login to application) Content-Type: text/plain Accept: */* Request Body: cột Test Datas 2. Kiểm tra thông tin Event của giao dịch theo đường dẫn Financial Services Analytical Applications Transactions Filtering > Financial services Sanctions Pack > Transaction Filtering Alert List Chọn Filter, nhập thông tin tìm kiếm theo AlertID, nhấn <Search> Click mã AlertID và kiểm tra các thông tin Hoặc kiểm tra các thông tin trong file kết quả truy vấn Database | E40: {1:F01BFICCUHHAXXX0000000000} {2:I195BFICCUHHXXXXN} {3:{108:MT195TEST0001}} {4: :20:QRY2607240002 :21:NONREF :75:TO THI TUYET MAI -}{5:{MAC:00000000}{CHK:1A2B3C4D5E6F}} | F40: 2. Hệ thống sinh HIT tại tag 75 qua webservice NARRATIVE, khớp với danh sách AML Câu query kiểm tra kết quả (KET_QUA = Pass): SELECT CASE WHEN COUNT(1) >= 1 THEN 'Pass' ELSE 'Fail' END sql_check FROM fsi_rt_al_wls_response t WHERE n_grp_msg_id = :n_grp_msg_id AND n_webservice_id = 4 AND v_tag_name = '75' AND v_matched_list_rec_id = 'nhập lại' AND V_MATCHED_SUBLIST_NAME = 'AML'; | H40: High | I40: Manual | J40: Passed | K40: Untested
