Workbook

Sheet Cover
E8: Test Report
C11: Project Name: | E11: DỰ ÁN TRIỂN KHAI BẢN QUYỀN PHẦN MỀM HỆ THỐNG AML MỚI | G11: Reviewer:
C12: Document Code: | E12: MSB_AML_Testcase_KYC_UI_customize | G12: Position:
C13: Originator: | G13: Reviewed Date:
C14: Position: | G14: Approver:
C15: Created Date: | E15: 46153 | G15: Position:
C16: Version: | E16: 1.0 | G16: Approved Date:

Sheet Records
A1: TABLE OF CONTENT
A3: No | B3: Items | C3: Content
A4: 1 | B4: Cover | C4: Cover
A5: 2 | B5: Records | C5: Record of changes
A6: 3 | B6: Function | C6: List out all test cases of the application
A7: 4 | B7: Screen Element | C7: Screen Element test cases, which are based on the application's SRS
A9: Effective Date | B9: A, M, D | C9: Change Description | F9: New Version | G9: Author
A10: 46153 | B10: A | C10: Create new TC | F10: 1

Sheet Test Report
B2: SYSTEM TEST REPORT
A5: Project | B5: =#NAME? -> #NAME? | D5: Project manager
A6: Application | D6: Approved Date
A7: Consolidated By | D7: Reviewed By
A8: Build Versions | D8: Reviewed date
A9: Test Environment | B9: SIT
A10: Last Updated Date
A11: Test Execution Summary
A12: Reported by
A13: Date
A14: Test Results | B14: Passed | C14: Failed | D14: Pending | E14: Next | F14: Canel | G14: Untested | H14: Total
A15: Total | B15: =SUM(B16:B18) -> 190 | C15: =SUM(C16:C18) -> 0 | D15: =SUM(D16:D18) -> 0 | E15: =SUM(E16:E18) -> 0 | F15: =SUM(F16:F18) -> 0 | G15: =SUM(G16:G18) -> 69 | H15: =SUM(B15:G15) -> 259
A16: Cấu hình điện | B16: ='Cấu hình điện'!E6 -> 104 | C16: ='Cấu hình điện'!E7 -> 0 | D16: ='Cấu hình điện'!E8 -> 0 | E16: ='Cấu hình điện'!E12 -> 0 | F16: ='Cấu hình điện'!E9 -> 0 | G16: ='Cấu hình điện'!E10 -> 15 | H16: =SUM(B16:G16) -> 119
A17: Cấu hình chủ thể | B17: ='Cấu hình chủ thể'!E6 -> 86 | C17: ='Cấu hình chủ thể'!E7 -> 0 | D17: ='Cấu hình chủ thể'!E8 -> 0 | E17: ='Cấu hình chủ thể'!E11 -> 0 | F17: ='Cấu hình chủ thể'!E10 -> 0 | G17: ='Cấu hình chủ thể'!E9 -> 54 | H17: =SUM(B17:G17) -> 140
A18: Sàng lọc điện | B18: ='Sàng lọc điện'!E6 -> 0 | C18: ='Sàng lọc điện'!E7 -> 0 | D18: ='Sàng lọc điện'!E11 -> 0 | E18: ='Sàng lọc điện'!E10 -> 0 | F18: ='Sàng lọc điện'!E9 -> 0 | G18: ='Sàng lọc điện'!E8 -> 0 | H18: =SUM(B18:G18) -> 0
A19: Test coverage
A20: Test coverage | H20: =IFERROR(SUM(B15,C15,F15)/H15, 0) -> 0.73359073
A21: Test successful coverage | H21: =IFERROR(SUM(B15,F15)/H15, 0) -> 0.73359073
A22: Issues
A23: 1. Block testing issue
A24: 2. Critical defects
A29: Kết quả test mtr SIT
A30: Test Results | B30: Passed | C30: Failed | D30: Pending | E30: Next | F30: Canel | G30: Untested | H30: Total
A31: Total | B31: =SUM(B32:B96) -> 667 | C31: =SUM(C32:C96) -> 1 | D31: =SUM(D32:D96) -> 0 | E31: =SUM(E32:E96) -> 0 | F31: =SUM(F32:F96) -> 0 | G31: =SUM(G32:G96) -> 103 | H31: =SUM(B31:G31) -> 771
A32: Cấu hình điện | B32: =SUM(B33,B39,B47,B51,B56) -> 104 | C32: =SUM(C33,C39,C47,C51,C56) -> 0 | D32: =SUM(D33,D39,D47,D51,D56) -> 0 | E32: =SUM(E33,E39,E47,E51,E56) -> 0 | F32: =SUM(F33,F39,F47,F51,F56) -> 0 | G32: =SUM(G33,G39,G47,G51,G56) -> 0 | H32: =SUM(B32:G32) -> 104
A33: Bàn giao đợt 1 | B33: =SUM(B34:B38) -> 20 | C33: =SUM(C34:C38) -> 0 | D33: =SUM(D34:D38) -> 0 | E33: =SUM(E34:E38) -> 0 | F33: =SUM(F34:F38) -> 0 | G33: =SUM(G34:G38) -> 0 | H33: =SUM(B33:G33) -> 20
A34: MT195 | B34: =COUNTIFS('Cấu hình điện'!$O:$O,'Test Report'!$A34,'Cấu hình điện'!$K:$K,'Test Report'!B$30) -> 4 | C34: =COUNTIFS('Cấu hình điện'!$O:$O,'Test Report'!$A34,'Cấu hình điện'!$K:$K,'Test Report'!C$30) -> 0 | D34: =COUNTIFS('Cấu hình điện'!$O:$O,'Test Report'!$A34,'Cấu hình điện'!$K:$K,'Test Report'!D$30) -> 0 | E34: =COUNTIFS('Cấu hình điện'!$O:$O,'Test Report'!$A34,'Cấu hình điện'!$K:$K,'Test Report'!E$30) -> 0 | F34: =COUNTIFS('Cấu hình điện'!$O:$O,'Test Report'!$A34,'Cấu hình điện'!$K:$K,'Test Report'!F$30) -> 0 | G34: =COUNTIFS('Cấu hình điện'!$O:$O,'Test Report'!$A34,'Cấu hình điện'!$K:$K,'Test Report'!G$30) -> 0 | H34: =SUM(B34:G34) -> 4
A35: MT196 | B35: =COUNTIFS('Cấu hình điện'!$O:$O,'Test Report'!$A35,'Cấu hình điện'!$K:$K,'Test Report'!B$30) -> 4 | C35: =COUNTIFS('Cấu hình điện'!$O:$O,'Test Report'!$A35,'Cấu hình điện'!$K:$K,'Test Report'!C$30) -> 0 | D35: =COUNTIFS('Cấu hình điện'!$O:$O,'Test Report'!$A35,'Cấu hình điện'!$K:$K,'Test Report'!D$30) -> 0 | E35: =COUNTIFS('Cấu hình điện'!$O:$O,'Test Report'!$A35,'Cấu hình điện'!$K:$K,'Test Report'!E$30) -> 0 | F35: =COUNTIFS('Cấu hình điện'!$O:$O,'Test Report'!$A35,'Cấu hình điện'!$K:$K,'Test Report'!F$30) -> 0 | G35: =COUNTIFS('Cấu hình điện'!$O:$O,'Test Report'!$A35,'Cấu hình điện'!$K:$K,'Test Report'!G$30) -> 0 | H35: =SUM(B35:G35) -> 4
A36: MT199 | B36: =COUNTIFS('Cấu hình điện'!$O:$O,'Test Report'!$A36,'Cấu hình điện'!$K:$K,'Test Report'!B$30) -> 4 | C36: =COUNTIFS('Cấu hình điện'!$O:$O,'Test Report'!$A36,'Cấu hình điện'!$K:$K,'Test Report'!C$30) -> 0 | D36: =COUNTIFS('Cấu hình điện'!$O:$O,'Test Report'!$A36,'Cấu hình điện'!$K:$K,'Test Report'!D$30) -> 0 | E36: =COUNTIFS('Cấu hình điện'!$O:$O,'Test Report'!$A36,'Cấu hình điện'!$K:$K,'Test Report'!E$30) -> 0 | F36: =COUNTIFS('Cấu hình điện'!$O:$O,'Test Report'!$A36,'Cấu hình điện'!$K:$K,'Test Report'!F$30) -> 0 | G36: =COUNTIFS('Cấu hình điện'!$O:$O,'Test Report'!$A36,'Cấu hình điện'!$K:$K,'Test Report'!G$30) -> 0 | H36: =SUM(B36:G36) -> 4
A37: MT295 | B37: =COUNTIFS('Cấu hình điện'!$O:$O,'Test Report'!$A37,'Cấu hình điện'!$K:$K,'Test Report'!B$30) -> 4 | C37: =COUNTIFS('Cấu hình điện'!$O:$O,'Test Report'!$A37,'Cấu hình điện'!$K:$K,'Test Report'!C$30) -> 0 | D37: =COUNTIFS('Cấu hình điện'!$O:$O,'Test Report'!$A37,'Cấu hình điện'!$K:$K,'Test Report'!D$30) -> 0 | E37: =COUNTIFS('Cấu hình điện'!$O:$O,'Test Report'!$A37,'Cấu hình điện'!$K:$K,'Test Report'!E$30) -> 0 | F37: =COUNTIFS('Cấu hình điện'!$O:$O,'Test Report'!$A37,'Cấu hình điện'!$K:$K,'Test Report'!F$30) -> 0 | G37: =COUNTIFS('Cấu hình điện'!$O:$O,'Test Report'!$A37,'Cấu hình điện'!$K:$K,'Test Report'!G$30) -> 0 | H37: =SUM(B37:G37) -> 4
A38: MT296 | B38: =COUNTIFS('Cấu hình điện'!$O:$O,'Test Report'!$A38,'Cấu hình điện'!$K:$K,'Test Report'!B$30) -> 4 | C38: =COUNTIFS('Cấu hình điện'!$O:$O,'Test Report'!$A38,'Cấu hình điện'!$K:$K,'Test Report'!C$30) -> 0 | D38: =COUNTIFS('Cấu hình điện'!$O:$O,'Test Report'!$A38,'Cấu hình điện'!$K:$K,'Test Report'!D$30) -> 0 | E38: =COUNTIFS('Cấu hình điện'!$O:$O,'Test Report'!$A38,'Cấu hình điện'!$K:$K,'Test Report'!E$30) -> 0 | F38: =COUNTIFS('Cấu hình điện'!$O:$O,'Test Report'!$A38,'Cấu hình điện'!$K:$K,'Test Report'!F$30) -> 0 | G38: =COUNTIFS('Cấu hình điện'!$O:$O,'Test Report'!$A38,'Cấu hình điện'!$K:$K,'Test Report'!G$30) -> 0 | H38: =SUM(B38:G38) -> 4
A39: Bàn giao đợt 2 | B39: =SUM(B40:B46) -> 28 | C39: =SUM(C40:C46) -> 0 | D39: =SUM(D40:D46) -> 0 | E39: =SUM(E40:E46) -> 0 | F39: =SUM(F40:F46) -> 0 | G39: =SUM(G40:G46) -> 0 | H39: =SUM(H40:H46) -> 28
A40: MT299 | B40: =COUNTIFS('Cấu hình điện'!$O:$O,'Test Report'!$A40,'Cấu hình điện'!$K:$K,'Test Report'!B$30) -> 4 | C40: =COUNTIFS('Cấu hình điện'!$O:$O,'Test Report'!$A40,'Cấu hình điện'!$K:$K,'Test Report'!C$30) -> 0 | D40: =COUNTIFS('Cấu hình điện'!$O:$O,'Test Report'!$A40,'Cấu hình điện'!$K:$K,'Test Report'!D$30) -> 0 | E40: =COUNTIFS('Cấu hình điện'!$O:$O,'Test Report'!$A40,'Cấu hình điện'!$K:$K,'Test Report'!E$30) -> 0 | F40: =COUNTIFS('Cấu hình điện'!$O:$O,'Test Report'!$A40,'Cấu hình điện'!$K:$K,'Test Report'!F$30) -> 0 | G40: =COUNTIFS('Cấu hình điện'!$O:$O,'Test Report'!$A40,'Cấu hình điện'!$K:$K,'Test Report'!G$30) -> 0 | H40: =SUM(B40:G40) -> 4
A41: pacs.008 | B41: =COUNTIFS('Cấu hình điện'!$O:$O,'Test Report'!$A41,'Cấu hình điện'!$K:$K,'Test Report'!B$30) -> 4 | C41: =COUNTIFS('Cấu hình điện'!$O:$O,'Test Report'!$A41,'Cấu hình điện'!$K:$K,'Test Report'!C$30) -> 0 | D41: =COUNTIFS('Cấu hình điện'!$O:$O,'Test Report'!$A41,'Cấu hình điện'!$K:$K,'Test Report'!D$30) -> 0 | E41: =COUNTIFS('Cấu hình điện'!$O:$O,'Test Report'!$A41,'Cấu hình điện'!$K:$K,'Test Report'!E$30) -> 0 | F41: =COUNTIFS('Cấu hình điện'!$O:$O,'Test Report'!$A41,'Cấu hình điện'!$K:$K,'Test Report'!F$30) -> 0 | G41: =COUNTIFS('Cấu hình điện'!$O:$O,'Test Report'!$A41,'Cấu hình điện'!$K:$K,'Test Report'!G$30) -> 0 | H41: =SUM(B41:G41) -> 4
A42: MT499 | B42: =COUNTIFS('Cấu hình điện'!$O:$O,'Test Report'!$A42,'Cấu hình điện'!$K:$K,'Test Report'!B$30) -> 4 | C42: =COUNTIFS('Cấu hình điện'!$O:$O,'Test Report'!$A42,'Cấu hình điện'!$K:$K,'Test Report'!C$30) -> 0 | D42: =COUNTIFS('Cấu hình điện'!$O:$O,'Test Report'!$A42,'Cấu hình điện'!$K:$K,'Test Report'!D$30) -> 0 | E42: =COUNTIFS('Cấu hình điện'!$O:$O,'Test Report'!$A42,'Cấu hình điện'!$K:$K,'Test Report'!E$30) -> 0 | F42: =COUNTIFS('Cấu hình điện'!$O:$O,'Test Report'!$A42,'Cấu hình điện'!$K:$K,'Test Report'!F$30) -> 0 | G42: =COUNTIFS('Cấu hình điện'!$O:$O,'Test Report'!$A42,'Cấu hình điện'!$K:$K,'Test Report'!G$30) -> 0 | H42: =SUM(B42:G42) -> 4
A43: MT711 | B43: =COUNTIFS('Cấu hình điện'!$O:$O,'Test Report'!$A43,'Cấu hình điện'!$K:$K,'Test Report'!B$30) -> 4 | C43: =COUNTIFS('Cấu hình điện'!$O:$O,'Test Report'!$A43,'Cấu hình điện'!$K:$K,'Test Report'!C$30) -> 0 | D43: =COUNTIFS('Cấu hình điện'!$O:$O,'Test Report'!$A43,'Cấu hình điện'!$K:$K,'Test Report'!D$30) -> 0 | E43: =COUNTIFS('Cấu hình điện'!$O:$O,'Test Report'!$A43,'Cấu hình điện'!$K:$K,'Test Report'!E$30) -> 0 | F43: =COUNTIFS('Cấu hình điện'!$O:$O,'Test Report'!$A43,'Cấu hình điện'!$K:$K,'Test Report'!F$30) -> 0 | G43: =COUNTIFS('Cấu hình điện'!$O:$O,'Test Report'!$A43,'Cấu hình điện'!$K:$K,'Test Report'!G$30) -> 0 | H43: =SUM(B43:G43) -> 4
A44: MT799 | B44: =COUNTIFS('Cấu hình điện'!$O:$O,'Test Report'!$A44,'Cấu hình điện'!$K:$K,'Test Report'!B$30) -> 4 | C44: =COUNTIFS('Cấu hình điện'!$O:$O,'Test Report'!$A44,'Cấu hình điện'!$K:$K,'Test Report'!C$30) -> 0 | D44: =COUNTIFS('Cấu hình điện'!$O:$O,'Test Report'!$A44,'Cấu hình điện'!$K:$K,'Test Report'!D$30) -> 0 | E44: =COUNTIFS('Cấu hình điện'!$O:$O,'Test Report'!$A44,'Cấu hình điện'!$K:$K,'Test Report'!E$30) -> 0 | F44: =COUNTIFS('Cấu hình điện'!$O:$O,'Test Report'!$A44,'Cấu hình điện'!$K:$K,'Test Report'!F$30) -> 0 | G44: =COUNTIFS('Cấu hình điện'!$O:$O,'Test Report'!$A44,'Cấu hình điện'!$K:$K,'Test Report'!G$30) -> 0 | H44: =SUM(B44:G44) -> 4
A45: MT999 | B45: =COUNTIFS('Cấu hình điện'!$O:$O,'Test Report'!$A45,'Cấu hình điện'!$K:$K,'Test Report'!B$30) -> 4 | C45: =COUNTIFS('Cấu hình điện'!$O:$O,'Test Report'!$A45,'Cấu hình điện'!$K:$K,'Test Report'!C$30) -> 0 | D45: =COUNTIFS('Cấu hình điện'!$O:$O,'Test Report'!$A45,'Cấu hình điện'!$K:$K,'Test Report'!D$30) -> 0 | E45: =COUNTIFS('Cấu hình điện'!$O:$O,'Test Report'!$A45,'Cấu hình điện'!$K:$K,'Test Report'!E$30) -> 0 | F45: =COUNTIFS('Cấu hình điện'!$O:$O,'Test Report'!$A45,'Cấu hình điện'!$K:$K,'Test Report'!F$30) -> 0 | G45: =COUNTIFS('Cấu hình điện'!$O:$O,'Test Report'!$A45,'Cấu hình điện'!$K:$K,'Test Report'!G$30) -> 0 | H45: =SUM(B45:G45) -> 4
A46: pacs.009 | B46: =COUNTIFS('Cấu hình điện'!$O:$O,'Test Report'!$A46,'Cấu hình điện'!$K:$K,'Test Report'!B$30) -> 4 | C46: =COUNTIFS('Cấu hình điện'!$O:$O,'Test Report'!$A46,'Cấu hình điện'!$K:$K,'Test Report'!C$30) -> 0 | D46: =COUNTIFS('Cấu hình điện'!$O:$O,'Test Report'!$A46,'Cấu hình điện'!$K:$K,'Test Report'!D$30) -> 0 | E46: =COUNTIFS('Cấu hình điện'!$O:$O,'Test Report'!$A46,'Cấu hình điện'!$K:$K,'Test Report'!E$30) -> 0 | F46: =COUNTIFS('Cấu hình điện'!$O:$O,'Test Report'!$A46,'Cấu hình điện'!$K:$K,'Test Report'!F$30) -> 0 | G46: =COUNTIFS('Cấu hình điện'!$O:$O,'Test Report'!$A46,'Cấu hình điện'!$K:$K,'Test Report'!G$30) -> 0 | H46: =SUM(B46:G46) -> 4
A47: Bàn giao đợt 3 | B47: =SUM(B48:B50) -> 12 | C47: =SUM(C48:C50) -> 0 | D47: =SUM(D48:D50) -> 0 | E47: =SUM(E48:E50) -> 0 | F47: =SUM(F48:F50) -> 0 | G47: =SUM(G48:G50) -> 0 | H47: =SUM(H48:H50) -> 12
...

Sheet Cấu hình điện
A1: Functions | B1: Config EDQ
A2: Build Version | B2: v1.0
B4: High | C4: Medium | D4: Low | E4: Total
B5: =SUM(B6:B11) -> 0 | C5: =SUM(C6:C11) -> 119 | D5: =SUM(D6:D11) -> 0 | E5: =SUM(B5:D5) -> 119
A6: Passed | B6: =COUNTIFS($K$16:$K$163, $A6,$H$16:$H$163,B$4) -> 0 | C6: =COUNTIFS($K$16:$K$163, $A6,$H$16:$H$163,C$4) -> 104 | D6: =COUNTIFS($K$16:$K$163, $A6,$H$16:$H$163,D$4) -> 0 | E6: =SUM(B6:D6) -> 104
A7: Failed | B7: =COUNTIFS($K$16:$K$163, $A7,$H$16:$H$163,B$4) -> 0 | C7: =COUNTIFS($K$16:$K$163, $A7,$H$16:$H$163,C$4) -> 0 | D7: =COUNTIFS($K$16:$K$163, $A7,$H$16:$H$163,D$4) -> 0 | E7: =SUM(B7:D7) -> 0
A8: Pending | B8: =COUNTIFS($K$16:$K$163, $A8,$H$16:$H$163,B$4) -> 0 | C8: =COUNTIFS($K$16:$K$163, $A8,$H$16:$H$163,C$4) -> 0 | D8: =COUNTIFS($K$16:$K$163, $A8,$H$16:$H$163,D$4) -> 0 | E8: =SUM(B8:D8) -> 0
A9: Cancel | B9: =COUNTIFS($K$16:$K$163, $A9,$H$16:$H$163,B$4) -> 0 | C9: =COUNTIFS($K$16:$K$163, $A9,$H$16:$H$163,C$4) -> 0 | D9: =COUNTIFS($K$16:$K$163, $A9,$H$16:$H$163,D$4) -> 0 | E9: =SUM(B9:D9) -> 0
A10: Untested | B10: =COUNTIFS($K$16:$K$163, $A10,$H$16:$H$163,B$4) -> 0 | C10: =COUNTIFS($K$16:$K$163, $A10,$H$16:$H$163,C$4) -> 15 | D10: =COUNTIFS($K$16:$K$163, $A10,$H$16:$H$163,D$4) -> 0 | E10: =SUM(B10:D10) -> 15
A11: Accepted | B11: =COUNTIFS($K$16:$K$163, $A11,$H$16:$H$163,B$4) -> 0 | C11: =COUNTIFS($K$16:$K$163, $A11,$H$16:$H$163,C$4) -> 0 | D11: =COUNTIFS($K$16:$K$163, $A11,$H$16:$H$163,D$4) -> 0 | E11: =SUM(B11:D11) -> 0
A12: Next | B12: =COUNTIFS($K$16:$K$163, $A12,$H$16:$H$163,B$4) -> 0 | C12: =COUNTIFS($K$16:$K$163, $A12,$H$16:$H$163,C$4) -> 0 | D12: =COUNTIFS($K$16:$K$163, $A12,$H$16:$H$163,D$4) -> 0 | E12: =SUM(B12:D12) -> 0
A15: Test case Id | B15: Test case Title | C15: Pre-conditions | D15: Test Step | E15: Test Datas | F15: Expected result | G15: Test Environment | H15: Priority | I15: Automation Status | J15: 1st Test Results | K15: 2nd Test Results | L15: 3rd Test Result | M15: BugID | N15: Notes | O15: Key
B16: Kiểm tra config các trường của điện MT195
A17: MT195.01 | B17: Kiểm tra điện MT195 - Webservice IDENTIFIER được gán tương ứng với các trường trong điện | D17: 1. Login hệ thống TF bằng user admin 2. Truy cập theo đường dẫn Financial Services Analytical Applications Transactions Filtering/ Financial Services Sanctions Pack/ SWIFT Configuration Admin 3. Chọn điện MT195 trên drop down list 4. Sau khi bấm nút Save, click liên tiếp 2 lần button mũi tên sang phải (>) ở bên cạnh. 5. Chọn webservice IDENTIFIER trên dropdown list Screening webservice trên màn hình và kiểm tra các tags tương ứng được gán | F17: Thông tin hiển thị các field, field name tương ứng theo từng webservice đảm bảo đủ, đúng theo yêu cầu, có trạng thái Enable = Yes, bao gồm: Basic Header Block - LT Identifier Application Header Input - Receiver's Address Application Header Output - Full input SWIFT address | H17: Medium | I17: Manual | J17: Passed | K17: Passed | L17: Passed | O17: =LEFT(A17, FIND(".", A17) - 1) -> MT195
A18: MT195.02 | B18: Kiểm tra điện MT195 - Webservice COUNTRY AND CITY được gán tương ứng với các trường trong điện | D18: 1. Login hệ thống TF bằng user admin 2. Truy cập theo đường dẫn Financial Services Analytical Applications Transactions Filtering/ Financial Services Sanctions Pack/ SWIFT Configuration Admin 3. Chọn điện MT195 trên drop down list 4. Sau khi bấm nút Save, click liên tiếp 2 lần button mũi tên sang phải (>) ở bên cạnh. 5. Chọn webservice COUNTRY AND CITY trên dropdown list Screening webservice trên màn hình và kiểm tra các tags tương ứng được gán | F18: Thông tin hiển thị các field, field name tương ứng theo từng webservice đảm bảo đủ, đúng theo yêu cầu, có trạng thái Enable = Yes, bao gồm: Basic Header Block - LT Identifier Application Header Input - Receiver's Address Application Header Output - Full input SWIFT address | H18: Medium | I18: Manual | J18: Passed | K18: Passed | L18: Passed | O18: =LEFT(A18, FIND(".", A18) - 1) -> MT195
A19: MT195.03 | B19: Kiểm tra điện MT195 - Webservice NARRATIVE được gán tương ứng với các trường trong điện | D19: 1. Login hệ thống TF bằng user admin 2. Truy cập theo đường dẫn Financial Services Analytical Applications Transactions Filtering/ Financial Services Sanctions Pack/ SWIFT Configuration Admin 3. Chọn điện MT195 trên drop down list 4. Sau khi bấm nút Save, click liên tiếp 2 lần button mũi tên sang phải (>) ở bên cạnh. 5. Chọn webservice NARRATIVE trên dropdown list Screening webservice trên màn hình và kiểm tra các tags tương ứng được gán | F19: Thông tin hiển thị các field, field name tương ứng theo từng webservice đảm bảo đủ, đúng theo yêu cầu, có trạng thái Enable = Yes, bao gồm: 75 - Queries 77A - Narrative 79 - Narrative Description of the Message to Which the Query Relates Copy of at least the Mandatory Fields of the Original Message | H19: Medium | I19: Manual | J19: Passed | K19: Passed | L19: Passed | O19: =LEFT(A19, FIND(".", A19) - 1) -> MT195
A20: MT195.04 | B20: Kiểm tra điện MT195 - Webservice NAME AND ADDRESS được gán tương ứng với các trường trong điện | D20: 1. Login hệ thống TF bằng user admin 2. Truy cập theo đường dẫn Financial Services Analytical Applications Transactions Filtering/ Financial Services Sanctions Pack/ SWIFT Configuration Admin 3. Chọn điện MT195 trên drop down list 4. Sau khi bấm nút Save, click liên tiếp 2 lần button mũi tên sang phải (>) ở bên cạnh. 5. Chọn webservice NAME AND ADDRESS trên dropdown list Screening webservice trên màn hình và kiểm tra các tags tương ứng được gán | F20: Thông tin hiển thị các field, field name tương ứng theo từng webservice đảm bảo đủ, đúng theo yêu cầu, có trạng thái Enable = Yes, bao gồm: Basic Header Block - LT Identifier Application Header Input - Receiver's Address Application Header Output - Full input SWIFT address | H20: Medium | I20: Manual | J20: Passed | K20: Passed | L20: Passed | O20: =LEFT(A20, FIND(".", A20) - 1) -> MT195
B21: Kiểm tra config các trường của điện MT196 | O21: =LEFT(A21, FIND(".", A21) - 1) -> #VALUE!
A22: MT196.01 | B22: Kiểm tra điện MT196 - Webservice IDENTIFIER được gán tương ứng với các trường trong điện | D22: 1. Login hệ thống TF bằng user admin 2. Truy cập theo đường dẫn Financial Services Analytical Applications Transactions Filtering/ Financial Services Sanctions Pack/ SWIFT Configuration Admin 3. Chọn điện MT196 trên drop down list 4. Sau khi bấm nút Save, click liên tiếp 2 lần button mũi tên sang phải (>) ở bên cạnh. 5. Chọn webservice IDENTIFIER trên dropdown list Screening webservice trên màn hình và kiểm tra các tags tương ứng được gán | F22: Thông tin hiển thị các field, field name tương ứng theo từng webservice đảm bảo đủ, đúng theo yêu cầu, có trạng thái Enable = Yes, bao gồm: Basic Header Block - LT Identifier Application Header Input - Receiver's Address Application Header Output - Full input SWIFT address | H22: Medium | I22: Manual | J22: Passed | K22: Passed | L22: Passed | O22: =LEFT(A22, FIND(".", A22) - 1) -> MT196
A23: MT196.02 | B23: Kiểm tra điện MT196 - Webservice COUNTRY AND CITY được gán tương ứng với các trường trong điện | D23: 1. Login hệ thống TF bằng user admin 2. Truy cập theo đường dẫn Financial Services Analytical Applications Transactions Filtering/ Financial Services Sanctions Pack/ SWIFT Configuration Admin 3. Chọn điện MT196 trên drop down list 4. Sau khi bấm nút Save, click liên tiếp 2 lần button mũi tên sang phải (>) ở bên cạnh. 5. Chọn webservice COUNTRY AND CITY trên dropdown list Screening webservice trên màn hình và kiểm tra các tags tương ứng được gán | F23: Thông tin hiển thị các field, field name tương ứng theo từng webservice đảm bảo đủ, đúng theo yêu cầu, có trạng thái Enable = Yes, bao gồm: Basic Header Block - LT Identifier Application Header Input - Receiver's Address Application Header Output - Full input SWIFT address | H23: Medium | I23: Manual | J23: Passed | K23: Passed | L23: Passed | O23: =LEFT(A23, FIND(".", A23) - 1) -> MT196
A24: MT196.03 | B24: Kiểm tra điện MT196 - Webservice NARRATIVE được gán tương ứng với các trường trong điện | D24: 1. Login hệ thống TF bằng user admin 2. Truy cập theo đường dẫn Financial Services Analytical Applications Transactions Filtering/ Financial Services Sanctions Pack/ SWIFT Configuration Admin 3. Chọn điện MT196 trên drop down list 4. Sau khi bấm nút Save, click liên tiếp 2 lần button mũi tên sang phải (>) ở bên cạnh. 5. Chọn webservice NARRATIVE trên dropdown list Screening webservice trên màn hình và kiểm tra các tags tương ứng được gán | F24: Thông tin hiển thị các field, field name tương ứng theo từng webservice đảm bảo đủ, đúng theo yêu cầu, có trạng thái Enable = Yes, bao gồm: 76 - Answers 77A - Narrative 79 - Narrative Description of the Original Message to Which the Answer Relates Copy of at least the Mandatory Fields of the Original Message | H24: Medium | I24: Manual | J24: Passed | K24: Passed | L24: Passed | O24: =LEFT(A24, FIND(".", A24) - 1) -> MT196
A25: MT196.04 | B25: Kiểm tra điện MT196 - Webservice NAME AND ADDRESS được gán tương ứng với các trường trong điện | D25: 1. Login hệ thống TF bằng user admin 2. Truy cập theo đường dẫn Financial Services Analytical Applications Transactions Filtering/ Financial Services Sanctions Pack/ SWIFT Configuration Admin 3. Chọn điện MT196 trên drop down list 4. Sau khi bấm nút Save, click liên tiếp 2 lần button mũi tên sang phải (>) ở bên cạnh. 5. Chọn webservice NAME AND ADDRESS trên dropdown list Screening webservice trên màn hình và kiểm tra các tags tương ứng được gán | F25: Thông tin hiển thị các field, field name tương ứng theo từng webservice đảm bảo đủ, đúng theo yêu cầu, có trạng thái Enable = Yes, bao gồm: Basic Header Block - LT Identifier Application Header Input - Receiver's Address Application Header Output - Full input SWIFT address | H25: Medium | I25: Manual | J25: Passed | K25: Passed | L25: Passed | O25: =LEFT(A25, FIND(".", A25) - 1) -> MT196
B26: Kiểm tra config các trường của điện MT199 | O26: =LEFT(A26, FIND(".", A26) - 1) -> #VALUE!
A27: MT199.01 | B27: Kiểm tra điện MT199 - Webservice IDENTIFIER được gán tương ứng với các trường trong điện | D27: 1. Login hệ thống TF bằng user admin 2. Truy cập theo đường dẫn Financial Services Analytical Applications Transactions Filtering/ Financial Services Sanctions Pack/ SWIFT Configuration Admin 3. Chọn điện MT199 trên drop down list 4. Sau khi bấm nút Save, click liên tiếp 2 lần button mũi tên sang phải (>) ở bên cạnh. 5. Chọn webservice IDENTIFIER trên dropdown list Screening webservice trên màn hình và kiểm tra các tags tương ứng được gán | F27: Thông tin hiển thị các field, field name tương ứng theo từng webservice đảm bảo đủ, đúng theo yêu cầu, có trạng thái Enable = Yes, bao gồm: Basic Header Block - LT Identifier Application Header Input - Receiver's Address Application Header Output - Full input SWIFT address | H27: Medium | I27: Manual | J27: Passed | K27: Passed | L27: Passed | O27: =LEFT(A27, FIND(".", A27) - 1) -> MT199
A28: MT199.02 | B28: Kiểm tra điện MT199 - Webservice COUNTRY AND CITY được gán tương ứng với các trường trong điện | D28: 1. Login hệ thống TF bằng user admin 2. Truy cập theo đường dẫn Financial Services Analytical Applications Transactions Filtering/ Financial Services Sanctions Pack/ SWIFT Configuration Admin 3. Chọn điện MT199 trên drop down list 4. Sau khi bấm nút Save, click liên tiếp 2 lần button mũi tên sang phải (>) ở bên cạnh. 5. Chọn webservice COUNTRY AND CITY trên dropdown list Screening webservice trên màn hình và kiểm tra các tags tương ứng được gán | F28: Thông tin hiển thị các field, field name tương ứng theo từng webservice đảm bảo đủ, đúng theo yêu cầu, có trạng thái Enable = Yes, bao gồm: Basic Header Block - LT Identifier Application Header Input - Receiver's Address Application Header Output - Full input SWIFT address | H28: Medium | I28: Manual | J28: Passed | K28: Passed | L28: Passed | O28: =LEFT(A28, FIND(".", A28) - 1) -> MT199
A29: MT199.03 | B29: Kiểm tra điện MT199 - Webservice NARRATIVE được gán tương ứng với các trường trong điện | D29: 1. Login hệ thống TF bằng user admin 2. Truy cập theo đường dẫn Financial Services Analytical Applications Transactions Filtering/ Financial Services Sanctions Pack/ SWIFT Configuration Admin 3. Chọn điện MT199 trên drop down list 4. Sau khi bấm nút Save, click liên tiếp 2 lần button mũi tên sang phải (>) ở bên cạnh. 5. Chọn webservice NARRATIVE trên dropdown list Screening webservice trên màn hình và kiểm tra các tags tương ứng được gán | F29: Thông tin hiển thị các field, field name tương ứng theo từng webservice đảm bảo đủ, đúng theo yêu cầu, có trạng thái Enable = Yes, bao gồm: 79 - Narrative | H29: Medium | I29: Manual | J29: Passed | K29: Passed | L29: Passed | O29: =LEFT(A29, FIND(".", A29) - 1) -> MT199
A30: MT199.04 | B30: Kiểm tra điện MT199 - Webservice NAME AND ADDRESS được gán tương ứng với các trường trong điện | D30: 1. Login hệ thống TF bằng user admin 2. Truy cập theo đường dẫn Financial Services Analytical Applications Transactions Filtering/ Financial Services Sanctions Pack/ SWIFT Configuration Admin 3. Chọn điện MT199 trên drop down list 4. Sau khi bấm nút Save, click liên tiếp 2 lần button mũi tên sang phải (>) ở bên cạnh. 5. Chọn webservice NAME AND ADDRESS trên dropdown list Screening webservice trên màn hình và kiểm tra các tags tương ứng được gán | F30: Thông tin hiển thị các field, field name tương ứng theo từng webservice đảm bảo đủ, đúng theo yêu cầu, có trạng thái Enable = Yes, bao gồm: Basic Header Block - LT Identifier Application Header Input - Receiver's Address Application Header Output - Full input SWIFT address | H30: Medium | I30: Manual | J30: Passed | K30: Passed | L30: Passed | O30: =LEFT(A30, FIND(".", A30) - 1) -> MT199
B31: Kiểm tra config các trường của điện MT295 | O31: =LEFT(A31, FIND(".", A31) - 1) -> #VALUE!
A32: MT295.01 | B32: Kiểm tra điện MT295 - Webservice IDENTIFIER được gán tương ứng với các trường trong điện | D32: 1. Login hệ thống TF bằng user admin 2. Truy cập theo đường dẫn Financial Services Analytical Applications Transactions Filtering/ Financial Services Sanctions Pack/ SWIFT Configuration Admin 3. Chọn điện MT295 trên drop down list 4. Sau khi bấm nút Save, click liên tiếp 2 lần button mũi tên sang phải (>) ở bên cạnh. 5. Chọn webservice IDENTIFIER trên dropdown list Screening webservice trên màn hình và kiểm tra các tags tương ứng được gán | F32: Thông tin hiển thị các field, field name tương ứng theo từng webservice đảm bảo đủ, đúng theo yêu cầu, có trạng thái Enable = Yes, bao gồm: Basic Header Block - LT Identifier Application Header Input - Receiver's Address Application Header Output - Full input SWIFT address | H32: Medium | I32: Manual | J32: Passed | K32: Passed | L32: Passed | O32: =LEFT(A32, FIND(".", A32) - 1) -> MT295
A33: MT295.02 | B33: Kiểm tra điện MT295 - Webservice COUNTRY AND CITY được gán tương ứng với các trường trong điện | D33: 1. Login hệ thống TF bằng user admin 2. Truy cập theo đường dẫn Financial Services Analytical Applications Transactions Filtering/ Financial Services Sanctions Pack/ SWIFT Configuration Admin 3. Chọn điện MT295 trên drop down list 4. Sau khi bấm nút Save, click liên tiếp 2 lần button mũi tên sang phải (>) ở bên cạnh. 5. Chọn webservice COUNTRY AND CITY trên dropdown list Screening webservice trên màn hình và kiểm tra các tags tương ứng được gán | F33: Thông tin hiển thị các field, field name tương ứng theo từng webservice đảm bảo đủ, đúng theo yêu cầu, có trạng thái Enable = Yes, bao gồm: Basic Header Block - LT Identifier Application Header Input - Receiver's Address Application Header Output - Full input SWIFT address | H33: Medium | I33: Manual | J33: Passed | K33: Passed | L33: Passed | O33: =LEFT(A33, FIND(".", A33) - 1) -> MT295
A34: MT295.03 | B34: Kiểm tra điện MT295 - Webservice NARRATIVE được gán tương ứng với các trường trong điện | D34: 1. Login hệ thống TF bằng user admin 2. Truy cập theo đường dẫn Financial Services Analytical Applications Transactions Filtering/ Financial Services Sanctions Pack/ SWIFT Configuration Admin 3. Chọn điện MT295 trên drop down list 4. Sau khi bấm nút Save, click liên tiếp 2 lần button mũi tên sang phải (>) ở bên cạnh. 5. Chọn webservice NARRATIVE trên dropdown list Screening webservice trên màn hình và kiểm tra các tags tương ứng được gán | F34: Thông tin hiển thị các field, field name tương ứng theo từng webservice đảm bảo đủ, đúng theo yêu cầu, có trạng thái Enable = Yes, bao gồm: 75 - Queries 77A - Narrative 79 - Narrative Description of the Message to Which the Query Relates Copy of at least the Mandatory Fields of the Original Message | H34: Medium | I34: Manual | J34: Passed | K34: Passed | L34: Passed | O34: =LEFT(A34, FIND(".", A34) - 1) -> MT295
A35: MT295.04 | B35: Kiểm tra điện MT295 - Webservice NAME AND ADDRESS được gán tương ứng với các trường trong điện | D35: 1. Login hệ thống TF bằng user admin 2. Truy cập theo đường dẫn Financial Services Analytical Applications Transactions Filtering/ Financial Services Sanctions Pack/ SWIFT Configuration Admin 3. Chọn điện MT295 trên drop down list 4. Sau khi bấm nút Save, click liên tiếp 2 lần button mũi tên sang phải (>) ở bên cạnh. 5. Chọn webservice NAME AND ADDRESS trên dropdown list Screening webservice trên màn hình và kiểm tra các tags tương ứng được gán | F35: Thông tin hiển thị các field, field name tương ứng theo từng webservice đảm bảo đủ, đúng theo yêu cầu, có trạng thái Enable = Yes, bao gồm: Basic Header Block - LT Identifier Application Header Input - Receiver's Address Application Header Output - Full input SWIFT address | H35: Medium | I35: Manual | J35: Passed | K35: Passed | L35: Passed | O35: =LEFT(A35, FIND(".", A35) - 1) -> MT295
B36: Kiểm tra config các trường của điện MT296 | O36: =LEFT(A36, FIND(".", A36) - 1) -> #VALUE!
A37: MT296.01 | B37: Kiểm tra điện MT296 - Webservice IDENTIFIER được gán tương ứng với các trường trong điện | D37: 1. Login hệ thống TF bằng user admin 2. Truy cập theo đường dẫn Financial Services Analytical Applications Transactions Filtering/ Financial Services Sanctions Pack/ SWIFT Configuration Admin 3. Chọn điện MT296 trên drop down list 4. Sau khi bấm nút Save, click liên tiếp 2 lần button mũi tên sang phải (>) ở bên cạnh. 5. Chọn webservice IDENTIFIER trên dropdown list Screening webservice trên màn hình và kiểm tra các tags tương ứng được gán | F37: Thông tin hiển thị các field, field name tương ứng theo từng webservice đảm bảo đủ, đúng theo yêu cầu, có trạng thái Enable = Yes, bao gồm: Basic Header Block - LT Identifier Application Header Input - Receiver's Address Application Header Output - Full input SWIFT address | H37: Medium | I37: Manual | J37: Passed | K37: Passed | L37: Untested | O37: =LEFT(A37, FIND(".", A37) - 1) -> MT296
A38: MT296.02 | B38: Kiểm tra điện MT296 - Webservice COUNTRY AND CITY được gán tương ứng với các trường trong điện | D38: 1. Login hệ thống TF bằng user admin 2. Truy cập theo đường dẫn Financial Services Analytical Applications Transactions Filtering/ Financial Services Sanctions Pack/ SWIFT Configuration Admin 3. Chọn điện MT296 trên drop down list 4. Sau khi bấm nút Save, click liên tiếp 2 lần button mũi tên sang phải (>) ở bên cạnh. 5. Chọn webservice COUNTRY AND CITY trên dropdown list Screening webservice trên màn hình và kiểm tra các tags tương ứng được gán | F38: Thông tin hiển thị các field, field name tương ứng theo từng webservice đảm bảo đủ, đúng theo yêu cầu, có trạng thái Enable = Yes, bao gồm: Basic Header Block - LT Identifier Application Header Input - Receiver's Address Application Header Output - Full input SWIFT address | H38: Medium | I38: Manual | J38: Passed | K38: Passed | L38: Untested | O38: =LEFT(A38, FIND(".", A38) - 1) -> MT296
A39: MT296.03 | B39: Kiểm tra điện MT296 - Webservice NARRATIVE được gán tương ứng với các trường trong điện | D39: 1. Login hệ thống TF bằng user admin 2. Truy cập theo đường dẫn Financial Services Analytical Applications Transactions Filtering/ Financial Services Sanctions Pack/ SWIFT Configuration Admin 3. Chọn điện MT296 trên drop down list 4. Sau khi bấm nút Save, click liên tiếp 2 lần button mũi tên sang phải (>) ở bên cạnh. 5. Chọn webservice NARRATIVE trên dropdown list Screening webservice trên màn hình và kiểm tra các tags tương ứng được gán | F39: Thông tin hiển thị các field, field name tương ứng theo từng webservice đảm bảo đủ, đúng theo yêu cầu, có trạng thái Enable = Yes, bao gồm: 76 - Answers 77A - Narrative 79 - Narrative Description of the Message to Which the Query Relates Copy of at least the Mandatory Fields of the Original Message | H39: Medium | I39: Manual | J39: Passed | K39: Passed | L39: Untested | O39: =LEFT(A39, FIND(".", A39) - 1) -> MT296
A40: MT296.04 | B40: Kiểm tra điện MT296 - Webservice NAME AND ADDRESS được gán tương ứng với các trường trong điện | D40: 1. Login hệ thống TF bằng user admin 2. Truy cập theo đường dẫn Financial Services Analytical Applications Transactions Filtering/ Financial Services Sanctions Pack/ SWIFT Configuration Admin 3. Chọn điện MT296 trên drop down list 4. Sau khi bấm nút Save, click liên tiếp 2 lần button mũi tên sang phải (>) ở bên cạnh. 5. Chọn webservice NAME AND ADDRESS trên dropdown list Screening webservice trên màn hình và kiểm tra các tags tương ứng được gán | F40: Thông tin hiển thị các field, field name tương ứng theo từng webservice đảm bảo đủ, đúng theo yêu cầu, có trạng thái Enable = Yes, bao gồm: Basic Header Block - LT Identifier Application Header Input - Receiver's Address Application Header Output - Full input SWIFT address | H40: Medium | I40: Manual | J40: Passed | K40: Passed | L40: Untested | O40: =LEFT(A40, FIND(".", A40) - 1) -> MT296
B41: Kiểm tra config các trường của điện MT299 | O41: =LEFT(A41, FIND(".", A41) - 1) -> #VALUE!
A42: MT299.01 | B42: Kiểm tra điện MT299 - Webservice IDENTIFIER được gán tương ứng với các trường trong điện | D42: 1. Login hệ thống TF bằng user admin 2. Truy cập theo đường dẫn Financial Services Analytical Applications Transactions Filtering/ Financial Services Sanctions Pack/ SWIFT Configuration Admin 3. Chọn điện MT299 trên drop down list 4. Sau khi bấm nút Save, click liên tiếp 2 lần button mũi tên sang phải (>) ở bên cạnh. 5. Chọn webservice IDENTIFIER trên dropdown list Screening webservice trên màn hình và kiểm tra các tags tương ứng được gán | F42: Thông tin hiển thị các field, field name tương ứng theo từng webservice đảm bảo đủ, đúng theo yêu cầu, có trạng thái Enable = Yes, bao gồm: Basic Header Block - LT Identifier Application Header Input - Receiver's Address Application Header Output - Full input SWIFT address | H42: Medium | I42: Manual | J42: Passed | K42: Passed | L42: Untested | O42: =LEFT(A42, FIND(".", A42) - 1) -> MT299
A43: MT299.02 | B43: Kiểm tra điện MT299 - Webservice COUNTRY AND CITY được gán tương ứng với các trường trong điện | D43: 1. Login hệ thống TF bằng user admin 2. Truy cập theo đường dẫn Financial Services Analytical Applications Transactions Filtering/ Financial Services Sanctions Pack/ SWIFT Configuration Admin 3. Chọn điện MT299 trên drop down list 4. Sau khi bấm nút Save, click liên tiếp 2 lần button mũi tên sang phải (>) ở bên cạnh. 5. Chọn webservice COUNTRY AND CITY trên dropdown list Screening webservice trên màn hình và kiểm tra các tags tương ứng được gán | F43: Thông tin hiển thị các field, field name tương ứng theo từng webservice đảm bảo đủ, đúng theo yêu cầu, có trạng thái Enable = Yes, bao gồm: Basic Header Block - LT Identifier Application Header Input - Receiver's Address Application Header Output - Full input SWIFT address | H43: Medium | I43: Manual | J43: Passed | K43: Passed | L43: Untested | O43: =LEFT(A43, FIND(".", A43) - 1) -> MT299
...

Sheet Cấu hình chủ thể
A1: Functions | B1: Config EDQ
A2: Build Version | B2: v1.0
B4: High | C4: Medium | D4: Low | E4: Total
C5: =SUM(C6:C11) -> 134 | D5: =SUM(D6:D11) -> 0 | E5: =SUM(B5:D5) -> 134
A6: Passed | B6: =COUNTIFS($K:$K, $A$6,$H:$H,B$4) -> 0 | C6: =COUNTIFS($K:$K, $A$6,$H:$H,C$4) -> 86 | D6: =COUNTIFS($K:$K, $A$6,$H:$H,D$4) -> 0 | E6: =SUM(B6:D6) -> 86
A7: Failed | B7: =COUNTIFS($K:$K, $A$7,$H:$H,B$4) -> 0 | C7: =COUNTIFS($K:$K, $A$7,$H:$H,C$4) -> 0 | D7: =COUNTIFS($K:$K, $A$7,$H:$H,D$4) -> 0 | E7: =SUM(B7:D7) -> 0
A8: Pending | B8: =COUNTIFS($K:$K, $A$8,H:H,B$4) -> 0 | C8: =COUNTIFS($K:$K, $A$8,I:I,C$4) -> 0 | D8: =COUNTIFS($K:$K, $A$8,J:J,D$4) -> 0 | E8: =SUM(B8:D8) -> 0
A9: Untested | B9: =COUNTIFS($K:$K, $A$9,$H:$H,B$4) -> 6 | C9: =COUNTIFS($K:$K, $A$9,$H:$H,C$4) -> 48 | D9: =COUNTIFS($K:$K, $A$9,$H:$H,D$4) -> 0 | E9: =SUM(B9:D9) -> 54
A10: Cancel | B10: =COUNTIFS($K:$K, $A$10,$H:$H,B$4) -> 0 | C10: =COUNTIFS($K:$K, $A$10,$H:$H,C$4) -> 0 | D10: =COUNTIFS($K:$K, $A$10,$H:$H,D$4) -> 0 | E10: =SUM(B10:D10) -> 0
A11: Next | B11: =COUNTIFS($K:$K,$A$11,$H:$H,B$4) -> 0 | C11: =COUNTIFS($K:$K,$A$11,$H:$H,C$4) -> 0 | D11: =COUNTIFS($K:$K,$A$11,$H:$H,D$4) -> 0 | E11: =SUM(B11:D11) -> 0
A14: Test case Id | B14: Test case Title | C14: Pre-conditions | D14: Test Step | E14: Test Datas | F14: Expected result | G14: Test Environment | H14: Priority | I14: Automation Status | J14: 1st Test Results | K14: 2nd Test Results | L14: 3rd Test Results | M14: BugID | N14: Notes
B15: Kiểm tra cấu hình sàng lọc trường dữ liệu với chủ thể đối với điện MT195
A16: MT195_Config_EDQ.01 | B16: Kiểm tra các trường sàng lọc Narrative theo tất cả chủ thể | D16: 1. NSD đăng nhập EDQ Director bằng user được phân quyền 2. NSD truy cập theo đường dẫn Project/Transaction_Screening/ Reference Data/ MSB_TYPE_FOR_OBJ 3. Kiểm tra danh sách các trường được config với Type = "MT195" Webservice_Name = 4 và ENTITY = 'ALL' | F16: 3. Các trường config bao gồm: 75 77A 79 Additional data | H16: Medium | I16: Manual | J16: Passed | K16: Passed | L16: Passed | O16: =LEFT(A16, FIND("_", A16) - 1) -> MT195
A17: MT195_Config_EDQ.02 | B17: Kiểm tra các trường sàng lọc Name and Address theo chủ thể Entity | D17: 1. NSD đăng nhập EDQ Director bằng user được phân quyền 2. NSD truy cập theo đường dẫn Project/Transaction_Screening/ Reference Data/ MSB_TYPE_FOR_OBJ 3. Kiểm tra danh sách các trường được config với Type = "MT195" Webservice_Name = 1 và ENTITY = 'ENT' | F17: 3. Các trường config bao gồm: Basic Header Block Application Header - Input Application Header - Output | H17: Medium | I17: Manual | J17: Passed | K17: Passed | L17: Passed | O17: =LEFT(A17, FIND("_", A17) - 1) -> MT195
A18: MT195_Config_EDQ.03 | B18: Kiểm tra các trường sàng lọc Identifier theo chủ thể Entity | D18: 1. NSD đăng nhập EDQ Director bằng user được phân quyền 2. NSD truy cập theo đường dẫn Project/Transaction_Screening/ Reference Data/ MSB_TYPE_FOR_OBJ 3. Kiểm tra danh sách các trường được config với Type = "MT195" Webservice_Name = 2 và ENTITY = 'ENT' | F18: 3. Các trường config bao gồm: Basic Header Block Application Header - Input Application Header - Output | H18: Medium | I18: Manual | J18: Passed | K18: Passed | L18: Passed | O18: =LEFT(A18, FIND("_", A18) - 1) -> MT195
A19: MT195_Config_EDQ.04 | B19: Kiểm tra các trường sàng lọc Country | D19: 1. NSD đăng nhập EDQ Director bằng user được phân quyền 2. NSD truy cập theo đường dẫn Project/Transaction_Screening/ Reference Data/ MSB_TYPE_FOR_OBJ 3. Kiểm tra danh sách các trường được config với Type = "MT195" Webservice_Name = 3 và ENTITY = 'All' | F19: 3. Các trường config bao gồm: Basic Header Block Application Header - Input Application Header - Output | H19: Medium | I19: Manual | J19: Passed | K19: Passed | L19: Passed | O19: =LEFT(A19, FIND("_", A19) - 1) -> MT195
B20: Kiểm tra cấu hình sàng lọc trường dữ liệu với chủ thể đối với điện MT196
A21: MT196_Config_EDQ.01 | B21: Kiểm tra các trường sàng lọc Narrative theo tất cả chủ thể | D21: 1. NSD đăng nhập EDQ Director bằng user được phân quyền 2. NSD truy cập theo đường dẫn Project/Transaction_Screening/ Reference Data/ MSB_TYPE_FOR_OBJ 3. Kiểm tra danh sách các trường được config với Type = "MT196" Webservice_Name = 4 và ENTITY = 'ALL' | F21: 3. Các trường config bao gồm: 76 77A 79 Additional data | H21: Medium | I21: Manual | J21: Passed | K21: Passed | L21: Passed | O21: =LEFT(A21, FIND("_", A21) - 1) -> MT196
A22: MT196_Config_EDQ.02 | B22: Kiểm tra các trường sàng lọc Name and Address theo chủ thể Entity | D22: 1. NSD đăng nhập EDQ Director bằng user được phân quyền 2. NSD truy cập theo đường dẫn Project/Transaction_Screening/ Reference Data/ MSB_TYPE_FOR_OBJ 3. Kiểm tra danh sách các trường được config với Type = "MT196" Webservice_Name = 1 và ENTITY = 'ENT' | F22: 3. Các trường config bao gồm: Basic Header Block Application Header - Input Application Header - Output | H22: Medium | I22: Manual | J22: Passed | K22: Passed | L22: Passed | O22: =LEFT(A22, FIND("_", A22) - 1) -> MT196
A23: MT196_Config_EDQ.03 | B23: Kiểm tra các trường sàng lọc Identifier theo chủ thể Entity | D23: 1. NSD đăng nhập EDQ Director bằng user được phân quyền 2. NSD truy cập theo đường dẫn Project/Transaction_Screening/ Reference Data/ MSB_TYPE_FOR_OBJ 3. Kiểm tra danh sách các trường được config với Type = "MT196" Webservice_Name = 2 và ENTITY = 'ENT' | F23: 3. Các trường config bao gồm: Basic Header Block Application Header - Input Application Header - Output | H23: Medium | I23: Manual | J23: Passed | K23: Passed | L23: Passed | O23: =LEFT(A23, FIND("_", A23) - 1) -> MT196
A24: MT196_Config_EDQ.04 | B24: Kiểm tra các trường sàng lọc Country | D24: 1. NSD đăng nhập EDQ Director bằng user được phân quyền 2. NSD truy cập theo đường dẫn Project/Transaction_Screening/ Reference Data/ MSB_TYPE_FOR_OBJ 3. Kiểm tra danh sách các trường được config với Type = "MT196" Webservice_Name = 3 và ENTITY = 'All' | F24: 3. Các trường config bao gồm: Basic Header Block Application Header - Input Application Header - Output | H24: Medium | I24: Manual | J24: Passed | K24: Passed | L24: Passed | O24: =LEFT(A24, FIND("_", A24) - 1) -> MT196
B25: Kiểm tra cấu hình sàng lọc trường dữ liệu với chủ thể đối với điện MT199 | O25: =LEFT(A25, FIND("_", A25) - 1) -> #VALUE!
A26: MT199_Config_EDQ.01 | B26: Kiểm tra các trường sàng lọc Narrative theo tất cả chủ thể | D26: 1. NSD đăng nhập EDQ Director bằng user được phân quyền 2. NSD truy cập theo đường dẫn Project/Transaction_Screening/ Reference Data/ MSB_TYPE_FOR_OBJ 3. Kiểm tra danh sách các trường được config với Type = "MT199" Webservice_Name = 4 và ENTITY = 'ALL' | F26: 3. Các trường config bao gồm: 79 Additional data | H26: Medium | I26: Manual | J26: Passed | K26: Passed | L26: Passed | O26: =LEFT(A26, FIND("_", A26) - 1) -> MT199
A27: MT199_Config_EDQ.02 | B27: Kiểm tra các trường sàng lọc Name and Address theo chủ thể Entity | D27: 1. NSD đăng nhập EDQ Director bằng user được phân quyền 2. NSD truy cập theo đường dẫn Project/Transaction_Screening/ Reference Data/ MSB_TYPE_FOR_OBJ 3. Kiểm tra danh sách các trường được config với Type = "MT199" Webservice_Name = 1 và ENTITY = 'ENT' | F27: 3. Các trường config bao gồm: Basic Header Block Application Header - Input Application Header - Output | H27: Medium | I27: Manual | J27: Passed | K27: Passed | L27: Passed | O27: =LEFT(A27, FIND("_", A27) - 1) -> MT199
A28: MT199_Config_EDQ.03 | B28: Kiểm tra các trường sàng lọc Identifier theo chủ thể Entity | D28: 1. NSD đăng nhập EDQ Director bằng user được phân quyền 2. NSD truy cập theo đường dẫn Project/Transaction_Screening/ Reference Data/ MSB_TYPE_FOR_OBJ 3. Kiểm tra danh sách các trường được config với Type = "MT199" Webservice_Name = 2 và ENTITY = 'ENT' | F28: 3. Các trường config bao gồm: Basic Header Block Application Header - Input Application Header - Output | H28: Medium | I28: Manual | J28: Passed | K28: Passed | L28: Passed | O28: =LEFT(A28, FIND("_", A28) - 1) -> MT199
A29: MT199_Config_EDQ.04 | B29: Kiểm tra các trường sàng lọc Country | D29: 1. NSD đăng nhập EDQ Director bằng user được phân quyền 2. NSD truy cập theo đường dẫn Project/Transaction_Screening/ Reference Data/ MSB_TYPE_FOR_OBJ 3. Kiểm tra danh sách các trường được config với Type = "MT760" Webservice_Name = 3 và ENTITY = 'All' | F29: 3. Các trường config bao gồm: Basic Header Block Application Header - Input Application Header - Output | H29: Medium | I29: Manual | J29: Passed | K29: Passed | L29: Passed | O29: =LEFT(A29, FIND("_", A29) - 1) -> MT199
B30: Kiểm tra cấu hình sàng lọc trường dữ liệu với chủ thể đối với điện MT295 | O30: =LEFT(A30, FIND("_", A30) - 1) -> #VALUE!
A31: MT295_Config_EDQ.01 | B31: Kiểm tra các trường sàng lọc Narrative theo tất cả chủ thể | D31: 1. NSD đăng nhập EDQ Director bằng user được phân quyền 2. NSD truy cập theo đường dẫn Project/Transaction_Screening/ Reference Data/ MSB_TYPE_FOR_OBJ 3. Kiểm tra danh sách các trường được config với Type = "MT295" Webservice_Name = 4 và ENTITY = 'ALL' | F31: 3. Các trường config bao gồm: 75 77A 79 Additional data | H31: Medium | I31: Manual | J31: Passed | K31: Passed | L31: Passed | O31: =LEFT(A31, FIND("_", A31) - 1) -> MT295
A32: MT295_Config_EDQ.02 | B32: Kiểm tra các trường sàng lọc Name and Address theo chủ thể Entity | D32: 1. NSD đăng nhập EDQ Director bằng user được phân quyền 2. NSD truy cập theo đường dẫn Project/Transaction_Screening/ Reference Data/ MSB_TYPE_FOR_OBJ 3. Kiểm tra danh sách các trường được config với Type = "MT295" Webservice_Name = 1 và ENTITY = 'ENT' | F32: 3. Các trường config bao gồm: Basic Header Block Application Header - Input Application Header - Output | H32: Medium | I32: Manual | J32: Passed | K32: Passed | L32: Passed | O32: =LEFT(A32, FIND("_", A32) - 1) -> MT295
A33: MT295_Config_EDQ.03 | B33: Kiểm tra các trường sàng lọc Identifier theo chủ thể Entity | D33: 1. NSD đăng nhập EDQ Director bằng user được phân quyền 2. NSD truy cập theo đường dẫn Project/Transaction_Screening/ Reference Data/ MSB_TYPE_FOR_OBJ 3. Kiểm tra danh sách các trường được config với Type = "MT295" Webservice_Name = 2 và ENTITY = 'ENT' | F33: 3. Các trường config bao gồm: Basic Header Block Application Header - Input Application Header - Output | H33: Medium | I33: Manual | J33: Passed | K33: Passed | L33: Passed | O33: =LEFT(A33, FIND("_", A33) - 1) -> MT295
A34: MT295_Config_EDQ.04 | B34: Kiểm tra các trường sàng lọc Country | D34: 1. NSD đăng nhập EDQ Director bằng user được phân quyền 2. NSD truy cập theo đường dẫn Project/Transaction_Screening/ Reference Data/ MSB_TYPE_FOR_OBJ 3. Kiểm tra danh sách các trường được config với Type = "MT295" Webservice_Name = 3 và ENTITY = 'All' | F34: 3. Các trường config bao gồm: Basic Header Block Application Header - Input Application Header - Output | H34: Medium | I34: Manual | J34: Passed | K34: Passed | L34: Passed | O34: =LEFT(A34, FIND("_", A34) - 1) -> MT295
B35: Kiểm tra cấu hình sàng lọc trường dữ liệu với chủ thể đối với điện MT296 | O35: =LEFT(A35, FIND("_", A35) - 1) -> #VALUE!
A36: MT296_Config_EDQ.01 | B36: Kiểm tra các trường sàng lọc Narrative theo tất cả chủ thể | D36: 1. NSD đăng nhập EDQ Director bằng user được phân quyền 2. NSD truy cập theo đường dẫn Project/Transaction_Screening/ Reference Data/ MSB_TYPE_FOR_OBJ 3. Kiểm tra danh sách các trường được config với Type = "MT296" Webservice_Name = 4 và ENTITY = 'ALL' | F36: 3. Các trường config bao gồm: 76 77A 79 Additional data | H36: Medium | I36: Manual | J36: Passed | K36: Passed | L36: Passed | O36: =LEFT(A36, FIND("_", A36) - 1) -> MT296
A37: MT296_Config_EDQ.02 | B37: Kiểm tra các trường sàng lọc Name and Address theo chủ thể Entity | D37: 1. NSD đăng nhập EDQ Director bằng user được phân quyền 2. NSD truy cập theo đường dẫn Project/Transaction_Screening/ Reference Data/ MSB_TYPE_FOR_OBJ 3. Kiểm tra danh sách các trường được config với Type = "MT296" Webservice_Name = 1 và ENTITY = 'ENT' | F37: 3. Các trường config bao gồm: Basic Header Block Application Header - Input Application Header - Output | H37: Medium | I37: Manual | J37: Passed | K37: Passed | L37: Passed | O37: =LEFT(A37, FIND("_", A37) - 1) -> MT296
A38: MT296_Config_EDQ.03 | B38: Kiểm tra các trường sàng lọc Identifier theo chủ thể Entity | D38: 1. NSD đăng nhập EDQ Director bằng user được phân quyền 2. NSD truy cập theo đường dẫn Project/Transaction_Screening/ Reference Data/ MSB_TYPE_FOR_OBJ 3. Kiểm tra danh sách các trường được config với Type = "MT296" Webservice_Name = 2 và ENTITY = 'ENT' | F38: 3. Các trường config bao gồm: Basic Header Block Application Header - Input Application Header - Output | H38: Medium | I38: Manual | J38: Passed | K38: Passed | L38: Passed | O38: =LEFT(A38, FIND("_", A38) - 1) -> MT296
A39: MT296_Config_EDQ.04 | B39: Kiểm tra các trường sàng lọc Country | D39: 1. NSD đăng nhập EDQ Director bằng user được phân quyền 2. NSD truy cập theo đường dẫn Project/Transaction_Screening/ Reference Data/ MSB_TYPE_FOR_OBJ 3. Kiểm tra danh sách các trường được config với Type = "MT296" Webservice_Name = 3 và ENTITY = 'All' | F39: 3. Các trường config bao gồm: Basic Header Block Application Header - Input Application Header - Output | H39: Medium | I39: Manual | J39: Passed | K39: Passed | L39: Passed | O39: =LEFT(A39, FIND("_", A39) - 1) -> MT296
B40: Kiểm tra cấu hình sàng lọc trường dữ liệu với chủ thể đối với điện MT299 | O40: =LEFT(A40, FIND("_", A40) - 1) -> #VALUE!
A41: MT299_Config_EDQ.01 | B41: Kiểm tra các trường sàng lọc Narrative theo tất cả chủ thể | D41: 1. NSD đăng nhập EDQ Director bằng user được phân quyền 2. NSD truy cập theo đường dẫn Project/Transaction_Screening/ Reference Data/ MSB_TYPE_FOR_OBJ 3. Kiểm tra danh sách các trường được config với Type = "MT299" Webservice_Name = 4 và ENTITY = 'ALL' | F41: 3. Các trường config bao gồm: 79 | H41: Medium | I41: Manual | J41: Passed | K41: Passed | L41: Untested | O41: =LEFT(A41, FIND("_", A41) - 1) -> MT299
A42: MT299_Config_EDQ.02 | B42: Kiểm tra các trường sàng lọc Name and Address theo chủ thể Entity | D42: 1. NSD đăng nhập EDQ Director bằng user được phân quyền 2. NSD truy cập theo đường dẫn Project/Transaction_Screening/ Reference Data/ MSB_TYPE_FOR_OBJ 3. Kiểm tra danh sách các trường được config với Type = "MT299" Webservice_Name = 1 và ENTITY = 'ENT' | F42: 3. Các trường config bao gồm: Basic Header Block Application Header - Input Application Header - Output | H42: Medium | I42: Manual | J42: Passed | K42: Passed | L42: Untested | O42: =LEFT(A42, FIND("_", A42) - 1) -> MT299
A43: MT299_Config_EDQ.03 | B43: Kiểm tra các trường sàng lọc Identifier theo chủ thể Entity | D43: 1. NSD đăng nhập EDQ Director bằng user được phân quyền 2. NSD truy cập theo đường dẫn Project/Transaction_Screening/ Reference Data/ MSB_TYPE_FOR_OBJ 3. Kiểm tra danh sách các trường được config với Type = "MT299" Webservice_Name = 2 và ENTITY = 'ENT' | F43: 3. Các trường config bao gồm: Basic Header Block Application Header - Input Application Header - Output | H43: Medium | I43: Manual | J43: Passed | K43: Passed | L43: Untested | O43: =LEFT(A43, FIND("_", A43) - 1) -> MT299
...

Sheet Sàng lọc điện
A1: Functions | B1: Sàng lọc giao dịch (Tổng hợp MT + MX)
A2: Build Version | B2: v1.0
A4: Trạng thái | B4: High | C4: Medium | D4: Low | E4: Total
A5: Total | E5: =SUM(B5:D5) -> 0
A6: Passed | E6: =SUM(B6:D6) -> 0 | L6: 10
A7: Failed | E7: =SUM(B7:D7) -> 0 | L7: 5
A8: Untested | E8: =SUM(B8:D8) -> 0 | L8: 115
A9: Cancel | E9: =SUM(B9:D9) -> 0
A10: Next | E10: =SUM(B10:D10) -> 0
A11: Pending | E11: =SUM(B11:D11) -> 0
A13: Loại điện | B13: Test case Id | C13: Test case Title | D13: Pre-conditions | E13: Test Step | F13: Test Datas | G13: Expected result | H13: Test Environment | I13: Priority | J13: Automation Status | K13: 1st Test Results | L13: 2nd Test Results | M13: 3rd Test Result | N13: BugID | O13: Notes
A14: Sàng lọc giao dịch MT 196
A15: MT196 | B15: MT196.01 | C15: Sàng lọc giao dịch MT 196 - Identifier, Name and Address, Country and City - Entity | E15: 1. Đẩy giao dịch vào API Post Message với trường thông tin Basic Header Block, Application Header - Input có dữ liệu nằm trong các danh sách theo dõi - Upload file thông tin giao dịch có chứa các nội dung điện giao dịch 2. Kiểm tra thông tin Event của giao dịch theo đường dẫn Financial Services Analytical Applications Transactions Filtering > Financial services Sanctions Pack > Transaction Filtering Alert List Chọn Filter, nhập thông tin tìm kiếm theo AlertID, nhấn <Search> Click mã AlertID và kiểm tra các thông tin Hoặc kiểm tra các thông tin trong file kết quả truy vấn Database | F15: {1:F01BFICCUHHAXXX0000000000} {2:I196BFICCUHHXXXXN} {3:{108:MT196TEST0001}} {4: :20:ANS2607240001 :21:NONREF :76:AMENDMENT ACCEPTED -}{5:{MAC:00000000}{CHK:1A2B3C4D5E6F}} | G15: 2. Hệ thống trả kết quả: HIT với Webservice Identifier, Name and Address, Country and City loại chủ thể Entity; đồng thời HIT danh sách Quốc gia Knock-out (quốc gia cấm vận) và không HIT với chủ thể Individual, Vessel, Aircraft Câu query kiểm tra kết quả (KET_QUA = HIT): SELECT CASE WHEN COUNT(*) = 3 THEN 'HIT' ELSE 'NO HIT' END AS KET_QUA FROM ( SELECT T.N_WEBSERVICE_ID FROM FSI_RT_AL_WLS_RESPONSE T WHERE T.N_GRP_MSG_ID = :N_GRP_MSG_ID AND T.N_WEBSERVICE_ID IN (1, 2, 3) AND T.V_TAG_NAME IN ('Basic Header Block', 'Application Header - Input') GROUP BY T.N_WEBSERVICE_ID HAVING COUNT(DISTINCT T.V_TAG_NAME) = 2 AND COUNT(CASE WHEN UPPER(NVL(T.V_MATCHED_TYPE,DECODE(T.V_MATCHED_LIST_NAME,'Blacklisted Country','ENTITY','N/A'))) = 'ENTITY' THEN 1 END) > 0 AND COUNT(CASE WHEN UPPER(T.V_MATCHED_TYPE) = 'INDIVIDUAL' THEN 1 END) = 0 AND COUNT(CASE WHEN UPPER(T.V_MATCHED_TYPE) = 'VESSEL' THEN 1 END) = 0 AND COUNT(CASE WHEN UPPER(T.V_MATCHED_TYPE) = 'AIRCRAFT' THEN 1 END) = 0 ); | I15: High | J15: Manual | K15: Passed | L15: Passed | M15: Untested | O15: Nhóm tag quét giống nhau (Identifier, Name and Address, Country and City - Entity): Basic Header Block, Application Header - Input
A16: MT196 | B16: MT196.02 | C16: Sàng lọc giao dịch MT 196 - Identifier, Name and Address, Country and City - Entity | E16: 1. Đẩy giao dịch vào API Post Message với trường thông tin Application Header - Output có dữ liệu nằm trong các danh sách theo dõi <Link URL hệ thống AML ở môi trường SIT> Path: transaction-screening/v1/transaction-screening Method: POST Request Header: Authorization: Basic Auth (Username and password to login to application) Content-Type: text/plain Accept: */* Request Body: cột Test Datas 2. Kiểm tra thông tin Event của giao dịch theo đường dẫn Financial Services Analytical Applications Transactions Filtering > Financial services Sanctions Pack > Transaction Filtering Alert List Chọn Filter, nhập thông tin tìm kiếm theo AlertID, nhấn <Search> Click mã AlertID và kiểm tra các thông tin Hoặc kiểm tra các thông tin trong file kết quả truy vấn Database | F16: {1:F01BFICCUHHAXXX0000000000} {2:O1961201260724BFICCUHHAXXX00010000012607241201N} {3:{108:MT196TEST0003}} {4: :20:ANS2607240003 :21:NONREF :76:AMENDMENT ACCEPTED -}{5:{MAC:00000000}{CHK:1A2B3C4D5E6F}} | G16: 2. Hệ thống trả kết quả: HIT với Webservice Identifier, Name and Address, Country and City loại chủ thể Entity; đồng thời HIT danh sách Quốc gia Knock-out (quốc gia cấm vận) và không HIT với chủ thể Individual, Vessel, Aircraft Câu query kiểm tra kết quả (KET_QUA = HIT): SELECT CASE WHEN COUNT(*) = 3 THEN 'HIT' ELSE 'NO HIT' END AS KET_QUA FROM ( SELECT T.N_WEBSERVICE_ID FROM FSI_RT_AL_WLS_RESPONSE T WHERE T.N_GRP_MSG_ID = :N_GRP_MSG_ID AND T.N_WEBSERVICE_ID IN (1, 2, 3) AND T.V_TAG_NAME IN ('Application Header - Output') GROUP BY T.N_WEBSERVICE_ID HAVING COUNT(DISTINCT T.V_TAG_NAME) = 1 AND COUNT(CASE WHEN UPPER(NVL(T.V_MATCHED_TYPE,DECODE(T.V_MATCHED_LIST_NAME,'Blacklisted Country','ENTITY','N/A'))) = 'ENTITY' THEN 1 END) > 0 AND COUNT(CASE WHEN UPPER(T.V_MATCHED_TYPE) = 'INDIVIDUAL' THEN 1 END) = 0 AND COUNT(CASE WHEN UPPER(T.V_MATCHED_TYPE) = 'VESSEL' THEN 1 END) = 0 AND COUNT(CASE WHEN UPPER(T.V_MATCHED_TYPE) = 'AIRCRAFT' THEN 1 END) = 0 ); | I16: High | J16: Manual | K16: Passed | L16: Passed | M16: Untested | O16: Nhóm tag quét giống nhau (Identifier, Name and Address, Country and City - Entity): Basic Header Block, Application Header - Input
A17: MT196 | B17: MT196.03 | C17: Sàng lọc giao dịch MT 196 - Narrative - All | E17: 1. Đẩy giao dịch vào API Post Message với trường thông tin 76, 77A, 79 có dữ liệu nằm trong các danh sách theo dõi <Link URL hệ thống AML ở môi trường SIT> Path: transaction-screening/v1/transaction-screening Method: POST Request Header: Authorization: Basic Auth (Username and password to login to application) Content-Type: text/plain Accept: */* Request Body: cột Test Datas 2. Kiểm tra thông tin Event của giao dịch theo đường dẫn Financial Services Analytical Applications Transactions Filtering > Financial services Sanctions Pack > Transaction Filtering Alert List Chọn Filter, nhập thông tin tìm kiếm theo AlertID, nhấn <Search> Click mã AlertID và kiểm tra các thông tin Hoặc kiểm tra các thông tin trong file kết quả truy vấn Database | F17: {1:F01SCBLSGSGAXXX0000000000} {2:I196MCOBVNVXXXXXN} {3:{108:MT196TEST0002}} {4: :20:ANS2607240002 :21:NONREF :76:0099887766 :77A:0099887766 :79:0099887766 -}{5:{MAC:00000000}{CHK:1A2B3C4D5E6F}} | G17: 2. Hệ thống trả kết quả: HIT với Webservice Narrative loại chủ thể Individual, Entity, Port, Vessel, Aircraft và danh sách Stop Keywords Câu query kiểm tra kết quả (KET_QUA = HIT): SELECT CASE WHEN COUNT(*) = 3 THEN 'HIT' ELSE 'NO HIT' END AS KET_QUA FROM ( SELECT T.V_TAG_NAME FROM FSI_RT_AL_WLS_RESPONSE T WHERE T.N_GRP_MSG_ID = :N_GRP_MSG_ID AND T.N_WEBSERVICE_ID = 4 AND T.V_TAG_NAME IN ('76', '77A', '79') GROUP BY T.V_TAG_NAME HAVING COUNT(CASE WHEN UPPER(T.V_MATCHED_TYPE) = 'ENTITY' THEN 1 END) > 0 AND COUNT(CASE WHEN UPPER(T.V_MATCHED_TYPE) = 'INDIVIDUAL' THEN 1 END) > 0 AND COUNT(CASE WHEN UPPER(T.V_MATCHED_TYPE) = 'VESSEL' THEN 1 END) > 0 AND COUNT(CASE WHEN UPPER(T.V_MATCHED_TYPE) = 'AIRCRAFT' THEN 1 END) > 0 AND COUNT(CASE WHEN UPPER(T.V_MATCHED_TYPE) = 'PORT' THEN 1 END) > 0 AND COUNT(CASE WHEN UPPER(T.V_MATCHED_TYPE) = 'STK' THEN 1 END) > 0 ); | I17: High | J17: Manual | K17: Passed | L17: Passed | M17: Untested | O17: Nhóm tag quét giống nhau (Narrative or Free Text Information - All): 76, 77A, 79
A18: MT196 | B18: MT196.09 | C18: Sàng lọc giao dịch MT 196 - Copy of at least the Mandatory Fields of the Original Message - Narrative - All | D18: 1. Môi trường SIT hoạt động và API Post Message có thể truy cập. 2. Điện được cấu hình screening. 3. Có quyền tra cứu N_GRP_MSG_ID trên Database. | E18: 1. Mở API Post Message. 2. Gửi điện tại cột Test Datas. 3. Ghi nhận N_GRP_MSG_ID/AlertID. 4. Query FSI_RT_AL_WLS_RESPONSE theo N_GRP_MSG_ID. 5. Kiểm tra V_TAG_NAME đúng field mới mapping và giá trị đúng dữ liệu gửi. | F18: {1:F01MCOBVNVXAXXX0000000000} {2:I196SCBLUS33XXXXN} {3:{108:MT196TEST0909}} {4: :20:NZ126032502701 :21:S1626084GHMFKKHF :76:ATTN PAYMENTS INVESTIGATIONS :77A:PLEASE BE ADVISED. :11R:103 260325 :20:S1626084GHMFKKHF :76:0099887766 :79:0099887766 -}{5:{MAC:00000000}{CHK:123456789ABC}} | G18: 2. Hệ thống trả kết quả: HIT với Webservice Narrative loại chủ thể Individual, Entity, Port, Vessel, Aircraft và danh sách Stop Keywords Câu query kiểm tra kết quả (KET_QUA = HIT): SELECT CASE WHEN COUNT(*) = 1 THEN 'HIT' ELSE 'NO HIT' END AS KET_QUA FROM ( SELECT T.V_TAG_NAME FROM FSI_RT_AL_WLS_RESPONSE T WHERE T.N_GRP_MSG_ID = :N_GRP_MSG_ID AND T.N_WEBSERVICE_ID = 4 AND T.V_TAG_NAME IN ('Additional Data') GROUP BY T.V_TAG_NAME HAVING COUNT(CASE WHEN UPPER(T.V_MATCHED_TYPE) = 'ENTITY' THEN 1 END) > 0 AND COUNT(CASE WHEN UPPER(T.V_MATCHED_TYPE) = 'INDIVIDUAL' THEN 1 END) > 0 AND COUNT(CASE WHEN UPPER(T.V_MATCHED_TYPE) = 'VESSEL' THEN 1 END) > 0 AND COUNT(CASE WHEN UPPER(T.V_MATCHED_TYPE) = 'AIRCRAFT' THEN 1 END) > 0 AND COUNT(CASE WHEN UPPER(T.V_MATCHED_TYPE) = 'PORT' THEN 1 END) > 0 AND COUNT(CASE WHEN UPPER(T.V_MATCHED_TYPE) = 'STK' THEN 1 END) > 0 ); | H18: SIT | I18: High | J18: Manual | K18: Untested | L18: Untested | M18: Untested | O18: 09/09: Bổ sung trường Copy of at least the Mandatory Fields of the Original Message.
A19: MT195
