Workbook
Name AUTO: #REF!
Name nj: #REF!
Name PRIORITY: #REF!
Name STATUS: #REF!

Sheet Backup
A1: DỰ ÁN TRIỂN KHAI BẢN QUYỀN PHẦN MỀM HỆ THỐNG AML MỚI
B2: High | C2: Medium | D2: Low | E2: Total R1
A3: Pass | B3: =COUNTIFS($J$13:$J$439,A3,$H$13:$H$439,$B$2) -> 0 | C3: =COUNTIFS($J$13:$J$439,A3,$H$13:$H$439,$C$2) -> 0 | D3: =COUNTIFS($J$13:$J$439,A3,$H$13:$H$439,$D$2) -> 0 | E3: =SUM(B3:D3) -> 0
A4: Fail | B4: =COUNTIFS($J$13:$J$439,A4,$H$13:$H$439,$B$2) -> 0 | C4: =COUNTIFS($J$13:$J$439,A4,$H$13:$H$439,$C$2) -> 0 | D4: =COUNTIFS($J$13:$J$439,A4,$H$13:$H$439,$D$2) -> 0 | E4: =SUM(B4:D4) -> 0
A5: Pending | B5: =COUNTIFS($J$13:$J$439,A5,$H$13:$H$439,$B$2) -> 0 | C5: =COUNTIFS($J$13:$J$439,A5,$H$13:$H$439,$C$2) -> 0 | D5: =COUNTIFS($J$13:$J$439,A5,$H$13:$H$439,$D$2) -> 0 | E5: =SUM(B5:D5) -> 0
A6: Cancel | B6: =COUNTIFS($J$13:$J$439,A6,$H$13:$H$439,$B$2) -> 0 | C6: =COUNTIFS($J$13:$J$439,A6,$H$13:$H$439,$C$2) -> 0 | D6: =COUNTIFS($J$13:$J$439,A6,$H$13:$H$439,$D$2) -> 0 | E6: =SUM(B6:D6) -> 0
A7: Untested | B7: =COUNTIFS($J$13:$J$439,A7,$H$13:$H$439,$B$2) -> 356 | C7: =COUNTIFS($J$13:$J$439,A7,$H$13:$H$439,$C$2) -> 20 | D7: =COUNTIFS($J$13:$J$439,A7,$H$13:$H$439,$D$2) -> 2 | E7: =SUM(B7:D7) -> 378
A8: Next | B8: =COUNTIFS($J$13:$J$439,A8,$H$13:$H$439,$B$2) -> 0 | C8: =COUNTIFS($J$13:$J$439,A8,$H$13:$H$439,$C$2) -> 0 | D8: =COUNTIFS($J$13:$J$439,A8,$H$13:$H$439,$D$2) -> 0 | E8: =SUM(B8:D8) -> 0
E9: =SUM(E3:E7) -> 378
A11: ID Testcase | B11: Test case Title | C11: Pre-conditions | D11: Test Steps | E11: Test Datas | F11: Expected result | G11: Test Environment | H11: Priority | I11: Automation Status | J11: 1st Test Results | K11: 2st Test Results
A12: I. Authentication & Authorization
A13: AML_API_AUTH Xác thực và phân quyền truy cập API
A14: AML_API_AUTH_01 | B14: Gọi API với Authorization header hợp lệ | C14: Server đang chạy; Credentials hợp lệ: Basic a3ljYWRtbjpwYXNzd29yZDM= | D14: 1. Gửi POST request đến API endpoint 2. Đính kèm Authorization header đúng 3. Body là điện MT hợp lệ 4. Kiểm tra HTTP status và response body | E14: Headers: Authorization: Basic a3ljYWRtbjpwYXNzd29yZDM= Content-Type: application/json Params: transactionId: TF_AUTH_001 requestId: REQ_TF_AUTH_001 transactionType: MT branchCd: HN channel: T24 isCallBack: N Body: {1:F01SIIBSYDAXXXX0000000000} {2:I202ESSESESSXXXXN} {4: :20:MT202 :21:SENDEREFERENC001 :32A:170623CNY5000 :58D:/B/BENEFICIARYINST MAJESTUALIDAQ CUBA :72:PHONBEN -} {5:{MAC:12345678}{CHK:123456789ABC}} | F14: HTTP Status: 200 OK result: No-HIT hoặc HIT errorCode: 00 errorDetail: No Error transactionId: TF_AUTH_001 (echo lại) requestId: REQ_TF_AUTH_001 (echo lại) | G14: SIT | H14: High | I14: Manual | J14: Untested | K14: Untested
A15: AML_API_AUTH_02 | B15: Gọi API thiếu Authorization header | C15: Server đang chạy; Không có Authorization header trong request | D15: 1. Gửi POST request đến API endpoint 2. KHÔNG đính kèm Authorization header 3. Body là điện MT hợp lệ 4. Kiểm tra HTTP status trả về | E15: Headers: Content-Type: application/json Params: transactionId: TF_AUTH_002 requestId: REQ_TF_AUTH_002 transactionType: MT branchCd: HN channel: T24 isCallBack: N Body: {1:F01SIIBSYDAXXXX0000000000} {2:I202ESSESESSXXXXN} {4: :20:MT202 :21:SENDEREFERENC001 :32A:170623CNY5000 :58D:/B/BENEFICIARYINST MAJESTUALIDAQ CUBA :72:PHONBEN -} {5:{MAC:12345678}{CHK:123456789ABC}} | F15: HTTP Status: 401 Unauthorized (Không có body nghiệp vụ) | G15: SIT | H15: High | I15: Manual | J15: Untested | K15: Untested
A16: AML_API_AUTH_03 | B16: Gọi API với Authorization token sai | C16: Server đang chạy; Token Basic không hợp lệ | D16: 1. Gửi POST request đến API endpoint 2. Đính kèm Authorization: Basic WRONG_TOKEN 3. Body là điện MT hợp lệ 4. Kiểm tra HTTP status trả về | E16: Headers: Authorization: Basic WRONG_TOKEN Content-Type: application/json Params: transactionId: TF_AUTH_003 requestId: REQ_TF_AUTH_003 transactionType: MT branchCd: HN channel: T24 isCallBack: N Body: {1:F01SIIBSYDAXXXX0000000000} {2:I202ESSESESSXXXXN} {4: :20:MT202 :21:SENDEREFERENC001 :32A:170623CNY5000 :58D:/B/BENEFICIARYINST MAJESTUALIDAQ CUBA :72:PHONBEN -} {5:{MAC:12345678}{CHK:123456789ABC}} | F16: HTTP Status: 401 Unauthorized (Không có body nghiệp vụ) | G16: SIT | H16: High | I16: Manual | J16: Untested | K16: Untested
A17: II. Endpoint & HTTP Method
A18: AML_API_EP Kiểm tra endpoint và phương thức HTTP
A19: AML_API_EP_01 | B19: Gọi đúng endpoint với method POST | C19: Server đang chạy; Auth hợp lệ | D19: 1. Gửi POST request đến: /transaction-screening/v1/transaction-screening 2. Body là điện MT hợp lệ 3. Kiểm tra HTTP 200 và response body | E19: Headers: Authorization: Basic a3ljYWRtbjpwYXNzd29yZDM= Content-Type: application/json Params: transactionId: TF_EP_001 requestId: REQ_TF_EP_001 transactionType: MT branchCd: HN channel: T24 isCallBack: N Body: {1:F01SIIBSYDAXXXX0000000000} {2:I202ESSESESSXXXXN} {4: :20:MT202 :21:SENDEREFERENC001 :32A:170623CNY5000 :58D:/B/BENEFICIARYINST MAJESTUALIDAQ CUBA :72:PHONBEN -} {5:{MAC:12345678}{CHK:123456789ABC}} | F19: HTTP Status: 200 OK result: No-HIT hoặc HIT errorCode: 00 groupMessageId: (not null) | G19: SIT | H19: High | I19: Manual | J19: Untested | K19: Untested
A20: AML_API_EP_02 | B20: Gọi sai endpoint URL | C20: Server đang chạy; Auth hợp lệ | D20: 1. Gửi POST request đến URL sai: /wrong-path/v1/transaction-screening 2. Kiểm tra HTTP status trả về | E20: POST http://server:port/wrong-path/v1/transaction-screening Authorization: Basic a3ljYWRtbjpwYXNzd29yZDM= Content-Type: application/json | F20: HTTP Status: 404 Not Found (Không có body nghiệp vụ) | G20: SIT | H20: High | I20: Manual | J20: Untested | K20: Untested
A21: AML_API_EP_03 | B21: Gọi đúng endpoint nhưng dùng method GET | C21: Server đang chạy; Auth hợp lệ | D21: 1. Gửi GET request đến đúng endpoint 2. Không có body 3. Kiểm tra HTTP status trả về | E21: GET POST http://server:port/transaction-screening/v1/transaction-screening Authorization: Basic a3ljYWRtbjpwYXNzd29yZDM= Content-Type: application/json | F21: HTTP Status: 405 Method Not Allowed (Không có body nghiệp vụ) | G21: SIT | H21: Medium | I21: Manual | J21: Untested | K21: Untested
A22: AML_API_EP_04 | B22: Content-Type không phải application/json | C22: Server đang chạy; Auth hợp lệ | D22: 1. Gửi POST với Content-Type: text/plain 2. Body là điện MT 3. Kiểm tra response | E22: Authorization: Basic a3ljYWRtbjpwYXNzd29yZDM= Content-Type: text/plain Body: {1:F01SIIBSYDAXXXX0000000000} {2:I202ESSESESSXXXXN} {4: :20:MT202 :21:SENDEREFERENC001 :32A:170623CNY5000 :58D:/B/BENEFICIARYINST MAJESTUALIDAQ CUBA :72:PHONBEN -} {5:{MAC:12345678}{CHK:123456789ABC}} | F22: HTTP Status: 400 hoặc 200 Nếu 200: result=ERROR, errorCode=03 (Tùy implementation; ghi nhận thực tế) | G22: SIT | H22: Medium | I22: Manual | J22: Untested | K22: Untested
A23: III. Validation - Header Parameters
A24: AML_API_HDR Kiểm tra các trường bắt buộc / optional trong request params
A25: AML_API_HDR_01 | B25: Request đầy đủ tất cả field bắt buộc (MT) | C25: Auth hợp lệ; MT body đúng format | D25: 1. Gửi POST với đủ 7 fields: transactionId, requestId, transactionType=MT, branchCd, channel, isCallBack, requestUserId 2. Kiểm tra xử lý thành công | E25: Headers: Authorization: Basic a3ljYWRtbjpwYXNzd29yZDM= Content-Type: application/json Params: transactionId: TF_HDR_001 requestId: REQ_TF_HDR_001 transactionType: MT branchCd: HN channel: T24 isCallBack: N Body: {1:F01SIIBSYDAXXXX0000000000} {2:I202ESSESESSXXXXN} {4: :20:MT202 :21:SENDEREFERENC001 :32A:170623CNY5000 :58D:/B/BENEFICIARYINST MAJESTUALIDAQ CUBA :72:PHONBEN -} {5:{MAC:12345678}{CHK:123456789ABC}} | F25: HTTP Status: 200 OK result: No-HIT hoặc HIT errorCode: 00 errorDetail: No Error | G25: SIT | H25: High | I25: Manual | J25: Untested | K25: Untested
A26: AML_API_HDR_02 | B26: Thiếu transactionId (Mandatory) | C26: Auth hợp lệ | D26: 1. Gửi POST KHÔNG có transactionId 2. Các field khác đầy đủ 3. Kiểm tra errorCode trong response | E26: Headers: Authorization: Basic a3ljYWRtbjpwYXNzd29yZDM= Content-Type: application/json Params: requestId: REQ_HDR_002 transactionType: MT branchCd: HN channel: T24 isCallBack: N Body: {1:F01SIIBSYDAXXXX0000000000} {2:I202ESSESESSXXXXN} {4: :20:MT202 :21:SENDEREFERENC001 :32A:170623CNY5000 :58D:/B/BENEFICIARYINST MAJESTUALIDAQ CUBA :72:PHONBEN -} {5:{MAC:12345678}{CHK:123456789ABC}} | F26: HTTP Status: 200 OK result: ERROR errorCode: 01 errorDetail: Missing parameter score: (rỗng) alertId: (rỗng) processDate: null Verify: errorDetail nêu rõ field bị thiếu | G26: SIT | H26: High | I26: Manual | J26: Untested | K26: Untested
A27: AML_API_HDR_03 | B27: Thiếu requestId (Mandatory) | C27: Auth hợp lệ | D27: 1. Gửi POST KHÔNG có requestId 2. Các field khác đầy đủ 3. Kiểm tra errorCode | E27: Headers: Authorization: Basic a3ljYWRtbjpwYXNzd29yZDM= Content-Type: application/json Params: transactionId: TF_HDR_003 transactionType: MT branchCd: HN channel: T24 isCallBack: N Body: {1:F01SIIBSYDAXXXX0000000000} {2:I202ESSESESSXXXXN} {4: :20:MT202 :21:SENDEREFERENC001 :32A:170623CNY5000 :58D:/B/BENEFICIARYINST MAJESTUALIDAQ CUBA :72:PHONBEN -} {5:{MAC:12345678}{CHK:123456789ABC}} | F27: HTTP Status: 200 OK result: ERROR errorCode: 01 errorDetail: Missing parameter score: (rỗng) alertId: (rỗng) processDate: null | G27: SIT | H27: High | I27: Manual | J27: Untested | K27: Untested
A28: AML_API_HDR_04 | B28: Thiếu transactionType (Mandatory) | C28: Auth hợp lệ | D28: 1. Gửi POST KHÔNG có transactionType 2. Các field khác đầy đủ 3. Kiểm tra errorCode | E28: Headers: Authorization: Basic a3ljYWRtbjpwYXNzd29yZDM= Content-Type: application/json Params: transactionId: TF_HDR_004 requestId: REQ_HDR_004 branchCd: HN channel: T24 isCallBack: N Body: {1:F01SIIBSYDAXXXX0000000000} {2:I202ESSESESSXXXXN} {4: :20:MT202 :21:SENDEREFERENC001 :32A:170623CNY5000 :58D:/B/BENEFICIARYINST MAJESTUALIDAQ CUBA :72:PHONBEN -} {5:{MAC:12345678}{CHK:123456789ABC}} | F28: HTTP Status: 200 OK result: ERROR errorCode: 01 errorDetail: Missing parameter score: (rỗng) alertId: (rỗng) processDate: null | G28: SIT | H28: High | I28: Manual | J28: Untested | K28: Untested
A29: AML_API_HDR_05 | B29: Thiếu branchCd (Mandatory) | C29: Auth hợp lệ | D29: 1. Gửi POST KHÔNG có branchCd 2. Các field khác đầy đủ 3. Kiểm tra errorCode | E29: Headers: Authorization: Basic a3ljYWRtbjpwYXNzd29yZDM= Content-Type: application/json Params: transactionId: TF_HDR_005 requestId: REQ_HDR_005 transactionType: MT channel: T24 isCallBack: N Body: {1:F01SIIBSYDAXXXX0000000000} {2:I202ESSESESSXXXXN} {4: :20:MT202 :21:SENDEREFERENC001 :32A:170623CNY5000 :58D:/B/BENEFICIARYINST MAJESTUALIDAQ CUBA :72:PHONBEN -} {5:{MAC:12345678}{CHK:123456789ABC}} | F29: HTTP Status: 200 OK result: ERROR errorCode: 01 errorDetail: Missing parameter score: (rỗng) alertId: (rỗng) processDate: null | G29: SIT | H29: High | I29: Manual | J29: Untested | K29: Untested
A30: AML_API_HDR_06 | B30: Thiếu channel (Mandatory) | C30: Auth hợp lệ | D30: 1. Gửi POST KHÔNG có channel 2. Các field khác đầy đủ 3. Kiểm tra errorCode | E30: Headers: Authorization: Basic a3ljYWRtbjpwYXNzd29yZDM= Content-Type: application/json Params: transactionId: TF_HDR_006 requestId: REQ_HDR_006 transactionType: MT branchCd: HN isCallBack: N Body: {1:F01SIIBSYDAXXXX0000000000} {2:I202ESSESESSXXXXN} {4: :20:MT202 :21:SENDEREFERENC001 :32A:170623CNY5000 :58D:/B/BENEFICIARYINST MAJESTUALIDAQ CUBA :72:PHONBEN -} {5:{MAC:12345678}{CHK:123456789ABC}} | F30: HTTP Status: 200 OK result: ERROR errorCode: 01 errorDetail: Missing parameter score: (rỗng) alertId: (rỗng) processDate: null | G30: SIT | H30: High | I30: Manual | J30: Untested | K30: Untested
A31: AML_API_HDR_07 | B31: Thiếu isCallBack (Mandatory) | C31: Auth hợp lệ | D31: 1. Gửi POST KHÔNG có isCallBack 2. Các field khác đầy đủ 3. Kiểm tra errorCode | E31: Headers: Authorization: Basic a3ljYWRtbjpwYXNzd29yZDM= Content-Type: application/json Params: transactionId: TF_HDR_007 requestId: REQ_HDR_007 transactionType: MT branchCd: HN channel: T24 Body: {1:F01SIIBSYDAXXXX0000000000} {2:I202ESSESESSXXXXN} {4: :20:MT202 :21:SENDEREFERENC001 :32A:170623CNY5000 :58D:/B/BENEFICIARYINST MAJESTUALIDAQ CUBA :72:PHONBEN -} {5:{MAC:12345678}{CHK:123456789ABC}} | F31: HTTP Status: 200 OK result: ERROR errorCode: 01 errorDetail: Missing parameter score: (rỗng) alertId: (rỗng) processDate: null | G31: SIT | H31: High | I31: Manual | J31: Untested | K31: Untested
A32: AML_API_HDR_08 | B32: requestUserId là Optional – không truyền vẫn hợp lệ | C32: Auth hợp lệ; Không truyền requestUserId | D32: 1. Gửi POST đầy đủ 6 fields bắt buộc 2. Không có requestUserId (Optional) 3. Kiểm tra xử lý thành công | E32: Headers: Authorization: Basic a3ljYWRtbjpwYXNzd29yZDM= Content-Type: application/json Params: transactionId: TF_HDR_008 requestId: REQ_TF_HDR_008 transactionType: MT branchCd: HN channel: T24 isCallBack: N Body: {1:F01SIIBSYDAXXXX0000000000} {2:I202ESSESESSXXXXN} {4: :20:MT202 :21:SENDEREFERENC001 :32A:170623CNY5000 :58D:/B/BENEFICIARYINST MAJESTUALIDAQ CUBA :72:PHONBEN -} {5:{MAC:12345678}{CHK:123456789ABC}} | F32: HTTP Status: 200 OK result: No-HIT hoặc HIT errorCode: 00 errorDetail: No Error Verify: requestUserId optional không ảnh hưởng kết quả | G32: SIT | H32: Medium | I32: Manual | J32: Untested | K32: Untested
A33: AML_API_HDR_09 | B33: isCallBack = Y – AML cần callback sau khi Alert hoàn thành | C33: Auth hợp lệ; Hệ thống có endpoint nhận callback | D33: 1. Gửi POST với isCallBack=Y 2. Body là điện MT có HIT 3. Kiểm tra: a. Response trả ngay (HTTP 200) b. Sau khi Alert xử lý xong: AML callback về hệ thống | E33: Headers: Authorization: Basic a3ljYWRtbjpwYXNzd29yZDM= Content-Type: application/json Params: transactionId: TF_HDR_009 requestId: REQ_TF_HDR_009 transactionType: MT branchCd: HN channel: T24 isCallBack: Y Body: {1:F01SIIBSYDAXXXX0000000000} {2:I202ESSESESSXXXXN} {4: :20:MT202 :21:SENDEREFERENC001 :32A:170623CNY5000 :58D:/B/BENEFICIARYINST MAJESTUALIDAQ CUBA :72:PHONBEN -} {5:{MAC:12345678}{CHK:123456789ABC}} | F33: HTTP Status: 200 OK result: HIT hoặc No-HIT errorCode: 00 Verify callback: - AML gọi callback URL với alertId và kết quả - Hệ thống nguồn nhận được callback | G33: SIT | H33: High | I33: Manual | J33: Untested | K33: Untested
A34: AML_API_HDR_10 | B34: isCallBack = N – AML không callback | C34: Auth hợp lệ | D34: 1. Gửi POST với isCallBack=N 2. Body là điện MT 3. Kiểm tra không có callback | E34: Headers: Authorization: Basic a3ljYWRtbjpwYXNzd29yZDM= Content-Type: application/json Params: transactionId: TF_HDR_010 requestId: REQ_TF_HDR_010 transactionType: MT branchCd: HN channel: T24 isCallBack: N Body: {1:F01SIIBSYDAXXXX0000000000} {2:I202ESSESESSXXXXN} {4: :20:MT202 :21:SENDEREFERENC001 :32A:170623CNY5000 :58D:/B/BENEFICIARYINST MAJESTUALIDAQ CUBA :72:PHONBEN -} {5:{MAC:12345678}{CHK:123456789ABC}} | F34: HTTP Status: 200 OK result: No-HIT hoặc HIT errorCode: 00 Verify: AML KHÔNG gọi callback về hệ thống nguồn | G34: SIT | H34: Medium | I34: Manual | J34: Untested | K34: Untested
A35: AML_API_HDR_11 | B35: isCallBack giá trị không hợp lệ (khác Y/N) | C35: Auth hợp lệ | D35: 1. Gửi POST với isCallBack='X' 2. Kiểm tra response lỗi | E35: Headers: Authorization: Basic a3ljYWRtbjpwYXNzd29yZDM= Content-Type: application/json Params: transactionId: TF_HDR_011 requestId: REQ_TF_HDR_011 transactionType: MT branchCd: HN channel: T24 isCallBack: X Body: {1:F01SIIBSYDAXXXX0000000000} {2:I202ESSESESSXXXXN} {4: :20:MT202 :21:SENDEREFERENC001 :32A:170623CNY5000 :58D:/B/BENEFICIARYINST MAJESTUALIDAQ CUBA :72:PHONBEN -} {5:{MAC:12345678}{CHK:123456789ABC}} | F35: HTTP Status: 200 OK result: ERROR errorCode: 01 errorDetail: Missing parameter score: (rỗng) alertId: (rỗng) processDate: null isCallBack chỉ nhận Y hoặc N | G35: SIT | H35: Medium | I35: Manual | J35: Untested | K35: Untested
A36: AML_API_HDR_12 | B36: transactionId vượt độ dài tối đa (>100 ký tự) | C36: Auth hợp lệ | D36: 1. Gửi POST với transactionId dài 101 ký tự 2. Kiểm tra response lỗi | E36: Params: transactionId: TF_AAAAAAAAAAAAAAAAAAAAAAAAAAAAAAAAAAAAAAAAAAAAAAAAAAAAAAAAAAAAAAAAAAAAAAAAAAAAAAAAAAAAAAAAAAAAAAAAA (độ dài=101, vượt varchar2(100)) | F36: HTTP Status: 200 OK result: ERROR errorCode: 01 errorDetail: Missing parameter score: (rỗng) alertId: (rỗng) processDate: null varchar2(100): quá độ dài tối đa | G36: SIT | H36: Medium | I36: Manual | J36: Untested | K36: Untested
A37: AML_API_HDR_13 | B37: transactionType không hợp lệ (giá trị không được hỗ trợ) | C37: Auth hợp lệ | D37: 1. Gửi POST với transactionType='UNKNOWN_TYPE' 2. Kiểm tra response lỗi | E37: Headers: Authorization: Basic a3ljYWRtbjpwYXNzd29yZDM= Content-Type: application/json Params: transactionId: TF_HDR_013 requestId: REQ_TF_HDR_013 transactionType: UNKNOWN_TYPE branchCd: HN channel: T24 isCallBack: N Body: {1:F01SIIBSYDAXXXX0000000000} {2:I202ESSESESSXXXXN} {4: :20:MT202 :21:SENDEREFERENC001 :32A:170623CNY5000 :58D:/B/BENEFICIARYINST MAJESTUALIDAQ CUBA :72:PHONBEN -} {5:{MAC:12345678}{CHK:123456789ABC}} | F37: HTTP Status: 200 OK result: ERROR errorCode: 03 errorDetail: Invalid message format score: (rỗng) alertId: (rỗng) processDate: null transactionType hợp lệ: MT / MX_IN / MX_OUT / MSB001 / MSB002 / MSB003 | G37: SIT | H37: Medium | I37: Manual | J37: Untested | K37: Untested
A38: IV. Sàng lọc điện MT Standard
A39: AML_API_MT Kiểm tra sàng lọc với điện SWIFT MT Standard
A40: AML_API_MT_01 | B40: MT hợp lệ – kết quả No-HIT | C40: Auth hợp lệ; Body MT đúng format SWIFT; Thông tin điện không có match cấm vận | D40: 1. Gửi POST với transactionType=MT 2. Body là điện SWIFT MT chuẩn 3. Kiểm tra result=No-HIT 4. Verify các fields response | E40: Headers: Authorization: Basic a3ljYWRtbjpwYXNzd29yZDM= Content-Type: application/json Params: transactionId: TF_MT_001 requestId: REQ_TF_MT_001 transactionType: MT branchCd: HN channel: T24 isCallBack: N Body: {1:F01SIIBSYDAXXXX0000000000} {2:I202ESSESESSXXXXN} {4: :20:MT202 :21:SENDEREFERENC001 :32A:170623CNY5000 :58D:/B/BENEFICIARYINST MAJESTUALIDAQ CUBA :72:PHONBEN -} {5:{MAC:12345678}{CHK:123456789ABC}} | F40: HTTP Status: 200 OK result: No-HIT errorCode: 00 errorDetail: No Error score: 0 alertId: (rỗng) groupMessageId: (not null, auto-generated) processDate: dd-mm-yyyy hh:mi:ss | G40: SIT | H40: High | I40: Manual | J40: Untested | K40: Untested
A41: AML_API_MT_02 | B41: MT hợp lệ – kết quả HIT (có match cấm vận) | C41: Auth hợp lệ; Body MT có tên/thông tin nằm trong danh sách cấm vận; (Không phải Knock-out country) | D41: 1. Gửi POST với transactionType=MT 2. Body điện MT có tên match danh sách cấm vận 3. Kiểm tra result=HIT 4. Verify alertId được sinh | E41: Headers: Authorization: Basic a3ljYWRtbjpwYXNzd29yZDM= Content-Type: application/json Params: transactionId: TF_MT_002 requestId: REQ_TF_MT_002 transactionType: MT branchCd: HN channel: T24 isCallBack: N Body: {1:F01SIIBSYDAXXXX0000000000} {2:I202ESSESESSXXXXN} {4: :20:MT202 :21:SENDEREFERENC001 :32A:170623CNY5000 :58D:/B/BENEFICIARYINST MAJESTUALIDAQ CUBA :72:PHONBEN -} {5:{MAC:12345678}{CHK:123456789ABC}} | F41: HTTP Status: 200 OK result: HIT errorCode: 00 errorDetail: No Error score: > 0 alertId: (not null, số nguyên) groupMessageId: (not null) processDate: dd-mm-yyyy hh:mi:ss | G41: SIT | H41: High | I41: Manual | J41: Untested | K41: Untested
...

Sheet Report
A1: REPORT ROUND 2 SIT
A2: Tích hợp API | B2: Passed | C2: Failed | D2: Pending | E2: Cancel | F2: Untested | G2: Next
A3: API Sàng Lọc | B3: ='[1]API sàng lọc v2'!E25 -> 430 | C3: ='[1]API sàng lọc v2'!E26 -> 0 | D3: ='[1]API sàng lọc v2'!E27 -> 0 | E3: ='[1]API sàng lọc v2'!E28 -> 0 | F3: ='[1]API sàng lọc v2'!E29 -> 514 | G3: ='[1]API sàng lọc v2'!E30 -> 0
A4: API Search | B4: ='API Search'!E4 -> 23 | C4: ='API Search'!E5 -> 0 | D4: ='API Search'!E6 -> 0 | E4: ='API Search'!E7 -> 0 | F4: ='API Search'!E8 -> 0 | G4: ='API Search'!E9 -> 0
A5: API Callback | B5: ='API Callback'!E4 -> 19 | C5: ='API Callback'!E5 -> 0 | D5: ='API Callback'!E6 -> 0 | E5: ='API Callback'!E7 -> 0 | F5: ='API Callback'!E8 -> 0 | G5: ='API Callback'!E9 -> 0
A6: Tổng | B6: =SUM(B3:B5) -> 472 | C6: =SUM(C3:C5) -> 0 | D6: =SUM(D3:D5) -> 0 | E6: =SUM(E3:E5) -> 0 | F6: =SUM(F3:F5) -> 514 | G6: =SUM(G3:G5) -> 0
A24: Passed
A25: Failed
A26: Pending
A27: Cancel
A28: Untested
A29: Next

Sheet API sàng lọc v2
A1: ROUND 2
B2: High | C2: Medium | D2: Low | E2: Total
B3: =SUM(B4:B8) -> 34 | C3: =SUM(C4:C8) -> 163 | D3: =SUM(D4:D8) -> 1 | E3: =SUM(B3:D3) -> 944
A4: Passed | B4: =COUNTIFS($K:$K,$B$2,$O:$O,A4) -> 34 | C4: =COUNTIFS($K:$K,C2,$O:$O,A4) -> 163 | D4: =COUNTIFS($K:$K,D2,$O:$O,A4) -> 1 | E4: =SUM(B4:D4) -> 198
A5: Failed | B5: =COUNTIFS($K:$K,B2,$O:$O,A5) -> 0 | C5: =COUNTIFS($K:$K,C2,$O:$O,A5) -> 0 | D5: =COUNTIFS($K:$K,D3,$O:$O,A5) -> 1 | E5: =SUM(B5:D5) -> 1
A6: Pending | B6: =COUNTIFS($K:$K,$B$2,$O:$O,A6) -> 0 | C6: =COUNTIFS($K:$K,$C$2,$O:$O,A6) -> 0 | D6: =COUNTIFS($K:$K,D4,$O:$O,A6) -> 0 | E6: =SUM(B6:D6) -> 0
A7: Cancel | B7: =COUNTIFS($K:$K,$B$2,$O:$O,A7) -> 0 | C7: =COUNTIFS($K:$K,$C$2,$O:$O,A7) -> 0 | D7: =COUNTIFS($K:$K,D5,$O:$O,A7) -> 1 | E7: =SUM(B7:D7) -> 1
A8: Untested | B8: =COUNTIFS($K:$K,$B$2,$O:$O,A8) -> 0 | C8: =COUNTIFS($K:$K,$C$2,$O:$O,A8) -> 0 | D8: =COUNTIFS($K:$K,D6,$O:$O,A8) -> 0 | E8: =SUM(B8:D8) -> 0
A9: Next | B9: =COUNTIFS($K:$K,$B$2,$O:$O,A9) -> 0 | C9: =COUNTIFS($K:$K,$C$2,$O:$O,A9) -> 0 | D9: =COUNTIFS($K:$K,D7,$O:$O,A9) -> 0 | E9: =SUM(B9:D9) -> 0
A11: ROUND 3
B12: High | C12: Medium | D12: Low | E12: Total
B13: =SUM(B14:B18) -> 34 | C13: =SUM(C14:C18) -> 0 | D13: =SUM(D14:D18) -> 0 | E13: =SUM(B13:D13) -> 34
A14: Passed | B14: =COUNTIFS($K:$K,B$2,$P:$P,A14) -> 0 | C14: =COUNTIFS($K:$K,C$2,$P:$P,B14) -> 0 | D14: =COUNTIFS($K:$K,D$2,$P:$P,C14) -> 0 | E14: =SUM(B14:D14) -> 0
A15: Failed | B15: =COUNTIFS($K:$K,B$2,$P:$P,A15) -> 0 | C15: =COUNTIFS($K:$K,C$2,$P:$P,B15) -> 0 | D15: =COUNTIFS($K:$K,D$2,$P:$P,C15) -> 0 | E15: =SUM(B15:D15) -> 0
A16: Pending | B16: =COUNTIFS($K:$K,B$2,$P:$P,A16) -> 0 | C16: =COUNTIFS($K:$K,C$2,$P:$P,B16) -> 0 | D16: =COUNTIFS($K:$K,D$2,$P:$P,C16) -> 0 | E16: =SUM(B16:D16) -> 0
A17: Cancel | B17: =COUNTIFS($K:$K,B$2,$P:$P,A17) -> 0 | C17: =COUNTIFS($K:$K,C$2,$P:$P,B17) -> 0 | D17: =COUNTIFS($K:$K,D$2,$P:$P,C17) -> 0 | E17: =SUM(B17:D17) -> 0
A18: Untested | B18: =COUNTIFS($K:$K,B$2,$P:$P,A18) -> 34 | C18: =COUNTIFS($K:$K,C$2,$P:$P,B18) -> 0 | D18: =COUNTIFS($K:$K,D$2,$P:$P,C18) -> 0 | E18: =SUM(B18:D18) -> 34
A19: Next | B19: =COUNTIFS($K:$K,B$2,$P:$P,A19) -> 0 | C19: =COUNTIFS($K:$K,C$2,$P:$P,B19) -> 0 | D19: =COUNTIFS($K:$K,D$2,$P:$P,C19) -> 0 | E19: =SUM(B19:D19) -> 0
A22: ROUND 2
B23: High | C23: Medium | D23: Low | E23: Total
B24: =SUM(B25:B29) -> 34 | C24: =SUM(C25:C29) -> 163 | D24: =SUM(D25:D29) -> 1 | E24: =SUM(B24:D24) -> 198
A25: Passed | B25: =COUNTIFS($K:$K,B$23,$O:$O,$A25) -> 34 | C25: =COUNTIFS($K:$K,C$23,$O:$O,$A25) -> 163 | D25: =COUNTIFS($K:$K,D$23,$O:$O,$A25) -> 1 | E25: =SUM(B25:D25) -> 198
A26: Failed | B26: =COUNTIFS($K:$K,B$23,$O:$O,$A26) -> 0 | C26: =COUNTIFS($K:$K,C$23,$O:$O,$A26) -> 0 | D26: =COUNTIFS($K:$K,D$23,$O:$O,$A26) -> 0 | E26: =SUM(B26:D26) -> 0
A27: Pending | B27: =COUNTIFS($K:$K,B$23,$O:$O,$A27) -> 0 | C27: =COUNTIFS($K:$K,C$23,$O:$O,$A27) -> 0 | D27: =COUNTIFS($K:$K,D$23,$O:$O,$A27) -> 0 | E27: =SUM(B27:D27) -> 0
A28: Cancel | B28: =COUNTIFS($K:$K,B$23,$O:$O,$A28) -> 0 | C28: =COUNTIFS($K:$K,C$23,$O:$O,$A28) -> 0 | D28: =COUNTIFS($K:$K,D$23,$O:$O,$A28) -> 0 | E28: =SUM(B28:D28) -> 0
A29: Untested | B29: =COUNTIFS($K:$K,B$23,$O:$O,$A29) -> 0 | C29: =COUNTIFS($K:$K,C$23,$O:$O,$A29) -> 0 | D29: =COUNTIFS($K:$K,D$23,$O:$O,$A29) -> 0 | E29: =SUM(B29:D29) -> 0
A30: Next | B30: =COUNTIFS($K:$K,B$23,$O:$O,$A30) -> 0 | C30: =COUNTIFS($K:$K,C$23,$O:$O,$A30) -> 0 | D30: =COUNTIFS($K:$K,D$23,$O:$O,$A30) -> 0 | E30: =SUM(B30:D30) -> 0
A32: Test Case ID | B32: Function | C32: Group Tests | D32: Risk Level | E32: Test Case Title | F32: Pre-conditions | G32: Test Steps | H32: Test Data | I32: Expected result | J32: Environment | K32: Priority | L32: Regression | M32: Automation | N32: 1st Test Results | O32: 2nd Test Results | P32: 3rd Test Results | Q32: Automation Test Results | R32: Actual result | S32: BugID | T32: Note
A33: NHÓM FUNCTION - Common
A34: AML_API_EP_01 | B34: NHÓM FUNCTION | C34: Common | D34: High | E34: Kiểm tra gọi API sàng lọc thành công với method POST, endpoint và Basic Auth hợp lệ | F34: - User/Quyền: Tài khoản tích hợp AML (Basic Auth YWE6YmI=) còn hiệu lực, có quyền gọi API sàng lọc giao dịch - Trạng thái hệ thống: Service transaction-screening đang chạy trên SIT (https://10.0.137.75:7001); hệ thống EDQ sẵn sàng nhận yêu cầu sàng lọc; không verify DB ([ASSUMPTION: không có tài liệu DB connection]) - Dữ liệu có sẵn: điện mẫu hợp lệ theo transactionType đang test; transactionId = TF_EP_001 | G34: 1. Gửi POST request tới API transaction-screening với method POST, endpoint và Basic Auth hợp lệ. 2. Kiểm tra thông tin HTTP Status và Response Body trả về. | H34: - Endpoint: POST https://10.0.137.75:7001/transaction-screening/v1/transaction-screening - Headers: Content-Type: application/json transactionId: TF_EP_001 requestId: REQ_TF_EP_001 transactionType: MT channel: T24 isCallBack: N requestUserId: 1 Cookie: JSESSIONID=y2YyMBjrxzc7dswUyMO_K0_EX5gYVjC42KjbIC1m8U3Wr_WC059j!663991662 branchCd: VN0001001 Authorization: Basic YWE6YmI= - Body: {1:F01MCOBVNVXAXXX0000000000} {2:O1951201260724BFICCUHHAXXX00010000012607241201N} {3:{108:MT195TEST0001}} {4: :20:QRY2607240001 :21:NONREF :75:PLEASE CONFIRM -}{5:{MAC:00000000}{CHK:1A2B3C4D5E6F}} | I34: 2. Kiểm tra thông tin HTTP Status trả về: 200 OK - Json trả về có kết quả sàng lọc: result = No-HIT hoặc HIT, errorCode = null, score = score - Json có dạng theo format: { "result": "No-HIT hoặc HIT", "transactionType": "transactionType", "score": "score", "groupMessageId": "groupMessageId", "requestId": "requestId", "processDate": "processDate", "channel": "channel", "errorCode": null, "errorDetail": null, "alertId": "alertId", "transactionId": "transactionId", "branchCd": "branchCd" } | J34: SIT | K34: High | L34: Yes | M34: Yes | N34: Untested | O34: Passed | P34: Untested
A35: AML_API_HDR_01 | B35: NHÓM FUNCTION | C35: Common | D35: High | E35: Kiểm tra gọi API sàng lọc thành công với đầy đủ 7 tham số header bắt buộc | F35: - User/Quyền: Tài khoản tích hợp AML (Basic Auth YWE6YmI=) còn hiệu lực, có quyền gọi API sàng lọc giao dịch - Trạng thái hệ thống: Service transaction-screening đang chạy trên SIT (https://10.0.137.75:7001); hệ thống EDQ sẵn sàng nhận yêu cầu sàng lọc; không verify DB ([ASSUMPTION: không có tài liệu DB connection]) - Dữ liệu có sẵn: điện mẫu hợp lệ theo transactionType đang test; transactionId = TF_HDR_001; MT body đúng format | G35: 1. Gửi POST request tới API transaction-screening với đầy đủ 7 tham số header bắt buộc. 2. Kiểm tra thông tin HTTP Status và Response Body trả về. | H35: - Endpoint: POST https://10.0.137.75:7001/transaction-screening/v1/transaction-screening - Headers: Content-Type: application/json transactionId: TF_HDR_001 requestId: REQ_TF_HDR_001 transactionType: MT channel: T24 isCallBack: N requestUserId: 1 Cookie: JSESSIONID=y2YyMBjrxzc7dswUyMO_K0_EX5gYVjC42KjbIC1m8U3Wr_WC059j!663991662 branchCd: VN0001001 Authorization: Basic YWE6YmI= - Body: {1:F01MCOBVNVXAXXX0000000000} {2:O1951201260724BFICCUHHAXXX00010000012607241201N} {3:{108:MT195TEST0001}} {4: :20:QRY2607240001 :21:NONREF :75:PLEASE CONFIRM -}{5:{MAC:00000000}{CHK:1A2B3C4D5E6F}} | I35: 2. Kiểm tra thông tin HTTP Status trả về: 200 OK - Json trả về có kết quả sàng lọc: result = No-HIT hoặc HIT, errorCode = null, score = score - Json có dạng theo format: { "result": "No-HIT hoặc HIT", "transactionType": "transactionType", "score": "score", "groupMessageId": "groupMessageId", "requestId": "requestId", "processDate": "processDate", "channel": "channel", "errorCode": null, "errorDetail": null, "alertId": "alertId", "transactionId": "transactionId", "branchCd": "branchCd" } | J35: SIT | K35: High | L35: Yes | M35: Yes | N35: Untested | O35: Passed | P35: Untested
A36: AML_API_NF_08 | B36: NHÓM FUNCTION | C36: Common | D36: High | E36: Kiểm tra API parse thành công điện hợp lệ với cả 6 giá trị transactionType | F36: - User/Quyền: Tài khoản tích hợp AML (Basic Auth YWE6YmI=) còn hiệu lực, có quyền gọi API sàng lọc giao dịch - Trạng thái hệ thống: Service transaction-screening đang chạy trên SIT (https://10.0.137.75:7001); hệ thống EDQ sẵn sàng nhận yêu cầu sàng lọc; không verify DB ([ASSUMPTION: không có tài liệu DB connection]) - Dữ liệu có sẵn: điện mẫu MX_IN hợp lệ, đầy đủ toàn bộ trường mandatory theo chuẩn; Body hợp lệ cho từng loại | G36: 1. Gửi POST request tới API transaction-screening với cả 6 giá trị transactionType. 2. Kiểm tra thông tin HTTP Status và Response Body trả về. | H36: - Endpoint: POST https://10.0.137.75:7001/transaction-screening/v1/transaction-screening - Headers: Content-Type: application/json transactionId: TF_AML_API_NF_08 requestId: REQ_AML_API_NF_08 transactionType: lần lượt MT, MX_IN, MX_OUT, MSB001, MSB002, MSB003 (6 request riêng biệt) channel: T24 isCallBack: N requestUserId: 1 Cookie: JSESSIONID=y2YyMBjrxzc7dswUyMO_K0_EX5gYVjC42KjbIC1m8U3Wr_WC059j!663991662 branchCd: VN0001001 Authorization: Basic YWE6YmI= - Ghi chú: Body: điện hợp lệ tương ứng từng transactionType (SWIFT MT / XML MX / JSON MSB001 / JSON MSB002 / JSON Array MSB003) - Body: {1:F01MCOBVNVXAXXX0000000000} {2:O2951201260724BFICCUHHAXXX00010000012607241201N} {3:{108:MT295TEST0001}} {4: :20:QRY2607240001 :21:NONREF :75:PLEASE CONFIRM STATUS OF TRANSACTION -}{5:{MAC:00000000}{CHK:1A2B3C4D5E6F}} | I36: 2. Kiểm tra thông tin HTTP Status trả về: 200 OK (cho cả 6 requests) - Json trả về có thông báo lỗi: errorCode = 00 cho cả 6 - transactionType echo đúng trong mỗi response - Smoke test: hệ thống xử lý được tất cả loại điện - Json có dạng theo format: { "errorCode": "00 cho cả 6" } | J36: SIT | K36: High | L36: Yes | M36: Yes | N36: Untested | O36: Passed | P36: Untested
A37: AML_API_NF_01 | B37: NHÓM FUNCTION | C37: Common | D37: High | E37: Kiểm tra API xử lý thành công khi 'channel' tại biên trên (Max = 100 ký tự) | F37: - User/Quyền: Tài khoản tích hợp AML (Basic Auth YWE6YmI=) còn hiệu lực, có quyền gọi API sàng lọc giao dịch - Trạng thái hệ thống: Service transaction-screening đang chạy trên SIT (https://10.0.137.75:7001); hệ thống EDQ sẵn sàng nhận yêu cầu sàng lọc; không verify DB ([ASSUMPTION: không có tài liệu DB connection]) - Dữ liệu có sẵn: điện mẫu hợp lệ theo transactionType đang test; transactionId = TF_NF_003 | G37: 1. Gửi POST request tới API transaction-screening với 'channel' tại biên trên (Max = 100 ký tự). 2. Kiểm tra thông tin HTTP Status và Response Body trả về. | H37: - Endpoint: POST https://10.0.137.75:7001/transaction-screening/v1/transaction-screening - Headers: Content-Type: application/json transactionId: TF_NF_003 requestId: REQ_TF_NF_003 transactionType: MT channel: CCCCCCCCCCCCCCCCCCCCCCCCCCCCCCCCCCCCCCCCCCCCCCCCCCCCCCCCCCCCCCCCCCCCCCCCCCCCCCCCCCCCCCCCCCCCCCCCCCCC isCallBack: N requestUserId: 1 Cookie: JSESSIONID=y2YyMBjrxzc7dswUyMO_K0_EX5gYVjC42KjbIC1m8U3Wr_WC059j!663991662 branchCd: VN0001001 Authorization: Basic YWE6YmI= - Body: {1:F01MCOBVNVXAXXX0000000000} {2:O2021201260724BFICCUHHAXXX00010000012607241201N} {3:{108:MT202TEST0001}} {4: :20:MT202 :21:SENDEREFERENC001 :32A:170623CNY5000 :58D:/B/BENEFICIARYINST MAJESTUALIDAQ CUBA :72:PHONBEN -} {5:{MAC:12345678}{CHK:123456789ABC}} | I37: 2. Kiểm tra thông tin HTTP Status trả về: 200 OK - Json trả về có kết quả sàng lọc: result = No-HIT hoặc HIT, errorCode = 00 - varchar2(100): giá trị tối đa được chấp nhận - Json có dạng theo format: { "result": "No-HIT hoặc HIT", "errorCode": 00 } | J37: SIT | K37: Medium | L37: Yes | M37: Yes | N37: Untested | O37: Passed | P37: Untested
A38: AML_API_NF_02 | B38: NHÓM FUNCTION | C38: Common | D38: High | E38: Kiểm tra API xử lý thành công khi 'transactionId' tại biên trên (Max = 100 ký tự) | F38: - User/Quyền: Tài khoản tích hợp AML (Basic Auth YWE6YmI=) còn hiệu lực, có quyền gọi API sàng lọc giao dịch - Trạng thái hệ thống: Service transaction-screening đang chạy trên SIT (https://10.0.137.75:7001); hệ thống EDQ sẵn sàng nhận yêu cầu sàng lọc; không verify DB ([ASSUMPTION: không có tài liệu DB connection]) - Dữ liệu có sẵn: điện mẫu hợp lệ theo transactionType đang test; transactionId = TTTTTTTTTTTTTTTTTTTTTTTTTTTTTTTTTTTTTTTTTTTTTTTTTTTTTTTTTTTTTTTTTTTTTTTTTTTTTTTTTTTTTTTTTTTTTTTTTTTT; Auth hop le va con han | G38: 1. Gửi POST request tới API transaction-screening với 'transactionId' tại biên trên (Max = 100 ký tự). 2. Kiểm tra thông tin HTTP Status và Response Body trả về. | H38: - Endpoint: POST https://10.0.137.75:7001/transaction-screening/v1/transaction-screening - Headers: Content-Type: application/json transactionId: TTTTTTTTTTTTTTTTTTTTTTTTTTTTTTTTTTTTTTTTTTTTTTTTTTTTTTTTTTTTTTTTTTTTTTTTTTTTTTTTTTTTTTTTTTTTTTTTTTTT requestId: REQ_TF_NEW_P3_006 transactionType: MT channel: T24 isCallBack: N requestUserId: 1 Cookie: JSESSIONID=y2YyMBjrxzc7dswUyMO_K0_EX5gYVjC42KjbIC1m8U3Wr_WC059j!663991662 branchCd: VN0001001 Authorization: Basic YWE6YmI= - Body: {1:F01MCOBVNVXAXXX0000000000} {2:O1951201260724BFICCUHHAXXX00010000012607241201N} {3:{108:MT195TEST0001}} {4: :20:QRY2607240001 :21:NONREF :75:PLEASE CONFIRM -}{5:{MAC:00000000}{CHK:1A2B3C4D5E6F}} | I38: 2. Kiểm tra thông tin HTTP Status trả về: 200 OK - Json trả về có kết quả sàng lọc: result = No-HIT hoặc HIT, errorCode = 00 - varchar2(100): giá trị tối đa được chấp nhận - Json có dạng theo format: { "result": "No-HIT hoặc HIT", "errorCode": 00 } | J38: SIT | K38: Medium | L38: Yes | M38: Yes | N38: Untested | O38: Passed | P38: Untested
A39: AML_API_NF_03 | B39: NHÓM FUNCTION | C39: Common | D39: High | E39: Kiểm tra API xử lý thành công khi 'requestId' tại biên trên (Max = 100 ký tự) | F39: - User/Quyền: Tài khoản tích hợp AML (Basic Auth YWE6YmI=) còn hiệu lực, có quyền gọi API sàng lọc giao dịch - Trạng thái hệ thống: Service transaction-screening đang chạy trên SIT (https://10.0.137.75:7001); hệ thống EDQ sẵn sàng nhận yêu cầu sàng lọc; không verify DB ([ASSUMPTION: không có tài liệu DB connection]) - Dữ liệu có sẵn: điện mẫu hợp lệ theo transactionType đang test; transactionId = TF_NEW_P3_007; Auth hop le va con han | G39: 1. Gửi POST request tới API transaction-screening với 'requestId' tại biên trên (Max = 100 ký tự). 2. Kiểm tra thông tin HTTP Status và Response Body trả về. | H39: - Endpoint: POST https://10.0.137.75:7001/transaction-screening/v1/transaction-screening - Headers: Content-Type: application/json transactionId: TF_NEW_P3_007 requestId: TTTTTTTTTTTTTTTTTTTTTTTTTTTTTTTTTTTTTTTTTTTTTTTTTTTTTTTTTTTTTTTTTTTTTTTTTTTTTTTTTTTTTTTTTTTTTTTTTTTT transactionType: MT channel: T24 isCallBack: N requestUserId: 1 Cookie: JSESSIONID=y2YyMBjrxzc7dswUyMO_K0_EX5gYVjC42KjbIC1m8U3Wr_WC059j!663991662 branchCd: VN0001001 Authorization: Basic YWE6YmI= - Body: {1:F01MCOBVNVXAXXX0000000000} {2:O1951201260724BFICCUHHAXXX00010000012607241201N} {3:{108:MT195TEST0001}} {4: :20:QRY2607240001 :21:NONREF :75:PLEASE CONFIRM -}{5:{MAC:00000000}{CHK:1A2B3C4D5E6F}} | I39: 2. Kiểm tra thông tin HTTP Status trả về: 200 OK - Json trả về có kết quả sàng lọc: result = No-HIT hoặc HIT, errorCode = 00 - varchar2(100): giá trị tối đa được chấp nhận - Json có dạng theo format: { "result": "No-HIT hoặc HIT", "errorCode": 00 } | J39: SIT | K39: Medium | L39: Yes | M39: Yes | N39: Untested | O39: Passed | P39: Untested
A40: AML_API_NF_04 | B40: NHÓM FUNCTION | C40: Common | D40: High | E40: Kiểm tra API xử lý thành công khi 'branchCd' tại biên trên (Max = 50 ký tự) | F40: - User/Quyền: Tài khoản tích hợp AML (Basic Auth YWE6YmI=) còn hiệu lực, có quyền gọi API sàng lọc giao dịch - Trạng thái hệ thống: Service transaction-screening đang chạy trên SIT (https://10.0.137.75:7001); hệ thống EDQ sẵn sàng nhận yêu cầu sàng lọc; không verify DB ([ASSUMPTION: không có tài liệu DB connection]) - Dữ liệu có sẵn: điện mẫu hợp lệ theo transactionType đang test; transactionId = TF_NEW_P3_008; Auth hop le va con han | G40: 1. Gửi POST request tới API transaction-screening với 'branchCd' tại biên trên (Max = 50 ký tự). 2. Kiểm tra thông tin HTTP Status và Response Body trả về. | H40: - Endpoint: POST https://10.0.137.75:7001/transaction-screening/v1/transaction-screening - Headers: Content-Type: application/json transactionId: TF_NEW_P3_008 requestId: REQ_TF_NEW_P3_008 transactionType: MT channel: T24 isCallBack: N requestUserId: 1 Cookie: JSESSIONID=y2YyMBjrxzc7dswUyMO_K0_EX5gYVjC42KjbIC1m8U3Wr_WC059j!663991662 branchCd: BBBBBBBBBBBBBBBBBBBBBBBBBBBBBBBBBBBBBBBBBBBBBBBBBB Authorization: Basic YWE6YmI= - Body: {1:F01MCOBVNVXAXXX0000000000} {2:O1951201260724BFICCUHHAXXX00010000012607241201N} {3:{108:MT195TEST0001}} {4: :20:QRY2607240001 :21:NONREF :75:PLEASE CONFIRM -}{5:{MAC:00000000}{CHK:1A2B3C4D5E6F}} | I40: 2. Kiểm tra thông tin HTTP Status trả về: 200 OK - Json trả về có kết quả sàng lọc: result = No-HIT hoặc HIT, errorCode = 00 - varchar2(100): giá trị tối đa được chấp nhận - Json có dạng theo format: { "result": "No-HIT hoặc HIT", "errorCode": 00 } | J40: SIT | K40: Medium | L40: Yes | M40: Yes | N40: Untested | O40: Passed | P40: Untested
A41: AML_API_NF_05 | B41: NHÓM FUNCTION | C41: Common | D41: High | E41: Kiểm tra API phân biệt đúng nghiệp vụ khi cùng body nhưng khác transactionType (MSB001 vs MSB002) | F41: - User/Quyền: Tài khoản tích hợp AML (Basic Auth YWE6YmI=) còn hiệu lực, có quyền gọi API sàng lọc giao dịch - Trạng thái hệ thống: Service transaction-screening đang chạy trên SIT (https://10.0.137.75:7001); hệ thống EDQ sẵn sàng nhận yêu cầu sàng lọc; không verify DB ([ASSUMPTION: không có tài liệu DB connection]) - Dữ liệu có sẵn: điện mẫu MSB001 hợp lệ, đầy đủ toàn bộ trường mandatory theo chuẩn; transactionId = TF_NF_008; Body MSB001 và MSB002 có cùng schema nhưng key khác | G41: 1. Gửi POST request tới API transaction-screening với cùng body nhưng khác transactionType (MSB001 vs MSB002). 2. Kiểm tra thông tin HTTP Status và Response Body trả về. | H41: - Endpoint: POST https://10.0.137.75:7001/transaction-screening/v1/transaction-screening - Headers: Content-Type: application/json transactionId: TF_NF_008 requestId: REQ_TF_NF_008 transactionType: MSB001 channel: T24 isCallBack: N requestUserId: 1 Cookie: JSESSIONID=y2YyMBjrxzc7dswUyMO_K0_EX5gYVjC42KjbIC1m8U3Wr_WC059j!663991662 branchCd: VN0001001 Authorization: Basic YWE6YmI= - Body: { "Bank01": { "MSB001": { "Sender": {"FullName":"TRAN VAN SENDER","DOB":"1985-05-20", "Nationalities":[{"SenderCitizenship":"VN"}], "Id":[{"IdNumber":"037085001234"}], "ResidenceAddress":[{"Address":"123 Nguyen Trai, Ha Noi","Country":"VN"}]}, "Receiver": {"FullName":"JOHN RECEIVER SMITH","DOB":"1990-11-12", "Nationalities":[{"Citizenship":"US"}], "Id":[{"IdNumber":"A12345678"}], "ResidenceAddress":[{"Address":"456 Broadway, New York","Country":"US"}]}, "BeneficiaryBankName":"VIETCOMBANK HO CHI MINH", "BeneficiaryBankBicCode":"BFTVBNVX002","BeneficiaryBankCountry":"VN", "RemittingBankName":"CITIBANK NEW YORK", "RemittingBankBicCode":"CITIUS33XXX","RemittingBankCountry":"US" } } } | I41: 2. Kiểm tra thông tin HTTP Status trả về: 200 OK ((cả 2 lần)) - Lần 1 (MSB001): result=No-HIT/HIT, errorCode=00 - Lần 2 (MSB002): result=No-HIT/HIT, errorCode=00 - Verify: transactionType echo đúng trong mỗi response - Json có dạng theo format: [PENDING_DOC] — TC gốc/PTTK không mô tả cấu trúc response | J41: SIT | K41: Medium | L41: Yes | M41: Yes | N41: Untested | O41: Passed | P41: Untested
A42: NHÓM FUNCTION - MT
A43: AML_API_MT_01 | B43: NHÓM FUNCTION | C43: MT | D43: High | E43: Kiểm tra gọi API sàng lọc thành công với dien MT ket qua No-HIT | F43: - User/Quyền: Tài khoản tích hợp AML (Basic Auth YWE6YmI=) còn hiệu lực, có quyền gọi API sàng lọc giao dịch - Trạng thái hệ thống: Service transaction-screening đang chạy trên SIT (https://10.0.137.75:7001); hệ thống EDQ sẵn sàng nhận yêu cầu sàng lọc; không verify DB ([ASSUMPTION: không có tài liệu DB connection]) - Dữ liệu có sẵn: điện mẫu hợp lệ theo transactionType đang test; transactionId = TF_MT_001; Body MT đúng format SWIFT; Thông tin điện không có match cấm vận | G43: 1. Gửi POST request tới API transaction-screening với dien MT ket qua No-HIT. 2. Kiểm tra thông tin HTTP Status và Response Body trả về. | H43: - Endpoint: POST https://10.0.137.75:7001/transaction-screening/v1/transaction-screening - Headers: Content-Type: application/json transactionId: TF_MT_001 requestId: REQ_TF_MT_001 transactionType: MT channel: T24 isCallBack: N requestUserId: 1 Cookie: JSESSIONID=y2YyMBjrxzc7dswUyMO_K0_EX5gYVjC42KjbIC1m8U3Wr_WC059j!663991662 branchCd: VN0001001 Authorization: Basic YWE6YmI= - Body: {1:F01MCOBVNVXAXXX0000000000} {2:O1961201260724BFICCUHHAXXX00010000012607241201N} {3:{108:MT196TEST0001}} {4: :20:ANS2607240002 :21:NONREF :76:00998877663 :77A:00998877663 :79:00998877663 -}{5:{MAC:00000000}{CHK:1A2B3C4D5E6F}} | I43: 2. Kiểm tra thông tin HTTP Status trả về: 200 OK [ASSUMPTION: TC gốc chỉ mô tả nội dung response, không nêu HTTP Status; API trả HTTP 200 cho mọi kết quả nghiệp vụ theo các TC cùng nhóm] - Json trả về có kết quả sàng lọc: result = "NO HIT", errorCode = null, score = 0 - Json có dạng theo format: { "transactionType": "transactionType", "result": "NO HIT", "score": 0, "groupMessageId": "groupMessageId", "requestId": "requestId", "processDate": "dd-mm-yyyy hh:mi:ss", "channel": "channel", "errorCode": null, "errorDetail": null, "alertId": "alertId", "transactionId": "transactionId", "branchCd": "branchCd" } | J43: SIT | K43: High | L43: Yes | M43: Yes | N43: Untested | O43: Passed | P43: Untested
A44: AML_API_MT_02 | B44: NHÓM FUNCTION | C44: MT | D44: High | E44: Kiểm tra API trả về kết quả sàng lọc HIT thành công với điện MT | F44: - User/Quyền: Tài khoản tích hợp AML (Basic Auth YWE6YmI=) còn hiệu lực, có quyền gọi API sàng lọc giao dịch - Trạng thái hệ thống: Service transaction-screening đang chạy trên SIT (https://10.0.137.75:7001); hệ thống EDQ sẵn sàng nhận yêu cầu sàng lọc; không verify DB ([ASSUMPTION: không có tài liệu DB connection]) - Dữ liệu có sẵn: điện mẫu hợp lệ theo transactionType đang test; transactionId = TF_MT_002; Body MT có tên/thông tin nằm trong danh sách cấm vận; (Không phải Knock-out country) | G44: 1. Gửi POST request tới API transaction-screening với điện MT (kỳ vọng kết quả HIT). 2. Kiểm tra thông tin HTTP Status và Response Body trả về. | H44: - Endpoint: POST https://10.0.137.75:7001/transaction-screening/v1/transaction-screening - Headers: Content-Type: application/json transactionId: TF_MT_002 requestId: REQ_TF_MT_002 transactionType: MT channel: T24 isCallBack: N requestUserId: 1 Cookie: JSESSIONID=y2YyMBjrxzc7dswUyMO_K0_EX5gYVjC42KjbIC1m8U3Wr_WC059j!663991662 branchCd: VN0001001 Authorization: Basic YWE6YmI= - Body: {1:F01MCOBVNVXAXXX0000000000} {2:O1961201260724BFICCUHHAXXX00010000012607241201N} {3:{108:MT196TEST0001}} {4: :20:ANS2607240002 :21:NONREF :76:00998877663 :77A:00998877663 :79:00998877663 -}{5:{MAC:00000000}{CHK:1A2B3C4D5E6F}} | I44: 2. Kiểm tra thông tin HTTP Status trả về: 200 OK [ASSUMPTION: TC gốc chỉ mô tả nội dung response, không nêu HTTP Status; API trả HTTP 200 cho mọi kết quả nghiệp vụ theo các TC cùng nhóm] - Json trả về có kết quả sàng lọc: result = "HIT", errorCode = null, score = score - Json có dạng theo format: { "transactionType": "transactionType", "result": "HIT", "score": "score", "groupMessageId": "groupMessageId", "requestId": "requestId", "processDate": "dd-mm-yyyy hh:mi:ss", "channel": "channel", "errorCode": null, "errorDetail": null, "alertId": "alertId", "transactionId": "transactionId", "branchCd": "branchCd" } | J44: SIT | K44: High | L44: Yes | M44: Yes | N44: Untested | O44: Passed | P44: Untested
...

Sheet Validate MSB001
A1: VALIDATE ĐIỆN MSB001 — chia block theo trường (Thiết kế tích hợp điện)
A2: Test Case ID | B2: Function | C2: Group Tests | D2: Risk Level | E2: Test Case Title | F2: Pre-conditions | G2: Test Steps | H2: Test Data | I2: Expected result | J2: Environment | K2: Priority | L2: Regression | M2: Automation | N2: 1st Test Results | O2: 2nd Test Results | P2: 3rd Test Results | Q2: Automation Test Results | R2: Actual result | S2: BugID | T2: Note
A3: NHÓM VALIDATE - Trường: Sender.FullName
A4: AML_MSB001_VAL_001 | B4: NHÓM VALIDATE | C4: Sender.FullName | D4: Medium | E4: Kiểm tra API từ chối Điện MSB001 thất bại khi thiếu trường mandatory Sender.FullName | F4: - User/Quyền: Tài khoản đăng nhập có quyền gọi API sàng lọc giao dịch - token còn hạn - Dữ liệu có sẵn: Thông tin dữ liệu mẫu MSB001 hợp lệ có thông số transactionType đang test, đầy đủ toàn bộ trường mandatory theo chuẩn, transactionId là TF_AML_MSB001_MND_02; Body MSB001 KHÔNG có trường Sender.FullName Các thông tin mandatory khác vẫn đủ thông tin | G4: 1. Gửi POST request tới API transaction-screening với Điện MSB001 thiếu trường mandatory Sender.FullName. 2. Kiểm tra thông tin HTTP Status và Response Body trả về. | H4: - Endpoint: POST https://10.0.137.75:7001/transaction-screening/v1/transaction-screening - Headers: Content-Type: application/json transactionId: TF_AML_MSB001_MND_02 requestId: REQ_TF_AML_MSB001_MND_02 transactionType: MSB001 channel: T24 isCallBack: N requestUserId: 1 Cookie: JSESSIONID=y2YyMBjrxzc7dswUyMO_K0_EX5gYVjC42KjbIC1m8U3Wr_WC059j!663991662 branchCd: VN0001001 Authorization: Basic YWE6YmI= - Body: { "MSB001": { "Sender": { "DOB": "1985-05-20", "Nationalities": [ { "Citizenship": "VN" } ], "Id": [ { "IdNumber": "037085001234" } ], "ResidenceAddress": [ { "Address": "123 Nguyen Trai, Thanh Xuan, Ha Noi", "Country": "VN" } ] }, "Receiver": { "FullName": "JOHN RECEIVER SMITH", "DOB": "1990-11-12", "Nationalities": [ { "Citizenship": "US" } ], "Id": [ { "IdNumber": "A12345678" } ], "ResidenceAddress": [ { "Address": "456 Broadway, New York, NY 10013", "Country": "US" } ] }, "SenderOrg": { "VnName": "Cong ty Co phan Xuat nhap khau ABC", "EngName": "ABC Import Export Joint Stock Company", "ShortName": "ABC IMPEX", "HeadquartersAddress": "789 Le Lai, District 1, Ho Chi Minh City", "HeadquartersCountry": "VN", "IncorporationDate": "2010-03-15", "Documents": [ { "DocumentNumber": "0102030405" } ] }, "ReceiverOrg": { "VnName": "Cong ty TNHH Giao nhan Toan Cau XYZ", "EngName": "XYZ Global Logistics Company Limited", "ShortName": "XYZ LOGISTICS", "HeadquartersAddress": "101 Marina Boulevard, Singapore 018989", "HeadquartersCountry": "SG", "IncorporationDate": "2015-08-22", "Documents": [ { "DocumentNumber": "REG987654" } ] }, "BeneficiaryBankName": "VIETCOMBANK HO CHI MINH", "BeneficiaryBankBicCode": "BFTVBNVX002", "BeneficiaryBankAddress": "29 Ben Chuong Duong, District 1, Ho Chi Minh City", "BeneficiaryBankCountry": "VN", "RemittingBankName": "CITIBANK NEW YORK", "RemittingBankBicCode": "CITIUS33XXX", "RemittingBankAddress": "399 Park Avenue, New York, NY 10022", "RemittingBankCountry": "US" } } | I4: 2. Kiểm tra thông tin HTTP Status trả về: 404 - Json trả về có thông báo lỗi: result = ERROR, errorCode = "03", errorDetail = "Message is not valid. Please correct the message and repost it" | J4: SIT | K4: Medium | L4: Yes | M4: Yes | N4: Untested | O4: Passed | P4: Untested | T4: [DANH LAI ID] ID goc: AML_MSB001_MND_02 | Da gop 1 ban trung tu sheet ROUND 1
A5: AML_MSB001_VAL_002 | B5: NHÓM VALIDATE | C5: Sender.FullName | D5: Medium | E5: Kiểm tra MSB001: trường Sender.FullName truyền null | F5: - Tài khoản tích hợp AML còn hiệu lực và có quyền gọi API. - Service transaction-screening và EDQ sẵn sàng, trừ TC mô phỏng lỗi hạ tầng. - Có payload MSB001 hợp lệ theo file Thiết kế tích hợp điện và Mapping điện NonSwift; giữ nguyên các trường khác. | G5: 1. Chuẩn bị request hợp lệ. 2. Gán Sender.FullName = null; các trường khác hợp lệ. 3. Gửi request. 4. Kiểm tra HTTP status, result, errorCode, errorDetail và thời gian phản hồi. | H5: - Endpoint: POST https://10.0.137.75:7001/transaction-screening/v1/transaction-screening - Headers hợp lệ: Content-Type=application/json; transactionId=AML_MSB001_BODY_001; requestId=REQ_AML_MSB001_BODY_001; transactionType=MSB001; branchCd=VN0001001; channel=T24; isCallBack=N; requestUserId=1; Authorization=Basic YWE6YmI= - Body: dùng payload MSB001 hợp lệ làm baseline, chỉ thay đổi đúng trường nêu trong TC. - Biến thể: Sender.FullName = null. - Theo Mapping điện NonSwift1: maxlength = 140 (Max140Text); trường mandatory. | I5: - HTTP 404 theo cơ chế response nghiệp vụ. - result = "ERROR". - errorCode = "03" (Invalid message format). - errorDetail chỉ rõ trường bắt buộc bị thiếu giá trị; không tạo kết quả sàng lọc sai. | J5: SIT | K5: Medium | L5: Yes | M5: No | N5: Untested | O5: Untested | P5: Untested | T5: [DANH LAI ID] ID goc: AML_MSB001_BODY_001
A6: AML_MSB001_VAL_003 | B6: NHÓM VALIDATE | C6: Sender.FullName | D6: Medium | E6: Kiểm tra MSB001: trường Sender.FullName truyền chuỗi rỗng | F6: - Tài khoản tích hợp AML còn hiệu lực và có quyền gọi API. - Service transaction-screening và EDQ sẵn sàng, trừ TC mô phỏng lỗi hạ tầng. - Có payload MSB001 hợp lệ theo file Thiết kế tích hợp điện và Mapping điện NonSwift; giữ nguyên các trường khác. | G6: 1. Chuẩn bị request hợp lệ. 2. Gán Sender.FullName = ""; các trường khác hợp lệ. 3. Gửi request. 4. Kiểm tra HTTP status, result, errorCode, errorDetail và thời gian phản hồi. | H6: - Endpoint: POST https://10.0.137.75:7001/transaction-screening/v1/transaction-screening - Headers hợp lệ: Content-Type=application/json; transactionId=AML_MSB001_BODY_002; requestId=REQ_AML_MSB001_BODY_002; transactionType=MSB001; branchCd=VN0001001; channel=T24; isCallBack=N; requestUserId=1; Authorization=Basic YWE6YmI= - Body: dùng payload MSB001 hợp lệ làm baseline, chỉ thay đổi đúng trường nêu trong TC. - Biến thể: Sender.FullName = "". - Theo Mapping điện NonSwift1: maxlength = 140 (Max140Text); trường mandatory. | I6: - HTTP 404 theo cơ chế response nghiệp vụ. - result = "ERROR". - errorCode = "03" (Invalid message format). - errorDetail chỉ rõ trường bắt buộc bị thiếu giá trị; không tạo kết quả sàng lọc sai. | J6: SIT | K6: Medium | L6: Yes | M6: No | N6: Untested | O6: Untested | P6: Untested | T6: [DANH LAI ID] ID goc: AML_MSB001_BODY_002
A7: AML_MSB001_VAL_004 | B7: NHÓM VALIDATE | C7: Sender.FullName | D7: Medium | E7: Kiểm tra MSB001: trường Sender.FullName truyền vượt độ dài tối đa (141 ký tự) | F7: - Tài khoản tích hợp AML còn hiệu lực và có quyền gọi API. - Service transaction-screening và EDQ sẵn sàng, trừ TC mô phỏng lỗi hạ tầng. - Có payload MSB001 hợp lệ theo file Thiết kế tích hợp điện và Mapping điện NonSwift; giữ nguyên các trường khác. | G7: 1. Chuẩn bị request hợp lệ. 2. Gán Sender.FullName = chuỗi 141 ký tự, vượt giới hạn 140 ký tự theo Mapping điện NonSwift1; các trường khác hợp lệ. 3. Gửi request. 4. Kiểm tra HTTP status, result, errorCode, errorDetail và thời gian phản hồi. | H7: - Endpoint: POST https://10.0.137.75:7001/transaction-screening/v1/transaction-screening - Headers hợp lệ: Content-Type=application/json; transactionId=AML_MSB001_BODY_003; requestId=REQ_AML_MSB001_BODY_003; transactionType=MSB001; branchCd=VN0001001; channel=T24; isCallBack=N; requestUserId=1; Authorization=Basic YWE6YmI= - Body: dùng payload MSB001 hợp lệ làm baseline, chỉ thay đổi đúng trường nêu trong TC. - Biến thể: Sender.FullName = "XXXXXXXXXXXXXXXXXXXXXXXXXXXXXXXXXXXXXXXXXXXXXXXXXXXXXXXXXXXXXXXXXXXXXXXXXXXXXXXXXXXXXXXXXXXXXXXXXXXXXXXXXXXXXXXXXXXXXXXXXXXXXXXXXXXXXXXXXXXXX". - Theo Mapping điện NonSwift1: maxlength = 140 (Max140Text); trường mandatory. | I7: - HTTP 404 theo cơ chế response nghiệp vụ. - result = "ERROR". - errorCode = "03" (Invalid message format). - errorDetail chỉ rõ trường vượt độ dài tối đa 140 ký tự; API không truncate rồi xử lý tiếp. | J7: SIT | K7: Medium | L7: Yes | M7: No | N7: Untested | O7: Untested | P7: Untested | T7: [DANH LAI ID] ID goc: AML_MSB001_BODY_003
A8: AML_MSB001_VAL_005 | B8: NHÓM VALIDATE | C8: Sender.FullName | D8: High | E8: Kiểm tra MSB001: Sender.FullName chứa ký tự đặc biệt | F8: - Tài khoản tích hợp AML còn hiệu lực và có quyền gọi API. - Service transaction-screening và EDQ sẵn sàng, trừ TC mô phỏng lỗi hạ tầng. - Có payload MSB001 hợp lệ theo file Thiết kế tích hợp điện và Mapping điện NonSwift; giữ nguyên các trường khác. | G8: 1. Chuẩn bị request hợp lệ. 2. Gán Sender.FullName bằng tên có dấu nối, nháy đơn, dấu chấm và ký tự tiếng Việt. 3. Gửi request. 4. Kiểm tra HTTP status, result, errorCode, errorDetail và thời gian phản hồi. | H8: - Endpoint: POST https://10.0.137.75:7001/transaction-screening/v1/transaction-screening - Headers hợp lệ: Content-Type=application/json; transactionId=AML_MSB001_NAME_SENDER_FULLNAME; requestId=REQ_AML_MSB001_NAME_SENDER_FULLNAME; transactionType=MSB001; branchCd=VN0001001; channel=T24; isCallBack=N; requestUserId=1; Authorization=Basic YWE6YmI= - Body: dùng payload MSB001 hợp lệ làm baseline, chỉ thay đổi đúng trường nêu trong TC. - Sender.FullName = "NGUYỄN O'CONNOR-SMITH & CO., LTD.". | I8: - HTTP 200 OK. - API tiếp nhận và xử lý an toàn; result = No-HIT hoặc HIT. - errorCode = "00"; errorDetail không có lỗi validation. - Không truncate sai dữ liệu tại đúng biên maxlength. | J8: SIT | K8: Medium | L8: Yes | M8: No | N8: Untested | O8: Untested | P8: Untested | T8: [DANH LAI ID] ID goc: AML_MSB001_NAME_SENDER_FULLNAME
A9: AML_MSB001_VAL_006 | B9: NHÓM VALIDATE | C9: Sender.FullName | D9: High | E9: Kiểm tra MSB001: Sender.FullName truyền ký tự đặc biệt | F9: - Tài khoản tích hợp AML còn hiệu lực và có quyền gọi API. - Service transaction-screening và EDQ sẵn sàng. - Có payload MSB001 hợp lệ theo file Thiết kế tích hợp điện và Mapping điện NonSwift; chỉ thay đổi trường đang kiểm thử, giữ nguyên các trường khác. | G9: 1. Chuẩn bị request MSB001 hợp lệ. 2. Gán Sender.FullName = "O'CONNOR-SMITH & CO., LTD.". 3. Gửi request. 4. Kiểm tra HTTP status, result, errorCode, errorDetail và dữ liệu sau chuyển đổi sang MX. | H9: - Endpoint: POST https://10.0.137.75:7001/transaction-screening/v1/transaction-screening - Headers hợp lệ: Content-Type: application/json transactionId: AML_MSB001_NAME_001_SPEC requestId: REQ_AML_MSB001_NAME_001_SPEC transactionType: MSB001 branchCd: VN0001001 channel: T24 isCallBack: N requestUserId: 1 Authorization: Basic YWE6YmI= - Body: payload MSB001 hợp lệ theo mẫu trong file Thiết kế tích hợp điện. - Giá trị kiểm thử: Sender.FullName = "O'CONNOR-SMITH & CO., LTD." | I9: - HTTP 200 OK. - result = No-HIT hoặc HIT; errorCode = "00"; errorDetail không có lỗi validation. - Ký tự &, dấu nháy, dấu gạch nối, dấu chấm và dấu phẩy phải được escape đúng khi chuyển sang XML MX. - Điện MX sau chuyển đổi là XML hợp lệ và giá trị trường Name không bị truncate. | J9: SIT | K9: Medium | L9: Yes | M9: No | N9: Untested | O9: Untested | P9: Untested | T9: [DANH LAI ID] ID goc: AML_MSB001_NAME_001_SPEC
A10: AML_MSB001_VAL_007 | B10: NHÓM VALIDATE | C10: Sender.FullName | D10: High | E10: Kiểm tra MSB001: Sender.FullName truyền chữ có dấu | F10: - Tài khoản tích hợp AML còn hiệu lực và có quyền gọi API. - Service transaction-screening và EDQ sẵn sàng. - Có payload MSB001 hợp lệ theo file Thiết kế tích hợp điện và Mapping điện NonSwift; chỉ thay đổi trường đang kiểm thử, giữ nguyên các trường khác. | G10: 1. Chuẩn bị request MSB001 hợp lệ. 2. Gán Sender.FullName = "Công ty Cổ phần Ánh Dương". 3. Gửi request. 4. Kiểm tra HTTP status, result, errorCode, errorDetail và dữ liệu sau chuyển đổi sang MX. | H10: - Endpoint: POST https://10.0.137.75:7001/transaction-screening/v1/transaction-screening - Headers hợp lệ: Content-Type: application/json transactionId: AML_MSB001_NAME_002_VI requestId: REQ_AML_MSB001_NAME_002_VI transactionType: MSB001 branchCd: VN0001001 channel: T24 isCallBack: N requestUserId: 1 Authorization: Basic YWE6YmI= - Body: payload MSB001 hợp lệ theo mẫu trong file Thiết kế tích hợp điện. - Giá trị kiểm thử: Sender.FullName = "Công ty Cổ phần Ánh Dương" | I10: - HTTP 200 OK. - result = No-HIT hoặc HIT; errorCode = "00"; errorDetail không có lỗi validation. - Chuỗi Unicode tiếng Việt phải được giữ nguyên, không lỗi font/mã hóa khi chuyển sang XML MX. - Điện MX sau chuyển đổi là XML hợp lệ và giá trị trường Name không bị truncate. | J10: SIT | K10: Medium | L10: Yes | M10: No | N10: Untested | O10: Untested | P10: Untested | T10: [DANH LAI ID] ID goc: AML_MSB001_NAME_002_VI
A11: AML_MSB001_VAL_008 | B11: NHÓM VALIDATE | C11: Sender.FullName | D11: High | E11: Kiểm tra MSB001: Sender.FullName truyền chữ hoa | F11: - Tài khoản tích hợp AML còn hiệu lực và có quyền gọi API. - Service transaction-screening và EDQ sẵn sàng. - Có payload MSB001 hợp lệ theo file Thiết kế tích hợp điện và Mapping điện NonSwift; chỉ thay đổi trường đang kiểm thử, giữ nguyên các trường khác. | G11: 1. Chuẩn bị request MSB001 hợp lệ. 2. Gán Sender.FullName = "GLOBAL TRADING COMPANY". 3. Gửi request. 4. Kiểm tra HTTP status, result, errorCode, errorDetail và dữ liệu sau chuyển đổi sang MX. | H11: - Endpoint: POST https://10.0.137.75:7001/transaction-screening/v1/transaction-screening - Headers hợp lệ: Content-Type: application/json transactionId: AML_MSB001_NAME_003_UPPER requestId: REQ_AML_MSB001_NAME_003_UPPER transactionType: MSB001 branchCd: VN0001001 channel: T24 isCallBack: N requestUserId: 1 Authorization: Basic YWE6YmI= - Body: payload MSB001 hợp lệ theo mẫu trong file Thiết kế tích hợp điện. - Giá trị kiểm thử: Sender.FullName = "GLOBAL TRADING COMPANY" | I11: - HTTP 200 OK. - result = No-HIT hoặc HIT; errorCode = "00"; errorDetail không có lỗi validation. - Hệ thống chấp nhận chuỗi chữ hoa và giữ đúng dữ liệu khi chuyển sang XML MX. - Điện MX sau chuyển đổi là XML hợp lệ và giá trị trường Name không bị truncate. | J11: SIT | K11: Medium | L11: Yes | M11: No | N11: Untested | O11: Untested | P11: Untested | T11: [DANH LAI ID] ID goc: AML_MSB001_NAME_003_UPPER
A12: AML_MSB001_VAL_009 | B12: NHÓM VALIDATE | C12: Sender.FullName | D12: High | E12: Kiểm tra MSB001: Sender.FullName truyền chữ thường | F12: - Tài khoản tích hợp AML còn hiệu lực và có quyền gọi API. - Service transaction-screening và EDQ sẵn sàng. - Có payload MSB001 hợp lệ theo file Thiết kế tích hợp điện và Mapping điện NonSwift; chỉ thay đổi trường đang kiểm thử, giữ nguyên các trường khác. | G12: 1. Chuẩn bị request MSB001 hợp lệ. 2. Gán Sender.FullName = "global trading company". 3. Gửi request. 4. Kiểm tra HTTP status, result, errorCode, errorDetail và dữ liệu sau chuyển đổi sang MX. | H12: - Endpoint: POST https://10.0.137.75:7001/transaction-screening/v1/transaction-screening - Headers hợp lệ: Content-Type: application/json transactionId: AML_MSB001_NAME_004_LOWER requestId: REQ_AML_MSB001_NAME_004_LOWER transactionType: MSB001 branchCd: VN0001001 channel: T24 isCallBack: N requestUserId: 1 Authorization: Basic YWE6YmI= - Body: payload MSB001 hợp lệ theo mẫu trong file Thiết kế tích hợp điện. - Giá trị kiểm thử: Sender.FullName = "global trading company" | I12: - HTTP 200 OK. - result = No-HIT hoặc HIT; errorCode = "00"; errorDetail không có lỗi validation. - Hệ thống chấp nhận chuỗi chữ thường và giữ đúng dữ liệu khi chuyển sang XML MX. - Điện MX sau chuyển đổi là XML hợp lệ và giá trị trường Name không bị truncate. | J12: SIT | K12: Medium | L12: Yes | M12: No | N12: Untested | O12: Untested | P12: Untested | T12: [DANH LAI ID] ID goc: AML_MSB001_NAME_004_LOWER
