Workbook

Sheet Cover
E8: Test Report
C11: Project Name: | E11: DỰ ÁN TRIỂN KHAI BẢN QUYỀN PHẦN MỀM HỆ THỐNG AML MỚI | G11: Reviewer:
C12: Document Code: | E12: MSB_AML_Testcase_KYC_UI_customize | G12: Position:
C13: Originator: | G13: Reviewed Date:
C14: Position: | G14: Approver:
C15: Created Date: | E15: 46153 | G15: Position:
C16: Version: | E16: 1.0 | G16: Approved Date:

Sheet Records
A1: TABLE OF CONTENT
A3: No | B3: Items | C3: Content
A4: 1 | B4: Cover | C4: Cover
A5: 2 | B5: Records | C5: Record of changes
A6: 3 | B6: Function | C6: List out all test cases of the application
A7: 4 | B7: Screen Element | C7: Screen Element test cases, which are based on the application's SRS
A9: Effective Date | B9: A, M, D | C9: Change Description | F9: New Version | G9: Author
A10: 46153 | B10: A | C10: Create new TC | F10: 1

Sheet Test Report
B2: SYSTEM TEST REPORT
A5: Project | B5: =#NAME? -> #NAME? | D5: Project manager
A6: Application | D6: Approved Date
A7: Consolidated By | D7: Reviewed By
A8: Build Versions | D8: Reviewed date
A9: Test Environment | B9: SIT
A10: Last Updated Date
A11: Test Execution Summary
A12: Reported by
A13: Date
A14: Test Results | B14: Passed | C14: Failed | D14: Pending | E14: Next | F14: Canel | G14: Untested | H14: Total
A15: Total | B15: =SUM(B16:B18) -> 81 | C15: =SUM(C16:C18) -> 1 | D15: =SUM(D16:D18) -> 0 | E15: =SUM(E16:E18) -> 0 | F15: =SUM(F16:F18) -> 0 | G15: =SUM(G16:G18) -> 52 | H15: =SUM(B15:G15) -> 134
A16: Cấu hình điện | B16: ='Cấu hình điện'!E6 -> 31 | C16: ='Cấu hình điện'!E7 -> 1 | D16: ='Cấu hình điện'!E8 -> 0 | E16: ='Cấu hình điện'!E12 -> 0 | F16: ='Cấu hình điện'!E9 -> 0 | G16: ='Cấu hình điện'!E10 -> 0 | H16: =SUM(B16:G16) -> 32
A17: Cấu hình chủ thể | B17: ='Cấu hình chủ thể'!E6 -> 42 | C17: ='Cấu hình chủ thể'!E7 -> 0 | D17: ='Cấu hình chủ thể'!E8 -> 0 | E17: ='Cấu hình chủ thể'!E11 -> 0 | F17: ='Cấu hình chủ thể'!E10 -> 0 | G17: ='Cấu hình chủ thể'!E9 -> 0 | H17: =SUM(B17:G17) -> 42
A18: Sàng lọc điện | B18: ='Sàng lọc điện'!E6 -> 8 | C18: ='Sàng lọc điện'!E7 -> 0 | D18: ='Sàng lọc điện'!E11 -> 0 | E18: ='Sàng lọc điện'!E10 -> 0 | F18: ='Sàng lọc điện'!E9 -> 0 | G18: ='Sàng lọc điện'!E8 -> 52 | H18: =SUM(B18:G18) -> 60
A19: Test coverage
A20: Test coverage | H20: =IFERROR(SUM(B15,C15,F15)/H15, 0) -> 0.6119403
A21: Test successful coverage | H21: =IFERROR(SUM(B15,F15)/H15, 0) -> 0.60447761
A22: Issues
A23: 1. Block testing issue
A24: 2. Critical defects

Sheet Cấu hình điện
A1: Functions | B1: Config EDQ
A2: Build Version | B2: v1.0
B4: High | C4: Medium | D4: Low | E4: Total
B5: =SUM(B6:B11) -> 0 | C5: =SUM(C6:C11) -> 32 | D5: =SUM(D6:D11) -> 0 | E5: =SUM(B5:D5) -> 32
A6: Passed | B6: =COUNTIFS($J:$J, $A$6,$H:$H,B$4) -> 0 | C6: =COUNTIFS($J:$J, $A$6,$H:$H,C$4) -> 31 | D6: =COUNTIFS($J:$J, $A$6,$H:$H,D$4) -> 0 | E6: =SUM(B6:D6) -> 31
A7: Failed | B7: =COUNTIFS($J:$J, $A$7,$H:$H,B$4) -> 0 | C7: =COUNTIFS($J:$J, $A$7,$H:$H,C$4) -> 1 | D7: =COUNTIFS($J:$J, $A$7,$H:$H,D$4) -> 0 | E7: =SUM(B7:D7) -> 1
A8: Pending | B8: =COUNTIFS($J:$J, $A$8,H:H,B$4) -> 0 | C8: =COUNTIFS($J:$J, $A$8,I:I,C$4) -> 0 | D8: =COUNTIFS($J:$J, $A$8,J:J,D$4) -> 0 | E8: =SUM(B8:D8) -> 0
A9: Cancel | B9: =COUNTIFS($J:$J, $A$8,H:H,B$4) -> 0 | C9: =COUNTIFS($J:$J, $A$8,I:I,C$4) -> 0 | D9: =COUNTIFS($J:$J, $A$8,J:J,D$4) -> 0 | E9: =SUM(B9:D9) -> 0
A10: Untested | B10: =COUNTIFS($J:$J, $A$10,$H:$H,B$4) -> 0 | C10: =COUNTIFS($J:$J, $A$10,$H:$H,C$4) -> 0 | D10: =COUNTIFS($J:$J, $A$10,$H:$H,D$4) -> 0 | E10: =SUM(B10:D10) -> 0
A11: Accepted | B11: =COUNTIFS($J:$J, $A$11,$H:$H,B$4) -> 0 | C11: =COUNTIFS($J:$J, $A$11,$H:$H,C$4) -> 0 | D11: =COUNTIFS($J:$J, $A$11,$H:$H,D$4) -> 0 | E11: =SUM(B11:D11) -> 0
A12: Next | B12: =COUNTIFS($J:$J, $A$12,H:H,B$4) -> 0 | C12: =COUNTIFS($J:$J, $A$12,I:I,C$4) -> 0 | D12: =COUNTIFS($J:$J, $A$12,J:J,D$4) -> 0 | E12: =SUM(B12:D12) -> 0
A15: Test case Id | B15: Test case Title | C15: Pre-conditions | D15: Test Step | E15: Test Datas | F15: Expected result | G15: Test Environment | H15: Priority | I15: Automation Status | J15: 1st Test Results | K15: 2nd Test Results | L15: 3rd Test Result | M15: BugID | N15: Notes
B16: Kiểm tra config các trường của điện MT700
A17: MT700.01 | B17: Kiểm tra điện MT700 - Webservice IDENTIFIER được gán tương ứng với các trường trong điện | D17: 1. Login hệ thống TF bằng user admin 2. Truy cập theo đường dẫn Financial Services Analytical Applications Transactions Filtering/ Financial Services Sanctions Pack/ SWIFT Configuration Admin 3. Chọn điện MT700 trên drop down list 4. Sau khi bấm nút Save, click liên tiếp 2 lần button mũi tên sang phải (>) ở bên cạnh. 5. Chọn webservice IDENTIFIER trên dropdown list Screening webservice trên màn hình và kiểm tra các tags tương ứng được gán | F17: Thông tin hiển thị các field, field name tương ứng theo từng webservice đảm bảo đủ, đúng theo yêu cầu, có trạng thái Enable = Yes, bao gồm: Basic Header Block - LT Identifier Application Header Input - Receiver's Address Application Header Output - Full input SWIFT address 51A - Party Identifier 51A - Identifier Code 51D - Party Identifier 41A - Identifier Code 42A - Party Identifier 42A - Identifier Code 42D - Party Identifier 58A - Party Identifier 58A - Identifier Code 58D - Party Identifier 53A - Party Identifier 53A - Identifier Code 53D - Party Identifier 57A - Party Identifier 57A - Identifier Code 57B - Party Identifier 57D - Party Identifier | H17: Medium | I17: Manual | J17: Passed | K17: Untested | L17: Untested
A18: MT700.02 | B18: Kiểm tra điện MT700 - Webservice COUNTRY AND CITY được gán tương ứng với các trường trong điện | D18: 1. Login hệ thống TF bằng user admin 2. Truy cập theo đường dẫn Financial Services Analytical Applications Transactions Filtering/ Financial Services Sanctions Pack/ SWIFT Configuration Admin 3. Chọn điện MT700 trên drop down list 4. Sau khi bấm nút Save, click liên tiếp 2 lần button mũi tên sang phải (>) ở bên cạnh. 5. Chọn webservice COUNTRY AND CITY trên dropdown list Screening webservice trên màn hình và kiểm tra các tags tương ứng được gán | F18: Thông tin hiển thị các field, field name tương ứng theo từng webservice đảm bảo đủ, đúng theo yêu cầu, có trạng thái Enable = Yes, bao gồm: Basic Header Block - LT Identifier Application Header Input - Receiver's Address Application Header Output - Full input SWIFT address 51A - Identifier Code 50R (Sequence A) - Applicant Country 59R (Sequence B) - Beneficiary Country 41A - Identifier Code 42A - Identifier Code 58A - Identifier Code 53A - Identifier Code 57A - Identifier Code | H18: Medium | I18: Manual | J18: Passed | K18: Untested | L18: Untested
A19: MT700.03 | B19: Kiểm tra điện MT700 - Webservice PORT được gán tương ứng với các trường trong điện | D19: 1. Login hệ thống TF bằng user admin 2. Truy cập theo đường dẫn Financial Services Analytical Applications Transactions Filtering/ Financial Services Sanctions Pack/ SWIFT Configuration Admin 3. Chọn điện MT700 trên drop down list 4. Sau khi bấm nút Save, click liên tiếp 2 lần button mũi tên sang phải (>) ở bên cạnh. 5. Chọn webservice PORT trên dropdown list Screening webservice trên màn hình và kiểm tra các tags tương ứng được gán | F19: Thông tin hiển thị các field, field name tương ứng theo từng webservice đảm bảo đủ, đúng theo yêu cầu, có trạng thái Enable = Yes, bao gồm: 44A - Place of Taking in Charge/Dispatch from .../Place of Receipt 44E - Port of Loading/Airport of Departure 44F - Port of Discharge/Airport of Destination 44B - Place of Final Destination/For Transportation to .../Place of Delivery | H19: Medium | I19: Manual | J19: Passed | K19: Untested | L19: Untested
A20: MT700.04 | B20: Kiểm tra điện MT700 - Webservice NARRATIVE được gán tương ứng với các trường trong điện | D20: 1. Login hệ thống TF bằng user admin 2. Truy cập theo đường dẫn Financial Services Analytical Applications Transactions Filtering/ Financial Services Sanctions Pack/ SWIFT Configuration Admin 3. Chọn điện MT700 trên drop down list 4. Sau khi bấm nút Save, click liên tiếp 2 lần button mũi tên sang phải (>) ở bên cạnh. 5. Chọn webservice NARRATIVE trên dropdown list Screening webservice trên màn hình và kiểm tra các tags tương ứng được gán | F20: Thông tin hiển thị các field, field name tương ứng theo từng webservice đảm bảo đủ, đúng theo yêu cầu, có trạng thái Enable = Yes, bao gồm: 42M - Mixed Payment Details 42P - Negotiation/Deferred Payment Details 44A - Place of Taking in Charge/Dispatch from .../Place of Receipt 44E - Port of Loading/Airport of Departure 44F - Port of Discharge/Airport of Destination 44B - Place of Final Destination/For Transportation to .../Place of Delivery 45A - Description of Goods and/or Services 46A - Documents Required 47A - Additional Conditions 49G - Special Payment Conditions for Beneficiary 49H - Special Payment Conditions for Bank Only 71D - Charges 78K - Instructions to the Paying/Accepting/Negotiating Bank 72Z - Sender to Receiver Information | H20: Medium | I20: Manual | J20: Passed | K20: Untested | L20: Untested
A21: MT700.05 | B21: Kiểm tra điện MT700 - Webservice NAME AND ADDRESS được gán tương ứng với các trường trong điện | D21: 1. Login hệ thống TF bằng user admin 2. Truy cập theo đường dẫn Financial Services Analytical Applications Transactions Filtering/ Financial Services Sanctions Pack/ SWIFT Configuration Admin 3. Chọn điện MT700 trên drop down list 4. Sau khi bấm nút Save, click liên tiếp 2 lần button mũi tên sang phải (>) ở bên cạnh. 5. Chọn webservice NAME AND ADDRESS trên dropdown list Screening webservice trên màn hình và kiểm tra các tags tương ứng được gán | F21: Thông tin hiển thị các field, field name tương ứng theo từng webservice đảm bảo đủ, đúng theo yêu cầu, có trạng thái Enable = Yes, bao gồm: Basic Header Block - LT Identifier Application Header Input - Receiver's Address Application Header Output - Full input SWIFT address 51A - Identifier Code 51D - Name and Address 50N (Sequence A) - Applicant Name 59N (Sequence B) - Beneficiary Name 41A - Identifier Code 41D - Name and Address 42A - Identifier Code 42D - Name and Address 58A - Identifier Code 58D - Name and Address 53A - Identifier Code 53D - Name and Address 57A - Identifier Code 57D - Name and Address | H21: Medium | I21: Manual | J21: Passed | K21: Untested | L21: Untested
B22: Kiểm tra config các trường của điện MT707
A23: MT707.01 | B23: Kiểm tra điện MT707 - Webservice IDENTIFIER được gán tương ứng với các trường trong điện | D23: 1. Login hệ thống TF bằng user admin 2. Truy cập theo đường dẫn Financial Services Analytical Applications Transactions Filtering/ Financial Services Sanctions Pack/ SWIFT Configuration Admin 3. Chọn điện MT707 trên drop down list 4. Sau khi bấm nút Save, click liên tiếp 2 lần button mũi tên sang phải (>) ở bên cạnh. 5. Chọn webservice IDENTIFIER trên dropdown list Screening webservice trên màn hình và kiểm tra các tags tương ứng được gán | F23: Thông tin hiển thị các field, field name tương ứng theo từng webservice đảm bảo đủ, đúng theo yêu cầu, có trạng thái Enable = Yes, bao gồm: Basic Header Block - LT Identifier Application Header Input - Receiver's Address Application Header Output - Full input SWIFT address 52A - Party Identifier 52A - Identifier Code 52D - Party Identifier 41A - Identifier Code 42A - Party Identifier 42A - Identifier Code 42D - Party Identifier 58A - Party Identifier 58A - Identifier Code 58D - Party Identifier 53A - Party Identifier 53A - Identifier Code 53D - Party Identifier 57A - Party Identifier 57A - Identifier Code 57B - Party Identifier 57D - Party Identifier | H23: Medium | I23: Manual | J23: Passed | K23: Untested | L23: Untested
A24: MT707.02 | B24: Kiểm tra điện MT707 - Webservice COUNTRY AND CITY được gán tương ứng với các trường trong điện | D24: 1. Login hệ thống TF bằng user admin 2. Truy cập theo đường dẫn Financial Services Analytical Applications Transactions Filtering/ Financial Services Sanctions Pack/ SWIFT Configuration Admin 3. Chọn điện MT707 trên drop down list 4. Sau khi bấm nút Save, click liên tiếp 2 lần button mũi tên sang phải (>) ở bên cạnh. 5. Chọn webservice COUNTRY AND CITY trên dropdown list Screening webservice trên màn hình và kiểm tra các tags tương ứng được gán | F24: Thông tin hiển thị các field, field name tương ứng theo từng webservice đảm bảo đủ, đúng theo yêu cầu, có trạng thái Enable = Yes, bao gồm: Basic Header Block - LT Identifier Application Header Input - Receiver's Address Application Header Output - Full input SWIFT address 52A - Identifier Code 50W (Sequence A) - Non-Bank Issuer Country 50R (Sequence B) - Changed Applicant Country 59R (Sequence C) - Beneficiary Country 41A - Identifier Code 42A - Identifier Code 58A - Identifier Code 53A - Identifier Code 57A - Identifier Code | H24: Medium | I24: Manual | J24: Passed | K24: Untested | L24: Untested
A25: MT707.03 | B25: Kiểm tra điện MT707 - Webservice PORT được gán tương ứng với các trường trong điện | D25: 1. Login hệ thống TF bằng user admin 2. Truy cập theo đường dẫn Financial Services Analytical Applications Transactions Filtering/ Financial Services Sanctions Pack/ SWIFT Configuration Admin 3. Chọn điện MT707 trên drop down list 4. Sau khi bấm nút Save, click liên tiếp 2 lần button mũi tên sang phải (>) ở bên cạnh. 5. Chọn webservice PORT trên dropdown list Screening webservice trên màn hình và kiểm tra các tags tương ứng được gán | F25: Thông tin hiển thị các field, field name tương ứng theo từng webservice đảm bảo đủ, đúng theo yêu cầu, có trạng thái Enable = Yes, bao gồm: 44A - Place of Taking in Charge/Dispatch from .../Place of Receipt 44E - Port of Loading/Airport of Departure 44F - Port of Discharge/Airport of Destination 44B - Place of Final Destination/For Transportation to .../Place of Delivery | H25: Medium | I25: Manual | J25: Passed | K25: Untested | L25: Untested
A26: MT707.04 | B26: Kiểm tra điện MT707 - Webservice NARRATIVE được gán tương ứng với các trường trong điện | D26: 1. Login hệ thống TF bằng user admin 2. Truy cập theo đường dẫn Financial Services Analytical Applications Transactions Filtering/ Financial Services Sanctions Pack/ SWIFT Configuration Admin 3. Chọn điện MT707 trên drop down list 4. Sau khi bấm nút Save, click liên tiếp 2 lần button mũi tên sang phải (>) ở bên cạnh. 5. Chọn webservice NARRATIVE trên dropdown list Screening webservice trên màn hình và kiểm tra các tags tương ứng được gán | F26: Thông tin hiển thị các field, field name tương ứng theo từng webservice đảm bảo đủ, đúng theo yêu cầu, có trạng thái Enable = Yes, bao gồm: 42M - Mixed Payment Details 42P - Negotiation/Deferred Payment Details 44A - Place of Taking in Charge/Dispatch from .../Place of Receipt 44E - Port of Loading/Airport of Departure 44F - Port of Discharge/Airport of Destination 44B - Place of Final Destination/For Transportation to .../Place of Delivery 45B - Description of Goods and/or Services 46B - Documents Required 47B - Additional Conditions 49M - Special Payment Conditions for Beneficiary 49N - Special Payment Conditions for Bank Only 71D - Charges 71N - Amendment Charge Payable By 78K - Instructions to the Paying/Accepting/Negotiating Bank 72Z - Sender to Receiver Information | H26: Medium | I26: Manual | J26: Passed | K26: Untested | L26: Untested
A27: MT707.05 | B27: Kiểm tra điện MT707 - Webservice NAME AND ADDRESS được gán tương ứng với các trường trong điện | D27: 1. Login hệ thống TF bằng user admin 2. Truy cập theo đường dẫn Financial Services Analytical Applications Transactions Filtering/ Financial Services Sanctions Pack/ SWIFT Configuration Admin 3. Chọn điện MT707 trên drop down list 4. Sau khi bấm nút Save, click liên tiếp 2 lần button mũi tên sang phải (>) ở bên cạnh. 5. Chọn webservice NAME AND ADDRESS trên dropdown list Screening webservice trên màn hình và kiểm tra các tags tương ứng được gán | F27: Thông tin hiển thị các field, field name tương ứng theo từng webservice đảm bảo đủ, đúng theo yêu cầu, có trạng thái Enable = Yes, bao gồm: Basic Header Block - LT Identifier Application Header Input - Receiver's Address Application Header Output - Full input SWIFT address 52A - Identifier Code 52D - Name and Address 50E (Sequence A) - Non-Bank Issuer Name 50N (Sequence B) - Changed Applicant Name 59N (Sequence C) - Beneficiary Name 41A - Identifier Code 41D - Name and Address 42A - Identifier Code 42D - Name and Address 58A - Identifier Code 58D - Name and Address 53A - Identifier Code 53D - Name and Address 57A - Identifier Code 57D - Name and Address | H27: Medium | I27: Manual | J27: Passed | K27: Untested | L27: Untested
B28: Kiểm tra config các trường của điện MT710
A29: MT710.01 | B29: Kiểm tra điện MT710 - Webservice IDENTIFIER được gán tương ứng với các trường trong điện | D29: 1. Login hệ thống TF bằng user admin 2. Truy cập theo đường dẫn Financial Services Analytical Applications Transactions Filtering/ Financial Services Sanctions Pack/ SWIFT Configuration Admin 3. Chọn điện MT710 trên drop down list 4. Sau khi bấm nút Save, click liên tiếp 2 lần button mũi tên sang phải (>) ở bên cạnh. 5. Chọn webservice IDENTIFIER trên dropdown list Screening webservice trên màn hình và kiểm tra các tags tương ứng được gán | F29: Thông tin hiển thị các field, field name tương ứng theo từng webservice đảm bảo đủ, đúng theo yêu cầu, có trạng thái Enable = Yes, bao gồm: Basic Header Block - LT Identifier Application Header Input - Receiver's Address Application Header Output - Full input SWIFT address 52A - Party Identifier 52A - Identifier Code 52D - Party Identifier 51A - Party Identifier 51A - Identifier Code 41A - Identifier Code 42A - Party Identifier 42A - Identifier Code 42D - Party Identifier 58A - Party Identifier 58A - Identifier Code 58D - Party Identifier 53A - Party Identifier 53A - Identifier Code 53D - Party Identifier 57A - Party Identifier 57A - Identifier Code 57B - Party Identifier 57D - Party Identifier | H29: Medium | I29: Manual | J29: Passed | K29: Untested | L29: Untested
A30: MT710.02 | B30: Kiểm tra điện MT710 - Webservice COUNTRY AND CITY được gán tương ứng với các trường trong điện | D30: 1. Login hệ thống TF bằng user admin 2. Truy cập theo đường dẫn Financial Services Analytical Applications Transactions Filtering/ Financial Services Sanctions Pack/ SWIFT Configuration Admin 3. Chọn điện MT710 trên drop down list 4. Sau khi bấm nút Save, click liên tiếp 2 lần button mũi tên sang phải (>) ở bên cạnh. 5. Chọn webservice COUNTRY AND CITY trên dropdown list Screening webservice trên màn hình và kiểm tra các tags tương ứng được gán | F30: Thông tin hiển thị các field, field name tương ứng theo từng webservice đảm bảo đủ, đúng theo yêu cầu, có trạng thái Enable = Yes, bao gồm: Basic Header Block - LT Identifier Application Header Input - Receiver's Address Application Header Output - Full input SWIFT address 52A - Identifier Code 50W (Sequence A) - Non-Bank Issuer Country 51A - Identifier Code 50R (Sequence B) - Applicant Country 59R (Sequence C) - Beneficiary Country 41A - Identifier Code 42A - Identifier Code 58A - Identifier Code 53A - Identifier Code 57A - Identifier Code | H30: Medium | I30: Manual | J30: Passed | K30: Untested | L30: Untested
A31: MT710.03 | B31: Kiểm tra điện MT710 - Webservice PORT được gán tương ứng với các trường trong điện | D31: 1. Login hệ thống TF bằng user admin 2. Truy cập theo đường dẫn Financial Services Analytical Applications Transactions Filtering/ Financial Services Sanctions Pack/ SWIFT Configuration Admin 3. Chọn điện MT710 trên drop down list 4. Sau khi bấm nút Save, click liên tiếp 2 lần button mũi tên sang phải (>) ở bên cạnh. 5. Chọn webservice PORT trên dropdown list Screening webservice trên màn hình và kiểm tra các tags tương ứng được gán | F31: Thông tin hiển thị các field, field name tương ứng theo từng webservice đảm bảo đủ, đúng theo yêu cầu, có trạng thái Enable = Yes, bao gồm: 44A - Place of Taking in Charge/Dispatch from .../Place of Receipt 44E - Port of Loading/Airport of Departure 44F - Port of Discharge/Airport of Destination 44B - Place of Final Destination/For Transportation to .../Place of Delivery | H31: Medium | I31: Manual | J31: Passed | K31: Untested | L31: Untested
A32: MT710.04 | B32: Kiểm tra điện MT710 - Webservice NARRATIVE được gán tương ứng với các trường trong điện | D32: 1. Login hệ thống TF bằng user admin 2. Truy cập theo đường dẫn Financial Services Analytical Applications Transactions Filtering/ Financial Services Sanctions Pack/ SWIFT Configuration Admin 3. Chọn điện MT710 trên drop down list 4. Sau khi bấm nút Save, click liên tiếp 2 lần button mũi tên sang phải (>) ở bên cạnh. 5. Chọn webservice NARRATIVE trên dropdown list Screening webservice trên màn hình và kiểm tra các tags tương ứng được gán | F32: Thông tin hiển thị các field, field name tương ứng theo từng webservice đảm bảo đủ, đúng theo yêu cầu, có trạng thái Enable = Yes, bao gồm: 42M - Mixed Payment Details 42P - Negotiation/Deferred Payment Details 44A - Place of Taking in Charge/Dispatch from .../Place of Receipt 44E - Port of Loading/Airport of Departure 44F - Port of Discharge/Airport of Destination 44B - Place of Final Destination/For Transportation to .../Place of Delivery 45A - Description of Goods and/or Services 46A - Documents Required 47A - Additional Conditions 49G - Special Payment Conditions for Beneficiary 49H - Special Payment Conditions for Bank Only 71D - Charges 78K - Instructions to the Paying/Accepting/Negotiating Bank 72Z - Sender to Receiver Information | H32: Medium | I32: Manual | J32: Passed | K32: Untested | L32: Untested
A33: MT710.05 | B33: Kiểm tra điện MT710 - Webservice NAME AND ADDRESS được gán tương ứng với các trường trong điện | D33: 1. Login hệ thống TF bằng user admin 2. Truy cập theo đường dẫn Financial Services Analytical Applications Transactions Filtering/ Financial Services Sanctions Pack/ SWIFT Configuration Admin 3. Chọn điện MT710 trên drop down list 4. Sau khi bấm nút Save, click liên tiếp 2 lần button mũi tên sang phải (>) ở bên cạnh. 5. Chọn webservice NAME AND ADDRESS trên dropdown list Screening webservice trên màn hình và kiểm tra các tags tương ứng được gán | F33: Thông tin hiển thị các field, field name tương ứng theo từng webservice đảm bảo đủ, đúng theo yêu cầu, có trạng thái Enable = Yes, bao gồm: Basic Header Block - LT Identifier Application Header Input - Receiver's Address Application Header Output - Full input SWIFT address 52A - Identifier Code 52D - Name and Address 50E (Sequence A) - Non-Bank Issuer Name 51A - Identifier Code 51A - Name and Address 50N (Sequence B) - Applicant Name 59N (Sequence C) - Beneficiary Name 41A - Identifier Code 41D - Name and Address 42A - Identifier Code 42D - Name and Address 58A - Identifier Code 58D - Name and Address 53A - Identifier Code 53D - Name and Address 57A - Identifier Code 57D - Name and Address | H33: Medium | I33: Manual | J33: Passed | K33: Untested | L33: Untested
B34: Kiểm tra config các trường của điện MT720
A35: MT720.01 | B35: Kiểm tra điện MT720 - Webservice IDENTIFIER được gán tương ứng với các trường trong điện | D35: 1. Login hệ thống TF bằng user admin 2. Truy cập theo đường dẫn Financial Services Analytical Applications Transactions Filtering/ Financial Services Sanctions Pack/ SWIFT Configuration Admin 3. Chọn điện MT720 trên drop down list 4. Sau khi bấm nút Save, click liên tiếp 2 lần button mũi tên sang phải (>) ở bên cạnh. 5. Chọn webservice IDENTIFIER trên dropdown list Screening webservice trên màn hình và kiểm tra các tags tương ứng được gán | F35: Thông tin hiển thị các field, field name tương ứng theo từng webservice đảm bảo đủ, đúng theo yêu cầu, có trạng thái Enable = Yes, bao gồm: Basic Header Block - LT Identifier Application Header Input - Receiver's Address Application Header Output - Full input SWIFT address 52A - Party Identifier 52A - Identifier Code 52D - Party Identifier 41A - Identifier Code 42A - Party Identifier 42A - Identifier Code 42D - Party Identifier 58A - Party Identifier 58A - Identifier Code 58D - Party Identifier 57A - Party Identifier 57A - Identifier Code 57B - Party Identifier 57D - Party Identifier | H35: Medium | I35: Manual | J35: Passed | K35: Untested | L35: Untested
A36: MT720.02 | B36: Kiểm tra điện MT720 - Webservice COUNTRY AND CITY được gán tương ứng với các trường trong điện | D36: 1. Login hệ thống TF bằng user admin 2. Truy cập theo đường dẫn Financial Services Analytical Applications Transactions Filtering/ Financial Services Sanctions Pack/ SWIFT Configuration Admin 3. Chọn điện MT720 trên drop down list 4. Sau khi bấm nút Save, click liên tiếp 2 lần button mũi tên sang phải (>) ở bên cạnh. 5. Chọn webservice COUNTRY AND CITY trên dropdown list Screening webservice trên màn hình và kiểm tra các tags tương ứng được gán | F36: Thông tin hiển thị các field, field name tương ứng theo từng webservice đảm bảo đủ, đúng theo yêu cầu, có trạng thái Enable = Yes, bao gồm: Basic Header Block - LT Identifier Application Header Input - Receiver's Address Application Header Output - Full input SWIFT address 52A - Identifier Code 50W (Sequence A) - Non-Bank Issuer Country 50R (Sequence B) - First Beneficiary Country 59R (Sequence C) - Second Beneficiary Country 41A - Identifier Code 42A - Identifier Code 58A - Identifier Code 57A - Identifier Code | H36: Medium | I36: Manual | J36: Passed | K36: Untested | L36: Untested
A37: MT720.03 | B37: Kiểm tra điện MT720 - Webservice PORT được gán tương ứng với các trường trong điện | D37: 1. Login hệ thống TF bằng user admin 2. Truy cập theo đường dẫn Financial Services Analytical Applications Transactions Filtering/ Financial Services Sanctions Pack/ SWIFT Configuration Admin 3. Chọn điện MT720 trên drop down list 4. Sau khi bấm nút Save, click liên tiếp 2 lần button mũi tên sang phải (>) ở bên cạnh. 5. Chọn webservice PORT trên dropdown list Screening webservice trên màn hình và kiểm tra các tags tương ứng được gán | F37: Thông tin hiển thị các field, field name tương ứng theo từng webservice đảm bảo đủ, đúng theo yêu cầu, có trạng thái Enable = Yes, bao gồm: 44A - Place of Taking in Charge/Dispatch from .../Place of Receipt 44E - Port of Loading/Airport of Departure 44F - Port of Discharge/Airport of Destination 44B - Place of Final Destination/For Transportation to .../Place of Delivery | H37: Medium | I37: Manual | J37: Passed | K37: Untested | L37: Untested
A38: MT720.04 | B38: Kiểm tra điện MT720 - Webservice NARRATIVE được gán tương ứng với các trường trong điện | D38: 1. Login hệ thống TF bằng user admin 2. Truy cập theo đường dẫn Financial Services Analytical Applications Transactions Filtering/ Financial Services Sanctions Pack/ SWIFT Configuration Admin 3. Chọn điện MT720 trên drop down list 4. Sau khi bấm nút Save, click liên tiếp 2 lần button mũi tên sang phải (>) ở bên cạnh. 5. Chọn webservice NARRATIVE trên dropdown list Screening webservice trên màn hình và kiểm tra các tags tương ứng được gán | F38: Thông tin hiển thị các field, field name tương ứng theo từng webservice đảm bảo đủ, đúng theo yêu cầu, có trạng thái Enable = Yes, bao gồm: 42M - Mixed Payment Details 42P - Negotiation/Deferred Payment Details 44A - Place of Taking in Charge/Dispatch from .../Place of Receipt 44E - Port of Loading/Airport of Departure 44F - Port of Discharge/Airport of Destination 44B - Place of Final Destination/For Transportation to .../Place of Delivery 45A - Description of Goods and/or Services 46A - Documents Required 47A - Additional Conditions 49G - Special Payment Conditions for Beneficiary 49H - Special Payment Conditions for Bank Only 71D - Charges 78K - Instructions to the Paying/Accepting/Negotiating Bank 78D - Instructions from Transferring Bank 72Z - Sender to Receiver Information | H38: Medium | I38: Manual | J38: Passed | K38: Untested | L38: Untested
A39: MT720.05 | B39: Kiểm tra điện MT720 - Webservice NAME AND ADDRESS được gán tương ứng với các trường trong điện | D39: 1. Login hệ thống TF bằng user admin 2. Truy cập theo đường dẫn Financial Services Analytical Applications Transactions Filtering/ Financial Services Sanctions Pack/ SWIFT Configuration Admin 3. Chọn điện MT720 trên drop down list 4. Sau khi bấm nút Save, click liên tiếp 2 lần button mũi tên sang phải (>) ở bên cạnh. 5. Chọn webservice NAME AND ADDRESS trên dropdown list Screening webservice trên màn hình và kiểm tra các tags tương ứng được gán | F39: Thông tin hiển thị các field, field name tương ứng theo từng webservice đảm bảo đủ, đúng theo yêu cầu, có trạng thái Enable = Yes, bao gồm: Basic Header Block - LT Identifier Application Header Input - Receiver's Address Application Header Output - Full input SWIFT address 52A - Identifier Code 52D - Name and Address 50E (Sequence A) - Non-Bank Issuer Name 50N (Sequence B) - First Beneficiary Name 59N (Sequence C) - Second Beneficiary Name 41A - Identifier Code 41D - Name and Address 42A - Identifier Code 42D - Name and Address 58A - Identifier Code 58D - Name and Address 57A - Identifier Code 57D - Name and Address | H39: Medium | I39: Manual | J39: Passed | K39: Untested | L39: Untested
B40: Kiểm tra config các trường của điện MT740
A41: MT740.01 | B41: Kiểm tra điện MT740 - Webservice IDENTIFIER được gán tương ứng với các trường trong điện | D41: 1. Login hệ thống TF bằng user admin 2. Truy cập theo đường dẫn Financial Services Analytical Applications Transactions Filtering/ Financial Services Sanctions Pack/ SWIFT Configuration Admin 3. Chọn điện MT740 trên drop down list 4. Sau khi bấm nút Save, click liên tiếp 2 lần button mũi tên sang phải (>) ở bên cạnh. 5. Chọn webservice IDENTIFIER trên dropdown list Screening webservice trên màn hình và kiểm tra các tags tương ứng được gán | F41: Thông tin hiển thị các field, field name tương ứng theo từng webservice đảm bảo đủ, đúng theo yêu cầu, có trạng thái Enable = Yes, bao gồm: Basic Header Block - LT Identifier Application Header Input - Receiver's Address Application Header Output - Full input SWIFT address 58A - Party Identifier 58A - Identifier Code 58D - Party Identifier 41A - Identifier Code 42A - Party Identifier 42A - Identifier Code 42D - Party Identifier | H41: Medium | I41: Manual | J41: Passed | K41: Untested | L41: Untested
A42: MT740.02 | B42: Kiểm tra điện MT740 - Webservice COUNTRY AND CITY được gán tương ứng với các trường trong điện | D42: 1. Login hệ thống TF bằng user admin 2. Truy cập theo đường dẫn Financial Services Analytical Applications Transactions Filtering/ Financial Services Sanctions Pack/ SWIFT Configuration Admin 3. Chọn điện MT740 trên drop down list 4. Sau khi bấm nút Save, click liên tiếp 2 lần button mũi tên sang phải (>) ở bên cạnh. 5. Chọn webservice COUNTRY AND CITY trên dropdown list Screening webservice trên màn hình và kiểm tra các tags tương ứng được gán | F42: Thông tin hiển thị các field, field name tương ứng theo từng webservice đảm bảo đủ, đúng theo yêu cầu, có trạng thái Enable = Yes, bao gồm: Basic Header Block - LT Identifier Application Header Input - Receiver's Address Application Header Output - Full input SWIFT address 58A - Identifier Code 59R (Sequence A) - Beneficiary Country 41A - Identifier Code 42A - Identifier Code | H42: Medium | I42: Manual | J42: Passed | K42: Untested | L42: Untested
A43: MT740.03 | B43: Kiểm tra điện MT740 - Webservice NARRATIVE được gán tương ứng với các trường trong điện | D43: 1. Login hệ thống TF bằng user admin 2. Truy cập theo đường dẫn Financial Services Analytical Applications Transactions Filtering/ Financial Services Sanctions Pack/ SWIFT Configuration Admin 3. Chọn điện MT740 trên drop down list 4. Sau khi bấm nút Save, click liên tiếp 2 lần button mũi tên sang phải (>) ở bên cạnh. 5. Chọn webservice NARRATIVE trên dropdown list Screening webservice trên màn hình và kiểm tra các tags tương ứng được gán | F43: Thông tin hiển thị các field, field name tương ứng theo từng webservice đảm bảo đủ, đúng theo yêu cầu, có trạng thái Enable = Yes, bao gồm: 42M - Mixed Payment Details 42P - Negotiation/Deferred Payment Details 71D - Other Charges 72Z - Sender to Receiver Information | H43: Medium | I43: Manual | J43: Passed | K43: Untested | L43: Untested
...

Sheet Cấu hình chủ thể
A1: Functions | B1: Config EDQ
A2: Build Version | B2: v1.0
B4: High | C4: Medium | D4: Low | E4: Total
C5: =SUM(C6:C11) -> 42 | D5: =SUM(D6:D11) -> 0 | E5: =SUM(B5:D5) -> 42
A6: Passed | B6: =COUNTIFS($J:$J, $A$6,$H:$H,B$4) -> 0 | C6: =COUNTIFS($J:$J, $A$6,$H:$H,C$4) -> 42 | D6: =COUNTIFS($J:$J, $A$6,$H:$H,D$4) -> 0 | E6: =SUM(B6:D6) -> 42
A7: Failed | B7: =COUNTIFS($J:$J, $A$7,$H:$H,B$4) -> 0 | C7: =COUNTIFS($J:$J, $A$7,$H:$H,C$4) -> 0 | D7: =COUNTIFS($J:$J, $A$7,$H:$H,D$4) -> 0 | E7: =SUM(B7:D7) -> 0
A8: Pending | B8: =COUNTIFS($J:$J, $A$8,H:H,B$4) -> 0 | C8: =COUNTIFS($J:$J, $A$8,I:I,C$4) -> 0 | D8: =COUNTIFS($J:$J, $A$8,J:J,D$4) -> 0 | E8: =SUM(B8:D8) -> 0
A9: Untested | B9: =COUNTIFS($J:$J, $A$9,$H:$H,B$4) -> 0 | C9: =COUNTIFS($J:$J, $A$9,$H:$H,C$4) -> 0 | D9: =COUNTIFS($J:$J, $A$9,$H:$H,D$4) -> 0 | E9: =SUM(B9:D9) -> 0
A10: Cancel | B10: =COUNTIFS($J:$J, $A$10,$H:$H,B$4) -> 0 | C10: =COUNTIFS($J:$J, $A$10,$H:$H,C$4) -> 0 | D10: =COUNTIFS($J:$J, $A$10,$H:$H,D$4) -> 0 | E10: =SUM(B10:D10) -> 0
A11: Next | B11: =COUNTIFS($J:$J,$A$11,$H:$H,B$4) -> 0 | C11: =COUNTIFS($J:$J,$A$11,$H:$H,C$4) -> 0 | D11: =COUNTIFS($J:$J,$A$11,$H:$H,D$4) -> 0 | E11: =SUM(B11:D11) -> 0
A14: Test case Id | B14: Test case Title | C14: Pre-conditions | D14: Test Step | E14: Test Datas | F14: Expected result | G14: Test Environment | H14: Priority | I14: Automation Status | J14: 1st Test Results | K14: 2nd Test Results | L14: 3rd Test Results | M14: BugID | N14: Notes
B15: Kiểm tra cấu hình sàng lọc trường dữ liệu với chủ thể đối với điện MT700
A16: MT700_Config_EDQ.01 | B16: Kiểm tra các trường sàng lọc Name and Address theo chủ thể Entity | D16: 1. NSD đăng nhập EDQ Director bằng user được phân quyền 2. NSD truy cập theo đường dẫn Project/Transaction_Screening/ Reference Data/ MSB_TYPE_FOR_OBJ 3. Kiểm tra danh sách các trường được config với Type = "MT700" Webservice_Name = 1 và ENTITY = 'ENT' | F16: 3. Các trường config bao gồm: Basic Header Block Application Header - Input Application Header - Output 41A 41D 42A 42D 50N 51A 51D 53A 53D 57A 57D 58A 58D 59N | H16: Medium | I16: Manual | J16: Passed | K16: Untested | L16: Untested
A17: MT700_Config_EDQ.02 | B17: Kiểm tra các trường sàng lọc Identifier theo chủ thể Entity | D17: 1. NSD đăng nhập EDQ Director bằng user được phân quyền 2. NSD truy cập theo đường dẫn Project/Transaction_Screening/ Reference Data/ MSB_TYPE_FOR_OBJ 3. Kiểm tra danh sách các trường được config với Type = "MT700" Webservice_Name = 2 và ENTITY = 'ENT' | F17: 3. Các trường config bao gồm: Basic Header Block Application Header - Input Application Header - Output 41A 42A 42D 51A 51D 53A 53D 57A 57B 57D 58A 58D | H17: Medium | I17: Manual | J17: Passed | K17: Untested | L17: Untested
A18: MT700_Config_EDQ.03 | B18: Kiểm tra các trường sàng lọc Country | D18: 1. NSD đăng nhập EDQ Director bằng user được phân quyền 2. NSD truy cập theo đường dẫn Project/Transaction_Screening/ Reference Data/ MSB_TYPE_FOR_OBJ 3. Kiểm tra danh sách các trường được config với Type = "MT700" Webservice_Name = 3 và ENTITY = 'All' | F18: 3. Các trường config bao gồm: Basic Header Block Application Header - Input Application Header - Output 41A 42A 50R 51A 53A 57A 58A 59R | H18: Medium | I18: Manual | J18: Passed | K18: Untested | L18: Untested
A19: MT700_Config_EDQ.04 | B19: Kiểm tra các trường sàng lọc Narrative theo Stop KeyWords | D19: 1. NSD đăng nhập EDQ Director bằng user được phân quyền 2. NSD truy cập theo đường dẫn Project/Transaction_Screening/ Reference Data/ MSB_TYPE_FOR_OBJ 3. Kiểm tra danh sách các trường được config với Type = "MT700" Webservice_Name = 4 và ENTITY = 'STK' | F19: 3. Các trường config bao gồm: 45A | H19: Medium | I19: Manual | J19: Passed | K19: Untested | L19: Untested
A20: MT700_Config_EDQ.05 | B20: Kiểm tra các trường sàng lọc Narrative theo chủ thể Port | D20: 1. NSD đăng nhập EDQ Director bằng user được phân quyền 2. NSD truy cập theo đường dẫn Project/Transaction_Screening/ Reference Data/ MSB_TYPE_FOR_OBJ 3. Kiểm tra danh sách các trường được config với Type = "MT700" Webservice_Name = 4 và ENTITY = 'POR' | F20: 3. Các trường config bao gồm: 44A 44B 44E 44F | H20: Medium | I20: Manual | J20: Passed | K20: Untested | L20: Untested
A21: MT700_Config_EDQ.06 | B21: Kiểm tra các trường sàng lọc Narrative theo tất cả chủ thể | D21: 1. NSD đăng nhập EDQ Director bằng user được phân quyền 2. NSD truy cập theo đường dẫn Project/Transaction_Screening/ Reference Data/ MSB_TYPE_FOR_OBJ 3. Kiểm tra danh sách các trường được config với Type = "MT700" Webservice_Name = 4 và ENTITY = 'ALL' | F21: 3. Các trường config bao gồm: 42M 42P 46A 47A 49G 49H 71D 72Z 78K | H21: Medium | I21: Manual | J21: Passed | K21: Untested | L21: Untested
A22: MT700_Config_EDQ.07 | B22: Kiểm tra các trường sàng lọc Port | D22: 1. NSD đăng nhập EDQ Director bằng user được phân quyền 2. NSD truy cập theo đường dẫn Project/Transaction_Screening/ Reference Data/ MSB_TYPE_FOR_OBJ 3. Kiểm tra danh sách các trường được config với Type = "MT700" Webservice_Name = 5 và ENTITY = 'All' | F22: 3. Các trường config bao gồm: 44A 44B 44E 44F | H22: Medium | I22: Manual | J22: Passed | K22: Untested | L22: Untested
B23: Kiểm tra cấu hình sàng lọc trường dữ liệu với chủ thể đối với điện MT707
A24: MT707_Config_EDQ.01 | B24: Kiểm tra các trường sàng lọc Name and Address theo chủ thể Entity | D24: 1. NSD đăng nhập EDQ Director bằng user được phân quyền 2. NSD truy cập theo đường dẫn Project/Transaction_Screening/ Reference Data/ MSB_TYPE_FOR_OBJ 3. Kiểm tra danh sách các trường được config với Type = "MT707" Webservice_Name = 1 và ENTITY = 'ENT' | F24: 3. Các trường config bao gồm: Basic Header Block Application Header - Input Application Header - Output 41A 41D 42A 42D 50E 50N 52A 52D 53A 53D 57A 57D 58A 58D 59N | H24: Medium | I24: Manual | J24: Passed | K24: Untested | L24: Untested
A25: MT707_Config_EDQ.02 | B25: Kiểm tra các trường sàng lọc Identifier theo chủ thể Entity | D25: 1. NSD đăng nhập EDQ Director bằng user được phân quyền 2. NSD truy cập theo đường dẫn Project/Transaction_Screening/ Reference Data/ MSB_TYPE_FOR_OBJ 3. Kiểm tra danh sách các trường được config với Type = "MT707" Webservice_Name = 2 và ENTITY = 'ENT' | F25: 3. Các trường config bao gồm: Basic Header Block Application Header - Input Application Header - Output 41A 42A 42D 52A 52D 53A 53D 57A 57B 57D 58A 58D | H25: Medium | I25: Manual | J25: Passed | K25: Untested | L25: Untested
A26: MT707_Config_EDQ.03 | B26: Kiểm tra các trường sàng lọc Country | D26: 1. NSD đăng nhập EDQ Director bằng user được phân quyền 2. NSD truy cập theo đường dẫn Project/Transaction_Screening/ Reference Data/ MSB_TYPE_FOR_OBJ 3. Kiểm tra danh sách các trường được config với Type = "MT707" Webservice_Name = 3 và ENTITY = 'All' | F26: 3. Các trường config bao gồm: Basic Header Block Application Header - Input Application Header - Output 41A 42A 50R 50W 52A 53A 57A 58A 59R | H26: Medium | I26: Manual | J26: Passed | K26: Untested | L26: Untested
A27: MT707_Config_EDQ.04 | B27: Kiểm tra các trường sàng lọc Narrative theo Stop KeyWords | D27: 1. NSD đăng nhập EDQ Director bằng user được phân quyền 2. NSD truy cập theo đường dẫn Project/Transaction_Screening/ Reference Data/ MSB_TYPE_FOR_OBJ 3. Kiểm tra danh sách các trường được config với Type = "MT707" Webservice_Name = 4 và ENTITY = 'STK' | F27: 3. Các trường config bao gồm: 45B | H27: Medium | I27: Manual | J27: Passed | K27: Untested | L27: Untested
A28: MT707_Config_EDQ.05 | B28: Kiểm tra các trường sàng lọc Narrative theo chủ thể Port | D28: 1. NSD đăng nhập EDQ Director bằng user được phân quyền 2. NSD truy cập theo đường dẫn Project/Transaction_Screening/ Reference Data/ MSB_TYPE_FOR_OBJ 3. Kiểm tra danh sách các trường được config với Type = "MT707" Webservice_Name = 4 và ENTITY = 'POR' | F28: 3. Các trường config bao gồm: 44A 44B 44E 44F | H28: Medium | I28: Manual | J28: Passed | K28: Untested | L28: Untested
A29: MT707_Config_EDQ.06 | B29: Kiểm tra các trường sàng lọc Narrative theo tất cả chủ thể | D29: 1. NSD đăng nhập EDQ Director bằng user được phân quyền 2. NSD truy cập theo đường dẫn Project/Transaction_Screening/ Reference Data/ MSB_TYPE_FOR_OBJ 3. Kiểm tra danh sách các trường được config với Type = "MT707" Webservice_Name = 4 và ENTITY = 'ALL' | F29: 3. Các trường config bao gồm: 42M 42P 46B 47B 49M 49N 71D 71N 72Z 78K | H29: Medium | I29: Manual | J29: Passed | K29: Untested | L29: Untested
A30: MT707_Config_EDQ.07 | B30: Kiểm tra các trường sàng lọc Port | D30: 1. NSD đăng nhập EDQ Director bằng user được phân quyền 2. NSD truy cập theo đường dẫn Project/Transaction_Screening/ Reference Data/ MSB_TYPE_FOR_OBJ 3. Kiểm tra danh sách các trường được config với Type = "MT707" Webservice_Name = 5 và ENTITY = 'All' | F30: 3. Các trường config bao gồm: 44A 44B 44E 44F | H30: Medium | I30: Manual | J30: Passed | K30: Untested | L30: Untested
B31: Kiểm tra cấu hình sàng lọc trường dữ liệu với chủ thể đối với điện MT710
A32: MT710_Config_EDQ.01 | B32: Kiểm tra các trường sàng lọc Name and Address theo chủ thể Entity | D32: 1. NSD đăng nhập EDQ Director bằng user được phân quyền 2. NSD truy cập theo đường dẫn Project/Transaction_Screening/ Reference Data/ MSB_TYPE_FOR_OBJ 3. Kiểm tra danh sách các trường được config với Type = "MT710" Webservice_Name = 1 và ENTITY = 'ENT' | F32: 3. Các trường config bao gồm: Basic Header Block Application Header - Input Application Header - Output 41A 41D 42A 42D 50E 50N 51A 51D 52A 52D 53A 53D 57A 57D 58A 58D 59N | H32: Medium | I32: Manual | J32: Passed | K32: Untested | L32: Untested
A33: MT710_Config_EDQ.02 | B33: Kiểm tra các trường sàng lọc Identifier theo chủ thể Entity | D33: 1. NSD đăng nhập EDQ Director bằng user được phân quyền 2. NSD truy cập theo đường dẫn Project/Transaction_Screening/ Reference Data/ MSB_TYPE_FOR_OBJ 3. Kiểm tra danh sách các trường được config với Type = "MT710" Webservice_Name = 2 và ENTITY = 'ENT' | F33: 3. Các trường config bao gồm: Basic Header Block Application Header - Input Application Header - Output 41A 42A 42D 51A 51D 52A 52D 53A 53D 57A 57B 57D 58A 58D | H33: Medium | I33: Manual | J33: Passed | K33: Untested | L33: Untested
A34: MT710_Config_EDQ.03 | B34: Kiểm tra các trường sàng lọc Country | D34: 1. NSD đăng nhập EDQ Director bằng user được phân quyền 2. NSD truy cập theo đường dẫn Project/Transaction_Screening/ Reference Data/ MSB_TYPE_FOR_OBJ 3. Kiểm tra danh sách các trường được config với Type = "MT710" Webservice_Name = 3 và ENTITY = 'All' | F34: 3. Các trường config bao gồm: Basic Header Block Application Header - Input Application Header - Output 41A 42A 50R 50W 51A 52A 53A 57A 58A 59R | H34: Medium | I34: Manual | J34: Passed | K34: Untested | L34: Untested
A35: MT710_Config_EDQ.04 | B35: Kiểm tra các trường sàng lọc Narrative theo Stop KeyWords | D35: 1. NSD đăng nhập EDQ Director bằng user được phân quyền 2. NSD truy cập theo đường dẫn Project/Transaction_Screening/ Reference Data/ MSB_TYPE_FOR_OBJ 3. Kiểm tra danh sách các trường được config với Type = "MT710" Webservice_Name = 4 và ENTITY = 'STK' | F35: 3. Các trường config bao gồm: 45A | H35: Medium | I35: Manual | J35: Passed | K35: Untested | L35: Untested
A36: MT710_Config_EDQ.05 | B36: Kiểm tra các trường sàng lọc Narrative theo chủ thể Port | D36: 1. NSD đăng nhập EDQ Director bằng user được phân quyền 2. NSD truy cập theo đường dẫn Project/Transaction_Screening/ Reference Data/ MSB_TYPE_FOR_OBJ 3. Kiểm tra danh sách các trường được config với Type = "MT710" Webservice_Name = 4 và ENTITY = 'POR' | F36: 3. Các trường config bao gồm: 44A 44B 44E 44F | H36: Medium | I36: Manual | J36: Passed | K36: Untested | L36: Untested
A37: MT710_Config_EDQ.06 | B37: Kiểm tra các trường sàng lọc Narrative theo tất cả chủ thể | D37: 1. NSD đăng nhập EDQ Director bằng user được phân quyền 2. NSD truy cập theo đường dẫn Project/Transaction_Screening/ Reference Data/ MSB_TYPE_FOR_OBJ 3. Kiểm tra danh sách các trường được config với Type = "MT710" Webservice_Name = 4 và ENTITY = 'ALL' | F37: 3. Các trường config bao gồm: 42M 42P 46A 47A 49G 49H 71D 72Z 78D 78K | H37: Medium | I37: Manual | J37: Passed | K37: Untested | L37: Untested
A38: MT710_Config_EDQ.07 | B38: Kiểm tra các trường sàng lọc Port | D38: 1. NSD đăng nhập EDQ Director bằng user được phân quyền 2. NSD truy cập theo đường dẫn Project/Transaction_Screening/ Reference Data/ MSB_TYPE_FOR_OBJ 3. Kiểm tra danh sách các trường được config với Type = "MT710" Webservice_Name = 5 và ENTITY = 'All' | F38: 3. Các trường config bao gồm: 44A 44B 44E 44F | H38: Medium | I38: Manual | J38: Passed | K38: Untested | L38: Untested
B39: Kiểm tra cấu hình sàng lọc trường dữ liệu với chủ thể đối với điện MT720
A40: MT720_Config_EDQ.01 | B40: Kiểm tra các trường sàng lọc Name and Address theo chủ thể Entity | D40: 1. NSD đăng nhập EDQ Director bằng user được phân quyền 2. NSD truy cập theo đường dẫn Project/Transaction_Screening/ Reference Data/ MSB_TYPE_FOR_OBJ 3. Kiểm tra danh sách các trường được config với Type = "MT720" Webservice_Name = 1 và ENTITY = 'ENT' | F40: 3. Các trường config bao gồm: Basic Header Block Application Header - Input Application Header - Output 41A 41D 42A 42D 50E 50N 52A 52D 57A 57D 58A 58D 59N | H40: Medium | I40: Manual | J40: Passed | K40: Untested | L40: Untested
A41: MT720_Config_EDQ.02 | B41: Kiểm tra các trường sàng lọc Identifier theo chủ thể Entity | D41: 1. NSD đăng nhập EDQ Director bằng user được phân quyền 2. NSD truy cập theo đường dẫn Project/Transaction_Screening/ Reference Data/ MSB_TYPE_FOR_OBJ 3. Kiểm tra danh sách các trường được config với Type = "MT720" Webservice_Name = 2 và ENTITY = 'ENT' | F41: 3. Các trường config bao gồm: Basic Header Block Application Header - Input Application Header - Output 41A 42A 42D 52A 52D 57A 57B 57D 58A 58D | H41: Medium | I41: Manual | J41: Passed | K41: Untested | L41: Untested
A42: MT720_Config_EDQ.03 | B42: Kiểm tra các trường sàng lọc Country | D42: 1. NSD đăng nhập EDQ Director bằng user được phân quyền 2. NSD truy cập theo đường dẫn Project/Transaction_Screening/ Reference Data/ MSB_TYPE_FOR_OBJ 3. Kiểm tra danh sách các trường được config với Type = "MT720" Webservice_Name = 3 và ENTITY = 'All' | F42: 3. Các trường config bao gồm: Basic Header Block Application Header - Input Application Header - Output 41A 42A 50R 50W 52A 57A 58A 59R | H42: Medium | I42: Manual | J42: Passed | K42: Untested | L42: Untested
A43: MT720_Config_EDQ.04 | B43: Kiểm tra các trường sàng lọc Narrative theo Stop KeyWords | D43: 1. NSD đăng nhập EDQ Director bằng user được phân quyền 2. NSD truy cập theo đường dẫn Project/Transaction_Screening/ Reference Data/ MSB_TYPE_FOR_OBJ 3. Kiểm tra danh sách các trường được config với Type = "MT720" Webservice_Name = 4 và ENTITY = 'STK' | F43: 3. Các trường config bao gồm: 45A | H43: Medium | I43: Manual | J43: Passed | K43: Untested | L43: Untested
...

Sheet Sàng lọc điện
A1: Functions | B1: Sàng lọc giao dịch (Tổng hợp MT + MX)
A2: Build Version | B2: v1.0
A4: Trạng thái | B4: High | C4: Medium | D4: Low | E4: Total
A5: Total | B5: =COUNTIFS($I$14:$I$80,"High") -> 60 | C5: =COUNTIFS($I$14:$I$80,"Medium") -> 0 | D5: =COUNTIFS($I$14:$I$80,"Low") -> 0 | E5: =SUM(B5:D5) -> 60
A6: Passed | B6: =COUNTIFS($K$14:$K$80,$A$6,$I$14:$I$80,"High") -> 8 | C6: =COUNTIFS($K$14:$K$80,$A$6,$I$14:$I$80,"Medium") -> 0 | D6: =COUNTIFS($K$14:$K$80,$A$6,$I$14:$I$80,"Low") -> 0 | E6: =SUM(B6:D6) -> 8 | L6: 10
A7: Failed | B7: =COUNTIFS($K$14:$K$80,$A$7,$I$14:$I$80,"High") -> 0 | C7: =COUNTIFS($K$14:$K$80,$A$7,$I$14:$I$80,"Medium") -> 0 | D7: =COUNTIFS($K$14:$K$80,$A$7,$I$14:$I$80,"Low") -> 0 | E7: =SUM(B7:D7) -> 0 | L7: 5
A8: Untested | B8: =COUNTIFS($K$14:$K$80,$A$8,$I$14:$I$80,"High") -> 52 | C8: =COUNTIFS($K$14:$K$80,$A$8,$I$14:$I$80,"Medium") -> 0 | D8: =COUNTIFS($K$14:$K$80,$A$8,$I$14:$I$80,"Low") -> 0 | E8: =SUM(B8:D8) -> 52 | L8: 115
A9: Cancel | B9: =COUNTIFS($K$14:$K$80,$A$9,$I$14:$I$80,"High") -> 0 | C9: =COUNTIFS($K$14:$K$80,$A$9,$I$14:$I$80,"Medium") -> 0 | D9: =COUNTIFS($K$14:$K$80,$A$9,$I$14:$I$80,"Low") -> 0 | E9: =SUM(B9:D9) -> 0
A10: Next | B10: =COUNTIFS($K$14:$K$80,$A$10,$I$14:$I$80,"High") -> 0 | C10: =COUNTIFS($K$14:$K$80,$A$10,$I$14:$I$80,"High") -> 0 | D10: =COUNTIFS($K$14:$K$80,$A$10,$I$14:$I$80,"High") -> 0 | E10: =COUNTIFS($K$14:$K$80,$A$10,$I$14:$I$80,"High") -> 0
A11: Pending | B11: =COUNTIFS($K$14:$K$80,$A$11,$I$14:$I$80,"High") -> 0 | C11: =COUNTIFS($K$14:$K$80,$A$11,$I$14:$I$80,"Medium") -> 0 | D11: =COUNTIFS($K$14:$K$80,$A$11,$I$14:$I$80,"Low") -> 0 | E11: =SUM(B11:D11) -> 0
A13: Loại điện | B13: Test case Id | C13: Test case Title | D13: Pre-conditions | E13: Test Step | F13: Test Datas | G13: Expected result | H13: Test Environment | I13: Priority | J13: Automation Status | K13: 1st Test Results | L13: 2nd Test Results | M13: 3rd Test Result | N13: BugID | O13: Notes
A14: Sàng lọc giao dịch MT 700
A15: MT700 | B15: MT700.01 | C15: Sàng lọc giao dịch MT 700 - Identifier, Name and Address, Country and City - Entity | E15: 1. Đẩy giao dịch vào API Post Message với trường thông tin Basic Header Block, Application Header - Input, 51A, 41A, 42A, 58A, 53A, 57A có dữ liệu nằm trong các danh sách theo dõi <Link URL hệ thống AML ở môi trường SIT> Path: transaction-screening/v1/transaction-screening Method: POST Request Header: Authorization: Basic Auth (Username and password to login to application) Content-Type: text/plain Accept: */* Request Body: cột Test Datas 2. Kiểm tra thông tin Event của giao dịch theo đường dẫn Financial Services Analytical Applications Transactions Filtering > Financial services Sanctions Pack > Transaction Filtering Alert List Chọn Filter, nhập thông tin tìm kiếm theo AlertID, nhấn <Search> Click mã AlertID và kiểm tra các thông tin Hoặc kiểm tra các thông tin trong file kết quả truy vấn Database | F15: {1:F01BFICCUHHAXXX0000000000} {2:I700BFICCUHHXXXXN} {3:{108:MT700TEST0001}} {4: :27:1/1 :40A:IRREVOCABLE :20:DCI2607240001 :31C:260415 :40E:UCP LATEST VERSION :31D:261231SINGAPORE :51A:BFICCUHH :50N:MEKONG TRADING JOINT STOCK CO :50S:12 NGUYEN HUE STREET :50T:HO CHI MINH CITY :50R:VN :59N:SUNRISE IMPORT EXPORT PTE LTD :59S:18 MARINA BOULEVARD :59T:SINGAPORE :59R:SG :32B:USD50000, :41A:BFICCUHH7 BY PAYMENT :42C:AT SIGHT :42A:BFICCUHH :49:WITHOUT :58A:BFICCUHH :53A:BFICCUHH :57A:BFICCUHH -}{5:{MAC:00000000}{CHK:1A2B3C4D5E6F}} | G15: 2. Hệ thống trả kết quả: HIT với Webservice Identifier, Name and Address, Country and City loại chủ thể Entity; đồng thời HIT danh sách Quốc gia Knock-out (quốc gia cấm vận) và không HIT với chủ thể Individual, Vessel, Aircraft Câu query kiểm tra kết quả (KET_QUA = HIT): SELECT CASE WHEN COUNT(*) = 3 THEN 'HIT' ELSE 'NO HIT' END AS KET_QUA FROM ( SELECT T.N_WEBSERVICE_ID FROM FSI_RT_AL_WLS_RESPONSE T WHERE T.N_GRP_MSG_ID = :N_GRP_MSG_ID AND T.N_WEBSERVICE_ID IN (1, 2, 3) AND T.V_TAG_NAME IN ( 'Basic Header Block', 'Application Header - Input', '51A', '41A', '42A', '58A', '53A', '57A' ) GROUP BY T.N_WEBSERVICE_ID HAVING COUNT(DISTINCT T.V_TAG_NAME) = 8 AND COUNT(CASE WHEN UPPER(NVL(T.V_MATCHED_TYPE,DECODE(T.V_MATCHED_LIST_NAME,'Blacklisted Country','ENTITY','N/A'))) = 'ENTITY' THEN 1 END) > 0 AND COUNT(CASE WHEN UPPER(T.V_MATCHED_TYPE) = 'INDIVIDUAL' THEN 1 END) = 0 AND COUNT(CASE WHEN UPPER(T.V_MATCHED_TYPE) = 'VESSEL' THEN 1 END) = 0 AND COUNT(CASE WHEN UPPER(T.V_MATCHED_TYPE) = 'AIRCRAFT' THEN 1 END) = 0 ); | I15: High | J15: Manual | K15: Untested | L15: Untested | M15: Untested | O15: Nhóm tag quét giống nhau (Identifier, Name and Address, Country and City - Entity): Basic Header Block, Application Header - Input, 51A, 41A, 42A, 58A, 53A, 57A
A16: MT700 | B16: MT700.02 | C16: Sàng lọc giao dịch MT 700 - Identifier, Name and Address, Country and City - Entity | E16: 1. Đẩy giao dịch vào API Post Message với trường thông tin Application Header - Output có dữ liệu nằm trong các danh sách theo dõi <Link URL hệ thống AML ở môi trường SIT> Path: transaction-screening/v1/transaction-screening Method: POST Request Header: Authorization: Basic Auth (Username and password to login to application) Content-Type: text/plain Accept: */* Request Body: cột Test Datas 2. Kiểm tra thông tin Event của giao dịch theo đường dẫn Financial Services Analytical Applications Transactions Filtering > Financial services Sanctions Pack > Transaction Filtering Alert List Chọn Filter, nhập thông tin tìm kiếm theo AlertID, nhấn <Search> Click mã AlertID và kiểm tra các thông tin Hoặc kiểm tra các thông tin trong file kết quả truy vấn Database | F16: {1:F01MCOBVNVXAXXX0000000000} {2:O7001201260724BFICCUHHAXXX00010000012607241201N} {3:{108:MT700TEST0008}} {4: :27:1/1 :40A:IRREVOCABLE :20:DCI2607240008 :31C:260415 :40E:UCP LATEST VERSION :31D:261231SINGAPORE :51A:SCBLSGSG :50N:MEKONG TRADING JOINT STOCK CO :50S:12 NGUYEN HUE STREET :50T:HO CHI MINH CITY :50R:VN :59N:SUNRISE IMPORT EXPORT PTE LTD :59S:18 MARINA BOULEVARD :59T:SINGAPORE :59R:SG :32B:USD50000, :41A:SCBLSGSG BY PAYMENT :42C:AT SIGHT :42A:SCBLSGSG :49:WITHOUT :58A:SCBLSGSG :53A:SCBLSGSG :57A:SCBLSGSG -}{5:{MAC:00000000}{CHK:1A2B3C4D5E6F}} | G16: 2. Hệ thống trả kết quả: HIT với Webservice Identifier, Name and Address, Country and City loại chủ thể Entity; đồng thời HIT danh sách Quốc gia Knock-out (quốc gia cấm vận) và không HIT với chủ thể Individual, Vessel, Aircraft Câu query kiểm tra kết quả (KET_QUA = HIT): SELECT CASE WHEN COUNT(*) = 3 THEN 'HIT' ELSE 'NO HIT' END AS KET_QUA FROM ( SELECT T.N_WEBSERVICE_ID FROM FSI_RT_AL_WLS_RESPONSE T WHERE T.N_GRP_MSG_ID = :N_GRP_MSG_ID AND T.N_WEBSERVICE_ID IN (1, 2, 3) AND T.V_TAG_NAME = 'Application Header - Output' GROUP BY T.N_WEBSERVICE_ID HAVING COUNT(DISTINCT T.V_TAG_NAME) = 1 AND COUNT(CASE WHEN UPPER(NVL(T.V_MATCHED_TYPE,DECODE(T.V_MATCHED_LIST_NAME,'Blacklisted Country','ENTITY','N/A'))) = 'ENTITY' THEN 1 END) > 0 AND COUNT(CASE WHEN UPPER(T.V_MATCHED_TYPE) = 'INDIVIDUAL' THEN 1 END) = 0 AND COUNT(CASE WHEN UPPER(T.V_MATCHED_TYPE) = 'VESSEL' THEN 1 END) = 0 AND COUNT(CASE WHEN UPPER(T.V_MATCHED_TYPE) = 'AIRCRAFT' THEN 1 END) = 0 ); | I16: High | J16: Manual | K16: Untested | L16: Untested | M16: Untested | O16: Nhóm tag quét giống nhau (Identifier, Name and Address, Country and City - Entity): Application Header - Output
A17: MT700 | B17: MT700.03 | C17: Sàng lọc giao dịch MT 700 - Name and Address - Entity | E17: 1. Đẩy giao dịch vào API Post Message với trường thông tin 51D, 50N, 59N, 41D, 42D, 58D, 53D, 57D có dữ liệu nằm trong các danh sách theo dõi <Link URL hệ thống AML ở môi trường SIT> Path: transaction-screening/v1/transaction-screening Method: POST Request Header: Authorization: Basic Auth (Username and password to login to application) Content-Type: text/plain Accept: */* Request Body: cột Test Datas 2. Kiểm tra thông tin Event của giao dịch theo đường dẫn Financial Services Analytical Applications Transactions Filtering > Financial services Sanctions Pack > Transaction Filtering Alert List Chọn Filter, nhập thông tin tìm kiếm theo AlertID, nhấn <Search> Click mã AlertID và kiểm tra các thông tin Hoặc kiểm tra các thông tin trong file kết quả truy vấn Database | F17: {1:F01SCBLSGSGAXXX0000000000} {2:I700MCOBVNVXXXXXN} {3:{108:MT700TEST0002}} {4: :27:1/1 :40A:IRREVOCABLE :20:DCI2607240002 :31C:260415 :40E:UCP LATEST VERSION :31D:261231SINGAPORE :51D:SUMMIT EMBER :50N:SUMMIT EMBER :50S:12 NGUYEN HUE STREET :50T:HO CHI MINH CITY :50R:IR :59N:SUMMIT EMBER :59S:18 MARINA BOULEVARD :59T:SINGAPORE :59R:IR :32B:USD50000, :41D:SUMMIT EMBER BY PAYMENT :42C:AT SIGHT :42D:SUMMIT EMBER :49:WITHOUT :58D:SUMMIT EMBER :53D:SUMMIT EMBER :57D:SUMMIT EMBER -}{5:{MAC:00000000}{CHK:1A2B3C4D5E6F}} | G17: 2. Hệ thống trả kết quả: HIT với Webservice Name and Address loại chủ thể Entity và không HIT với chủ thể Individual, Vessel, Aircraft Và tag 50N, 59N HIT với rule [E001C] Part-standardized name exact, country Câu query kiểm tra kết quả (KET_QUA = HIT): SELECT CASE WHEN COUNT(*) = 8 THEN 'HIT' ELSE 'NO HIT' END AS KET_QUA FROM ( SELECT T.V_TAG_NAME FROM FSI_RT_AL_WLS_RESPONSE T WHERE T.N_GRP_MSG_ID = :N_GRP_MSG_ID AND T.N_WEBSERVICE_ID = 1 AND T.V_TAG_NAME IN ('51D', '50N(Sequence A)', '59N(Sequence B)', '41D', '42D', '58D', '53D', '57D') GROUP BY T.V_TAG_NAME HAVING COUNT(CASE WHEN UPPER(T.V_MATCHED_TYPE) = 'ENTITY' THEN 1 END) > 0 AND COUNT(CASE WHEN UPPER(T.V_MATCHED_TYPE) = 'INDIVIDUAL' THEN 1 END) = 0 AND COUNT(CASE WHEN UPPER(T.V_MATCHED_TYPE) = 'VESSEL' THEN 1 END) = 0 AND COUNT(CASE WHEN UPPER(T.V_MATCHED_TYPE) = 'AIRCRAFT' THEN 1 END) = 0 AND COUNT(CASEWHEN T.V_TAG_NAME = '50N(Sequence A)' AND UPPER(TRIM(T.V_RULE_NAME)) LIKE '%E001C%' THEN END ) > 0 AND COUNT( CASE WHEN T.V_TAG_NAME = '59N(Sequence B)' AND UPPER(TRIM(T.V_RULE_NAME)) LIKE '%E001C%' THEN 1 END) > 0 ); | I17: High | J17: Manual | K17: Untested | L17: Untested | M17: Untested | O17: Nhóm tag quét giống nhau (Name and Address - Entity): 51D, 50N, 59N, 41D, 42D, 58D, 53D, 57D | P17: Update testdata các tag có đuôi R thành IR và Expected result thêm tag 50N, 59N HIT với rule [E001C] Part-standardized name exact, country sau đó thêm điều kiện cho câu query
A18: MT700 | B18: MT700.04 | C18: Sàng lọc giao dịch MT 700 - Identifier - Entity | E18: 1. Đẩy giao dịch vào API Post Message với trường thông tin 51A, 42A, 58A, 53A, 57A có dữ liệu nằm trong các danh sách theo dõi <Link URL hệ thống AML ở môi trường SIT> Path: transaction-screening/v1/transaction-screening Method: POST Request Header: Authorization: Basic Auth (Username and password to login to application) Content-Type: text/plain Accept: */* Request Body: cột Test Datas 2. Kiểm tra thông tin Event của giao dịch theo đường dẫn Financial Services Analytical Applications Transactions Filtering > Financial services Sanctions Pack > Transaction Filtering Alert List Chọn Filter, nhập thông tin tìm kiếm theo AlertID, nhấn <Search> Click mã AlertID và kiểm tra các thông tin Hoặc kiểm tra các thông tin trong file kết quả truy vấn Database | F18: {1:F01SCBLSGSGAXXX0000000000} {2:I700MCOBVNVXXXXXN} {3:{108:MT700TEST0003}} {4: :27:1/1 :40A:IRREVOCABLE :20:DCI2607240003 :31C:260415 :40E:UCP LATEST VERSION :31D:261231SINGAPORE :51A:/BFICCUHH SCBLSGSG :50N:MEKONG TRADING JOINT STOCK CO :50S:12 NGUYEN HUE STREET :50T:HO CHI MINH CITY :50R:VN :59N:SUNRISE IMPORT EXPORT PTE LTD :59S:18 MARINA BOULEVARD :59T:SINGAPORE :59R:SG :32B:USD50000, :41A:SCBLSGSG BY PAYMENT :42C:AT SIGHT :42A:/BFICCUHH SCBLSGSG :49:WITHOUT :58A:/BFICCUHH SCBLSGSG :53A:/BFICCUHH SCBLSGSG :57A:/BFICCUHH SCBLSGSG -}{5:{MAC:00000000}{CHK:1A2B3C4D5E6F}} | G18: 2. Hệ thống trả kết quả: HIT với Webservice Identifier loại chủ thể Entity và không HIT với chủ thể Individual, Vessel, Aircraft, Port Câu query kiểm tra kết quả (KET_QUA = HIT): SELECT CASE WHEN COUNT(*) = 5 THEN 'HIT' ELSE 'NO HIT' END AS KET_QUA FROM ( SELECT T.V_TAG_NAME FROM FSI_RT_AL_WLS_RESPONSE T WHERE T.N_GRP_MSG_ID = :N_GRP_MSG_ID AND T.N_WEBSERVICE_ID = 2 AND T.V_TAG_NAME IN ('51A', '42A', '58A', '53A', '57A') GROUP BY T.V_TAG_NAME HAVING COUNT(CASE WHEN UPPER(T.V_MATCHED_TYPE) = 'ENTITY' THEN 1 END) > 0 AND COUNT(CASE WHEN UPPER(T.V_MATCHED_TYPE) = 'INDIVIDUAL' THEN 1 END) = 0 AND COUNT(CASE WHEN UPPER(T.V_MATCHED_TYPE) = 'VESSEL' THEN 1 END) = 0 AND COUNT(CASE WHEN UPPER(T.V_MATCHED_TYPE) = 'AIRCRAFT' THEN 1 END) = 0 AND COUNT(CASE WHEN UPPER(T.V_MATCHED_TYPE) = 'PORT' THEN 1 END) = 0 ); | I18: High | J18: Manual | K18: Untested | L18: Untested | M18: Untested | O18: Nhóm tag quét giống nhau (Identifier - Entity): 51A, 42A, 58A, 53A, 57A
